Workbook

Sheet cRIO-9024 Benchmark
A1: LV RT 2013 cRIO Single-Point Benchmark Results (Hz)
A2: cRIO-9024, LV RT 2013.1a4, NI-RIO 13.0.0d114 (9205/9264) - 2min settling time - Isolated Network, REBOOT before each test
A3: Test | D3: Number of Channels, Rate (Hz) | J3: Number of Channels, Period (uS)
A4: Acronym | B4: Description | C4: I/O Mode | D4: 1 | E4: 4 | F4: 16 | G4: 32 | H4: 64 | I4: 80 | J4: 1 | K4: 4 | L4: 16 | M4: 32 | N4: 64 | O4: 80
A5: T1a | B5: AI / AO | C5: Polling | D5: 73726 | E5: 26141 | F5: 6947 | G5: 3508 | H5: 3140 | I5: 2373 | J5: =(1/D5)*1000000 -> 13.563736 | K5: =(1/E5)*1000000 -> 38.254084 | L5: =(1/F5)*1000000 -> 143.94703 | M5: =(1/G5)*1000000 -> 285.06271 | N5: =(1/H5)*1000000 -> 318.47134 | O5: =(1/I5)*1000000 -> 421.4075
A6: T1b | B6: AI / AO | C6: Interrupts | D6: 28363 | E6: 15816 | F6: 5304 | G6: 2888 | H6: 2529 | I6: 2352 | J6: =(1/D6)*1000000 -> 35.257201 | K6: =(1/E6)*1000000 -> 63.227112 | L6: =(1/F6)*1000000 -> 188.53695 | M6: =(1/G6)*1000000 -> 346.26039 | N6: =(1/H6)*1000000 -> 395.41321 | O6: =(1/I6)*1000000 -> 425.17007
A7: T2a | B7: AI/PID/AO | C7: Polling | D7: 68123 | E7: 22299 | F7: 6281 | G7: 3112 | H7: 2315 | I7: 2084 | J7: =(1/D7)*1000000 -> 14.67933 | K7: =(1/E7)*1000000 -> 44.84506 | L7: =(1/F7)*1000000 -> 159.21032 | M7: =(1/G7)*1000000 -> 321.33676 | N7: =(1/H7)*1000000 -> 431.96544 | O7: =(1/I7)*1000000 -> 479.84645
A8: T2b | B8: AI/PID/AO | C8: Interrupts | D8: 20602 | E8: 11334 | F8: 4474 | G8: 2469 | H8: 2014 | I8: 1816 | J8: =(1/D8)*1000000 -> 48.538977 | K8: =(1/E8)*1000000 -> 88.230104 | L8: =(1/F8)*1000000 -> 223.51363 | M8: =(1/G8)*1000000 -> 405.02228 | N8: =(1/H8)*1000000 -> 496.52433 | O8: =(1/I8)*1000000 -> 550.66079
A9: T3 | B9: AI/AO/Local Logging | C9: Interrupts | D9: 17450 | E9: 10095 | F9: 4134 | G9: 2524 | H9: 2159 | I9: 2001 | J9: =(1/D9)*1000000 -> 57.30659 | K9: =(1/E9)*1000000 -> 99.05894 | L9: =(1/F9)*1000000 -> 241.89647 | M9: =(1/G9)*1000000 -> 396.19651 | N9: =(1/H9)*1000000 -> 463.1774 | O9: =(1/I9)*1000000 -> 499.75012
A10: T4 | B10: AI/AO/Host Comm. | C10: Interrupts | D10: 15550 | E10: 9624 | F10: 4257 | G10: 2488 | H10: 2159 | I10: 2031 | J10: =(1/D10)*1000000 -> 64.308682 | K10: =(1/E10)*1000000 -> 103.9069 | L10: =(1/F10)*1000000 -> 234.90721 | M10: =(1/G10)*1000000 -> 401.92926 | N10: =(1/H10)*1000000 -> 463.1774 | O10: =(1/I10)*1000000 -> 492.36829

Sheet Proto 2013
A1: LV RT 2013 cRIO Single-Point Benchmark Results (Hz) | Q1: Max Numbers
A2: cRIO-9068 (red board), LV RT 2013b11, NI-RIO 13.0.0d174 (9205/9264)
A3: Test | D3: Number of Channels, Rate (Hz) | J3: Number of Channels, Period (uS) | Q3: Test | T3: Number of Channels, Rate (Hz) | Z3: Number of Channels, Period (uS)
A4: Acronym | B4: Description | C4: I/O Mode | D4: 1 | E4: 4 | F4: 16 | G4: 32 | H4: 64 | I4: 80 | J4: 1 | K4: 4 | L4: 16 | M4: 32 | N4: 64 | O4: 80 | Q4: Acronym | R4: Description | S4: I/O Mode | T4: 1 | U4: 4 | V4: 16 | W4: 32 | X4: 64 | Y4: 80 | Z4: 1 | AA4: 4 | AB4: 16 | AC4: 32 | AD4: 64 | AE4: 80
A5: T1a | B5: AI / AO | C5: Polling | D5: 38628 | E5: 21650 | F5: 6505 | J5: =IF(D5="","",(1/D5)*1000000) -> 25.887957 | K5: =IF(E5="","",(1/E5)*1000000) -> 46.189376 | L5: =IF(F5="","",(1/F5)*1000000) -> 153.7279 | M5: =IF(G5="","",(1/G5)*1000000) | N5: =IF(H5="","",(1/H5)*1000000) | O5: =IF(I5="","",(1/I5)*1000000) | Q5: T1a | R5: AI / AO | S5: Polling | T5: 48469 | U5: 21759 | V5: 6538 | Z5: =IF(T5="","",(1/T5)*1000000) -> 20.631744 | AA5: =IF(U5="","",(1/U5)*1000000) -> 45.957994 | AB5: =IF(V5="","",(1/V5)*1000000) -> 152.95197 | AC5: =IF(W5="","",(1/W5)*1000000) | AD5: =IF(X5="","",(1/X5)*1000000) | AE5: =IF(Y5="","",(1/Y5)*1000000)
A6: T1b | B6: AI / AO | C6: Interrupts | D6: 9958 | E6: 7893 | F6: 4162 | J6: =IF(D6="","",(1/D6)*1000000) -> 100.42177 | K6: =IF(E6="","",(1/E6)*1000000) -> 126.69454 | L6: =IF(F6="","",(1/F6)*1000000) -> 240.2691 | M6: =IF(G6="","",(1/G6)*1000000) | N6: =IF(H6="","",(1/H6)*1000000) | O6: =IF(I6="","",(1/I6)*1000000) | Q6: T1b | R6: AI / AO | S6: Interrupts | T6: 9975 | U6: 8323 | V6: 4267 | Z6: =IF(T6="","",(1/T6)*1000000) -> 100.25063 | AA6: =IF(U6="","",(1/U6)*1000000) -> 120.14898 | AB6: =IF(V6="","",(1/V6)*1000000) -> 234.35669 | AC6: =IF(W6="","",(1/W6)*1000000) | AD6: =IF(X6="","",(1/X6)*1000000) | AE6: =IF(Y6="","",(1/Y6)*1000000)
A7: T2a | B7: AI/PID/AO | C7: Polling | D7: 42589 | E7: 12740 | F7: 4852 | J7: =IF(D7="","",(1/D7)*1000000) -> 23.480241 | K7: =IF(E7="","",(1/E7)*1000000) -> 78.492936 | L7: =IF(F7="","",(1/F7)*1000000) -> 206.10058 | M7: =IF(G7="","",(1/G7)*1000000) | N7: =IF(H7="","",(1/H7)*1000000) | O7: =IF(I7="","",(1/I7)*1000000) | Q7: T2a | R7: AI/PID/AO | S7: Polling | T7: 42803 | U7: 14737 | V7: 4876 | Z7: =IF(T7="","",(1/T7)*1000000) -> 23.362848 | AA7: =IF(U7="","",(1/U7)*1000000) -> 67.856416 | AB7: =IF(V7="","",(1/V7)*1000000) -> 205.08614 | AC7: =IF(W7="","",(1/W7)*1000000) | AD7: =IF(X7="","",(1/X7)*1000000) | AE7: =IF(Y7="","",(1/Y7)*1000000)
A8: T2b | B8: AI/PID/AO | C8: Interrupts | D8: 9246 | E8: 6798 | F8: 3451 | J8: =IF(D8="","",(1/D8)*1000000) -> 108.15488 | K8: =IF(E8="","",(1/E8)*1000000) -> 147.10209 | L8: =IF(F8="","",(1/F8)*1000000) -> 289.77108 | M8: =IF(G8="","",(1/G8)*1000000) | N8: =IF(H8="","",(1/H8)*1000000) | O8: =IF(I8="","",(1/I8)*1000000) | Q8: T2b | R8: AI/PID/AO | S8: Interrupts | T8: 9773 | U8: 6958 | V8: 3468 | Z8: =IF(T8="","",(1/T8)*1000000) -> 102.32273 | AA8: =IF(U8="","",(1/U8)*1000000) -> 143.71946 | AB8: =IF(V8="","",(1/V8)*1000000) -> 288.35063 | AC8: =IF(W8="","",(1/W8)*1000000) | AD8: =IF(X8="","",(1/X8)*1000000) | AE8: =IF(Y8="","",(1/Y8)*1000000)
A9: T3 | B9: AI/AO/Local Logging | C9: Interrupts | D9: 4445 | E9: 3895 | F9: 3416 | J9: =IF(D9="","",(1/D9)*1000000) -> 224.97188 | K9: =IF(E9="","",(1/E9)*1000000) -> 256.73941 | L9: =IF(F9="","",(1/F9)*1000000) -> 292.74005 | M9: =IF(G9="","",(1/G9)*1000000) | N9: =IF(H9="","",(1/H9)*1000000) | O9: =IF(I9="","",(1/I9)*1000000) | Q9: T3 | R9: AI/AO/Local Logging | S9: Interrupts | T9: 4629 | U9: 4109 | V9: 3445 | Z9: =IF(T9="","",(1/T9)*1000000) -> 216.02938 | AA9: =IF(U9="","",(1/U9)*1000000) -> 243.36822 | AB9: =IF(V9="","",(1/V9)*1000000) -> 290.27576 | AC9: =IF(W9="","",(1/W9)*1000000) | AD9: =IF(X9="","",(1/X9)*1000000) | AE9: =IF(Y9="","",(1/Y9)*1000000)
A10: T4 | B10: AI/AO/Host Comm. | C10: Interrupts | D10: 4457 | E10: 4014 | F10: 3317 | J10: =IF(D10="","",(1/D10)*1000000) -> 224.36617 | K10: =IF(E10="","",(1/E10)*1000000) -> 249.12805 | L10: =IF(F10="","",(1/F10)*1000000) -> 301.47724 | M10: =IF(G10="","",(1/G10)*1000000) | N10: =IF(H10="","",(1/H10)*1000000) | O10: =IF(I10="","",(1/I10)*1000000) | Q10: T4 | R10: AI/AO/Host Comm. | S10: Interrupts | T10: 4480 | U10: 4103 | V10: 3374 | Z10: =IF(T10="","",(1/T10)*1000000) -> 223.21429 | AA10: =IF(U10="","",(1/U10)*1000000) -> 243.7241 | AB10: =IF(V10="","",(1/V10)*1000000) -> 296.38411 | AC10: =IF(W10="","",(1/W10)*1000000) | AD10: =IF(X10="","",(1/X10)*1000000) | AE10: =IF(Y10="","",(1/Y10)*1000000)
A12: Result Improvement vs. cRIO-9024 (% & uS)
A13: Test | D13: Number of Channels (%) | J13: Number of Channels, Difference in Period (uS)
A14: Acronym | B14: Description | C14: I/O Mode | D14: 1 | E14: 4 | F14: 16 | G14: 32 | H14: 64 | I14: 80 | J14: 1 | K14: 4 | L14: 16 | M14: 32 | N14: 64 | O14: 80
A15: T1a | B15: AI / AO | C15: Polling | D15: =IF(D5="","",(D5-'cRIO-9024 Benchmark'!D5)/'cRIO-9024 Benchmark'!D5) -> -0.47606001 | E15: =IF(E5="","",(E5-'cRIO-9024 Benchmark'!E5)/'cRIO-9024 Benchmark'!E5) -> -0.17179909 | F15: =IF(F5="","",(F5-'cRIO-9024 Benchmark'!F5)/'cRIO-9024 Benchmark'!F5) -> -0.063624586 | G15: =IF(G5="","",(G5-'cRIO-9024 Benchmark'!G5)/'cRIO-9024 Benchmark'!G5) | H15: =IF(H5="","",(H5-'cRIO-9024 Benchmark'!H5)/'cRIO-9024 Benchmark'!H5) | I15: =IF(I5="","",(I5-'cRIO-9024 Benchmark'!I5)/'cRIO-9024 Benchmark'!I5) | J15: =IF(D15="","",J5-((1/'cRIO-9024 Benchmark'!D5)*1000000)) -> 12.324221 | K15: =IF(E15="","",K5-((1/'cRIO-9024 Benchmark'!E5)*1000000)) -> 7.9352928 | L15: =IF(F15="","",L5-((1/'cRIO-9024 Benchmark'!F5)*1000000)) -> 9.7808741 | M15: =IF(G15="","",M5-((1/'cRIO-9024 Benchmark'!G5)*1000000)) | N15: =IF(H15="","",N5-((1/'cRIO-9024 Benchmark'!H5)*1000000)) | O15: =IF(I15="","",O5-((1/'cRIO-9024 Benchmark'!I5)*1000000))
A16: T1b | B16: AI / AO | C16: Interrupts | D16: =IF(D6="","",(D6-'cRIO-9024 Benchmark'!D6)/'cRIO-9024 Benchmark'!D6) -> -0.64890879 | E16: =IF(E6="","",(E6-'cRIO-9024 Benchmark'!E6)/'cRIO-9024 Benchmark'!E6) -> -0.50094841 | F16: =IF(F6="","",(F6-'cRIO-9024 Benchmark'!F6)/'cRIO-9024 Benchmark'!F6) -> -0.2153092 | G16: =IF(G6="","",(G6-'cRIO-9024 Benchmark'!G6)/'cRIO-9024 Benchmark'!G6) | H16: =IF(H6="","",(H6-'cRIO-9024 Benchmark'!H6)/'cRIO-9024 Benchmark'!H6) | I16: =IF(I6="","",(I6-'cRIO-9024 Benchmark'!I6)/'cRIO-9024 Benchmark'!I6) | J16: =IF(D16="","",J6-((1/'cRIO-9024 Benchmark'!D6)*1000000)) -> 65.16457 | K16: =IF(E16="","",K6-((1/'cRIO-9024 Benchmark'!E6)*1000000)) -> 63.467428 | L16: =IF(F16="","",L6-((1/'cRIO-9024 Benchmark'!F6)*1000000)) -> 51.732148 | M16: =IF(G16="","",M6-((1/'cRIO-9024 Benchmark'!G6)*1000000)) | N16: =IF(H16="","",N6-((1/'cRIO-9024 Benchmark'!H6)*1000000)) | O16: =IF(I16="","",O6-((1/'cRIO-9024 Benchmark'!I6)*1000000))
A17: T2a | B17: AI/PID/AO | C17: Polling | D17: =IF(D7="","",(D7-'cRIO-9024 Benchmark'!D7)/'cRIO-9024 Benchmark'!D7) -> -0.37482201 | E17: =IF(E7="","",(E7-'cRIO-9024 Benchmark'!E7)/'cRIO-9024 Benchmark'!E7) -> -0.42867393 | F17: =IF(F7="","",(F7-'cRIO-9024 Benchmark'!F7)/'cRIO-9024 Benchmark'!F7) -> -0.22751154 | G17: =IF(G7="","",(G7-'cRIO-9024 Benchmark'!G7)/'cRIO-9024 Benchmark'!G7) | H17: =IF(H7="","",(H7-'cRIO-9024 Benchmark'!H7)/'cRIO-9024 Benchmark'!H7) | I17: =IF(I7="","",(I7-'cRIO-9024 Benchmark'!I7)/'cRIO-9024 Benchmark'!I7) | J17: =IF(D17="","",J7-((1/'cRIO-9024 Benchmark'!D7)*1000000)) -> 8.8009113 | K17: =IF(E17="","",K7-((1/'cRIO-9024 Benchmark'!E7)*1000000)) -> 33.647875 | L17: =IF(F17="","",L7-((1/'cRIO-9024 Benchmark'!F7)*1000000)) -> 46.89026 | M17: =IF(G17="","",M7-((1/'cRIO-9024 Benchmark'!G7)*1000000)) | N17: =IF(H17="","",N7-((1/'cRIO-9024 Benchmark'!H7)*1000000)) | O17: =IF(I17="","",O7-((1/'cRIO-9024 Benchmark'!I7)*1000000))
A18: T2b | B18: AI/PID/AO | C18: Interrupts | D18: =IF(D8="","",(D8-'cRIO-9024 Benchmark'!D8)/'cRIO-9024 Benchmark'!D8) -> -0.55120862 | E18: =IF(E8="","",(E8-'cRIO-9024 Benchmark'!E8)/'cRIO-9024 Benchmark'!E8) -> -0.40021175 | F18: =IF(F8="","",(F8-'cRIO-9024 Benchmark'!F8)/'cRIO-9024 Benchmark'!F8) -> -0.22865445 | G18: =IF(G8="","",(G8-'cRIO-9024 Benchmark'!G8)/'cRIO-9024 Benchmark'!G8) | H18: =IF(H8="","",(H8-'cRIO-9024 Benchmark'!H8)/'cRIO-9024 Benchmark'!H8) | I18: =IF(I8="","",(I8-'cRIO-9024 Benchmark'!I8)/'cRIO-9024 Benchmark'!I8) | J18: =IF(D18="","",J8-((1/'cRIO-9024 Benchmark'!D8)*1000000)) -> 59.615901 | K18: =IF(E18="","",K8-((1/'cRIO-9024 Benchmark'!E8)*1000000)) -> 58.871985 | L18: =IF(F18="","",L8-((1/'cRIO-9024 Benchmark'!F8)*1000000)) -> 66.257447 | M18: =IF(G18="","",M8-((1/'cRIO-9024 Benchmark'!G8)*1000000)) | N18: =IF(H18="","",N8-((1/'cRIO-9024 Benchmark'!H8)*1000000)) | O18: =IF(I18="","",O8-((1/'cRIO-9024 Benchmark'!I8)*1000000))
A19: T3 | B19: AI/AO/Local Logging | C19: Interrupts | D19: =IF(D9="","",(D9-'cRIO-9024 Benchmark'!D9)/'cRIO-9024 Benchmark'!D9) -> -0.74527221 | E19: =IF(E9="","",(E9-'cRIO-9024 Benchmark'!E9)/'cRIO-9024 Benchmark'!E9) -> -0.61416543 | F19: =IF(F9="","",(F9-'cRIO-9024 Benchmark'!F9)/'cRIO-9024 Benchmark'!F9) -> -0.17368166 | G19: =IF(G9="","",(G9-'cRIO-9024 Benchmark'!G9)/'cRIO-9024 Benchmark'!G9) | H19: =IF(H9="","",(H9-'cRIO-9024 Benchmark'!H9)/'cRIO-9024 Benchmark'!H9) | I19: =IF(I9="","",(I9-'cRIO-9024 Benchmark'!I9)/'cRIO-9024 Benchmark'!I9) | J19: =IF(D19="","",J9-((1/'cRIO-9024 Benchmark'!D9)*1000000)) -> 167.66529 | K19: =IF(E19="","",K9-((1/'cRIO-9024 Benchmark'!E9)*1000000)) -> 157.68047 | L19: =IF(F19="","",L9-((1/'cRIO-9024 Benchmark'!F9)*1000000)) -> 50.843579 | M19: =IF(G19="","",M9-((1/'cRIO-9024 Benchmark'!G9)*1000000)) | N19: =IF(H19="","",N9-((1/'cRIO-9024 Benchmark'!H9)*1000000)) | O19: =IF(I19="","",O9-((1/'cRIO-9024 Benchmark'!I9)*1000000))
A20: T4 | B20: AI/AO/Host Comm. | C20: Interrupts | D20: =IF(D10="","",(D10-'cRIO-9024 Benchmark'!D10)/'cRIO-9024 Benchmark'!D10) -> -0.71337621 | E20: =IF(E10="","",(E10-'cRIO-9024 Benchmark'!E10)/'cRIO-9024 Benchmark'!E10) -> -0.58291771 | F20: =IF(F10="","",(F10-'cRIO-9024 Benchmark'!F10)/'cRIO-9024 Benchmark'!F10) -> -0.22081278 | G20: =IF(G10="","",(G10-'cRIO-9024 Benchmark'!G10)/'cRIO-9024 Benchmark'!G10) | H20: =IF(H10="","",(H10-'cRIO-9024 Benchmark'!H10)/'cRIO-9024 Benchmark'!H10) | I20: =IF(I10="","",(I10-'cRIO-9024 Benchmark'!I10)/'cRIO-9024 Benchmark'!I10) | J20: =IF(D20="","",J10-((1/'cRIO-9024 Benchmark'!D10)*1000000)) -> 160.05748 | K20: =IF(E20="","",K10-((1/'cRIO-9024 Benchmark'!E10)*1000000)) -> 145.22115 | L20: =IF(F20="","",L10-((1/'cRIO-9024 Benchmark'!F10)*1000000)) -> 66.570027 | M20: =IF(G20="","",M10-((1/'cRIO-9024 Benchmark'!G10)*1000000)) | N20: =IF(H20="","",N10-((1/'cRIO-9024 Benchmark'!H10)*1000000)) | O20: =IF(I20="","",O10-((1/'cRIO-9024 Benchmark'!I10)*1000000))
A22: Result Improvement vs. RIO's "green board" results (% & uS)
A23: Test | D23: % | E23: Difference in Period (uS)
A24: Acronym | B24: Description | C24: I/O Mode | D24: 1ch | E24: 1ch
A25: T1a | B25: AI / AO | C25: Polling | D25: =IF(D5="","",(D5-35380)/35380) -> 0.091803279 | E25: =IF(D5="","",J5-((1/35380)*1000000)) -> -2.3765993
A26: T1b | B26: AI / AO | C26: Interrupts | D26: =IF(D6="","",(D6-9711)/9711) -> 0.025435074 | E26: =IF(D6="","",J6-((1/9711)*1000000)) -> -2.5542352
A27: T2a | B27: AI/PID/AO | C27: Polling | D27: =IF(D7="","",(D7-31192)/31192) -> 0.36538215 | E27: =IF(D7="","",J7-((1/31192)*1000000)) -> -8.5792611
A28: T2b | B28: AI/PID/AO | C28: Interrupts | D28: =IF(D8="","",(D8-6490)/6490) -> 0.42465331 | E28: =IF(D8="","",J8-((1/6490)*1000000)) -> -45.928327
A29: T3 | B29: AI/AO/Local Logging | C29: Interrupts | D29: N/A | E29: N/A
A30: T4 | B30: AI/AO/Host Comm. | C30: Interrupts | D30: N/A | E30: N/A
A32: LV RT 2013 cRIO Single-Point Benchmark Results (Hz)
A33: cRIO-9068 (blue board), LV RT 2013b75, NI-RIO 13.0.0d229 (9205/9264) | Q33: Max Numbers
A34: Test | D34: Number of Channels, Rate (Hz) | J34: Number of Channels, Period (uS) | Q34: Test | T34: Number of Channels, Rate (Hz) | Z34: Number of Channels, Period (uS)
A35: Case | B35: Description | C35: I/O Mode | D35: 1 | E35: 4 | F35: 16 | G35: 32 | H35: 64 | I35: 80 | J35: 1 | K35: 4 | L35: 16 | M35: 32 | N35: 64 | O35: 80 | Q35: Case | R35: Description | S35: I/O Mode | T35: 1 | U35: 4 | V35: 16 | W35: 32 | X35: 64 | Y35: 80 | Z35: 1 | AA35: 4 | AB35: 16 | AC35: 32 | AD35: 64 | AE35: 80
A36: T1a | B36: AI / AO | C36: Polling | D36: 49932 | E36: 36058 | F36: 15922 | J36: =IF(D36="","",(1/D36)*1000000) -> 20.027237 | K36: =IF(E36="","",(1/E36)*1000000) -> 27.733097 | L36: =IF(F36="","",(1/F36)*1000000) -> 62.80618 | M36: =IF(G36="","",(1/G36)*1000000) | N36: =IF(H36="","",(1/H36)*1000000) | O36: =IF(I36="","",(1/I36)*1000000) | Q36: T1a | R36: AI / AO | S36: Polling | T36: 51861 | U36: 36604 | V36: 15842 | Z36: =IF(T36="","",(1/T36)*1000000) -> 19.282312 | AA36: =IF(U36="","",(1/U36)*1000000) -> 27.319419 | AB36: =IF(V36="","",(1/V36)*1000000) -> 63.123343 | AC36: =IF(W36="","",(1/W36)*1000000) | AD36: =IF(X36="","",(1/X36)*1000000) | AE36: =IF(Y36="","",(1/Y36)*1000000)
A37: T1b | B37: AI / AO | C37: Interrupts | D37: 9975 | E37: 9118 | F37: 6980 | J37: =IF(D37="","",(1/D37)*1000000) -> 100.25063 | K37: =IF(E37="","",(1/E37)*1000000) -> 109.67317 | L37: =IF(F37="","",(1/F37)*1000000) -> 143.26648 | M37: =IF(G37="","",(1/G37)*1000000) | N37: =IF(H37="","",(1/H37)*1000000) | O37: =IF(I37="","",(1/I37)*1000000) | Q37: T1b | R37: AI / AO | S37: Interrupts | T37: 10257 | U37: 9338 | V37: 7085 | Z37: =IF(T37="","",(1/T37)*1000000) -> 97.494394 | AA37: =IF(U37="","",(1/U37)*1000000) -> 107.08931 | AB37: =IF(V37="","",(1/V37)*1000000) -> 141.14326 | AC37: =IF(W37="","",(1/W37)*1000000) | AD37: =IF(X37="","",(1/X37)*1000000) | AE37: =IF(Y37="","",(1/Y37)*1000000)
A38: T2a | B38: AI/PID/AO | C38: Polling | D38: 44933 | E38: 19931 | F38: 11669 | J38: =IF(D38="","",(1/D38)*1000000) -> 22.255358 | K38: =IF(E38="","",(1/E38)*1000000) -> 50.173097 | L38: =IF(F38="","",(1/F38)*1000000) -> 85.697146 | M38: =IF(G38="","",(1/G38)*1000000) | N38: =IF(H38="","",(1/H38)*1000000) | O38: =IF(I38="","",(1/I38)*1000000) | Q38: T2a | R38: AI/PID/AO | S38: Polling | T38: 46391 | U38: 25261 | V38: 11826 | Z38: =IF(T38="","",(1/T38)*1000000) -> 21.555905 | AA38: =IF(U38="","",(1/U38)*1000000) -> 39.586715 | AB38: =IF(V38="","",(1/V38)*1000000) -> 84.559445 | AC38: =IF(W38="","",(1/W38)*1000000) | AD38: =IF(X38="","",(1/X38)*1000000) | AE38: =IF(Y38="","",(1/Y38)*1000000)
A39: T2b | B39: AI/PID/AO | C39: Interrupts | D39: 9757 | E39: 8283 | F39: 5975 | J39: =IF(D39="","",(1/D39)*1000000) -> 102.49052 | K39: =IF(E39="","",(1/E39)*1000000) -> 120.7292 | L39: =IF(F39="","",(1/F39)*1000000) -> 167.36402 | M39: =IF(G39="","",(1/G39)*1000000) | N39: =IF(H39="","",(1/H39)*1000000) | O39: =IF(I39="","",(1/I39)*1000000) | Q39: T2b | R39: AI/PID/AO | S39: Interrupts | T39: 9910 | U39: 8847 | V39: 6223 | Z39: =IF(T39="","",(1/T39)*1000000) -> 100.90817 | AA39: =IF(U39="","",(1/U39)*1000000) -> 113.03267 | AB39: =IF(V39="","",(1/V39)*1000000) -> 160.6942 | AC39: =IF(W39="","",(1/W39)*1000000) | AD39: =IF(X39="","",(1/X39)*1000000) | AE39: =IF(Y39="","",(1/Y39)*1000000)
A40: T3 | B40: AI/AO/Local Logging | C40: Interrupts | D40: 4341 | E40: 7315 | F40: 5368 | J40: =IF(D40="","",(1/D40)*1000000) -> 230.36167 | K40: =IF(E40="","",(1/E40)*1000000) -> 136.7054 | L40: =IF(F40="","",(1/F40)*1000000) -> 186.28912 | M40: =IF(G40="","",(1/G40)*1000000) | N40: =IF(H40="","",(1/H40)*1000000) | O40: =IF(I40="","",(1/I40)*1000000) | Q40: T3 | R40: AI/AO/Local Logging | S40: Interrupts | T40: 4508 | U40: 7315 | V40: 5371 | Z40: =IF(T40="","",(1/T40)*1000000) -> 221.82786 | AA40: =IF(U40="","",(1/U40)*1000000) -> 136.7054 | AB40: =IF(V40="","",(1/V40)*1000000) -> 186.18507 | AC40: =IF(W40="","",(1/W40)*1000000) | AD40: =IF(X40="","",(1/X40)*1000000) | AE40: =IF(Y40="","",(1/Y40)*1000000)
A41: T4 | B41: AI/AO/Host Comm. | C41: Interrupts | D41: 4306 | E41: 7170 | F41: 5447 | J41: =IF(D41="","",(1/D41)*1000000) -> 232.23409 | K41: =IF(E41="","",(1/E41)*1000000) -> 139.47001 | L41: =IF(F41="","",(1/F41)*1000000) -> 183.5873 | M41: =IF(G41="","",(1/G41)*1000000) | N41: =IF(H41="","",(1/H41)*1000000) | O41: =IF(I41="","",(1/I41)*1000000) | Q41: T4 | R41: AI/AO/Host Comm. | S41: Interrupts | T41: 4419 | U41: 7315 | V41: 6187 | Z41: =IF(T41="","",(1/T41)*1000000) -> 226.29554 | AA41: =IF(U41="","",(1/U41)*1000000) -> 136.7054 | AB41: =IF(V41="","",(1/V41)*1000000) -> 161.62922 | AC41: =IF(W41="","",(1/W41)*1000000) | AD41: =IF(X41="","",(1/X41)*1000000) | AE41: =IF(Y41="","",(1/Y41)*1000000)
D42: T1a: first run was actually 992, not sure why since subsequent runs were not affected by this.
A43: Result Improvement vs. "red board" (% & uS) | Q43: Result Improvement vs. cRIO-9024 (% & uS)
...

Sheet 2014
A1: LV RT 2014 cRIO Single-Point Benchmark Results (Hz)
A2: cRIO-9068, LV RT 2014b22, NI-RIO 14.0.0d228 (9205/9264)
A3: Test | D3: Number of Channels, Rate (Hz) | J3: Number of Channels, Period (uS)
A4: Acronym | B4: Description | C4: I/O Mode | D4: 1 | E4: 4 | F4: 16 | G4: 32 | H4: 64 | I4: 80 | J4: 1 | K4: 4 | L4: 16 | M4: 32 | N4: 64 | O4: 80
A5: T1a | B5: AI / AO | C5: Polling | D5: 46575 | E5: 20232 | F5: 6431 | J5: =IF(D5="","",(1/D5)*1000000) -> 21.470746 | K5: =IF(E5="","",(1/E5)*1000000) -> 49.426651 | L5: =IF(F5="","",(1/F5)*1000000) -> 155.49681 | M5: =IF(G5="","",(1/G5)*1000000) | N5: =IF(H5="","",(1/H5)*1000000) | O5: =IF(I5="","",(1/I5)*1000000)
A6: T1b | B6: AI / AO | C6: Interrupts | D6: 10553 | E6: 8241 | F6: 4245 | J6: =IF(D6="","",(1/D6)*1000000) -> 94.759784 | K6: =IF(E6="","",(1/E6)*1000000) -> 121.3445 | L6: =IF(F6="","",(1/F6)*1000000) -> 235.57126 | M6: =IF(G6="","",(1/G6)*1000000) | N6: =IF(H6="","",(1/H6)*1000000) | O6: =IF(I6="","",(1/I6)*1000000)
A7: T2a | B7: AI/PID/AO | C7: Polling | D7: 41595 | E7: 17542 | F7: 5618 | J7: =IF(D7="","",(1/D7)*1000000) -> 24.041351 | K7: =IF(E7="","",(1/E7)*1000000) -> 57.006043 | L7: =IF(F7="","",(1/F7)*1000000) -> 177.99929 | M7: =IF(G7="","",(1/G7)*1000000) | N7: =IF(H7="","",(1/H7)*1000000) | O7: =IF(I7="","",(1/I7)*1000000)
A8: T2b | B8: AI/PID/AO | C8: Interrupts | D8: 10234 | E8: 7675 | F8: 3981 | J8: =IF(D8="","",(1/D8)*1000000) -> 97.713504 | K8: =IF(E8="","",(1/E8)*1000000) -> 130.29316 | L8: =IF(F8="","",(1/F8)*1000000) -> 251.19317 | M8: =IF(G8="","",(1/G8)*1000000) | N8: =IF(H8="","",(1/H8)*1000000) | O8: =IF(I8="","",(1/I8)*1000000)
A9: T3 | B9: AI/AO/Local Logging | C9: Interrupts | D9: 4413 | E9: 7911 | F9: 4267 | J9: =IF(D9="","",(1/D9)*1000000) -> 226.60322 | K9: =IF(E9="","",(1/E9)*1000000) -> 126.40627 | L9: =IF(F9="","",(1/F9)*1000000) -> 234.35669 | M9: =IF(G9="","",(1/G9)*1000000) | N9: =IF(H9="","",(1/H9)*1000000) | O9: =IF(I9="","",(1/I9)*1000000)
A10: T4 | B10: AI/AO/Host Comm. | C10: Interrupts | D10: 4469 | E10: 7299 | F10: 4200 | J10: =IF(D10="","",(1/D10)*1000000) -> 223.76371 | K10: =IF(E10="","",(1/E10)*1000000) -> 137.00507 | L10: =IF(F10="","",(1/F10)*1000000) -> 238.09524 | M10: =IF(G10="","",(1/G10)*1000000) | N10: =IF(H10="","",(1/H10)*1000000) | O10: =IF(I10="","",(1/I10)*1000000)
A11: http://us-aus-rtweb1.natinst.com/Reports/RT/2014/performance/rtlinux/rtperf-9068/sp_online_poll/2014-02-13_13-37-38/HTML/2014-02-13_13-44-05_SinglePointBenchmarks_ATS.html
A12: Result Improvement vs. 2013 (% & uS)
A13: Test | D13: Number of Channels (%) | J13: Number of Channels, Difference in Period (uS)
A14: Acronym | B14: Description | C14: I/O Mode | D14: 1 | E14: 4 | F14: 16 | G14: 32 | H14: 64 | I14: 80 | J14: 1 | K14: 4 | L14: 16 | M14: 32 | N14: 64 | O14: 80
A15: T1a | B15: AI / AO | C15: Polling | D15: =IF(D5="","",(D5-'Proto 2013'!D58)/'Proto 2013'!D58) -> -0.0018644722 | E15: =IF(E5="","",(E5-'Proto 2013'!E58)/'Proto 2013'!E58) -> -0.030430824 | F15: =IF(F5="","",(F5-'Proto 2013'!F58)/'Proto 2013'!F58) -> 0.071297684 | G15: =IF(G5="","",(G5-'Proto 2013'!G58)/'Proto 2013'!G58) | H15: =IF(H5="","",(H5-'Proto 2013'!H58)/'Proto 2013'!H58) | I15: =IF(I5="","",(I5-'Proto 2013'!I58)/'Proto 2013'!I58) | J15: =IF(D15="","",J5-((1/'Proto 2013'!D58)*1000000)) -> 0.040031608 | K15: =IF(E15="","",K5-((1/'Proto 2013'!E58)*1000000)) -> 1.5040937 | L15: =IF(F15="","",L5-((1/'Proto 2013'!F58)*1000000)) -> -11.086563 | M15: =IF(G15="","",M5-((1/'Proto 2013'!G58)*1000000)) | N15: =IF(H15="","",N5-((1/'Proto 2013'!H58)*1000000)) | O15: =IF(I15="","",O5-((1/'Proto 2013'!I58)*1000000))
A16: T1b | B16: AI / AO | C16: Interrupts | D16: =IF(D6="","",(D6-'Proto 2013'!D59)/'Proto 2013'!D59) -> -0.033342493 | E16: =IF(E6="","",(E6-'Proto 2013'!E59)/'Proto 2013'!E59) -> -0.023925145 | F16: =IF(F6="","",(F6-'Proto 2013'!F59)/'Proto 2013'!F59) -> -0.029714286 | G16: =IF(G6="","",(G6-'Proto 2013'!G59)/'Proto 2013'!G59) | H16: =IF(H6="","",(H6-'Proto 2013'!H59)/'Proto 2013'!H59) | I16: =IF(I6="","",(I6-'Proto 2013'!I59)/'Proto 2013'!I59) | J16: =IF(D16="","",J6-((1/'Proto 2013'!D59)*1000000)) -> 3.1595275 | K16: =IF(E16="","",K6-((1/'Proto 2013'!E59)*1000000)) -> 2.9031847 | L16: =IF(F16="","",L6-((1/'Proto 2013'!F59)*1000000)) -> 6.9998317 | M16: =IF(G16="","",M6-((1/'Proto 2013'!G59)*1000000)) | N16: =IF(H16="","",N6-((1/'Proto 2013'!H59)*1000000)) | O16: =IF(I16="","",O6-((1/'Proto 2013'!I59)*1000000))
A17: T2a | B17: AI/PID/AO | C17: Polling | D17: =IF(D7="","",(D7-'Proto 2013'!D60)/'Proto 2013'!D60) -> 0.041020122 | E17: =IF(E7="","",(E7-'Proto 2013'!E60)/'Proto 2013'!E60) -> 0.06703163 | F17: =IF(F7="","",(F7-'Proto 2013'!F60)/'Proto 2013'!F60) -> -0.0033705872 | G17: =IF(G7="","",(G7-'Proto 2013'!G60)/'Proto 2013'!G60) | H17: =IF(H7="","",(H7-'Proto 2013'!H60)/'Proto 2013'!H60) | I17: =IF(I7="","",(I7-'Proto 2013'!I60)/'Proto 2013'!I60) | J17: =IF(D17="","",J7-((1/'Proto 2013'!D60)*1000000)) -> -0.98617916 | K17: =IF(E17="","",K7-((1/'Proto 2013'!E60)*1000000)) -> -3.821208 | L17: =IF(F17="","",L7-((1/'Proto 2013'!F60)*1000000)) -> 0.59996212 | M17: =IF(G17="","",M7-((1/'Proto 2013'!G60)*1000000)) | N17: =IF(H17="","",N7-((1/'Proto 2013'!H60)*1000000)) | O17: =IF(I17="","",O7-((1/'Proto 2013'!I60)*1000000))
A18: T2b | B18: AI/PID/AO | C18: Interrupts | D18: =IF(D8="","",(D8-'Proto 2013'!D61)/'Proto 2013'!D61) -> 0.10829543 | E18: =IF(E8="","",(E8-'Proto 2013'!E61)/'Proto 2013'!E61) -> 0.018309672 | F18: =IF(F8="","",(F8-'Proto 2013'!F61)/'Proto 2013'!F61) -> 0.022079589 | G18: =IF(G8="","",(G8-'Proto 2013'!G61)/'Proto 2013'!G61) | H18: =IF(H8="","",(H8-'Proto 2013'!H61)/'Proto 2013'!H61) | I18: =IF(I8="","",(I8-'Proto 2013'!I61)/'Proto 2013'!I61) | J18: =IF(D18="","",J8-((1/'Proto 2013'!D61)*1000000)) -> -10.581926 | K18: =IF(E18="","",K8-((1/'Proto 2013'!E61)*1000000)) -> -2.3856251 | L18: =IF(F18="","",L8-((1/'Proto 2013'!F61)*1000000)) -> -5.546242 | M18: =IF(G18="","",M8-((1/'Proto 2013'!G61)*1000000)) | N18: =IF(H18="","",N8-((1/'Proto 2013'!H61)*1000000)) | O18: =IF(I18="","",O8-((1/'Proto 2013'!I61)*1000000))
A19: T3 | B19: AI/AO/Local Logging | C19: Interrupts | D19: =IF(D9="","",(D9-'Proto 2013'!D62)/'Proto 2013'!D62) -> 0.00523918 | E19: =IF(E9="","",(E9-'Proto 2013'!E62)/'Proto 2013'!E62) -> 0.18516854 | F19: =IF(F9="","",(F9-'Proto 2013'!F62)/'Proto 2013'!F62) -> 0.2184466 | G19: =IF(G9="","",(G9-'Proto 2013'!G62)/'Proto 2013'!G62) | H19: =IF(H9="","",(H9-'Proto 2013'!H62)/'Proto 2013'!H62) | I19: =IF(I9="","",(I9-'Proto 2013'!I62)/'Proto 2013'!I62) | J19: =IF(D19="","",J9-((1/'Proto 2013'!D62)*1000000)) -> -1.187215 | K19: =IF(E19="","",K9-((1/'Proto 2013'!E62)*1000000)) -> -23.406464 | L19: =IF(F19="","",L9-((1/'Proto 2013'!F62)*1000000)) -> -51.194423 | M19: =IF(G19="","",M9-((1/'Proto 2013'!G62)*1000000)) | N19: =IF(H19="","",N9-((1/'Proto 2013'!H62)*1000000)) | O19: =IF(I19="","",O9-((1/'Proto 2013'!I62)*1000000))
A20: T4 | B20: AI/AO/Host Comm. | C20: Interrupts | D20: =IF(D10="","",(D10-'Proto 2013'!D63)/'Proto 2013'!D63) -> 0.0094872374 | E20: =IF(E10="","",(E10-'Proto 2013'!E63)/'Proto 2013'!E63) -> 0.27160279 | F20: =IF(F10="","",(F10-'Proto 2013'!F63)/'Proto 2013'!F63) -> 0.15543329 | G20: =IF(G10="","",(G10-'Proto 2013'!G63)/'Proto 2013'!G63) | H20: =IF(H10="","",(H10-'Proto 2013'!H63)/'Proto 2013'!H63) | I20: =IF(I10="","",(I10-'Proto 2013'!I63)/'Proto 2013'!I63) | J20: =IF(D20="","",J10-((1/'Proto 2013'!D63)*1000000)) -> -2.1228994 | K20: =IF(E20="","",K10-((1/'Proto 2013'!E63)*1000000)) -> -37.210959 | L20: =IF(F20="","",L10-((1/'Proto 2013'!F63)*1000000)) -> -37.007926 | M20: =IF(G20="","",M10-((1/'Proto 2013'!G63)*1000000)) | N20: =IF(H20="","",N10-((1/'Proto 2013'!H63)*1000000)) | O20: =IF(I20="","",O10-((1/'Proto 2013'!I63)*1000000))
A23: LV RT 2014 cRIO Single-Point Benchmark Results (Hz)
A24: cRIO-9068, LV RT 2014b142, NI-RIO 14.0.0d311 (9205/9264)
A25: Test | D25: Number of Channels, Rate (Hz) | J25: Number of Channels, Period (uS)
A26: Acronym | B26: Description | C26: I/O Mode | D26: 1 | E26: 4 | F26: 16 | G26: 32 | H26: 64 | I26: 80 | J26: 1 | K26: 4 | L26: 16 | M26: 32 | N26: 64 | O26: 80
A27: T1a | B27: AI / AO | C27: Polling | D27: 38628 | E27: 20232 | F27: 6399 | J27: =IF(D27="","",(1/D27)*1000000) -> 25.887957 | K27: =IF(E27="","",(1/E27)*1000000) -> 49.426651 | L27: =IF(F27="","",(1/F27)*1000000) -> 156.27442 | M27: =IF(G27="","",(1/G27)*1000000) | N27: =IF(H27="","",(1/H27)*1000000) | O27: =IF(I27="","",(1/I27)*1000000) | P27: 1ch next lowest 46847, we saw similar outliers in 2013
A28: T1b | B28: AI / AO | C28: Interrupts | D28: 10563 | E28: 8295 | F28: 4404 | J28: =IF(D28="","",(1/D28)*1000000) -> 94.670075 | K28: =IF(E28="","",(1/E28)*1000000) -> 120.55455 | L28: =IF(F28="","",(1/F28)*1000000) -> 227.0663 | M28: =IF(G28="","",(1/G28)*1000000) | N28: =IF(H28="","",(1/H28)*1000000) | O28: =IF(I28="","",(1/I28)*1000000)
A29: T2a | B29: AI/PID/AO | C29: Polling | D29: 39959 | E29: 17685 | F29: 5776 | J29: =IF(D29="","",(1/D29)*1000000) -> 25.025651 | K29: =IF(E29="","",(1/E29)*1000000) -> 56.545095 | L29: =IF(F29="","",(1/F29)*1000000) -> 173.13019 | M29: =IF(G29="","",(1/G29)*1000000) | N29: =IF(H29="","",(1/H29)*1000000) | O29: =IF(I29="","",(1/I29)*1000000)
A30: T2b | B30: AI/PID/AO | C30: Interrupts | D30: 10541 | E30: 7468 | F30: 3995 | J30: =IF(D30="","",(1/D30)*1000000) -> 94.86766 | K30: =IF(E30="","",(1/E30)*1000000) -> 133.90466 | L30: =IF(F30="","",(1/F30)*1000000) -> 250.31289 | M30: =IF(G30="","",(1/G30)*1000000) | N30: =IF(H30="","",(1/H30)*1000000) | O30: =IF(I30="","",(1/I30)*1000000)
A31: T3 | B31: AI/AO/Local Logging | C31: Interrupts | D31: 4463 | E31: 7667 | F31: 4162 | J31: =IF(D31="","",(1/D31)*1000000) -> 224.06453 | K31: =IF(E31="","",(1/E31)*1000000) -> 130.42911 | L31: =IF(F31="","",(1/F31)*1000000) -> 240.2691 | M31: =IF(G31="","",(1/G31)*1000000) | N31: =IF(H31="","",(1/H31)*1000000) | O31: =IF(I31="","",(1/I31)*1000000)
A32: T4 | B32: AI/AO/Host Comm. | C32: Interrupts | D32: 4468 | E32: 5932 | F32: 4162 | J32: =IF(D32="","",(1/D32)*1000000) -> 223.81379 | K32: =IF(E32="","",(1/E32)*1000000) -> 168.57721 | L32: =IF(F32="","",(1/F32)*1000000) -> 240.2691 | M32: =IF(G32="","",(1/G32)*1000000) | N32: =IF(H32="","",(1/H32)*1000000) | O32: =IF(I32="","",(1/I32)*1000000)
A33: http://us-aus-rtweb1.natinst.com/Reports/RT/2014/performance/rtlinux/rtperf-9068/sp_online_poll/2014-05-08_16-49-43/
A34: Result Improvement vs. 2013 (% & uS)
A35: Test | D35: Number of Channels (%) | J35: Number of Channels, Difference in Period (uS)
A36: Acronym | B36: Description | C36: I/O Mode | D36: 1 | E36: 4 | F36: 16 | G36: 32 | H36: 64 | I36: 80 | J36: 1 | K36: 4 | L36: 16 | M36: 32 | N36: 64 | O36: 80
A37: T1a | B37: AI / AO | C37: Polling | D37: =IF(D27="","",(D27-'Proto 2013'!D58)/'Proto 2013'!D58) -> -0.17217436 | E37: =IF(E27="","",(E27-'Proto 2013'!E58)/'Proto 2013'!E58) -> -0.030430824 | F37: =IF(F27="","",(F27-'Proto 2013'!F58)/'Proto 2013'!F58) -> 0.065967016 | G37: =IF(G27="","",(G27-'Proto 2013'!G58)/'Proto 2013'!G58) | H37: =IF(H27="","",(H27-'Proto 2013'!H58)/'Proto 2013'!H58) | I37: =IF(I27="","",(I27-'Proto 2013'!I58)/'Proto 2013'!I58) | J37: =IF(D37="","",J27-((1/'Proto 2013'!D58)*1000000)) -> 4.4572424 | K37: =IF(E37="","",K27-((1/'Proto 2013'!E58)*1000000)) -> 1.5040937 | L37: =IF(F37="","",L27-((1/'Proto 2013'!F58)*1000000)) -> -10.308957 | M37: =IF(G37="","",M27-((1/'Proto 2013'!G58)*1000000)) | N37: =IF(H37="","",N27-((1/'Proto 2013'!H58)*1000000)) | O37: =IF(I37="","",O27-((1/'Proto 2013'!I58)*1000000))
A38: T1b | B38: AI / AO | C38: Interrupts | D38: =IF(D28="","",(D28-'Proto 2013'!D59)/'Proto 2013'!D59) -> -0.032426491 | E38: =IF(E28="","",(E28-'Proto 2013'!E59)/'Proto 2013'!E59) -> -0.017529314 | F38: =IF(F28="","",(F28-'Proto 2013'!F59)/'Proto 2013'!F59) -> 0.0066285714 | G38: =IF(G28="","",(G28-'Proto 2013'!G59)/'Proto 2013'!G59) | H38: =IF(H28="","",(H28-'Proto 2013'!H59)/'Proto 2013'!H59) | I38: =IF(I28="","",(I28-'Proto 2013'!I59)/'Proto 2013'!I59) | J38: =IF(D38="","",J28-((1/'Proto 2013'!D59)*1000000)) -> 3.0698183 | K38: =IF(E38="","",K28-((1/'Proto 2013'!E59)*1000000)) -> 2.1132386 | L38: =IF(F38="","",L28-((1/'Proto 2013'!F59)*1000000)) -> -1.5051252 | M38: =IF(G38="","",M28-((1/'Proto 2013'!G59)*1000000)) | N38: =IF(H38="","",N28-((1/'Proto 2013'!H59)*1000000)) | O38: =IF(I38="","",O28-((1/'Proto 2013'!I59)*1000000))
A39: T2a | B39: AI/PID/AO | C39: Polling | D39: =IF(D29="","",(D29-'Proto 2013'!D60)/'Proto 2013'!D60) -> 7.5082591e-05 | E39: =IF(E29="","",(E29-'Proto 2013'!E60)/'Proto 2013'!E60) -> 0.075729927 | F39: =IF(F29="","",(F29-'Proto 2013'!F60)/'Proto 2013'!F60) -> 0.024658506 | G39: =IF(G29="","",(G29-'Proto 2013'!G60)/'Proto 2013'!G60) | H39: =IF(H29="","",(H29-'Proto 2013'!H60)/'Proto 2013'!H60) | I39: =IF(I29="","",(I29-'Proto 2013'!I60)/'Proto 2013'!I60) | J39: =IF(D39="","",J29-((1/'Proto 2013'!D60)*1000000)) -> -0.0018789907 | K39: =IF(E39="","",K29-((1/'Proto 2013'!E60)*1000000)) -> -4.2821559 | L39: =IF(F39="","",L29-((1/'Proto 2013'!F60)*1000000)) -> -4.269132 | M39: =IF(G39="","",M29-((1/'Proto 2013'!G60)*1000000)) | N39: =IF(H39="","",N29-((1/'Proto 2013'!H60)*1000000)) | O39: =IF(I39="","",O29-((1/'Proto 2013'!I60)*1000000))
A40: T2b | B40: AI/PID/AO | C40: Interrupts | D40: =IF(D30="","",(D30-'Proto 2013'!D61)/'Proto 2013'!D61) -> 0.14154213 | E40: =IF(E30="","",(E30-'Proto 2013'!E61)/'Proto 2013'!E61) -> -0.0091548361 | F40: =IF(F30="","",(F30-'Proto 2013'!F61)/'Proto 2013'!F61) -> 0.025673941 | G40: =IF(G30="","",(G30-'Proto 2013'!G61)/'Proto 2013'!G61) | H40: =IF(H30="","",(H30-'Proto 2013'!H61)/'Proto 2013'!H61) | I40: =IF(I30="","",(I30-'Proto 2013'!I61)/'Proto 2013'!I61) | J40: =IF(D40="","",J30-((1/'Proto 2013'!D61)*1000000)) -> -13.42777 | K40: =IF(E40="","",K30-((1/'Proto 2013'!E61)*1000000)) -> 1.2258752 | L40: =IF(F40="","",L30-((1/'Proto 2013'!F61)*1000000)) -> -6.4265184 | M40: =IF(G40="","",M30-((1/'Proto 2013'!G61)*1000000)) | N40: =IF(H40="","",N30-((1/'Proto 2013'!H61)*1000000)) | O40: =IF(I40="","",O30-((1/'Proto 2013'!I61)*1000000))
A41: T3 | B41: AI/AO/Local Logging | C41: Interrupts | D41: =IF(D31="","",(D31-'Proto 2013'!D62)/'Proto 2013'!D62) -> 0.016628702 | E41: =IF(E31="","",(E31-'Proto 2013'!E62)/'Proto 2013'!E62) -> 0.14861423 | F41: =IF(F31="","",(F31-'Proto 2013'!F62)/'Proto 2013'!F62) -> 0.18846374 | G41: =IF(G31="","",(G31-'Proto 2013'!G62)/'Proto 2013'!G62) | H41: =IF(H31="","",(H31-'Proto 2013'!H62)/'Proto 2013'!H62) | I41: =IF(I31="","",(I31-'Proto 2013'!I62)/'Proto 2013'!I62) | J41: =IF(D41="","",J31-((1/'Proto 2013'!D62)*1000000)) -> -3.7259022 | K41: =IF(E41="","",K31-((1/'Proto 2013'!E62)*1000000)) -> -19.383622 | L41: =IF(F41="","",L31-((1/'Proto 2013'!F62)*1000000)) -> -45.282012 | M41: =IF(G41="","",M31-((1/'Proto 2013'!G62)*1000000)) | N41: =IF(H41="","",N31-((1/'Proto 2013'!H62)*1000000)) | O41: =IF(I41="","",O31-((1/'Proto 2013'!I62)*1000000))
A42: T4 | B42: AI/AO/Host Comm. | C42: Interrupts | D42: =IF(D32="","",(D32-'Proto 2013'!D63)/'Proto 2013'!D63) -> 0.0092613508 | E42: =IF(E32="","",(E32-'Proto 2013'!E63)/'Proto 2013'!E63) -> 0.033449477 | F42: =IF(F32="","",(F32-'Proto 2013'!F63)/'Proto 2013'!F63) -> 0.14497937 | G42: =IF(G32="","",(G32-'Proto 2013'!G63)/'Proto 2013'!G63) | H42: =IF(H32="","",(H32-'Proto 2013'!H63)/'Proto 2013'!H63) | I42: =IF(I32="","",(I32-'Proto 2013'!I63)/'Proto 2013'!I63) | J42: =IF(D42="","",J32-((1/'Proto 2013'!D63)*1000000)) -> -2.072818 | K42: =IF(E42="","",K32-((1/'Proto 2013'!E63)*1000000)) -> -5.6388195 | L42: =IF(F42="","",L32-((1/'Proto 2013'!F63)*1000000)) -> -34.834062 | M42: =IF(G42="","",M32-((1/'Proto 2013'!G63)*1000000)) | N42: =IF(H42="","",N32-((1/'Proto 2013'!H63)*1000000)) | O42: =IF(I42="","",O32-((1/'Proto 2013'!I63)*1000000))
...

Sheet 2015
A1: LV RT 2015 cRIO Single-Point Benchmark Results (Hz)
A2: cRIO-9068, LV RT 2015 b2, NI-RIO 15.0.0.0 (9205/9264)
A3: Test | D3: Number of Channels, Rate (Hz) | J3: Number of Channels, Period (uS)
A4: Acronym | B4: Description | C4: I/O Mode | D4: 1 | E4: 4 | F4: 16 | G4: 32 | H4: 64 | I4: 80 | J4: 1 | K4: 4 | L4: 16 | M4: 32 | N4: 64 | O4: 80
A5: T1a | B5: AI / AO | C5: Polling | D5: 35000 | E5: 18706 | F5: 6003 | J5: =IF(D5="","",(1/D5)*1000000) -> 28.571429 | K5: =IF(E5="","",(1/E5)*1000000) -> 53.458783 | L5: =IF(F5="","",(1/F5)*1000000) -> 166.58337 | M5: =IF(G5="","",(1/G5)*1000000) | N5: =IF(H5="","",(1/H5)*1000000) | O5: =IF(I5="","",(1/I5)*1000000)
A6: T1b | B6: AI / AO | C6: Interrupts | D6: 7744 | E6: 6453 | F6: 3856 | J6: =IF(D6="","",(1/D6)*1000000) -> 129.13223 | K6: =IF(E6="","",(1/E6)*1000000) -> 154.96668 | L6: =IF(F6="","",(1/F6)*1000000) -> 259.3361 | M6: =IF(G6="","",(1/G6)*1000000) | N6: =IF(H6="","",(1/H6)*1000000) | O6: =IF(I6="","",(1/I6)*1000000)
A7: T2a | B7: AI/PID/AO | C7: Polling | D7: 30925 | E7: 15408 | F7: 5514 | J7: =IF(D7="","",(1/D7)*1000000) -> 32.336297 | K7: =IF(E7="","",(1/E7)*1000000) -> 64.90135 | L7: =IF(F7="","",(1/F7)*1000000) -> 181.35655 | M7: =IF(G7="","",(1/G7)*1000000) | N7: =IF(H7="","",(1/H7)*1000000) | O7: =IF(I7="","",(1/I7)*1000000)
A8: T2b | B8: AI/PID/AO | C8: Interrupts | D8: 7628 | E8: 5761 | F8: 3592 | J8: =IF(D8="","",(1/D8)*1000000) -> 131.09596 | K8: =IF(E8="","",(1/E8)*1000000) -> 173.58098 | L8: =IF(F8="","",(1/F8)*1000000) -> 278.39644 | M8: =IF(G8="","",(1/G8)*1000000) | N8: =IF(H8="","",(1/H8)*1000000) | O8: =IF(I8="","",(1/I8)*1000000)
A9: T3 | B9: AI/AO/Local Logging | C9: Interrupts | D9: 5120 | E9: 5992 | F9: 3566 | J9: =IF(D9="","",(1/D9)*1000000) -> 195.3125 | K9: =IF(E9="","",(1/E9)*1000000) -> 166.88919 | L9: =IF(F9="","",(1/F9)*1000000) -> 280.42625 | M9: =IF(G9="","",(1/G9)*1000000) | N9: =IF(H9="","",(1/H9)*1000000) | O9: =IF(I9="","",(1/I9)*1000000)
A10: T4 | B10: AI/AO/Host Comm. | C10: Interrupts | D10: 876 | E10: 4493 | F10: 3289 | J10: =IF(D10="","",(1/D10)*1000000) -> 1141.5525 | K10: =IF(E10="","",(1/E10)*1000000) -> 222.56844 | L10: =IF(F10="","",(1/F10)*1000000) -> 304.04378 | M10: =IF(G10="","",(1/G10)*1000000) | N10: =IF(H10="","",(1/H10)*1000000) | O10: =IF(I10="","",(1/I10)*1000000)
A11: http://us-aus-rtweb1.natinst.com/Reports/RT/2015/performance/rtlinux/rtperf-9068/sp_online_poll/2015-01-21_01-02-40/HTML/2015-01-21_01-13-54_SinglePointBenchmarks_ATS.html#Test_cRIO-Benchmark.lvproj%5CRT%20Target%5CAI-AO-FILE%5CTest_cRIO_AI-AO-FILE_01_INT
A12: Result Improvement vs. 2014 SP1 (% & uS)
A13: Test | D13: Number of Channels (%) | J13: Number of Channels, Difference in Period (uS)
A14: Acronym | B14: Description | C14: I/O Mode | D14: 1 | E14: 4 | F14: 16 | G14: 32 | H14: 64 | I14: 80 | J14: 1 | K14: 4 | L14: 16 | M14: 32 | N14: 64 | O14: 80
A15: T1a | B15: AI / AO | C15: Polling | D15: =IF(D5="","",(D5-'2014'!D48)/'2014'!D48) -> -0.21777222 | E15: =IF(E5="","",(E5-'2014'!E48)/'2014'!E48) -> -0.11605708 | F15: =IF(F5="","",(F5-'2014'!F48)/'2014'!F48) -> -0.070743034 | G15: =IF(G5="","",(G5-'2014'!G48)/'2014'!G48) | H15: =IF(H5="","",(H5-'2014'!H48)/'2014'!H48) | I15: =IF(I5="","",(I5-'2014'!I48)/'2014'!I48) | J15: =IF(D15="","",J5-'2014'!J48) -> 6.2220633 | K15: =IF(E15="","",K5-'2014'!K48) -> 6.2042705 | L15: =IF(F15="","",L5-'2014'!L48) -> 11.784613 | M15: =IF(G15="","",M5-((1/'2014'!G48)*1000000)) | N15: =IF(H15="","",N5-((1/'2014'!H48)*1000000)) | O15: =IF(I15="","",O5-((1/'2014'!I48)*1000000))
A16: T1b | B16: AI / AO | C16: Interrupts | D16: =IF(D6="","",(D6-'2014'!D49)/'2014'!D49) -> -0.25951425 | E16: =IF(E6="","",(E6-'2014'!E49)/'2014'!E49) -> -0.22949254 | F16: =IF(F6="","",(F6-'2014'!F49)/'2014'!F49) -> -0.11111111 | G16: =IF(G6="","",(G6-'2014'!G49)/'2014'!G49) | H16: =IF(H6="","",(H6-'2014'!H49)/'2014'!H49) | I16: =IF(I6="","",(I6-'2014'!I49)/'2014'!I49) | J16: =IF(D16="","",J6-'2014'!J49) -> 33.511654 | K16: =IF(E16="","",K6-'2014'!K49) -> 35.563697 | L16: =IF(F16="","",L6-'2014'!L49) -> 28.815122 | M16: =IF(G16="","",M6-((1/'2014'!G49)*1000000)) | N16: =IF(H16="","",N6-((1/'2014'!H49)*1000000)) | O16: =IF(I16="","",O6-((1/'2014'!I49)*1000000))
A17: T2a | B17: AI/PID/AO | C17: Polling | D17: =IF(D7="","",(D7-'2014'!D50)/'2014'!D50) -> -0.22602363 | E17: =IF(E7="","",(E7-'2014'!E50)/'2014'!E50) -> -0.10553814 | F17: =IF(F7="","",(F7-'2014'!F50)/'2014'!F50) -> -0.018162393 | G17: =IF(G7="","",(G7-'2014'!G50)/'2014'!G50) | H17: =IF(H7="","",(H7-'2014'!H50)/'2014'!H50) | I17: =IF(I7="","",(I7-'2014'!I50)/'2014'!I50) | J17: =IF(D17="","",J7-'2014'!J50) -> 7.3087672 | K17: =IF(E17="","",K7-'2014'!K50) -> 6.8495678 | L17: =IF(F17="","",L7-'2014'!L50) -> 3.2938689 | M17: =IF(G17="","",M7-((1/'2014'!G50)*1000000)) | N17: =IF(H17="","",N7-((1/'2014'!H50)*1000000)) | O17: =IF(I17="","",O7-((1/'2014'!I50)*1000000))
A18: T2b | B18: AI/PID/AO | C18: Interrupts | D18: =IF(D8="","",(D8-'2014'!D51)/'2014'!D51) -> -0.25790447 | E18: =IF(E8="","",(E8-'2014'!E51)/'2014'!E51) -> -0.22857525 | F18: =IF(F8="","",(F8-'2014'!F51)/'2014'!F51) -> -0.098167211 | G18: =IF(G8="","",(G8-'2014'!G51)/'2014'!G51) | H18: =IF(H8="","",(H8-'2014'!H51)/'2014'!H51) | I18: =IF(I8="","",(I8-'2014'!I51)/'2014'!I51) | J18: =IF(D18="","",J8-'2014'!J51) -> 33.810234 | K18: =IF(E18="","",K8-'2014'!K51) -> 39.676316 | L18: =IF(F18="","",L8-'2014'!L51) -> 27.329402 | M18: =IF(G18="","",M8-((1/'2014'!G51)*1000000)) | N18: =IF(H18="","",N8-((1/'2014'!H51)*1000000)) | O18: =IF(I18="","",O8-((1/'2014'!I51)*1000000))
A19: T3 | B19: AI/AO/Local Logging | C19: Interrupts | D19: =IF(D9="","",(D9-'2014'!D52)/'2014'!D52) -> 0.15601716 | E19: =IF(E9="","",(E9-'2014'!E52)/'2014'!E52) -> -0.22131254 | F19: =IF(F9="","",(F9-'2014'!F52)/'2014'!F52) -> -0.13885535 | G19: =IF(G9="","",(G9-'2014'!G52)/'2014'!G52) | H19: =IF(H9="","",(H9-'2014'!H52)/'2014'!H52) | I19: =IF(I9="","",(I9-'2014'!I52)/'2014'!I52) | J19: =IF(D19="","",J9-'2014'!J52) -> -30.472101 | K19: =IF(E19="","",K9-'2014'!K52) -> 36.93467 | L19: =IF(F19="","",L9-'2014'!L52) -> 38.938685 | M19: =IF(G19="","",M9-((1/'2014'!G52)*1000000)) | N19: =IF(H19="","",N9-((1/'2014'!H52)*1000000)) | O19: =IF(I19="","",O9-((1/'2014'!I52)*1000000))
A20: T4 | B20: AI/AO/Host Comm. | C20: Interrupts | D20: =IF(D10="","",(D10-'2014'!D53)/'2014'!D53) -> -0.80013689 | E20: =IF(E10="","",(E10-'2014'!E53)/'2014'!E53) -> -0.12246094 | F20: =IF(F10="","",(F10-'2014'!F53)/'2014'!F53) -> -0.19426752 | G20: =IF(G10="","",(G10-'2014'!G53)/'2014'!G53) | H20: =IF(H10="","",(H10-'2014'!H53)/'2014'!H53) | I20: =IF(I10="","",(I10-'2014'!I53)/'2014'!I53) | J20: =IF(D20="","",J10-'2014'!J53) -> 913.39828 | K20: =IF(E20="","",K10-'2014'!K53) -> 27.25594 | L20: =IF(F20="","",L10-'2014'!L53) -> 59.06583 | M20: =IF(G20="","",M10-((1/'2014'!G53)*1000000)) | N20: =IF(H20="","",N10-((1/'2014'!H53)*1000000)) | O20: =IF(I20="","",O10-((1/'2014'!I53)*1000000))
A23: LV RT 2015 cRIO Single-Point Benchmark Results (Hz)
A24: cRIO-9068, LV RT 2015b30, NI-RIO 15.0.0.0 (9205/9264)
A25: Test | D25: Number of Channels, Rate (Hz) | J25: Number of Channels, Period (uS)
A26: Acronym | B26: Description | C26: I/O Mode | D26: 1 | E26: 4 | F26: 16 | G26: 32 | H26: 64 | I26: 80 | J26: 1 | K26: 4 | L26: 16 | M26: 32 | N26: 64 | O26: 80
A27: T1a | B27: AI / AO | C27: Polling | D27: 47550 | E27: 20740 | F27: 6558 | J27: =IF(D27="","",(1/D27)*1000000) -> 21.030494 | K27: =IF(E27="","",(1/E27)*1000000) -> 48.216008 | L27: =IF(F27="","",(1/F27)*1000000) -> 152.48551 | M27: =IF(G27="","",(1/G27)*1000000) | N27: =IF(H27="","",(1/H27)*1000000) | O27: =IF(I27="","",(1/I27)*1000000) | P27: 1ch next lowest 46847, we saw similar outliers in 2013
A28: T1b | B28: AI / AO | C28: Interrupts | D28: 11095 | E28: 8499 | F28: 4432 | J28: =IF(D28="","",(1/D28)*1000000) -> 90.130689 | K28: =IF(E28="","",(1/E28)*1000000) -> 117.6609 | L28: =IF(F28="","",(1/F28)*1000000) -> 225.63177 | M28: =IF(G28="","",(1/G28)*1000000) | N28: =IF(H28="","",(1/H28)*1000000) | O28: =IF(I28="","",(1/I28)*1000000)
A29: T2a | B29: AI/PID/AO | C29: Polling | D29: 45129 | E29: 18290 | F29: 5577 | J29: =IF(D29="","",(1/D29)*1000000) -> 22.158701 | K29: =IF(E29="","",(1/E29)*1000000) -> 54.674686 | L29: =IF(F29="","",(1/F29)*1000000) -> 179.30787 | M29: =IF(G29="","",(1/G29)*1000000) | N29: =IF(H29="","",(1/H29)*1000000) | O29: =IF(I29="","",(1/I29)*1000000)
A30: T2b | B30: AI/PID/AO | C30: Interrupts | D30: 10520 | E30: 7882 | F30: 4161 | J30: =IF(D30="","",(1/D30)*1000000) -> 95.057034 | K30: =IF(E30="","",(1/E30)*1000000) -> 126.87135 | L30: =IF(F30="","",(1/F30)*1000000) -> 240.32684 | M30: =IF(G30="","",(1/G30)*1000000) | N30: =IF(H30="","",(1/H30)*1000000) | O30: =IF(I30="","",(1/I30)*1000000)
A31: T3 | B31: AI/AO/Local Logging | C31: Interrupts | D31: 9224 | E31: 8295 | F31: 4340 | J31: =IF(D31="","",(1/D31)*1000000) -> 108.41284 | K31: =IF(E31="","",(1/E31)*1000000) -> 120.55455 | L31: =IF(F31="","",(1/F31)*1000000) -> 230.41475 | M31: =IF(G31="","",(1/G31)*1000000) | N31: =IF(H31="","",(1/H31)*1000000) | O31: =IF(I31="","",(1/I31)*1000000)
A32: T4 | B32: AI/AO/Host Comm. | C32: Interrupts | D32: 8307 | E32: 6675 | F32: 4300 | J32: =IF(D32="","",(1/D32)*1000000) -> 120.3804 | K32: =IF(E32="","",(1/E32)*1000000) -> 149.81273 | L32: =IF(F32="","",(1/F32)*1000000) -> 232.55814 | M32: =IF(G32="","",(1/G32)*1000000) | N32: =IF(H32="","",(1/H32)*1000000) | O32: =IF(I32="","",(1/I32)*1000000)
A33: http://us-aus-rtweb1.natinst.com/Reports/RT/2015/performance/rtlinux/rtperf-9068/sp_online_poll/2015-02-17_23-55-58/HTML/2015-02-18_00-07-07_SinglePointBenchmarks_ATS.html#TSsummary
A34: Result Improvement vs. 2014 SP1 (% & uS)
A35: Test | D35: Number of Channels (%) | J35: Number of Channels, Difference in Period (uS)
A36: Acronym | B36: Description | C36: I/O Mode | D36: 1 | E36: 4 | F36: 16 | G36: 32 | H36: 64 | I36: 80 | J36: 1 | K36: 4 | L36: 16 | M36: 32 | N36: 64 | O36: 80
A37: T1a | B37: AI / AO | C37: Polling | D37: =IF(D27="","",(D27-'2014'!D48)/'2014'!D48) -> 0.062712319 | E37: =IF(E27="","",(E27-'2014'!E48)/'2014'!E48) -> -0.019941404 | F37: =IF(F27="","",(F27-'2014'!F48)/'2014'!F48) -> 0.015170279 | G37: =IF(G27="","",(G27-'2014'!G48)/'2014'!G48) | H37: =IF(H27="","",(H27-'2014'!H48)/'2014'!H48) | I37: =IF(I27="","",(I27-'2014'!I48)/'2014'!I48) | J37: =IF(D37="","",J27-'2014'!J48) -> -1.3188711 | K37: =IF(E37="","",K27-'2014'!K48) -> 0.96149491 | L37: =IF(F37="","",L27-'2014'!L48) -> -2.3132477 | M37: =IF(G37="","",M27-((1/'2014'!G48)*1000000)) | N37: =IF(H37="","",N27-((1/'2014'!H48)*1000000)) | O37: =IF(I37="","",O27-((1/'2014'!I48)*1000000))
A38: T1b | B38: AI / AO | C38: Interrupts | D38: =IF(D28="","",(D28-'2014'!D49)/'2014'!D49) -> 0.060910308 | E38: =IF(E28="","",(E28-'2014'!E49)/'2014'!E49) -> 0.01480597 | F38: =IF(F28="","",(F28-'2014'!F49)/'2014'!F49) -> 0.021668972 | G38: =IF(G28="","",(G28-'2014'!G49)/'2014'!G49) | H38: =IF(H28="","",(H28-'2014'!H49)/'2014'!H49) | I38: =IF(I28="","",(I28-'2014'!I49)/'2014'!I49) | J38: =IF(D38="","",J28-'2014'!J49) -> -5.489888 | K38: =IF(E38="","",K28-'2014'!K49) -> -1.7420838 | L38: =IF(F38="","",L28-'2014'!L49) -> -4.8892085 | M38: =IF(G38="","",M28-((1/'2014'!G49)*1000000)) | N38: =IF(H38="","",N28-((1/'2014'!H49)*1000000)) | O38: =IF(I38="","",O28-((1/'2014'!I49)*1000000))
A39: T2a | B39: AI/PID/AO | C39: Polling | D39: =IF(D29="","",(D29-'2014'!D50)/'2014'!D50) -> 0.12946741 | E39: =IF(E29="","",(E29-'2014'!E50)/'2014'!E50) -> 0.061767096 | F39: =IF(F29="","",(F29-'2014'!F50)/'2014'!F50) -> -0.0069444444 | G39: =IF(G29="","",(G29-'2014'!G50)/'2014'!G50) | H39: =IF(H29="","",(H29-'2014'!H50)/'2014'!H50) | I39: =IF(I29="","",(I29-'2014'!I50)/'2014'!I50) | J39: =IF(D39="","",J29-'2014'!J50) -> -2.8688297 | K39: =IF(E39="","",K29-'2014'!K50) -> -3.3770966 | L39: =IF(F39="","",L29-'2014'!L50) -> 1.2451936 | M39: =IF(G39="","",M29-((1/'2014'!G50)*1000000)) | N39: =IF(H39="","",N29-((1/'2014'!H50)*1000000)) | O39: =IF(I39="","",O29-((1/'2014'!I50)*1000000))
A40: T2b | B40: AI/PID/AO | C40: Interrupts | D40: =IF(D30="","",(D30-'2014'!D51)/'2014'!D51) -> 0.02344586 | E40: =IF(E30="","",(E30-'2014'!E51)/'2014'!E51) -> 0.055436529 | F40: =IF(F30="","",(F30-'2014'!F51)/'2014'!F51) -> 0.044689932 | G40: =IF(G30="","",(G30-'2014'!G51)/'2014'!G51) | H40: =IF(H30="","",(H30-'2014'!H51)/'2014'!H51) | I40: =IF(I30="","",(I30-'2014'!I51)/'2014'!I51) | J40: =IF(D40="","",J30-'2014'!J51) -> -2.228694 | K40: =IF(E40="","",K30-'2014'!K51) -> -7.0333074 | L40: =IF(F40="","",L30-'2014'!L51) -> -10.74019 | M40: =IF(G40="","",M30-((1/'2014'!G51)*1000000)) | N40: =IF(H40="","",N30-((1/'2014'!H51)*1000000)) | O40: =IF(I40="","",O30-((1/'2014'!I51)*1000000))
A41: T3 | B41: AI/AO/Local Logging | C41: Interrupts | D41: =IF(D31="","",(D31-'2014'!D52)/'2014'!D52) -> 1.0826372 | E41: =IF(E31="","",(E31-'2014'!E52)/'2014'!E52) -> 0.07797271 | F41: =IF(F31="","",(F31-'2014'!F52)/'2014'!F52) -> 0.048056025 | G41: =IF(G31="","",(G31-'2014'!G52)/'2014'!G52) | H41: =IF(H31="","",(H31-'2014'!H52)/'2014'!H52) | I41: =IF(I31="","",(I31-'2014'!I52)/'2014'!I52) | J41: =IF(D41="","",J31-'2014'!J52) -> -117.37177 | K41: =IF(E41="","",K31-'2014'!K52) -> -9.399965 | L41: =IF(F41="","",L31-'2014'!L52) -> -11.072817 | M41: =IF(G41="","",M31-((1/'2014'!G52)*1000000)) | N41: =IF(H41="","",N31-((1/'2014'!H52)*1000000)) | O41: =IF(I41="","",O31-((1/'2014'!I52)*1000000))
A42: T4 | B42: AI/AO/Host Comm. | C42: Interrupts | D42: =IF(D32="","",(D32-'2014'!D53)/'2014'!D53) -> 0.89527721 | E42: =IF(E32="","",(E32-'2014'!E53)/'2014'!E53) -> 0.30371094 | F42: =IF(F32="","",(F32-'2014'!F53)/'2014'!F53) -> 0.053405194 | G42: =IF(G32="","",(G32-'2014'!G53)/'2014'!G53) | H42: =IF(H32="","",(H32-'2014'!H53)/'2014'!H53) | I42: =IF(I32="","",(I32-'2014'!I53)/'2014'!I53) | J42: =IF(D42="","",J32-'2014'!J53) -> -107.77383 | K42: =IF(E42="","",K32-'2014'!K53) -> -45.499766 | L42: =IF(F42="","",L32-'2014'!L53) -> -12.419812 | M42: =IF(G42="","",M32-((1/'2014'!G53)*1000000)) | N42: =IF(H42="","",N32-((1/'2014'!H53)*1000000)) | O42: =IF(I42="","",O32-((1/'2014'!I53)*1000000))
...

Sheet 2016
A1: LV RT 2016 cRIO Single-Point Benchmark Results (Hz)
A2: cRIO-9068, LV RT 16.0b35, NI-RIO 16.0.0a4
A3: Test | D3: Number of Channels, Rate (Hz) | J3: Number of Channels, Period (uS)
A4: Acronym | B4: Description | C4: I/O Mode | D4: 1 | E4: 4 | F4: 16 | G4: 32 | H4: 64 | I4: 80 | J4: 1 | K4: 4 | L4: 16 | M4: 32 | N4: 64 | O4: 80
A5: T1a | B5: AI / AO | C5: Polling | D5: 20576 | E5: 15648 | F5: 5943 | J5: =IF(D5="","",(1/D5)*1000000) -> 48.600311 | K5: =IF(E5="","",(1/E5)*1000000) -> 63.90593 | L5: =IF(F5="","",(1/F5)*1000000) -> 168.26519 | M5: =IF(G5="","",(1/G5)*1000000) | N5: =IF(H5="","",(1/H5)*1000000) | O5: =IF(I5="","",(1/I5)*1000000)
A6: T1b | B6: AI / AO | C6: Interrupts | D6: 1191 | E6: 6592 | F6: 3857 | J6: =IF(D6="","",(1/D6)*1000000) -> 839.63056 | K6: =IF(E6="","",(1/E6)*1000000) -> 151.69903 | L6: =IF(F6="","",(1/F6)*1000000) -> 259.26886 | M6: =IF(G6="","",(1/G6)*1000000) | N6: =IF(H6="","",(1/H6)*1000000) | O6: =IF(I6="","",(1/I6)*1000000)
A7: T2a | B7: AI/PID/AO | C7: Polling | D7: 26417 | E7: 14409 | F7: 5331 | J7: =IF(D7="","",(1/D7)*1000000) -> 37.854412 | K7: =IF(E7="","",(1/E7)*1000000) -> 69.401069 | L7: =IF(F7="","",(1/F7)*1000000) -> 187.58207 | M7: =IF(G7="","",(1/G7)*1000000) | N7: =IF(H7="","",(1/H7)*1000000) | O7: =IF(I7="","",(1/I7)*1000000)
A8: T2b | B8: AI/PID/AO | C8: Interrupts | D8: 7927 | E8: 6275 | F8: 3633 | J8: =IF(D8="","",(1/D8)*1000000) -> 126.15113 | K8: =IF(E8="","",(1/E8)*1000000) -> 159.36255 | L8: =IF(F8="","",(1/F8)*1000000) -> 275.25461 | M8: =IF(G8="","",(1/G8)*1000000) | N8: =IF(H8="","",(1/H8)*1000000) | O8: =IF(I8="","",(1/I8)*1000000)
A9: T3 | B9: AI/AO/Local Logging | C9: Interrupts | D9: 8172 | E9: 6421 | F9: 3683 | J9: =IF(D9="","",(1/D9)*1000000) -> 122.36907 | K9: =IF(E9="","",(1/E9)*1000000) -> 155.73898 | L9: =IF(F9="","",(1/F9)*1000000) -> 271.51778 | M9: =IF(G9="","",(1/G9)*1000000) | N9: =IF(H9="","",(1/H9)*1000000) | O9: =IF(I9="","",(1/I9)*1000000)
A10: T4 | B10: AI/AO/Host Comm. | C10: Interrupts | D10: 8094 | E10: 6453 | F10: 3673 | J10: =IF(D10="","",(1/D10)*1000000) -> 123.54831 | K10: =IF(E10="","",(1/E10)*1000000) -> 154.96668 | L10: =IF(F10="","",(1/F10)*1000000) -> 272.25701 | M10: =IF(G10="","",(1/G10)*1000000) | N10: =IF(H10="","",(1/H10)*1000000) | O10: =IF(I10="","",(1/I10)*1000000)
A11: Link to report : 9068_sp_online_poll_16.0b35
A12: Result Improvement vs. 2015 (% & uS)
A13: Test | D13: Number of Channels (%) | J13: Number of Channels, Difference in Period (uS)
A14: Acronym | B14: Description | C14: I/O Mode | D14: 1 | E14: 4 | F14: 16 | G14: 32 | H14: 64 | I14: 80 | J14: 1 | K14: 4 | L14: 16 | M14: 32 | N14: 64 | O14: 80
A15: T1a | B15: AI / AO | C15: Polling | D15: =IF(D5="","",(D5-'2015'!D92)/'2015'!D92) -> -0.55610209 | E15: =IF(E5="","",(E5-'2015'!E92)/'2015'!E92) -> -0.28167462 | F15: =IF(F5="","",(F5-'2015'!F92)/'2015'!F92) -> -0.091006424 | G15: =IF(G5="","",(G5-'2014'!#REF!)/'2014'!#REF!) | H15: =IF(H5="","",(H5-'2014'!#REF!)/'2014'!#REF!) | I15: =IF(I5="","",(I5-'2014'!#REF!)/'2014'!#REF!) | J15: =J5 - '2015'!J92 -> 27.026734 | K15: =K5 - '2015'!K92 -> 18.000679 | L15: =L5 - '2015'!L92 -> 15.313213 | M15: =IF(G15="","",M5-((1/'Proto 2013'!G15)*1000000)) | N15: =IF(H15="","",N5-((1/'Proto 2013'!H15)*1000000)) | O15: =IF(I15="","",O5-((1/'Proto 2013'!I15)*1000000))
A16: T1b | B16: AI / AO | C16: Interrupts | D16: =IF(D6="","",(D6-'2015'!D93)/'2015'!D93) -> -0.88925051 | E16: =IF(E6="","",(E6-'2015'!E93)/'2015'!E93) -> -0.21336516 | F16: =IF(F6="","",(F6-'2015'!F93)/'2015'!F93) -> -0.13169743 | G16: =IF(G6="","",(G6-'2014'!#REF!)/'2014'!#REF!) | H16: =IF(H6="","",(H6-'2014'!#REF!)/'2014'!#REF!) | I16: =IF(I6="","",(I6-'2014'!#REF!)/'2014'!#REF!) | J16: =J6 - '2015'!J93 -> 746.64191 | K16: =K6 - '2015'!K93 -> 32.367287 | L16: =L6 - '2015'!L93 -> 34.145044 | M16: =IF(G16="","",M6-((1/'Proto 2013'!G16)*1000000)) | N16: =IF(H16="","",N6-((1/'Proto 2013'!H16)*1000000)) | O16: =IF(I16="","",O6-((1/'Proto 2013'!I16)*1000000))
A17: T2a | B17: AI/PID/AO | C17: Polling | D17: =IF(D7="","",(D7-'2015'!D94)/'2015'!D94) -> -0.36081202 | E17: =IF(E7="","",(E7-'2015'!E94)/'2015'!E94) -> -0.20092059 | F17: =IF(F7="","",(F7-'2015'!F94)/'2015'!F94) -> -0.0087393083 | G17: =IF(G7="","",(G7-'2014'!#REF!)/'2014'!#REF!) | H17: =IF(H7="","",(H7-'2014'!#REF!)/'2014'!#REF!) | I17: =IF(I7="","",(I7-'2014'!#REF!)/'2014'!#REF!) | J17: =J7 - '2015'!J94 -> 13.658327 | K17: =K7 - '2015'!K94 -> 13.944103 | L17: =L7 - '2015'!L94 -> 1.6393375 | M17: =IF(G17="","",M7-((1/'Proto 2013'!G17)*1000000)) | N17: =IF(H17="","",N7-((1/'Proto 2013'!H17)*1000000)) | O17: =IF(I17="","",O7-((1/'Proto 2013'!I17)*1000000))
A18: T2b | B18: AI/PID/AO | C18: Interrupts | D18: =IF(D8="","",(D8-'2015'!D95)/'2015'!D95) -> -0.2365405 | E18: =IF(E8="","",(E8-'2015'!E95)/'2015'!E95) -> -0.20910008 | F18: =IF(F8="","",(F8-'2015'!F95)/'2015'!F95) -> -0.12182741 | G18: =IF(G8="","",(G8-'2014'!#REF!)/'2014'!#REF!) | H18: =IF(H8="","",(H8-'2014'!#REF!)/'2014'!#REF!) | I18: =IF(I8="","",(I8-'2014'!#REF!)/'2014'!#REF!) | J18: =J8 - '2015'!J95 -> 29.839851 | K18: =K8 - '2015'!K95 -> 33.322721 | L18: =L8 - '2015'!L95 -> 33.533557 | M18: =IF(G18="","",M8-((1/'Proto 2013'!G18)*1000000)) | N18: =IF(H18="","",N8-((1/'Proto 2013'!H18)*1000000)) | O18: =IF(I18="","",O8-((1/'Proto 2013'!I18)*1000000))
A19: T3 | B19: AI/AO/Local Logging | C19: Interrupts | D19: =IF(D9="","",(D9-'2015'!D96)/'2015'!D96) -> 0.020224719 | E19: =IF(E9="","",(E9-'2015'!E96)/'2015'!E96) -> -0.16664504 | F19: =IF(F9="","",(F9-'2015'!F96)/'2015'!F96) -> -0.10909531 | G19: =IF(G9="","",(G9-'2014'!#REF!)/'2014'!#REF!) | H19: =IF(H9="","",(H9-'2014'!#REF!)/'2014'!#REF!) | I19: =IF(I9="","",(I9-'2014'!#REF!)/'2014'!#REF!) | J19: =J9 - '2015'!J96 -> -2.47488 | K19: =K9 - '2015'!K96 -> 25.953128 | L19: =L9 - '2015'!L96 -> 29.621316 | M19: =IF(G19="","",M9-((1/'Proto 2013'!G19)*1000000)) | N19: =IF(H19="","",N9-((1/'Proto 2013'!H19)*1000000)) | O19: =IF(I19="","",O9-((1/'Proto 2013'!I19)*1000000))
A20: T4 | B20: AI/AO/Host Comm. | C20: Interrupts | D20: =IF(D10="","",(D10-'2015'!D97)/'2015'!D97) -> 0.010486891 | E20: =IF(E10="","",(E10-'2015'!E97)/'2015'!E97) -> -0.12036532 | F20: =IF(F10="","",(F10-'2015'!F97)/'2015'!F97) -> -0.10957576 | G20: =IF(G10="","",(G10-'2014'!#REF!)/'2014'!#REF!) | H20: =IF(H10="","",(H10-'2014'!#REF!)/'2014'!#REF!) | I20: =IF(I10="","",(I10-'2014'!#REF!)/'2014'!#REF!) | J20: =J10 - '2015'!J97 -> -1.2956377 | K20: =K10 - '2015'!K97 -> 18.652615 | L20: =L10 - '2015'!L97 -> 29.832768 | M20: =IF(G20="","",M10-((1/'Proto 2013'!G20)*1000000)) | N20: =IF(H20="","",N10-((1/'Proto 2013'!H20)*1000000)) | O20: =IF(I20="","",O10-((1/'Proto 2013'!I20)*1000000))
A22: LV RT 2016 cRIO Single-Point Benchmark Results (Hz)
A23: cRIO-9068, LV RT 16.0b40, NI-RIO 16.0.0a4
A24: Test | D24: Number of Channels, Rate (Hz) | J24: Number of Channels, Period (uS)
A25: Acronym | B25: Description | C25: I/O Mode | D25: 1 | E25: 4 | F25: 16 | G25: 32 | H25: 64 | I25: 80 | J25: 1 | K25: 4 | L25: 16 | M25: 32 | N25: 64 | O25: 80
A26: T1a | B26: AI / AO | C26: Polling | D26: 25675 | E26: 15359 | F26: 4763 | J26: =IF(D26="","",(1/D26)*1000000) -> 38.948393 | K26: =IF(E26="","",(1/E26)*1000000) -> 65.108405 | L26: =IF(F26="","",(1/F26)*1000000) -> 209.95171 | M26: =IF(G26="","",(1/G26)*1000000) | N26: =IF(H26="","",(1/H26)*1000000) | O26: =IF(I26="","",(1/I26)*1000000)
A27: T1b | B27: AI / AO | C27: Interrupts | D27: 1191 | E27: 5934 | F27: 3555 | J27: =IF(D27="","",(1/D27)*1000000) -> 839.63056 | K27: =IF(E27="","",(1/E27)*1000000) -> 168.52039 | L27: =IF(F27="","",(1/F27)*1000000) -> 281.29395 | M27: =IF(G27="","",(1/G27)*1000000) | N27: =IF(H27="","",(1/H27)*1000000) | O27: =IF(I27="","",(1/I27)*1000000)
A28: T2a | B28: AI/PID/AO | C28: Polling | D28: 18345 | E28: 13424 | F28: 5000 | J28: =IF(D28="","",(1/D28)*1000000) -> 54.510766 | K28: =IF(E28="","",(1/E28)*1000000) -> 74.493445 | L28: =IF(F28="","",(1/F28)*1000000) -> 200 | M28: =IF(G28="","",(1/G28)*1000000) | N28: =IF(H28="","",(1/H28)*1000000) | O28: =IF(I28="","",(1/I28)*1000000)
A29: T2b | B29: AI/PID/AO | C29: Interrupts | D29: 6916 | E29: 5562 | F29: 3112 | J29: =IF(D29="","",(1/D29)*1000000) -> 144.59225 | K29: =IF(E29="","",(1/E29)*1000000) -> 179.79144 | L29: =IF(F29="","",(1/F29)*1000000) -> 321.33676 | M29: =IF(G29="","",(1/G29)*1000000) | N29: =IF(H29="","",(1/H29)*1000000) | O29: =IF(I29="","",(1/I29)*1000000)
A30: T3 | B30: AI/AO/Local Logging | C30: Interrupts | D30: 7524 | E30: 6325 | F30: 3555 | J30: =IF(D30="","",(1/D30)*1000000) -> 132.90803 | K30: =IF(E30="","",(1/E30)*1000000) -> 158.10277 | L30: =IF(F30="","",(1/F30)*1000000) -> 281.29395 | M30: =IF(G30="","",(1/G30)*1000000) | N30: =IF(H30="","",(1/H30)*1000000) | O30: =IF(I30="","",(1/I30)*1000000)
A31: T4 | B31: AI/AO/Host Comm. | C31: Interrupts | D31: 7477 | E31: 6255 | F31: 3534 | J31: =IF(D31="","",(1/D31)*1000000) -> 133.74348 | K31: =IF(E31="","",(1/E31)*1000000) -> 159.8721 | L31: =IF(F31="","",(1/F31)*1000000) -> 282.96548 | M31: =IF(G31="","",(1/G31)*1000000) | N31: =IF(H31="","",(1/H31)*1000000) | O31: =IF(I31="","",(1/I31)*1000000)
A32: Link to report : 9068_sp_online_poll_16.0b40
A33: Result Improvement vs. 2015 (% & uS)
A34: Test | D34: Number of Channels (%) | J34: Number of Channels, Difference in Period (uS)
A35: Acronym | B35: Description | C35: I/O Mode | D35: 1 | E35: 4 | F35: 16 | G35: 32 | H35: 64 | I35: 80 | J35: 1 | K35: 4 | L35: 16 | M35: 32 | N35: 64 | O35: 80
A36: T1a | B36: AI / AO | C36: Polling | D36: =IF(D26="","",(D26-'2015'!D92)/'2015'!D92) -> -0.44609842 | E36: =IF(E26="","",(E26-'2015'!E92)/'2015'!E92) -> -0.29494124 | F36: =IF(F26="","",(F26-'2015'!F92)/'2015'!F92) -> -0.27148975 | G36: =IF(G26="","",(G26-'2014'!G5)/'2014'!G5) | H36: =IF(H26="","",(H26-'2014'!H5)/'2014'!H5) | I36: =IF(I26="","",(I26-'2014'!I5)/'2014'!I5) | J36: =J26 - '2015'!J92 -> 17.374817 | K36: =K26 - '2015'!K92 -> 19.203154 | L36: =L26 - '2015'!L92 -> 56.999738 | M36: =IF(G36="","",M26-((1/'Proto 2013'!G36)*1000000)) | N36: =IF(H36="","",N26-((1/'Proto 2013'!H36)*1000000)) | O36: =IF(I36="","",O26-((1/'Proto 2013'!I36)*1000000))
A37: T1b | B37: AI / AO | C37: Interrupts | D37: =IF(D27="","",(D27-'2015'!D93)/'2015'!D93) -> -0.88925051 | E37: =IF(E27="","",(E27-'2015'!E93)/'2015'!E93) -> -0.29188544 | F37: =IF(F27="","",(F27-'2015'!F93)/'2015'!F93) -> -0.19968483 | G37: =IF(G27="","",(G27-'2014'!G6)/'2014'!G6) | H37: =IF(H27="","",(H27-'2014'!H6)/'2014'!H6) | I37: =IF(I27="","",(I27-'2014'!I6)/'2014'!I6) | J37: =J27 - '2015'!J93 -> 746.64191 | K37: =K27 - '2015'!K93 -> 49.188649 | L37: =L27 - '2015'!L93 -> 56.170134 | M37: =IF(G37="","",M27-((1/'Proto 2013'!G37)*1000000)) | N37: =IF(H37="","",N27-((1/'Proto 2013'!H37)*1000000)) | O37: =IF(I37="","",O27-((1/'Proto 2013'!I37)*1000000))
