Workbook

Sheet Comparisons
A1: LV RT 2013 cRIO Single-Point Benchmark Results (Hz)
A2: cRIO-9068, LV RT 2013, NI-RIO 13.0 (9205/9264) - 2min settling time
A3: Test | D3: Number of Channels, Rate (Hz) | J3: Number of Channels, Period (uS)
A4: Acronym | B4: Description | C4: I/O Mode | D4: 1 | E4: 4 | F4: 16 | G4: 32 | H4: 64 | I4: 80 | J4: 1 | K4: 4 | L4: 16 | M4: 32 | N4: 64 | O4: 80
A5: T1a | B5: AI / AO | C5: Polling | D5: 46662 | E5: 20867 | F5: 6003 | J5: =(1/D5)*1000000 -> 21.430715 | K5: =(1/E5)*1000000 -> 47.922557 | L5: =(1/F5)*1000000 -> 166.58337 | M5: =(1/G5)*1000000 -> #DIV/0! | N5: =(1/H5)*1000000 -> #DIV/0! | O5: =(1/I5)*1000000 -> #DIV/0!
A6: T1b | B6: AI / AO | C6: Interrupts | D6: 10917 | E6: 8443 | F6: 4375 | J6: =(1/D6)*1000000 -> 91.600256 | K6: =(1/E6)*1000000 -> 118.44131 | L6: =(1/F6)*1000000 -> 228.57143 | M6: =(1/G6)*1000000 -> #DIV/0! | N6: =(1/H6)*1000000 -> #DIV/0! | O6: =(1/I6)*1000000 -> #DIV/0!
A7: T2a | B7: AI/PID/AO | C7: Polling | D7: 39956 | E7: 16440 | F7: 5637 | J7: =(1/D7)*1000000 -> 25.02753 | K7: =(1/E7)*1000000 -> 60.827251 | L7: =(1/F7)*1000000 -> 177.39933 | M7: =(1/G7)*1000000 -> #DIV/0! | N7: =(1/H7)*1000000 -> #DIV/0! | O7: =(1/I7)*1000000 -> #DIV/0!
A8: T2b | B8: AI/PID/AO | C8: Interrupts | D8: 9234 | E8: 7537 | F8: 3895 | J8: =(1/D8)*1000000 -> 108.29543 | K8: =(1/E8)*1000000 -> 132.67878 | L8: =(1/F8)*1000000 -> 256.73941 | M8: =(1/G8)*1000000 -> #DIV/0! | N8: =(1/H8)*1000000 -> #DIV/0! | O8: =(1/I8)*1000000 -> #DIV/0!
A9: T3 | B9: AI/AO/Local Logging | C9: Interrupts | D9: 4390 | E9: 6675 | F9: 3502 | J9: =(1/D9)*1000000 -> 227.79043 | K9: =(1/E9)*1000000 -> 149.81273 | L9: =(1/F9)*1000000 -> 285.55111 | M9: =(1/G9)*1000000 -> #DIV/0! | N9: =(1/H9)*1000000 -> #DIV/0! | O9: =(1/I9)*1000000 -> #DIV/0!
A10: T4 | B10: AI/AO/Host Comm. | C10: Interrupts | D10: 4427 | E10: 5740 | F10: 3635 | J10: =(1/D10)*1000000 -> 225.8866 | K10: =(1/E10)*1000000 -> 174.21603 | L10: =(1/F10)*1000000 -> 275.10316 | M10: =(1/G10)*1000000 -> #DIV/0! | N10: =(1/H10)*1000000 -> #DIV/0! | O10: =(1/I10)*1000000 -> #DIV/0!
A12: LV RT 2013 cRIO Single-Point Benchmark Results (Hz)
A13: cRIO-9024, LV RT 2013rc35, NI-RIO 13.0.0a14 (9205/9264) - 2min settling time - Isolated Network, WITH REBOOTs
A14: Test | D14: Number of Channels, Rate (Hz) | J14: Number of Channels, Period (uS)
A15: Acronym | B15: Description | C15: I/O Mode | D15: 1 | E15: 4 | F15: 16 | G15: 32 | H15: 64 | I15: 80 | J15: 1 | K15: 4 | L15: 16 | M15: 32 | N15: 64 | O15: 80
A16: T1a | B16: AI / AO | C16: Polling | D16: 73726 | E16: 25908 | F16: 7005 | G16: 3508 | H16: 3156 | I16: 2478 | J16: =IF(D16="","",(1/D16)*1000000) -> 13.563736 | K16: =IF(E16="","",(1/E16)*1000000) -> 38.598116 | L16: =IF(F16="","",(1/F16)*1000000) -> 142.75517 | M16: =IF(G16="","",(1/G16)*1000000) -> 285.06271 | N16: =IF(H16="","",(1/H16)*1000000) -> 316.85678 | O16: =IF(I16="","",(1/I16)*1000000) -> 403.55125
A17: T1b | B17: AI / AO | C17: Interrupts | D17: 24523 | E17: 14839 | F17: 5291 | G17: 2876 | H17: 2534 | I17: 2380 | J17: =IF(D17="","",(1/D17)*1000000) -> 40.778045 | K17: =IF(E17="","",(1/E17)*1000000) -> 67.389986 | L17: =IF(F17="","",(1/F17)*1000000) -> 189.00019 | M17: =IF(G17="","",(1/G17)*1000000) -> 347.70515 | N17: =IF(H17="","",(1/H17)*1000000) -> 394.63299 | O17: =IF(I17="","",(1/I17)*1000000) -> 420.16807
A18: T2a | B18: AI/PID/AO | C18: Polling | D18: 71146 | E18: 21887 | J18: =IF(D18="","",(1/D18)*1000000) -> 14.055604 | K18: =IF(E18="","",(1/E18)*1000000) -> 45.689222 | L18: =IF(F18="","",(1/F18)*1000000) | M18: =IF(G18="","",(1/G18)*1000000) | N18: =IF(H18="","",(1/H18)*1000000) | O18: =IF(I18="","",(1/I18)*1000000)
A19: T2b | B19: AI/PID/AO | C19: Interrupts | D19: 19433 | E19: 10996 | J19: =IF(D19="","",(1/D19)*1000000) -> 51.458859 | K19: =IF(E19="","",(1/E19)*1000000) -> 90.942161 | L19: =IF(F19="","",(1/F19)*1000000) | M19: =IF(G19="","",(1/G19)*1000000) | N19: =IF(H19="","",(1/H19)*1000000) | O19: =IF(I19="","",(1/I19)*1000000)
A20: T3 | B20: AI/AO/Local Logging | C20: Interrupts | D20: 14820 | E20: 9178 | J20: =IF(D20="","",(1/D20)*1000000) -> 67.476383 | K20: =IF(E20="","",(1/E20)*1000000) -> 108.9562 | L20: =IF(F20="","",(1/F20)*1000000) | M20: =IF(G20="","",(1/G20)*1000000) | N20: =IF(H20="","",(1/H20)*1000000) | O20: =IF(I20="","",(1/I20)*1000000)
A21: T4 | B21: AI/AO/Host Comm. | C21: Interrupts | D21: 13566 | E21: 8901 | J21: =IF(D21="","",(1/D21)*1000000) -> 73.713696 | K21: =IF(E21="","",(1/E21)*1000000) -> 112.34693 | L21: =IF(F21="","",(1/F21)*1000000) | M21: =IF(G21="","",(1/G21)*1000000) | N21: =IF(H21="","",(1/H21)*1000000) | O21: =IF(I21="","",(1/I21)*1000000)

Sheet Proto 2014
A1: LV RT 2014 cRIO Single-Point Benchmark Results (Hz) | Q1: Max Numbers
A2: cRIO-9033 (revA) LV RT 2014a82, NI-RIO 14.0.0d209 (9205/9264)
A3: Test | D3: Number of Channels, Rate (Hz) | J3: Number of Channels, Period (uS) | Q3: Test | T3: Number of Channels, Rate (Hz) | Z3: Number of Channels, Period (uS)
A4: Acronym | B4: Description | C4: I/O Mode | D4: 1 | E4: 4 | F4: 16 | G4: 32 | H4: 64 | I4: 80 | J4: 1 | K4: 4 | L4: 16 | M4: 32 | N4: 64 | O4: 80 | Q4: Acronym | R4: Description | S4: I/O Mode | T4: 1 | U4: 4 | V4: 16 | W4: 32 | X4: 64 | Y4: 80 | Z4: 1 | AA4: 4 | AB4: 16 | AC4: 32 | AD4: 64 | AE4: 80
A5: T1a | B5: AI / AO | C5: Polling | D5: 42324 | E5: 19832 | F5: 6019 | J5: =IF(D5="","",(1/D5)*1000000) -> 23.627256 | K5: =IF(E5="","",(1/E5)*1000000) -> 50.423558 | L5: =IF(F5="","",(1/F5)*1000000) -> 166.14055 | M5: =IF(G5="","",(1/G5)*1000000) | N5: =IF(H5="","",(1/H5)*1000000) | O5: =IF(I5="","",(1/I5)*1000000) | Q5: T1a | R5: AI / AO | S5: Polling | T5: 43616 | U5: 20094 | V5: 6080 | Z5: =IF(T5="","",(1/T5)*1000000) -> 22.927366 | AA5: =IF(U5="","",(1/U5)*1000000) -> 49.766099 | AB5: =IF(V5="","",(1/V5)*1000000) -> 164.47368 | AC5: =IF(W5="","",(1/W5)*1000000) | AD5: =IF(X5="","",(1/X5)*1000000) | AE5: =IF(Y5="","",(1/Y5)*1000000)
A6: T1b | B6: AI / AO | C6: Interrupts | D6: 13314 | E6: 10273 | F6: 4200 | J6: =IF(D6="","",(1/D6)*1000000) -> 75.108908 | K6: =IF(E6="","",(1/E6)*1000000) -> 97.342548 | L6: =IF(F6="","",(1/F6)*1000000) -> 238.09524 | M6: =IF(G6="","",(1/G6)*1000000) | N6: =IF(H6="","",(1/H6)*1000000) | O6: =IF(I6="","",(1/I6)*1000000) | Q6: T1b | R6: AI / AO | S6: Interrupts | T6: 13974 | U6: 10347 | V6: 4314 | Z6: =IF(T6="","",(1/T6)*1000000) -> 71.561471 | AA6: =IF(U6="","",(1/U6)*1000000) -> 96.646371 | AB6: =IF(V6="","",(1/V6)*1000000) -> 231.80343 | AC6: =IF(W6="","",(1/W6)*1000000) | AD6: =IF(X6="","",(1/X6)*1000000) | AE6: =IF(Y6="","",(1/Y6)*1000000)
A7: T2a | B7: AI/PID/AO | C7: Polling | D7: 40668 | E7: 17969 | F7: 5809 | J7: =IF(D7="","",(1/D7)*1000000) -> 24.589358 | K7: =IF(E7="","",(1/E7)*1000000) -> 55.6514 | L7: =IF(F7="","",(1/F7)*1000000) -> 172.14667 | M7: =IF(G7="","",(1/G7)*1000000) | N7: =IF(H7="","",(1/H7)*1000000) | O7: =IF(I7="","",(1/I7)*1000000) | Q7: T2a | R7: AI/PID/AO | S7: Polling | T7: 41671 | U7: 18202 | V7: 5809 | Z7: =IF(T7="","",(1/T7)*1000000) -> 23.997504 | AA7: =IF(U7="","",(1/U7)*1000000) -> 54.939018 | AB7: =IF(V7="","",(1/V7)*1000000) -> 172.14667 | AC7: =IF(W7="","",(1/W7)*1000000) | AD7: =IF(X7="","",(1/X7)*1000000) | AE7: =IF(Y7="","",(1/Y7)*1000000)
A8: T2b | B8: AI/PID/AO | C8: Interrupts | D8: 13166 | E8: 7373 | F8: 4039 | J8: =IF(D8="","",(1/D8)*1000000) -> 75.953213 | K8: =IF(E8="","",(1/E8)*1000000) -> 135.63 | L8: =IF(F8="","",(1/F8)*1000000) -> 247.58604 | M8: =IF(G8="","",(1/G8)*1000000) | N8: =IF(H8="","",(1/H8)*1000000) | O8: =IF(I8="","",(1/I8)*1000000) | Q8: T2b | R8: AI/PID/AO | S8: Interrupts | T8: 13248 | U8: 8681 | V8: 4146 | Z8: =IF(T8="","",(1/T8)*1000000) -> 75.483092 | AA8: =IF(U8="","",(1/U8)*1000000) -> 115.1941 | AB8: =IF(V8="","",(1/V8)*1000000) -> 241.19633 | AC8: =IF(W8="","",(1/W8)*1000000) | AD8: =IF(X8="","",(1/X8)*1000000) | AE8: =IF(Y8="","",(1/Y8)*1000000)
A9: T3 | B9: AI/AO/Local Logging | C9: Interrupts | D9: 10528 | E9: 7667 | F9: 4267 | J9: =IF(D9="","",(1/D9)*1000000) -> 94.984802 | K9: =IF(E9="","",(1/E9)*1000000) -> 130.42911 | L9: =IF(F9="","",(1/F9)*1000000) -> 234.35669 | M9: =IF(G9="","",(1/G9)*1000000) | N9: =IF(H9="","",(1/H9)*1000000) | O9: =IF(I9="","",(1/I9)*1000000) | Q9: T3 | R9: AI/AO/Local Logging | S9: Interrupts | T9: 12840 | U9: 8768 | V9: 4340 | Z9: =IF(T9="","",(1/T9)*1000000) -> 77.88162 | AA9: =IF(U9="","",(1/U9)*1000000) -> 114.05109 | AB9: =IF(V9="","",(1/V9)*1000000) -> 230.41475 | AC9: =IF(W9="","",(1/W9)*1000000) | AD9: =IF(X9="","",(1/X9)*1000000) | AE9: =IF(Y9="","",(1/Y9)*1000000)
A10: T4 | B10: AI/AO/Host Comm. | C10: Interrupts | D10: 11669 | E10: 8415 | F10: 4293 | J10: =IF(D10="","",(1/D10)*1000000) -> 85.697146 | K10: =IF(E10="","",(1/E10)*1000000) -> 118.83541 | L10: =IF(F10="","",(1/F10)*1000000) -> 232.93734 | M10: =IF(G10="","",(1/G10)*1000000) | N10: =IF(H10="","",(1/H10)*1000000) | O10: =IF(I10="","",(1/I10)*1000000) | Q10: T4 | R10: AI/AO/Host Comm. | S10: Interrupts | T10: 12712 | U10: 8528 | V10: 4362 | Z10: =IF(T10="","",(1/T10)*1000000) -> 78.665828 | AA10: =IF(U10="","",(1/U10)*1000000) -> 117.26079 | AB10: =IF(V10="","",(1/V10)*1000000) -> 229.25264 | AC10: =IF(W10="","",(1/W10)*1000000) | AD10: =IF(X10="","",(1/X10)*1000000) | AE10: =IF(Y10="","",(1/Y10)*1000000)
A11: RIO IRQ priority bumped to 96
A12: Result Improvement vs. 2013 cRIO-9068 (% & uS)
A13: Test | D13: Number of Channels (%) | J13: Number of Channels, Difference in Period (uS)
A14: Acronym | B14: Description | C14: I/O Mode | D14: 1 | E14: 4 | F14: 16 | G14: 32 | H14: 64 | I14: 80 | J14: 1 | K14: 4 | L14: 16 | M14: 32 | N14: 64 | O14: 80
A15: T1a | B15: AI / AO | C15: Polling | D15: =IF(D5="","",(D5-Comparisons!D5)/Comparisons!D5) -> -0.09296644 | E15: =IF(E5="","",(E5-Comparisons!E5)/Comparisons!E5) -> -0.049599847 | F15: =IF(F5="","",(F5-Comparisons!F5)/Comparisons!F5) -> 0.002665334 | G15: =IF(G5="","",(G5-Comparisons!G5)/Comparisons!G5) | H15: =IF(H5="","",(H5-Comparisons!H5)/Comparisons!H5) | I15: =IF(I5="","",(I5-Comparisons!I5)/Comparisons!I5) | J15: =IF(D15="","",J5-((1/Comparisons!D5)*1000000)) -> 2.1965419 | K15: =IF(E15="","",K5-((1/Comparisons!E5)*1000000)) -> 2.5010007 | L15: =IF(F15="","",L5-((1/Comparisons!F5)*1000000)) -> -0.44282007 | M15: =IF(G15="","",M5-((1/Comparisons!G5)*1000000)) | N15: =IF(H15="","",N5-((1/Comparisons!H5)*1000000)) | O15: =IF(I15="","",O5-((1/Comparisons!I5)*1000000))
A16: T1b | B16: AI / AO | C16: Interrupts | D16: =IF(D6="","",(D6-Comparisons!D6)/Comparisons!D6) -> 0.21956581 | E16: =IF(E6="","",(E6-Comparisons!E6)/Comparisons!E6) -> 0.2167476 | F16: =IF(F6="","",(F6-Comparisons!F6)/Comparisons!F6) -> -0.04 | G16: =IF(G6="","",(G6-Comparisons!G6)/Comparisons!G6) | H16: =IF(H6="","",(H6-Comparisons!H6)/Comparisons!H6) | I16: =IF(I6="","",(I6-Comparisons!I6)/Comparisons!I6) | J16: =IF(D16="","",J6-((1/Comparisons!D6)*1000000)) -> -16.491349 | K16: =IF(E16="","",K6-((1/Comparisons!E6)*1000000)) -> -21.098764 | L16: =IF(F16="","",L6-((1/Comparisons!F6)*1000000)) -> 9.5238095 | M16: =IF(G16="","",M6-((1/Comparisons!G6)*1000000)) | N16: =IF(H16="","",N6-((1/Comparisons!H6)*1000000)) | O16: =IF(I16="","",O6-((1/Comparisons!I6)*1000000))
A17: T2a | B17: AI/PID/AO | C17: Polling | D17: =IF(D7="","",(D7-Comparisons!D7)/Comparisons!D7) -> 0.017819602 | E17: =IF(E7="","",(E7-Comparisons!E7)/Comparisons!E7) -> 0.093004866 | F17: =IF(F7="","",(F7-Comparisons!F7)/Comparisons!F7) -> 0.030512684 | G17: =IF(G7="","",(G7-Comparisons!G7)/Comparisons!G7) | H17: =IF(H7="","",(H7-Comparisons!H7)/Comparisons!H7) | I17: =IF(I7="","",(I7-Comparisons!I7)/Comparisons!I7) | J17: =IF(D17="","",J7-((1/Comparisons!D7)*1000000)) -> -0.43817256 | K17: =IF(E17="","",K7-((1/Comparisons!E7)*1000000)) -> -5.175851 | L17: =IF(F17="","",L7-((1/Comparisons!F7)*1000000)) -> -5.2526569 | M17: =IF(G17="","",M7-((1/Comparisons!G7)*1000000)) | N17: =IF(H17="","",N7-((1/Comparisons!H7)*1000000)) | O17: =IF(I17="","",O7-((1/Comparisons!I7)*1000000))
A18: T2b | B18: AI/PID/AO | C18: Interrupts | D18: =IF(D8="","",(D8-Comparisons!D8)/Comparisons!D8) -> 0.42581763 | E18: =IF(E8="","",(E8-Comparisons!E8)/Comparisons!E8) -> -0.021759321 | F18: =IF(F8="","",(F8-Comparisons!F8)/Comparisons!F8) -> 0.036970475 | G18: =IF(G8="","",(G8-Comparisons!G8)/Comparisons!G8) | H18: =IF(H8="","",(H8-Comparisons!H8)/Comparisons!H8) | I18: =IF(I8="","",(I8-Comparisons!I8)/Comparisons!I8) | J18: =IF(D18="","",J8-((1/Comparisons!D8)*1000000)) -> -32.342217 | K18: =IF(E18="","",K8-((1/Comparisons!E8)*1000000)) -> 2.9512167 | L18: =IF(F18="","",L8-((1/Comparisons!F8)*1000000)) -> -9.1533734 | M18: =IF(G18="","",M8-((1/Comparisons!G8)*1000000)) | N18: =IF(H18="","",N8-((1/Comparisons!H8)*1000000)) | O18: =IF(I18="","",O8-((1/Comparisons!I8)*1000000))
A19: T3 | B19: AI/AO/Local Logging | C19: Interrupts | D19: =IF(D9="","",(D9-Comparisons!D9)/Comparisons!D9) -> 1.3981777 | E19: =IF(E9="","",(E9-Comparisons!E9)/Comparisons!E9) -> 0.14861423 | F19: =IF(F9="","",(F9-Comparisons!F9)/Comparisons!F9) -> 0.2184466 | G19: =IF(G9="","",(G9-Comparisons!G9)/Comparisons!G9) | H19: =IF(H9="","",(H9-Comparisons!H9)/Comparisons!H9) | I19: =IF(I9="","",(I9-Comparisons!I9)/Comparisons!I9) | J19: =IF(D19="","",J9-((1/Comparisons!D9)*1000000)) -> -132.80563 | K19: =IF(E19="","",K9-((1/Comparisons!E9)*1000000)) -> -19.383622 | L19: =IF(F19="","",L9-((1/Comparisons!F9)*1000000)) -> -51.194423 | M19: =IF(G19="","",M9-((1/Comparisons!G9)*1000000)) | N19: =IF(H19="","",N9-((1/Comparisons!H9)*1000000)) | O19: =IF(I19="","",O9-((1/Comparisons!I9)*1000000))
A20: T4 | B20: AI/AO/Host Comm. | C20: Interrupts | D20: =IF(D10="","",(D10-Comparisons!D10)/Comparisons!D10) -> 1.6358708 | E20: =IF(E10="","",(E10-Comparisons!E10)/Comparisons!E10) -> 0.46602787 | F20: =IF(F10="","",(F10-Comparisons!F10)/Comparisons!F10) -> 0.18101788 | G20: =IF(G10="","",(G10-Comparisons!G10)/Comparisons!G10) | H20: =IF(H10="","",(H10-Comparisons!H10)/Comparisons!H10) | I20: =IF(I10="","",(I10-Comparisons!I10)/Comparisons!I10) | J20: =IF(D20="","",J10-((1/Comparisons!D10)*1000000)) -> -140.18946 | K20: =IF(E20="","",K10-((1/Comparisons!E10)*1000000)) -> -55.380615 | L20: =IF(F20="","",L10-((1/Comparisons!F10)*1000000)) -> -42.165824 | M20: =IF(G20="","",M10-((1/Comparisons!G10)*1000000)) | N20: =IF(H20="","",N10-((1/Comparisons!H10)*1000000)) | O20: =IF(I20="","",O10-((1/Comparisons!I10)*1000000))
A22: LV RT 2013 cRIO Single-Point Benchmark Results (Hz)
A23: cRIO-9068 (blue board), LV RT 2013b75, NI-RIO 13.0.0d229 (9205/9264) | Q23: Max Numbers
A24: Test | D24: Number of Channels, Rate (Hz) | J24: Number of Channels, Period (uS) | Q24: Test | T24: Number of Channels, Rate (Hz) | Z24: Number of Channels, Period (uS)
A25: Case | B25: Description | C25: I/O Mode | D25: 1 | E25: 4 | F25: 16 | G25: 32 | H25: 64 | I25: 80 | J25: 1 | K25: 4 | L25: 16 | M25: 32 | N25: 64 | O25: 80 | Q25: Case | R25: Description | S25: I/O Mode | T25: 1 | U25: 4 | V25: 16 | W25: 32 | X25: 64 | Y25: 80 | Z25: 1 | AA25: 4 | AB25: 16 | AC25: 32 | AD25: 64 | AE25: 80
A26: T1a | B26: AI / AO | C26: Polling | D26: 49932 | E26: 36058 | F26: 15922 | J26: =IF(D26="","",(1/D26)*1000000) -> 20.027237 | K26: =IF(E26="","",(1/E26)*1000000) -> 27.733097 | L26: =IF(F26="","",(1/F26)*1000000) -> 62.80618 | M26: =IF(G26="","",(1/G26)*1000000) | N26: =IF(H26="","",(1/H26)*1000000) | O26: =IF(I26="","",(1/I26)*1000000) | Q26: T1a | R26: AI / AO | S26: Polling | T26: 51861 | U26: 36604 | V26: 15842 | Z26: =IF(T26="","",(1/T26)*1000000) -> 19.282312 | AA26: =IF(U26="","",(1/U26)*1000000) -> 27.319419 | AB26: =IF(V26="","",(1/V26)*1000000) -> 63.123343 | AC26: =IF(W26="","",(1/W26)*1000000) | AD26: =IF(X26="","",(1/X26)*1000000) | AE26: =IF(Y26="","",(1/Y26)*1000000)
A27: T1b | B27: AI / AO | C27: Interrupts | D27: 9975 | E27: 9118 | F27: 6980 | J27: =IF(D27="","",(1/D27)*1000000) -> 100.25063 | K27: =IF(E27="","",(1/E27)*1000000) -> 109.67317 | L27: =IF(F27="","",(1/F27)*1000000) -> 143.26648 | M27: =IF(G27="","",(1/G27)*1000000) | N27: =IF(H27="","",(1/H27)*1000000) | O27: =IF(I27="","",(1/I27)*1000000) | Q27: T1b | R27: AI / AO | S27: Interrupts | T27: 10257 | U27: 9338 | V27: 7085 | Z27: =IF(T27="","",(1/T27)*1000000) -> 97.494394 | AA27: =IF(U27="","",(1/U27)*1000000) -> 107.08931 | AB27: =IF(V27="","",(1/V27)*1000000) -> 141.14326 | AC27: =IF(W27="","",(1/W27)*1000000) | AD27: =IF(X27="","",(1/X27)*1000000) | AE27: =IF(Y27="","",(1/Y27)*1000000)
A28: T2a | B28: AI/PID/AO | C28: Polling | D28: 44933 | E28: 19931 | F28: 11669 | J28: =IF(D28="","",(1/D28)*1000000) -> 22.255358 | K28: =IF(E28="","",(1/E28)*1000000) -> 50.173097 | L28: =IF(F28="","",(1/F28)*1000000) -> 85.697146 | M28: =IF(G28="","",(1/G28)*1000000) | N28: =IF(H28="","",(1/H28)*1000000) | O28: =IF(I28="","",(1/I28)*1000000) | Q28: T2a | R28: AI/PID/AO | S28: Polling | T28: 46391 | U28: 25261 | V28: 11826 | Z28: =IF(T28="","",(1/T28)*1000000) -> 21.555905 | AA28: =IF(U28="","",(1/U28)*1000000) -> 39.586715 | AB28: =IF(V28="","",(1/V28)*1000000) -> 84.559445 | AC28: =IF(W28="","",(1/W28)*1000000) | AD28: =IF(X28="","",(1/X28)*1000000) | AE28: =IF(Y28="","",(1/Y28)*1000000)
A29: T2b | B29: AI/PID/AO | C29: Interrupts | D29: 9757 | E29: 8283 | F29: 5975 | J29: =IF(D29="","",(1/D29)*1000000) -> 102.49052 | K29: =IF(E29="","",(1/E29)*1000000) -> 120.7292 | L29: =IF(F29="","",(1/F29)*1000000) -> 167.36402 | M29: =IF(G29="","",(1/G29)*1000000) | N29: =IF(H29="","",(1/H29)*1000000) | O29: =IF(I29="","",(1/I29)*1000000) | Q29: T2b | R29: AI/PID/AO | S29: Interrupts | T29: 9910 | U29: 8847 | V29: 6223 | Z29: =IF(T29="","",(1/T29)*1000000) -> 100.90817 | AA29: =IF(U29="","",(1/U29)*1000000) -> 113.03267 | AB29: =IF(V29="","",(1/V29)*1000000) -> 160.6942 | AC29: =IF(W29="","",(1/W29)*1000000) | AD29: =IF(X29="","",(1/X29)*1000000) | AE29: =IF(Y29="","",(1/Y29)*1000000)
A30: T3 | B30: AI/AO/Local Logging | C30: Interrupts | D30: 4341 | E30: 7315 | F30: 5368 | J30: =IF(D30="","",(1/D30)*1000000) -> 230.36167 | K30: =IF(E30="","",(1/E30)*1000000) -> 136.7054 | L30: =IF(F30="","",(1/F30)*1000000) -> 186.28912 | M30: =IF(G30="","",(1/G30)*1000000) | N30: =IF(H30="","",(1/H30)*1000000) | O30: =IF(I30="","",(1/I30)*1000000) | Q30: T3 | R30: AI/AO/Local Logging | S30: Interrupts | T30: 4508 | U30: 7315 | V30: 5371 | Z30: =IF(T30="","",(1/T30)*1000000) -> 221.82786 | AA30: =IF(U30="","",(1/U30)*1000000) -> 136.7054 | AB30: =IF(V30="","",(1/V30)*1000000) -> 186.18507 | AC30: =IF(W30="","",(1/W30)*1000000) | AD30: =IF(X30="","",(1/X30)*1000000) | AE30: =IF(Y30="","",(1/Y30)*1000000)
A31: T4 | B31: AI/AO/Host Comm. | C31: Interrupts | D31: 4306 | E31: 7170 | F31: 5447 | J31: =IF(D31="","",(1/D31)*1000000) -> 232.23409 | K31: =IF(E31="","",(1/E31)*1000000) -> 139.47001 | L31: =IF(F31="","",(1/F31)*1000000) -> 183.5873 | M31: =IF(G31="","",(1/G31)*1000000) | N31: =IF(H31="","",(1/H31)*1000000) | O31: =IF(I31="","",(1/I31)*1000000) | Q31: T4 | R31: AI/AO/Host Comm. | S31: Interrupts | T31: 4419 | U31: 7315 | V31: 6187 | Z31: =IF(T31="","",(1/T31)*1000000) -> 226.29554 | AA31: =IF(U31="","",(1/U31)*1000000) -> 136.7054 | AB31: =IF(V31="","",(1/V31)*1000000) -> 161.62922 | AC31: =IF(W31="","",(1/W31)*1000000) | AD31: =IF(X31="","",(1/X31)*1000000) | AE31: =IF(Y31="","",(1/Y31)*1000000)
D32: T1a: first run was actually 992, not sure why since subsequent runs were not affected by this.
A33: Result Improvement vs. "red board" (% & uS) | Q33: Result Improvement vs. cRIO-9024 (% & uS)
A34: Test | D34: Number of Channels (%) | J34: Number of Channels, Difference in Period (uS) | Q34: Test | T34: Number of Channels (%) | Z34: Number of Channels, Difference in Period (uS)
A35: Case | B35: Description | C35: I/O Mode | D35: 1 | E35: 4 | F35: 16 | G35: 32 | H35: 64 | I35: 80 | J35: 1 | K35: 4 | L35: 16 | M35: 32 | N35: 64 | O35: 80 | Q35: Case | R35: Description | S35: I/O Mode | T35: 1 | U35: 4 | V35: 16 | W35: 32 | X35: 64 | Y35: 80 | Z35: 1 | AA35: 4 | AB35: 16 | AC35: 32 | AD35: 64 | AE35: 80
A36: T1a | B36: AI / AO | C36: Polling | D36: =IF(D26="","",(D26-D5)/D5) -> 0.17975617 | E36: =IF(E26="","",(E26-E5)/E5) -> 0.81817265 | F36: =IF(F26="","",(F26-F5)/F5) -> 1.6452899 | G36: =IF(G26="","",(G26-Comparisons!G36)/Comparisons!G36) | H36: =IF(H26="","",(H26-Comparisons!H36)/Comparisons!H36) | I36: =IF(I26="","",(I26-Comparisons!I36)/Comparisons!I36) | J36: =IF(D36="","",J26-((1/D5)*1000000)) -> -3.6000194 | K36: =IF(E36="","",K26-((1/E5)*1000000)) -> -22.690461 | L36: =IF(F36="","",L26-((1/F5)*1000000)) -> -103.33437 | M36: =IF(G36="","",M26-((1/Comparisons!G36)*1000000)) | N36: =IF(H36="","",N26-((1/Comparisons!H36)*1000000)) | O36: =IF(I36="","",O26-((1/Comparisons!I36)*1000000)) | Q36: T1a | R36: AI / AO | S36: Polling | T36: =IF(D26="","",(D26-Comparisons!D5)/Comparisons!D5) -> 0.070078436 | U36: =IF(E26="","",(E26-Comparisons!E5)/Comparisons!E5) -> 0.72799157 | V36: =IF(F26="","",(F26-Comparisons!F5)/Comparisons!F5) -> 1.6523405 | W36: =IF(W26="","",(W26-Comparisons!W36)/Comparisons!W36) | X36: =IF(X26="","",(X26-Comparisons!X36)/Comparisons!X36) | Y36: =IF(Y26="","",(Y26-Comparisons!Y36)/Comparisons!Y36) | Z36: =IF(D26="","",J26-((1/Comparisons!D5)*1000000)) -> -1.4034775 | AA36: =IF(E26="","",K26-((1/Comparisons!E5)*1000000)) -> -20.18946 | AB36: =IF(F26="","",L26-((1/Comparisons!F5)*1000000)) -> -103.77719 | AC36: =IF(W36="","",AC26-((1/Comparisons!W36)*1000000)) | AD36: =IF(X36="","",AD26-((1/Comparisons!X36)*1000000)) | AE36: =IF(Y36="","",AE26-((1/Comparisons!Y36)*1000000))
A37: T1b | B37: AI / AO | C37: Interrupts | D37: =IF(D27="","",(D27-D6)/D6) -> -0.25078864 | E37: =IF(E27="","",(E27-E6)/E6) -> -0.11243064 | F37: =IF(F27="","",(F27-F6)/F6) -> 0.66190476 | G37: =IF(G27="","",(G27-Comparisons!G37)/Comparisons!G37) | H37: =IF(H27="","",(H27-Comparisons!H37)/Comparisons!H37) | I37: =IF(I27="","",(I27-Comparisons!I37)/Comparisons!I37) | J37: =IF(D37="","",J27-((1/D6)*1000000)) -> 25.141719 | K37: =IF(E37="","",K27-((1/E6)*1000000)) -> 12.330626 | L37: =IF(F37="","",L27-((1/F6)*1000000)) -> -94.828762 | M37: =IF(G37="","",M27-((1/Comparisons!G37)*1000000)) | N37: =IF(H37="","",N27-((1/Comparisons!H37)*1000000)) | O37: =IF(I37="","",O27-((1/Comparisons!I37)*1000000)) | Q37: T1b | R37: AI / AO | S37: Interrupts | T37: =IF(D27="","",(D27-Comparisons!D6)/Comparisons!D6) -> -0.086287442 | U37: =IF(E27="","",(E27-Comparisons!E6)/Comparisons!E6) -> 0.079947886 | V37: =IF(F27="","",(F27-Comparisons!F6)/Comparisons!F6) -> 0.59542857 | W37: =IF(W27="","",(W27-Comparisons!W37)/Comparisons!W37) | X37: =IF(X27="","",(X27-Comparisons!X37)/Comparisons!X37) | Y37: =IF(Y27="","",(Y27-Comparisons!Y37)/Comparisons!Y37) | Z37: =IF(D27="","",J27-((1/Comparisons!D6)*1000000)) -> 8.6503701 | AA37: =IF(E27="","",K27-((1/Comparisons!E6)*1000000)) -> -8.7681384 | AB37: =IF(F27="","",L27-((1/Comparisons!F6)*1000000)) -> -85.304953 | AC37: =IF(W37="","",AC27-((1/Comparisons!W37)*1000000)) | AD37: =IF(X37="","",AD27-((1/Comparisons!X37)*1000000)) | AE37: =IF(Y37="","",AE27-((1/Comparisons!Y37)*1000000))
A38: T2a | B38: AI/PID/AO | C38: Polling | D38: =IF(D28="","",(D28-D7)/D7) -> 0.10487361 | E38: =IF(E28="","",(E28-E7)/E7) -> 0.10918805 | F38: =IF(F28="","",(F28-F7)/F7) -> 1.0087795 | G38: =IF(G28="","",(G28-Comparisons!G38)/Comparisons!G38) | H38: =IF(H28="","",(H28-Comparisons!H38)/Comparisons!H38) | I38: =IF(I28="","",(I28-Comparisons!I38)/Comparisons!I38) | J38: =IF(D38="","",J28-((1/D7)*1000000)) -> -2.3339997 | K38: =IF(E38="","",K28-((1/E7)*1000000)) -> -5.4783024 | L38: =IF(F38="","",L28-((1/F7)*1000000)) -> -86.449523 | M38: =IF(G38="","",M28-((1/Comparisons!G38)*1000000)) | N38: =IF(H38="","",N28-((1/Comparisons!H38)*1000000)) | O38: =IF(I38="","",O28-((1/Comparisons!I38)*1000000)) | Q38: T2a | R38: AI/PID/AO | S38: Polling | T38: =IF(D28="","",(D28-Comparisons!D7)/Comparisons!D7) -> 0.12456202 | U38: =IF(E28="","",(E28-Comparisons!E7)/Comparisons!E7) -> 0.21234793 | V38: =IF(F28="","",(F28-Comparisons!F7)/Comparisons!F7) -> 1.0700727 | W38: =IF(W28="","",(W28-Comparisons!W38)/Comparisons!W38) | X38: =IF(X28="","",(X28-Comparisons!X38)/Comparisons!X38) | Y38: =IF(Y28="","",(Y28-Comparisons!Y38)/Comparisons!Y38) | Z38: =IF(D28="","",J28-((1/Comparisons!D7)*1000000)) -> -2.7721723 | AA38: =IF(E28="","",K28-((1/Comparisons!E7)*1000000)) -> -10.654153 | AB38: =IF(F28="","",L28-((1/Comparisons!F7)*1000000)) -> -91.70218 | AC38: =IF(W38="","",AC28-((1/Comparisons!W38)*1000000)) | AD38: =IF(X38="","",AD28-((1/Comparisons!X38)*1000000)) | AE38: =IF(Y38="","",AE28-((1/Comparisons!Y38)*1000000))
A39: T2b | B39: AI/PID/AO | C39: Interrupts | D39: =IF(D29="","",(D29-D8)/D8) -> -0.2589245 | E39: =IF(E29="","",(E29-E8)/E8) -> 0.1234233 | F39: =IF(F29="","",(F29-F8)/F8) -> 0.47932657 | G39: =IF(G29="","",(G29-Comparisons!G39)/Comparisons!G39) | H39: =IF(H29="","",(H29-Comparisons!H39)/Comparisons!H39) | I39: =IF(I29="","",(I29-Comparisons!I39)/Comparisons!I39) | J39: =IF(D39="","",J29-((1/D8)*1000000)) -> 26.537307 | K39: =IF(E39="","",K29-((1/E8)*1000000)) -> -14.900797 | L39: =IF(F39="","",L29-((1/F8)*1000000)) -> -80.222019 | M39: =IF(G39="","",M29-((1/Comparisons!G39)*1000000)) | N39: =IF(H39="","",N29-((1/Comparisons!H39)*1000000)) | O39: =IF(I39="","",O29-((1/Comparisons!I39)*1000000)) | Q39: T2b | R39: AI/PID/AO | S39: Interrupts | T39: =IF(D29="","",(D29-Comparisons!D8)/Comparisons!D8) -> 0.05663851 | U39: =IF(E29="","",(E29-Comparisons!E8)/Comparisons!E8) -> 0.098978373 | V39: =IF(F29="","",(F29-Comparisons!F8)/Comparisons!F8) -> 0.53401797 | W39: =IF(W29="","",(W29-Comparisons!W39)/Comparisons!W39) | X39: =IF(X29="","",(X29-Comparisons!X39)/Comparisons!X39) | Y39: =IF(Y29="","",(Y29-Comparisons!Y39)/Comparisons!Y39) | Z39: =IF(D29="","",J29-((1/Comparisons!D8)*1000000)) -> -5.8049103 | AA39: =IF(E29="","",K29-((1/Comparisons!E8)*1000000)) -> -11.94958 | AB39: =IF(F29="","",L29-((1/Comparisons!F8)*1000000)) -> -89.375393 | AC39: =IF(W39="","",AC29-((1/Comparisons!W39)*1000000)) | AD39: =IF(X39="","",AD29-((1/Comparisons!X39)*1000000)) | AE39: =IF(Y39="","",AE29-((1/Comparisons!Y39)*1000000))
A40: T3 | B40: AI/AO/Local Logging | C40: Interrupts | D40: =IF(D30="","",(D30-D9)/D9) -> -0.58767097 | E40: =IF(E30="","",(E30-E9)/E9) -> -0.045911047 | F40: =IF(F30="","",(F30-F9)/F9) -> 0.25802672 | G40: =IF(G30="","",(G30-Comparisons!G40)/Comparisons!G40) | H40: =IF(H30="","",(H30-Comparisons!H40)/Comparisons!H40) | I40: =IF(I30="","",(I30-Comparisons!I40)/Comparisons!I40) | J40: =IF(D40="","",J30-((1/D9)*1000000)) -> 135.37687 | K40: =IF(E40="","",K30-((1/E9)*1000000)) -> 6.2762881 | L40: =IF(F40="","",L30-((1/F9)*1000000)) -> -48.06757 | M40: =IF(G40="","",M30-((1/Comparisons!G40)*1000000)) | N40: =IF(H40="","",N30-((1/Comparisons!H40)*1000000)) | O40: =IF(I40="","",O30-((1/Comparisons!I40)*1000000)) | Q40: T3 | R40: AI/AO/Local Logging | S40: Interrupts | T40: =IF(D30="","",(D30-Comparisons!D9)/Comparisons!D9) -> -0.011161731 | U40: =IF(E30="","",(E30-Comparisons!E9)/Comparisons!E9) -> 0.09588015 | V40: =IF(F30="","",(F30-Comparisons!F9)/Comparisons!F9) -> 0.53283838 | W40: =IF(W30="","",(W30-Comparisons!W40)/Comparisons!W40) | X40: =IF(X30="","",(X30-Comparisons!X40)/Comparisons!X40) | Y40: =IF(Y30="","",(Y30-Comparisons!Y40)/Comparisons!Y40) | Z40: =IF(D30="","",J30-((1/Comparisons!D9)*1000000)) -> 2.571235 | AA40: =IF(E30="","",K30-((1/Comparisons!E9)*1000000)) -> -13.107334 | AB40: =IF(F30="","",L30-((1/Comparisons!F9)*1000000)) -> -99.261993 | AC40: =IF(W40="","",AC30-((1/Comparisons!W40)*1000000)) | AD40: =IF(X40="","",AD30-((1/Comparisons!X40)*1000000)) | AE40: =IF(Y40="","",AE30-((1/Comparisons!Y40)*1000000))
A41: T4 | B41: AI/AO/Host Comm. | C41: Interrupts | D41: =IF(D31="","",(D31-D10)/D10) -> -0.63098809 | E41: =IF(E31="","",(E31-E10)/E10) -> -0.14795009 | F41: =IF(F31="","",(F31-F10)/F10) -> 0.26880969 | G41: =IF(G31="","",(G31-Comparisons!G41)/Comparisons!G41) | H41: =IF(H31="","",(H31-Comparisons!H41)/Comparisons!H41) | I41: =IF(I31="","",(I31-Comparisons!I41)/Comparisons!I41) | J41: =IF(D41="","",J31-((1/D10)*1000000)) -> 146.53695 | K41: =IF(E41="","",K31-((1/E10)*1000000)) -> 20.634601 | L41: =IF(F41="","",L31-((1/F10)*1000000)) -> -49.350044 | M41: =IF(G41="","",M31-((1/Comparisons!G41)*1000000)) | N41: =IF(H41="","",N31-((1/Comparisons!H41)*1000000)) | O41: =IF(I41="","",O31-((1/Comparisons!I41)*1000000)) | Q41: T4 | R41: AI/AO/Host Comm. | S41: Interrupts | T41: =IF(D31="","",(D31-Comparisons!D10)/Comparisons!D10) -> -0.027332279 | U41: =IF(E31="","",(E31-Comparisons!E10)/Comparisons!E10) -> 0.24912892 | V41: =IF(F31="","",(F31-Comparisons!F10)/Comparisons!F10) -> 0.49848693 | W41: =IF(W31="","",(W31-Comparisons!W41)/Comparisons!W41) | X41: =IF(X31="","",(X31-Comparisons!X41)/Comparisons!X41) | Y41: =IF(Y31="","",(Y31-Comparisons!Y41)/Comparisons!Y41) | Z41: =IF(D31="","",J31-((1/Comparisons!D10)*1000000)) -> 6.347487 | AA41: =IF(E31="","",K31-((1/Comparisons!E10)*1000000)) -> -34.746014 | AB41: =IF(F31="","",L31-((1/Comparisons!F10)*1000000)) -> -91.515868 | AC41: =IF(W41="","",AC31-((1/Comparisons!W41)*1000000)) | AD41: =IF(X41="","",AD31-((1/Comparisons!X41)*1000000)) | AE41: =IF(Y41="","",AE31-((1/Comparisons!Y41)*1000000))
...

Sheet 2015
A1: LV RT 2015 cRIO Single-Point Benchmark Results (Hz)
A2: cRIO-9033 LV RT 15.0b50, NI-RIO 14.5.0.0
A3: Test | D3: Number of Channels, Rate (Hz) | J3: Number of Channels, Period (uS)
A4: Case | B4: Description | C4: I/O Mode | D4: 1 | E4: 4 | F4: 16 | G4: 32 | H4: 64 | I4: 80 | J4: 1 | K4: 4 | L4: 16 | M4: 32 | N4: 64 | O4: 80
A5: T1a | B5: AI / AO | C5: Polling | D5: 42666 | E5: 43881 | F5: 20623 | J5: =IF(D5="","",(1/D5)*1000000) -> 23.437866 | K5: =IF(E5="","",(1/E5)*1000000) -> 22.788906 | L5: =IF(F5="","",(1/F5)*1000000) -> 48.489551 | M5: =IF(G5="","",(1/G5)*1000000) | N5: =IF(H5="","",(1/H5)*1000000) | O5: =IF(I5="","",(1/I5)*1000000)
A6: T1b | B6: AI / AO | C6: Interrupts | D6: 16526 | E6: 15288 | F6: 12487 | J6: =IF(D6="","",(1/D6)*1000000) -> 60.51071 | K6: =IF(E6="","",(1/E6)*1000000) -> 65.41078 | L6: =IF(F6="","",(1/F6)*1000000) -> 80.083287 | M6: =IF(G6="","",(1/G6)*1000000) | N6: =IF(H6="","",(1/H6)*1000000) | O6: =IF(I6="","",(1/I6)*1000000)
A7: T2a | B7: AI/PID/AO | C7: Polling | D7: 49427 | E7: 34310 | F7: 17802 | J7: =IF(D7="","",(1/D7)*1000000) -> 20.231857 | K7: =IF(E7="","",(1/E7)*1000000) -> 29.146022 | L7: =IF(F7="","",(1/F7)*1000000) -> 56.173464 | M7: =IF(G7="","",(1/G7)*1000000) | N7: =IF(H7="","",(1/H7)*1000000) | O7: =IF(I7="","",(1/I7)*1000000)
A8: T2b | B8: AI/PID/AO | C8: Interrupts | D8: 16609 | E8: 13841 | F8: 10804 | J8: =IF(D8="","",(1/D8)*1000000) -> 60.208321 | K8: =IF(E8="","",(1/E8)*1000000) -> 72.249115 | L8: =IF(F8="","",(1/F8)*1000000) -> 92.558312 | M8: =IF(G8="","",(1/G8)*1000000) | N8: =IF(H8="","",(1/H8)*1000000) | O8: =IF(I8="","",(1/I8)*1000000)
A9: T3 | B9: AI/AO/Local Logging | C9: Interrupts | D9: 13381 | E9: 13670 | F9: 10843 | J9: =IF(D9="","",(1/D9)*1000000) -> 74.73283 | K9: =IF(E9="","",(1/E9)*1000000) -> 73.15289 | L9: =IF(F9="","",(1/F9)*1000000) -> 92.225399 | M9: =IF(G9="","",(1/G9)*1000000) | N9: =IF(H9="","",(1/H9)*1000000) | O9: =IF(I9="","",(1/I9)*1000000)
A10: T4 | B10: AI/AO/Host Comm. | C10: Interrupts | D10: 10544 | E10: 13157 | F10: 8561 | J10: =IF(D10="","",(1/D10)*1000000) -> 94.840668 | K10: =IF(E10="","",(1/E10)*1000000) -> 76.005168 | L10: =IF(F10="","",(1/F10)*1000000) -> 116.80878 | M10: =IF(G10="","",(1/G10)*1000000) | N10: =IF(H10="","",(1/H10)*1000000) | O10: =IF(I10="","",(1/I10)*1000000)
A11: http://us-aus-rtweb1.natinst.com/Reports/RT/2015/performance/rtlinux/rtperf-smasher/sp_online_int_reboots/2015-03-12_10-24-24/HTML/2015-03-12_10-32-35_SinglePointBenchmarks_ATS.html
A12: Result Improvement vs. LV RT 14.0 released (with out UI)
A13: Test | D13: Number of Channels (%) | J13: Number of Channels, Difference in Period (uS)
A14: Acronym | B14: Description | C14: I/O Mode | D14: 1 | E14: 4 | F14: 16 | G14: 32 | H14: 64 | I14: 80 | J14: 1 | K14: 4 | L14: 16 | M14: 32 | N14: 64 | O14: 80
A15: T1a | B15: AI / AO | C15: Polling | D15: =IF(D35="","",(D35-'Proto 2014'!D184)/'Proto 2014'!D184) -> -0.076053532 | E15: =IF(E5="","",(E5-'Proto 2014'!E184)/'Proto 2014'!E184) -> 0.10281478 | F15: =IF(F5="","",(F5-'Proto 2014'!F184)/'Proto 2014'!F184) -> -0.0050176099 | G15: =IF(G5="","",(G5-#REF!)/#REF!) | H15: =IF(H5="","",(H5-#REF!)/#REF!) | I15: =IF(I5="","",(I5-#REF!)/#REF!) | J15: =J5-'Proto 2014'!J184 -> 1.7825325 | K15: =K5-'Proto 2014'!K184 -> -2.3430363 | L15: =L5-'Proto 2014'!L184 -> 0.24330165 | M15: =IF(G15="","",M5-((1/Comparisons!G5)*1000000)) | N15: =IF(H15="","",N5-((1/Comparisons!H5)*1000000)) | O15: =IF(I15="","",O5-((1/Comparisons!I5)*1000000))
A16: T1b | B16: AI / AO | C16: Interrupts | D16: =IF(D6="","",(D6-'Proto 2014'!D185)/'Proto 2014'!D185) -> 0.21140595 | E16: =IF(E6="","",(E6-'Proto 2014'!E185)/'Proto 2014'!E185) -> 0.25414274 | F16: =IF(F6="","",(F6-'Proto 2014'!F185)/'Proto 2014'!F185) -> 0.21788745 | G16: =IF(G6="","",(G6-#REF!)/#REF!) | H16: =IF(H6="","",(H6-#REF!)/#REF!) | I16: =IF(I6="","",(I6-#REF!)/#REF!) | J16: =J6-'Proto 2014'!J185 -> -12.792324 | K16: =K6-'Proto 2014'!K185 -> -16.623675 | L16: =L6-'Proto 2014'!L185 -> -17.449143 | M16: =IF(G16="","",M6-((1/Comparisons!G6)*1000000)) | N16: =IF(H16="","",N6-((1/Comparisons!H6)*1000000)) | O16: =IF(I16="","",O6-((1/Comparisons!I6)*1000000))
A17: T2a | B17: AI/PID/AO | C17: Polling | D17: =IF(D7="","",(D7-'Proto 2014'!D186)/'Proto 2014'!D186) -> 0.11896677 | E17: =IF(E7="","",(E7-'Proto 2014'!E186)/'Proto 2014'!E186) -> 0.030423161 | F17: =IF(F7="","",(F7-'Proto 2014'!F186)/'Proto 2014'!F186) -> 0.025401763 | G17: =IF(G7="","",(G7-#REF!)/#REF!) | H17: =IF(H7="","",(H7-#REF!)/#REF!) | I17: =IF(I7="","",(I7-#REF!)/#REF!) | J17: =J7-'Proto 2014'!J186 -> -2.4069186 | K17: =K7-'Proto 2014'!K186 -> -0.88671411 | L17: =L7-'Proto 2014'!L186 -> -1.426905 | M17: =IF(G17="","",M7-((1/Comparisons!G7)*1000000)) | N17: =IF(H17="","",N7-((1/Comparisons!H7)*1000000)) | O17: =IF(I17="","",O7-((1/Comparisons!I7)*1000000))
A18: T2b | B18: AI/PID/AO | C18: Interrupts | D18: =IF(D8="","",(D8-'Proto 2014'!D187)/'Proto 2014'!D187) -> 0.28702053 | E18: =IF(E8="","",(E8-'Proto 2014'!E187)/'Proto 2014'!E187) -> 0.15814576 | F18: =IF(F8="","",(F8-'Proto 2014'!F187)/'Proto 2014'!F187) -> 0.12249351 | G18: =IF(G8="","",(G8-#REF!)/#REF!) | H18: =IF(H8="","",(H8-#REF!)/#REF!) | I18: =IF(I8="","",(I8-#REF!)/#REF!) | J18: =J8-'Proto 2014'!J187 -> -17.281024 | K18: =K8-'Proto 2014'!K187 -> -11.425891 | L18: =L8-'Proto 2014'!L187 -> -11.337792 | M18: =IF(G18="","",M8-((1/Comparisons!G8)*1000000)) | N18: =IF(H18="","",N8-((1/Comparisons!H8)*1000000)) | O18: =IF(I18="","",O8-((1/Comparisons!I8)*1000000))
A19: T3 | B19: AI/AO/Local Logging | C19: Interrupts | D19: =IF(D9="","",(D9-'Proto 2014'!D188)/'Proto 2014'!D188) -> 0.39211402 | E19: =IF(E9="","",(E9-'Proto 2014'!E188)/'Proto 2014'!E188) -> 0.11619172 | F19: =IF(F9="","",(F9-'Proto 2014'!F188)/'Proto 2014'!F188) -> 0.058679945 | G19: =IF(G9="","",(G9-#REF!)/#REF!) | H19: =IF(H9="","",(H9-#REF!)/#REF!) | I19: =IF(I9="","",(I9-#REF!)/#REF!) | J19: =J9-'Proto 2014'!J188 -> -29.303791 | K19: =K9-'Proto 2014'!K188 -> -8.4997601 | L19: =L9-'Proto 2014'!L188 -> -5.4117814 | M19: =IF(G19="","",M9-((1/Comparisons!G9)*1000000)) | N19: =IF(H19="","",N9-((1/Comparisons!H9)*1000000)) | O19: =IF(I19="","",O9-((1/Comparisons!I9)*1000000))
A20: T4 | B20: AI/AO/Host Comm. | C20: Interrupts | D20: =IF(D10="","",(D10-'Proto 2014'!D189)/'Proto 2014'!D189) -> 0.19181643 | E20: =IF(E10="","",(E10-'Proto 2014'!E189)/'Proto 2014'!E189) -> 0.48717079 | F20: =IF(F10="","",(F10-'Proto 2014'!F189)/'Proto 2014'!F189) -> -0.16600097 | G20: =IF(G10="","",(G10-#REF!)/#REF!) | H20: =IF(H10="","",(H10-#REF!)/#REF!) | I20: =IF(I10="","",(I10-#REF!)/#REF!) | J20: =J10-'Proto 2014'!J189 -> -18.191999 | K20: =K10-'Proto 2014'!K189 -> -37.027498 | L20: =L10-'Proto 2014'!L189 -> 19.390372 | M20: =IF(G20="","",M10-((1/Comparisons!G10)*1000000)) | N20: =IF(H20="","",N10-((1/Comparisons!H10)*1000000)) | O20: =IF(I20="","",O10-((1/Comparisons!I10)*1000000))
A22: Result Improvement vs. LV RT 14.0 released (with UI)
A23: Test | D23: Number of Channels (%) | J23: Number of Channels, Difference in Period (uS)
A24: Acronym | B24: Description | C24: I/O Mode | D24: 1 | E24: 4 | F24: 16 | G24: 32 | H24: 64 | I24: 80 | J24: 1 | K24: 4 | L24: 16 | M24: 32 | N24: 64 | O24: 80
A25: T1a | B25: AI / AO | C25: Polling | D25: =IF(D5="","",(D5-'Proto 2014'!D163)/'Proto 2014'!D163) -> -0.071408362 | E25: =IF(E5="","",(E5-'Proto 2014'!E163)/'Proto 2014'!E163) -> 0.10467487 | F25: =IF(F5="","",(F5-'Proto 2014'!F163)/'Proto 2014'!F163) -> -0.0099851183 | G25: =IF(G15="","",(G15-#REF!)/#REF!) | H25: =IF(H15="","",(H15-#REF!)/#REF!) | I25: =IF(I15="","",(I15-#REF!)/#REF!) | J25: =J5-'Proto 2014'!J163 -> 1.6736596 | K25: =K5-'Proto 2014'!K163 -> -2.3854259 | L25: =L5-'Proto 2014'!L163 -> 0.4841739 | M25: =IF(G25="","",M15-((1/Comparisons!G15)*1000000)) | N25: =IF(H25="","",N15-((1/Comparisons!H15)*1000000)) | O25: =IF(I25="","",O15-((1/Comparisons!I15)*1000000))
A26: T1b | B26: AI / AO | C26: Interrupts | D26: =IF(D6="","",(D6-'Proto 2014'!D164)/'Proto 2014'!D164) -> 0.23503475 | E26: =IF(E6="","",(E6-'Proto 2014'!E164)/'Proto 2014'!E164) -> 0.18200093 | F26: =IF(F6="","",(F6-'Proto 2014'!F164)/'Proto 2014'!F164) -> 0.1966459 | G26: =IF(G16="","",(G16-#REF!)/#REF!) | H26: =IF(H16="","",(H16-#REF!)/#REF!) | I26: =IF(I16="","",(I16-#REF!)/#REF!) | J26: =J6-'Proto 2014'!J164 -> -14.22212 | K26: =K6-'Proto 2014'!K164 -> -11.904823 | L26: =L6-'Proto 2014'!L164 -> -15.74805 | M26: =IF(G26="","",M16-((1/Comparisons!G16)*1000000)) | N26: =IF(H26="","",N16-((1/Comparisons!H16)*1000000)) | O26: =IF(I26="","",O16-((1/Comparisons!I16)*1000000))
A27: T2a | B27: AI/PID/AO | C27: Polling | D27: =IF(D7="","",(D7-'Proto 2014'!D165)/'Proto 2014'!D165) -> 0.12782658 | E27: =IF(E7="","",(E7-'Proto 2014'!E165)/'Proto 2014'!E165) -> 0.038092645 | F27: =IF(F7="","",(F7-'Proto 2014'!F165)/'Proto 2014'!F165) -> -0.013521002 | G27: =IF(G17="","",(G17-#REF!)/#REF!) | H27: =IF(H17="","",(H17-#REF!)/#REF!) | I27: =IF(I17="","",(I17-#REF!)/#REF!) | J27: =J7-'Proto 2014'!J165 -> -2.5861692 | K27: =K7-'Proto 2014'!K165 -> -1.110249 | L27: =L7-'Proto 2014'!L165 -> 0.75952151 | M27: =IF(G27="","",M17-((1/Comparisons!G17)*1000000)) | N27: =IF(H27="","",N17-((1/Comparisons!H17)*1000000)) | O27: =IF(I27="","",O17-((1/Comparisons!I17)*1000000))
A28: T2b | B28: AI/PID/AO | C28: Interrupts | D28: =IF(D8="","",(D8-'Proto 2014'!D166)/'Proto 2014'!D166) -> 0.23486989 | E28: =IF(E8="","",(E8-'Proto 2014'!E166)/'Proto 2014'!E166) -> 0.13015432 | F28: =IF(F8="","",(F8-'Proto 2014'!F166)/'Proto 2014'!F166) -> 0.12039822 | G28: =IF(G18="","",(G18-#REF!)/#REF!) | H28: =IF(H18="","",(H18-#REF!)/#REF!) | I28: =IF(I18="","",(I18-#REF!)/#REF!) | J28: =J8-'Proto 2014'!J166 -> -14.141122 | K28: =K8-'Proto 2014'!K166 -> -9.4035347 | L28: =L8-'Proto 2014'!L166 -> -11.143856 | M28: =IF(G28="","",M18-((1/Comparisons!G18)*1000000)) | N28: =IF(H28="","",N18-((1/Comparisons!H18)*1000000)) | O28: =IF(I28="","",O18-((1/Comparisons!I18)*1000000))
A29: T3 | B29: AI/AO/Local Logging | C29: Interrupts | D29: =IF(D9="","",(D9-'Proto 2014'!D167)/'Proto 2014'!D167) -> 0.2603372 | E29: =IF(E9="","",(E9-'Proto 2014'!E167)/'Proto 2014'!E167) -> 0.18519161 | F29: =IF(F9="","",(F9-'Proto 2014'!F167)/'Proto 2014'!F167) -> 0.063873626 | G29: =IF(G19="","",(G19-#REF!)/#REF!) | H29: =IF(H19="","",(H19-#REF!)/#REF!) | I29: =IF(I19="","",(I19-#REF!)/#REF!) | J29: =J9-'Proto 2014'!J167 -> -19.455735 | K29: =K9-'Proto 2014'!K167 -> -13.547301 | L29: =L9-'Proto 2014'!L167 -> -5.8907707 | M29: =IF(G29="","",M19-((1/Comparisons!G19)*1000000)) | N29: =IF(H29="","",N19-((1/Comparisons!H19)*1000000)) | O29: =IF(I29="","",O19-((1/Comparisons!I19)*1000000))
A30: T4 | B30: AI/AO/Host Comm. | C30: Interrupts | D30: =IF(D10="","",(D10-'Proto 2014'!D168)/'Proto 2014'!D168) -> -0.033989922 | E30: =IF(E10="","",(E10-'Proto 2014'!E168)/'Proto 2014'!E168) -> 0.32164741 | F30: =IF(F10="","",(F10-'Proto 2014'!F168)/'Proto 2014'!F168) -> -0.17547915 | G30: =IF(G20="","",(G20-#REF!)/#REF!) | H30: =IF(H20="","",(H20-#REF!)/#REF!) | I30: =IF(I20="","",(I20-#REF!)/#REF!) | J30: =J10-'Proto 2014'!J168 -> 3.2236269 | K30: =K10-'Proto 2014'!K168 -> -24.446866 | L30: =L10-'Proto 2014'!L168 -> 20.497506 | M30: =IF(G30="","",M20-((1/Comparisons!G20)*1000000)) | N30: =IF(H30="","",N20-((1/Comparisons!H20)*1000000)) | O30: =IF(I30="","",O20-((1/Comparisons!I20)*1000000))
A32: cRIO-9033 LV RT 15.0rc16, CRIO 15.0.0
A33: Test | D33: Number of Channels, Rate (Hz) | J33: Number of Channels, Period (uS)
A34: Case | B34: Description | C34: I/O Mode | D34: 1 | E34: 4 | F34: 16 | G34: 32 | H34: 64 | I34: 80 | J34: 1 | K34: 4 | L34: 16 | M34: 32 | N34: 64 | O34: 80
A35: T1a | B35: AI / AO | C35: Polling | D35: 42666 | E35: 43007 | F35: 20641 | J35: =IF(D35="","",(1/D35)*1000000) -> 23.437866 | K35: =IF(E35="","",(1/E35)*1000000) -> 23.252029 | L35: =IF(F35="","",(1/F35)*1000000) -> 48.447265 | M35: =IF(G35="","",(1/G35)*1000000) | N35: =IF(H35="","",(1/H35)*1000000) | O35: =IF(I35="","",(1/I35)*1000000)
A36: T1b | B36: AI / AO | C36: Interrupts | D36: 16274 | E36: 15288 | F36: 12212 | J36: =IF(D36="","",(1/D36)*1000000) -> 61.447708 | K36: =IF(E36="","",(1/E36)*1000000) -> 65.41078 | L36: =IF(F36="","",(1/F36)*1000000) -> 81.886669 | M36: =IF(G36="","",(1/G36)*1000000) | N36: =IF(H36="","",(1/H36)*1000000) | O36: =IF(I36="","",(1/I36)*1000000)
A37: T2a | B37: AI/PID/AO | C37: Polling | D37: 49914 | E37: 37110 | F37: 19031 | J37: =IF(D37="","",(1/D37)*1000000) -> 20.034459 | K37: =IF(E37="","",(1/E37)*1000000) -> 26.946915 | L37: =IF(F37="","",(1/F37)*1000000) -> 52.545846 | M37: =IF(G37="","",(1/G37)*1000000) | N37: =IF(H37="","",(1/H37)*1000000) | O37: =IF(I37="","",(1/I37)*1000000)
A38: T2b | B38: AI/PID/AO | C38: Interrupts | D38: 15236 | E38: 14399 | F38: 10843 | J38: =IF(D38="","",(1/D38)*1000000) -> 65.634025 | K38: =IF(E38="","",(1/E38)*1000000) -> 69.449267 | L38: =IF(F38="","",(1/F38)*1000000) -> 92.225399 | M38: =IF(G38="","",(1/G38)*1000000) | N38: =IF(H38="","",(1/H38)*1000000) | O38: =IF(I38="","",(1/I38)*1000000)
A39: T3 | B39: AI/AO/Local Logging | C39: Interrupts | D39: 12740 | E39: 13670 | F39: 10843 | J39: =IF(D39="","",(1/D39)*1000000) -> 78.492936 | K39: =IF(E39="","",(1/E39)*1000000) -> 73.15289 | L39: =IF(F39="","",(1/F39)*1000000) -> 92.225399 | M39: =IF(G39="","",(1/G39)*1000000) | N39: =IF(H39="","",(1/H39)*1000000) | O39: =IF(I39="","",(1/I39)*1000000)
A40: T4 | B40: AI/AO/Host Comm. | C40: Interrupts | D40: 10458 | E40: 12974 | F40: 11041 | J40: =IF(D40="","",(1/D40)*1000000) -> 95.620578 | K40: =IF(E40="","",(1/E40)*1000000) -> 77.077231 | L40: =IF(F40="","",(1/F40)*1000000) -> 90.571506 | M40: =IF(G40="","",(1/G40)*1000000) | N40: =IF(H40="","",(1/H40)*1000000) | O40: =IF(I40="","",(1/I40)*1000000)
A41: http://us-aus-rtweb1.natinst.com/Reports/RT/2015/performance/rtlinux/rtperf-smasher/sp_online_int_reboots/2015-06-10_02-50-18/HTML/2015-06-10_02-57-40_SinglePointBenchmarks_ATS.html
A42: Result Improvement vs. LV RT 14.0 released (with out UI)
...

Sheet 2016
A1: LV RT 2016 cRIO Single-Point Benchmark Results (Hz)
A2: cRIO-9033 LV RT 16.0, NI-RIO 16.0
A3: Test | D3: Number of Channels, Rate (Hz) | J3: Number of Channels, Period (uS)
A4: Case | B4: Description | C4: I/O Mode | D4: 1 | E4: 4 | F4: 16 | G4: 32 | H4: 64 | I4: 80 | J4: 1 | K4: 4 | L4: 16 | M4: 32 | N4: 64 | O4: 80
A5: T1a | B5: AI / AO | C5: Polling | D5: 44814 | E5: 20094 | F5: 5843 | J5: =IF(D5="","",(1/D5)*1000000) -> 22.314455 | K5: =IF(E5="","",(1/E5)*1000000) -> 49.766099 | L5: =IF(F5="","",(1/F5)*1000000) -> 171.14496 | M5: =IF(G5="","",(1/G5)*1000000) | N5: =IF(H5="","",(1/H5)*1000000) | O5: =IF(I5="","",(1/I5)*1000000)
A6: T1b | B6: AI / AO | C6: Interrupts | D6: 14914 | E6: 10832 | F6: 4777 | J6: =IF(D6="","",(1/D6)*1000000) -> 67.051093 | K6: =IF(E6="","",(1/E6)*1000000) -> 92.319055 | L6: =IF(F6="","",(1/F6)*1000000) -> 209.3364 | M6: =IF(G6="","",(1/G6)*1000000) | N6: =IF(H6="","",(1/H6)*1000000) | O6: =IF(I6="","",(1/I6)*1000000)
A7: T2a | B7: AI/PID/AO | C7: Polling | D7: 43433 | E7: 18345 | F7: 5637 | J7: =IF(D7="","",(1/D7)*1000000) -> 23.023968 | K7: =IF(E7="","",(1/E7)*1000000) -> 54.510766 | L7: =IF(F7="","",(1/F7)*1000000) -> 177.39933 | M7: =IF(G7="","",(1/G7)*1000000) | N7: =IF(H7="","",(1/H7)*1000000) | O7: =IF(I7="","",(1/I7)*1000000)
A8: T2b | B8: AI/PID/AO | C8: Interrupts | D8: 14428 | E8: 10234 | F8: 4574 | J8: =IF(D8="","",(1/D8)*1000000) -> 69.309676 | K8: =IF(E8="","",(1/E8)*1000000) -> 97.713504 | L8: =IF(F8="","",(1/F8)*1000000) -> 218.62702 | M8: =IF(G8="","",(1/G8)*1000000) | N8: =IF(H8="","",(1/H8)*1000000) | O8: =IF(I8="","",(1/I8)*1000000)
A9: T3 | B9: AI/AO/Local Logging | C9: Interrupts | D9: 13487 | E9: 10101 | F9: 4615 | J9: =IF(D9="","",(1/D9)*1000000) -> 74.145473 | K9: =IF(E9="","",(1/E9)*1000000) -> 99.000099 | L9: =IF(F9="","",(1/F9)*1000000) -> 216.68472 | M9: =IF(G9="","",(1/G9)*1000000) | N9: =IF(H9="","",(1/H9)*1000000) | O9: =IF(I9="","",(1/I9)*1000000)
A10: T4 | B10: AI/AO/Host Comm. | C10: Interrupts | D10: 12362 | E10: 10051 | F10: 4641 | J10: =IF(D10="","",(1/D10)*1000000) -> 80.893059 | K10: =IF(E10="","",(1/E10)*1000000) -> 99.492588 | L10: =IF(F10="","",(1/F10)*1000000) -> 215.4708 | M10: =IF(G10="","",(1/G10)*1000000) | N10: =IF(H10="","",(1/H10)*1000000) | O10: =IF(I10="","",(1/I10)*1000000)
A11: 9033_sp_online_int_reboots_16.0 | E11: For 4ch and 16ch tests the numbers from 2015 are wrong and hence the comparison shows a regression above 50%
A12: Result Improvement vs. LV RT 15.0 released (with out UI)
A13: Test | D13: Number of Channels (%) | J13: Number of Channels, Difference in Period (uS)
A14: Acronym | B14: Description | C14: I/O Mode | D14: 1 | E14: 4 | F14: 16 | G14: 32 | H14: 64 | I14: 80 | J14: 1 | K14: 4 | L14: 16 | M14: 32 | N14: 64 | O14: 80
A15: T1a | B15: AI / AO | C15: Polling | D15: =IF(D5="","",(D5-'2015'!D35)/'2015'!D35) -> 0.050344537 | E15: =IF(E5="","",(E5-'2015'!E35)/'2015'!E35) -> -0.53277373 | F15: =IF(F5="","",(F5-'2015'!F35)/'2015'!F35) -> -0.71692263 | G15: =IF(G5="","",(G5-#REF!)/#REF!) | H15: =IF(H5="","",(H5-#REF!)/#REF!) | I15: =IF(I5="","",(I5-#REF!)/#REF!) | J15: =J5-'2015'!J35 -> -1.1234109 | K15: =K5-'2015'!K35 -> 26.514071 | L15: =L5-'2015'!L35 -> 122.69769 | M15: =IF(G15="","",M5-((1/Comparisons!#REF!)*1000000)) | N15: =IF(H15="","",N5-((1/Comparisons!#REF!)*1000000)) | O15: =IF(I15="","",O5-((1/Comparisons!#REF!)*1000000))
A16: T1b | B16: AI / AO | C16: Interrupts | D16: =IF(D6="","",(D6-'2015'!D36)/'2015'!D36) -> -0.083568883 | E16: =IF(E6="","",(E6-'2015'!E36)/'2015'!E36) -> -0.29147043 | F16: =IF(F6="","",(F6-'2015'!F36)/'2015'!F36) -> -0.60882738 | G16: =IF(G6="","",(G6-#REF!)/#REF!) | H16: =IF(H6="","",(H6-#REF!)/#REF!) | I16: =IF(I6="","",(I6-#REF!)/#REF!) | J16: =J6-'2015'!J36 -> 5.6033849 | K16: =K6-'2015'!K36 -> 26.908275 | L16: =L6-'2015'!L36 -> 127.44973 | M16: =IF(G16="","",M6-((1/Comparisons!#REF!)*1000000)) | N16: =IF(H16="","",N6-((1/Comparisons!#REF!)*1000000)) | O16: =IF(I16="","",O6-((1/Comparisons!#REF!)*1000000))
A17: T2a | B17: AI/PID/AO | C17: Polling | D17: =IF(D7="","",(D7-'2015'!D37)/'2015'!D37) -> -0.12984333 | E17: =IF(E7="","",(E7-'2015'!E37)/'2015'!E37) -> -0.50565885 | F17: =IF(F7="","",(F7-'2015'!F37)/'2015'!F37) -> -0.70379906 | G17: =IF(G7="","",(G7-#REF!)/#REF!) | H17: =IF(H7="","",(H7-#REF!)/#REF!) | I17: =IF(I7="","",(I7-#REF!)/#REF!) | J17: =J7-'2015'!J37 -> 2.9895087 | K17: =K7-'2015'!K37 -> 27.563851 | L17: =L7-'2015'!L37 -> 124.85348 | M17: =IF(G17="","",M7-((1/Comparisons!#REF!)*1000000)) | N17: =IF(H17="","",N7-((1/Comparisons!#REF!)*1000000)) | O17: =IF(I17="","",O7-((1/Comparisons!#REF!)*1000000))
A18: T2b | B18: AI/PID/AO | C18: Interrupts | D18: =IF(D8="","",(D8-'2015'!D38)/'2015'!D38) -> -0.053032292 | E18: =IF(E8="","",(E8-'2015'!E38)/'2015'!E38) -> -0.2892562 | F18: =IF(F8="","",(F8-'2015'!F38)/'2015'!F38) -> -0.57816103 | G18: =IF(G8="","",(G8-#REF!)/#REF!) | H18: =IF(H8="","",(H8-#REF!)/#REF!) | I18: =IF(I8="","",(I8-#REF!)/#REF!) | J18: =J8-'2015'!J38 -> 3.675651 | K18: =K8-'2015'!K38 -> 28.264237 | L18: =L8-'2015'!L38 -> 126.40162 | M18: =IF(G18="","",M8-((1/Comparisons!#REF!)*1000000)) | N18: =IF(H18="","",N8-((1/Comparisons!#REF!)*1000000)) | O18: =IF(I18="","",O8-((1/Comparisons!#REF!)*1000000))
A19: T3 | B19: AI/AO/Local Logging | C19: Interrupts | D19: =IF(D9="","",(D9-'2015'!D39)/'2015'!D39) -> 0.058634223 | E19: =IF(E9="","",(E9-'2015'!E39)/'2015'!E39) -> -0.26108266 | F19: =IF(F9="","",(F9-'2015'!F39)/'2015'!F39) -> -0.57437978 | G19: =IF(G9="","",(G9-#REF!)/#REF!) | H19: =IF(H9="","",(H9-#REF!)/#REF!) | I19: =IF(I9="","",(I9-#REF!)/#REF!) | J19: =J9-'2015'!J39 -> -4.3474622 | K19: =K9-'2015'!K39 -> 25.847209 | L19: =L9-'2015'!L39 -> 124.45932 | M19: =IF(G19="","",M9-((1/Comparisons!#REF!)*1000000)) | N19: =IF(H19="","",N9-((1/Comparisons!#REF!)*1000000)) | O19: =IF(I19="","",O9-((1/Comparisons!#REF!)*1000000))
A20: T4 | B20: AI/AO/Host Comm. | C20: Interrupts | D20: =IF(D10="","",(D10-'2015'!D40)/'2015'!D40) -> 0.18206158 | E20: =IF(E10="","",(E10-'2015'!E40)/'2015'!E40) -> -0.22529675 | F20: =IF(F10="","",(F10-'2015'!F40)/'2015'!F40) -> -0.57965764 | G20: =IF(G10="","",(G10-#REF!)/#REF!) | H20: =IF(H10="","",(H10-#REF!)/#REF!) | I20: =IF(I10="","",(I10-#REF!)/#REF!) | J20: =J10-'2015'!J40 -> -14.727518 | K20: =K10-'2015'!K40 -> 22.415356 | L20: =L10-'2015'!L40 -> 124.8993 | M20: =IF(G20="","",M10-((1/Comparisons!#REF!)*1000000)) | N20: =IF(H20="","",N10-((1/Comparisons!#REF!)*1000000)) | O20: =IF(I20="","",O10-((1/Comparisons!#REF!)*1000000))
A21: Result Improvement vs. LV RT 2015 SP1 released (with out UI)
A22: Test | D22: Number of Channels (%) | J22: Number of Channels, Difference in Period (uS)
A23: Acronym | B23: Description | C23: I/O Mode | D23: 1 | E23: 4 | F23: 16 | G23: 32 | H23: 64 | I23: 80 | J23: 1 | K23: 4 | L23: 16 | M23: 32 | N23: 64 | O23: 80
A24: T1a | B24: AI / AO | C24: Polling | D24: =IF(D5="","",(D5-'2015'!D127)/'2015'!D127) -> 0.050344537 | E24: =IF(E5="","",(E5-'2015'!E127)/'2015'!E127) -> -0.55186333 | F24: =IF(F5="","",(F5-'2015'!F127)/'2015'!F127) -> -0.71692263 | J24: =J5-'2015'!J127 -> -1.1234109 | K24: =K5-'2015'!K127 -> 27.464085 | L24: =L5-'2015'!L127 -> 122.69769 | M24: =IF(G24="","",M14-((1/Comparisons!#REF!)*1000000)) | N24: =IF(H24="","",N14-((1/Comparisons!#REF!)*1000000)) | O24: =IF(I24="","",O14-((1/Comparisons!#REF!)*1000000))
A25: T1b | B25: AI / AO | C25: Interrupts | D25: =IF(D6="","",(D6-'2015'!D128)/'2015'!D128) -> -0.1020531 | E25: =IF(E6="","",(E6-'2015'!E128)/'2015'!E128) -> -0.33407107 | F25: =IF(F6="","",(F6-'2015'!F128)/'2015'!F128) -> -0.60773526 | J25: =J6-'2015'!J128 -> 6.8427721 | K25: =K6-'2015'!K128 -> 30.841125 | L25: =L6-'2015'!L128 -> 127.22111 | M25: =IF(G25="","",M15-((1/Comparisons!#REF!)*1000000)) | N25: =IF(H25="","",N15-((1/Comparisons!#REF!)*1000000)) | O25: =IF(I25="","",O15-((1/Comparisons!#REF!)*1000000))
A26: T2a | B26: AI/PID/AO | C26: Polling | D26: =IF(D7="","",(D7-'2015'!D129)/'2015'!D129) -> -0.13419715 | E26: =IF(E7="","",(E7-'2015'!E129)/'2015'!E129) -> -0.5226013 | F26: =IF(F7="","",(F7-'2015'!F129)/'2015'!F129) -> -0.70035084 | J26: =J7-'2015'!J129 -> 3.0897509 | K26: =K7-'2015'!K129 -> 28.487397 | L26: =L7-'2015'!L129 -> 124.24177 | M26: =IF(G26="","",M16-((1/Comparisons!#REF!)*1000000)) | N26: =IF(H26="","",N16-((1/Comparisons!#REF!)*1000000)) | O26: =IF(I26="","",O16-((1/Comparisons!#REF!)*1000000))
A27: T2b | B27: AI/PID/AO | C27: Interrupts | D27: =IF(D8="","",(D8-'2015'!D130)/'2015'!D130) -> -0.15640531 | E27: =IF(E8="","",(E8-'2015'!E130)/'2015'!E130) -> -0.32381896 | F27: =IF(F8="","",(F8-'2015'!F130)/'2015'!F130) -> -0.57466989 | J27: =J8-'2015'!J130 -> 10.840401 | K27: =K8-'2015'!K130 -> 31.641486 | L27: =L8-'2015'!L130 -> 125.63837 | M27: =IF(G27="","",M17-((1/Comparisons!#REF!)*1000000)) | N27: =IF(H27="","",N17-((1/Comparisons!#REF!)*1000000)) | O27: =IF(I27="","",O17-((1/Comparisons!#REF!)*1000000))
A28: T3 | B28: AI/AO/Local Logging | C28: Interrupts | D28: =IF(D9="","",(D9-'2015'!D131)/'2015'!D131) -> -0.025576187 | E28: =IF(E9="","",(E9-'2015'!E131)/'2015'!E131) -> -0.30352341 | F28: =IF(F9="","",(F9-'2015'!F131)/'2015'!F131) -> -0.58974131 | J28: =J9-'2015'!J131 -> 1.8963585 | K28: =K9-'2015'!K131 -> 30.048848 | L28: =L9-'2015'!L131 -> 127.78793 | M28: =IF(G28="","",M18-((1/Comparisons!#REF!)*1000000)) | N28: =IF(H28="","",N18-((1/Comparisons!#REF!)*1000000)) | O28: =IF(I28="","",O18-((1/Comparisons!#REF!)*1000000))
A29: T4 | B29: AI/AO/Host Comm. | C29: Interrupts | D29: =IF(D10="","",(D10-'2015'!D132)/'2015'!D132) -> 0.18285332 | E29: =IF(E10="","",(E10-'2015'!E132)/'2015'!E132) -> -0.2614989 | F29: =IF(F10="","",(F10-'2015'!F132)/'2015'!F132) -> -0.58380414 | J29: =J10-'2015'!J132 -> -14.791564 | K29: =K10-'2015'!K132 -> 26.017202 | L29: =L10-'2015'!L132 -> 125.79275 | M29: =IF(G29="","",M19-((1/Comparisons!#REF!)*1000000)) | N29: =IF(H29="","",N19-((1/Comparisons!#REF!)*1000000)) | O29: =IF(I29="","",O19-((1/Comparisons!#REF!)*1000000))
A30: LV RT 2016 cRIO Single-Point Benchmark Results (Hz)
A31: cRIO-9033 LV RT 16.0b75, NI-RIO 16.0.0a13
A32: Test | D32: Number of Channels, Rate (Hz) | J32: Number of Channels, Period (uS)
A33: Case | B33: Description | C33: I/O Mode | D33: 1 | E33: 4 | F33: 16 | G33: 32 | H33: 64 | I33: 80 | J33: 1 | K33: 4 | L33: 16 | M33: 32 | N33: 64 | O33: 80
A34: T1a | B34: AI / AO | C34: Polling | D34: 45261 | E34: 19447 | F34: 5837 | J34: =IF(D34="","",(1/D34)*1000000) -> 22.094077 | K34: =IF(E34="","",(1/E34)*1000000) -> 51.421813 | L34: =IF(F34="","",(1/F34)*1000000) -> 171.32088 | M34: =IF(G34="","",(1/G34)*1000000) | N34: =IF(H34="","",(1/H34)*1000000) | O34: =IF(I34="","",(1/I34)*1000000)
A35: T1b | B35: AI / AO | C35: Interrupts | D35: 14335 | E35: 10647 | F35: 4721 | J35: =IF(D35="","",(1/D35)*1000000) -> 69.75933 | K35: =IF(E35="","",(1/E35)*1000000) -> 93.923171 | L35: =IF(F35="","",(1/F35)*1000000) -> 211.81953 | M35: =IF(G35="","",(1/G35)*1000000) | N35: =IF(H35="","",(1/H35)*1000000) | O35: =IF(I35="","",(1/I35)*1000000)
A36: T2a | B36: AI/PID/AO | C36: Polling | D36: 43514 | E36: 18345 | F36: 5628 | J36: =IF(D36="","",(1/D36)*1000000) -> 22.98111 | K36: =IF(E36="","",(1/E36)*1000000) -> 54.510766 | L36: =IF(F36="","",(1/F36)*1000000) -> 177.68301 | M36: =IF(G36="","",(1/G36)*1000000) | N36: =IF(H36="","",(1/H36)*1000000) | O36: =IF(I36="","",(1/I36)*1000000)
A37: T2b | B37: AI/PID/AO | C37: Interrupts | D37: 14835 | E37: 10234 | F37: 4555 | J37: =IF(D37="","",(1/D37)*1000000) -> 67.408156 | K37: =IF(E37="","",(1/E37)*1000000) -> 97.713504 | L37: =IF(F37="","",(1/F37)*1000000) -> 219.53897 | M37: =IF(G37="","",(1/G37)*1000000) | N37: =IF(H37="","",(1/H37)*1000000) | O37: =IF(I37="","",(1/I37)*1000000)
A38: T3 | B38: AI/AO/Local Logging | C38: Interrupts | D38: 12740 | E38: 10057 | F38: 4641 | J38: =IF(D38="","",(1/D38)*1000000) -> 78.492936 | K38: =IF(E38="","",(1/E38)*1000000) -> 99.433231 | L38: =IF(F38="","",(1/F38)*1000000) -> 215.4708 | M38: =IF(G38="","",(1/G38)*1000000) | N38: =IF(H38="","",(1/H38)*1000000) | O38: =IF(I38="","",(1/I38)*1000000)
A39: T4 | B39: AI/AO/Host Comm. | C39: Interrupts | D39: 13077 | E39: 9910 | F39: 4595 | J39: =IF(D39="","",(1/D39)*1000000) -> 76.470138 | K39: =IF(E39="","",(1/E39)*1000000) -> 100.90817 | L39: =IF(F39="","",(1/F39)*1000000) -> 217.62786 | M39: =IF(G39="","",(1/G39)*1000000) | N39: =IF(H39="","",(1/H39)*1000000) | O39: =IF(I39="","",(1/I39)*1000000)
A40: 9033_sp_online_int_reboots_16.0b75
...

Sheet 2017
A1: LV RT 2017 cRIO Single-Point Benchmark Results (Hz)
A2: cRIO-9033 LV RT 17.0d41, NI-RIO 16.0.0f0
A3: Test | D3: Number of Channels, Rate (Hz) | J3: Number of Channels, Period (uS)
A4: Case | B4: Description | C4: I/O Mode | D4: 1 | E4: 4 | F4: 16 | G4: 32 | H4: 64 | I4: 80 | J4: 1 | K4: 4 | L4: 16 | M4: 32 | N4: 64 | O4: 80
A5: T1a | B5: AI / AO | C5: Polling | D5: 45213 | E5: 20154 | F5: 5837 | J5: =IF(D5="","",(1/D5)*1000000) -> 22.117533 | K5: =IF(E5="","",(1/E5)*1000000) -> 49.617942 | L5: =IF(F5="","",(1/F5)*1000000) -> 171.32088 | M5: =IF(G5="","",(1/G5)*1000000) | N5: =IF(H5="","",(1/H5)*1000000) | O5: =IF(I5="","",(1/I5)*1000000)
A6: T1b | B6: AI / AO | C6: Interrupts | D6: 14899 | E6: 10681 | F6: 4777 | J6: =IF(D6="","",(1/D6)*1000000) -> 67.118599 | K6: =IF(E6="","",(1/E6)*1000000) -> 93.624192 | L6: =IF(F6="","",(1/F6)*1000000) -> 209.3364 | M6: =IF(G6="","",(1/G6)*1000000) | N6: =IF(H6="","",(1/H6)*1000000) | O6: =IF(I6="","",(1/I6)*1000000)
A7: T2a | B7: AI/PID/AO | C7: Polling | D7: 43297 | E7: 18305 | F7: 5637 | J7: =IF(D7="","",(1/D7)*1000000) -> 23.096288 | K7: =IF(E7="","",(1/E7)*1000000) -> 54.629883 | L7: =IF(F7="","",(1/F7)*1000000) -> 177.39933 | M7: =IF(G7="","",(1/G7)*1000000) | N7: =IF(H7="","",(1/H7)*1000000) | O7: =IF(I7="","",(1/I7)*1000000)
A8: T2b | B8: AI/PID/AO | C8: Interrupts | D8: 14663 | E8: 9955 | F8: 4481 | J8: =IF(D8="","",(1/D8)*1000000) -> 68.198868 | K8: =IF(E8="","",(1/E8)*1000000) -> 100.45203 | L8: =IF(F8="","",(1/F8)*1000000) -> 223.16447 | M8: =IF(G8="","",(1/G8)*1000000) | N8: =IF(H8="","",(1/H8)*1000000) | O8: =IF(I8="","",(1/I8)*1000000)
A9: T3 | B9: AI/AO/Local Logging | C9: Interrupts | D9: 13381 | E9: 10011 | F9: 4634 | J9: =IF(D9="","",(1/D9)*1000000) -> 74.73283 | K9: =IF(E9="","",(1/E9)*1000000) -> 99.890121 | L9: =IF(F9="","",(1/F9)*1000000) -> 215.79629 | M9: =IF(G9="","",(1/G9)*1000000) | N9: =IF(H9="","",(1/H9)*1000000) | O9: =IF(I9="","",(1/I9)*1000000)
A10: T4 | B10: AI/AO/Host Comm. | C10: Interrupts | D10: 11534 | E10: 9955 | F10: 4587 | J10: =IF(D10="","",(1/D10)*1000000) -> 86.700191 | K10: =IF(E10="","",(1/E10)*1000000) -> 100.45203 | L10: =IF(F10="","",(1/F10)*1000000) -> 218.00741 | M10: =IF(G10="","",(1/G10)*1000000) | N10: =IF(H10="","",(1/H10)*1000000) | O10: =IF(I10="","",(1/I10)*1000000)
A11: 9033_sp_online_int_reboots_17.0d41
A12: Result Improvement vs. LV RT 16.0 released (with out UI)
A13: Test | D13: Number of Channels (%) | J13: Number of Channels, Difference in Period (uS)
A14: Acronym | B14: Description | C14: I/O Mode | D14: 1 | E14: 4 | F14: 16 | G14: 32 | H14: 64 | I14: 80 | J14: 1 | K14: 4 | L14: 16 | M14: 32 | N14: 64 | O14: 80
A15: T1a | B15: AI / AO | C15: Polling | D15: =IF(D5="","",(D5-'2016'!D5)/'2016'!D5) -> 0.0089034677 | E15: =IF(E5="","",(E5-'2016'!E5)/'2016'!E5) -> 0.002985966 | F15: =IF(F5="","",(F5-'2016'!F5)/'2016'!F5) -> -0.0010268698 | G15: =IF(G5="","",(G5-#REF!)/#REF!) | H15: =IF(H5="","",(H5-#REF!)/#REF!) | I15: =IF(I5="","",(I5-#REF!)/#REF!) | J15: =J5-'2015'!J35 -> -1.3203336 | K15: =K5-'2015'!K35 -> 26.365913 | L15: =L5-'2015'!L35 -> 122.87362 | M15: =IF(G15="","",M5-((1/Comparisons!#REF!)*1000000)) | N15: =IF(H15="","",N5-((1/Comparisons!#REF!)*1000000)) | O15: =IF(I15="","",O5-((1/Comparisons!#REF!)*1000000))
A16: T1b | B16: AI / AO | C16: Interrupts | D16: =IF(D6="","",(D6-'2016'!D6)/'2016'!D6) -> -0.0010057664 | E16: =IF(E6="","",(E6-'2016'!E6)/'2016'!E6) -> -0.013940177 | F16: =IF(F6="","",(F6-'2016'!F6)/'2016'!F6) -> 0 | G16: =IF(G6="","",(G6-#REF!)/#REF!) | H16: =IF(H6="","",(H6-#REF!)/#REF!) | I16: =IF(I6="","",(I6-#REF!)/#REF!) | J16: =J6-'2015'!J36 -> 5.6708906 | K16: =K6-'2015'!K36 -> 28.213413 | L16: =L6-'2015'!L36 -> 127.44973 | M16: =IF(G16="","",M6-((1/Comparisons!#REF!)*1000000)) | N16: =IF(H16="","",N6-((1/Comparisons!#REF!)*1000000)) | O16: =IF(I16="","",O6-((1/Comparisons!#REF!)*1000000))
