Workbook

Sheet 8.2
A2: LV 8.2 Results
A3: PXI-8196, LV RT 8.2, NI-DAQmx 8.3 (These results are from the archive ftp://ftp.ni.com/pub/devzone/tut/archives2007.pdf)
A4: Test | B4: Description | C4: I/O Mode | D4: 1ch | G4: 4ch | J4: 16ch
A5: T1 | B5: AI / AO | C5: Polling | D5: 94800 | G5: 61900 | J5: 29200
A6: T2a | B6: AI/PID/AO | C6: Polling | D6: 89700 | G6: 54600 | J6: 26400
A7: T2b | B7: AI/PID/AO | C7: Interrupts | D7: 39400 | G7: 24400 | J7: 16900
A8: T3 | B8: AI/AO/Local Logging | C8: Interrupts | D8: 30700 | G8: 21000 | J8: 14300
A9: T4 | B9: AI/AO/Host communication | C9: Interrupts | D9: 36200 | G9: 24300 | J9: 16300

Sheet 8.6
A2: LV RT 8.6.0 Single-Point Benchmark Results
A3: PXI-8196, LV RT 8.6.0 rc1, NI-DAQmx 8.7.2,
A4: Test | B4: Description | C4: I/O Mode | D4: Rate 1 Channel | E4: Compare 8.2 | F4: Additonal Jitter (us) | G4: Rate 4 Channel | H4: Compare 8.2 | I4: Additonal Jitter (us) | J4: Rate 16 Channel | K4: Compare 8.2 | L4: Additonal Jitter (us)
A5: T1 | B5: AI / AO | C5: Polling | D5: 94800 | E5: =(D5-'8.2'!D5)/'8.2'!D5 -> 0 | F5: =(1/D5-1/'8.2'!D5)*1000000 -> 0 | G5: 59900 | H5: =(G5-'8.2'!G5)/'8.2'!G5 -> -0.032310178 | I5: =(1/G5-1/'8.2'!G5)*1000000 -> 0.53940197 | J5: 28300 | K5: =(J5-'8.2'!J5)/'8.2'!J5 -> -0.030821918 | L5: =(1/J5-1/'8.2'!J5)*1000000 -> 1.0891137
A6: T2a | B6: AI/PID/AO | C6: Polling | D6: 92165 | E6: =(D6-'8.2'!D6)/'8.2'!D6 -> 0.027480491 | F6: =(1/D6-1/'8.2'!D6)*1000000 -> -0.29816623 | G6: 54800 | H6: =(G6-'8.2'!G6)/'8.2'!G6 -> 0.0036630037 | I6: =(1/G6-1/'8.2'!G6)*1000000 -> -0.066843133 | J6: 26400 | K6: =(J6-'8.2'!J6)/'8.2'!J6 -> 0 | L6: =(1/J6-1/'8.2'!J6)*1000000 -> 0
A7: T2b | B7: AI/PID/AO | C7: Interrupts | D7: 39500 | E7: =(D7-'8.2'!D7)/'8.2'!D7 -> 0.0025380711 | F7: =(1/D7-1/'8.2'!D7)*1000000 -> -0.064254964 | G7: 24500 | H7: =(G7-'8.2'!G7)/'8.2'!G7 -> 0.0040983607 | I7: =(1/G7-1/'8.2'!G7)*1000000 -> -0.16728003 | J7: 16200 | K7: =(J7-'8.2'!J7)/'8.2'!J7 -> -0.041420118 | L7: =(1/J7-1/'8.2'!J7)*1000000 -> 2.5567974
A8: T3 | B8: AI/AO/Local Logging | C8: Interrupts | D8: 31200 | E8: =(D8-'8.2'!D8)/'8.2'!D8 -> 0.016286645 | F8: =(1/D8-1/'8.2'!D8)*1000000 -> -0.52200785 | G8: 20800 | H8: =(G8-'8.2'!G8)/'8.2'!G8 -> -0.0095238095 | I8: =(1/G8-1/'8.2'!G8)*1000000 -> 0.45787546 | J8: 14200 | K8: =(J8-'8.2'!J8)/'8.2'!J8 -> -0.006993007 | L8: =(1/J8-1/'8.2'!J8)*1000000 -> 0.49246528
A9: T4 | B9: AI/AO/Host communication | C9: Interrupts | D9: 36443 | E9: =(D9-'8.2'!D9)/'8.2'!D9 -> 0.0067127072 | F9: =(1/D9-1/'8.2'!D9)*1000000 -> -0.18419744 | G9: 23496 | H9: =(G9-'8.2'!G9)/'8.2'!G9 -> -0.03308642 | I9: =(1/G9-1/'8.2'!G9)*1000000 -> 1.4081724 | J9: 15313 | K9: =(J9-'8.2'!J9)/'8.2'!J9 -> -0.060552147 | L9: =(1/J9-1/'8.2'!J9)*1000000 -> 3.9542968

Sheet 2009
A2: LV RT 2009 Single-Point Benchmark Results
A3: PXI-8110, LV RT 2009, NI-DAQmx 8.9.5 (PXI-6259 and PXI-6723) No SMP support
A4: Test | B4: Description | C4: I/O Mode | D4: Rate 1 Channel | E4: Compared to LV 8.6 8196 | F4: Additonal Jitter (us) | G4: Rate 4 Channel | H4: Compared to LV 8.6 8196 | I4: Additonal Jitter (us) | J4: Rate 16 Channel | K4: Compared to LV 8.6 8196 | L4: Additonal Jitter (us)
A5: T1 | B5: AI / AO | C5: Polling | D5: 145985 | E5: =(D5-'8.6'!D5)/'8.6'!D5 -> 0.53992616 | F5: =(1/D5-1/'8.6'!D5)*1000000 -> -3.6985044 | G5: 77220 | H5: =(G5-'8.6'!G5)/'8.6'!G5 -> 0.28914858 | I5: =(1/G5-1/'8.6'!G5)*1000000 -> -3.7444779 | J5: 32787 | K5: =(J5-'8.6'!J5)/'8.6'!J5 -> 0.15855124 | L5: =(1/J5-1/'8.6'!J5)*1000000 -> -4.8357958
A6: T2a | B6: AI/PID/AO | C6: Polling | D6: 136986 | E6: =(D6-'8.6'!D6)/'8.6'!D6 -> 0.48631259 | F6: =(1/D6-1/'8.6'!D6)*1000000 -> -3.5500897 | G6: 69930 | H6: =(G6-'8.6'!G6)/'8.6'!G6 -> 0.27609489 | I6: =(1/G6-1/'8.6'!G6)*1000000 -> -3.9481609 | J6: 30722 | K6: =(J6-'8.6'!J6)/'8.6'!J6 -> 0.16371212 | L6: =(1/J6-1/'8.6'!J6)*1000000 -> -5.3288237
A7: T2b | B7: AI/PID/AO | C7: Interrupts | D7: 35088 | E7: =(D7-'8.6'!D7)/'8.6'!D7 -> -0.1116962 | F7: =(1/D7-1/'8.6'!D7)*1000000 -> 3.1833163 | G7: 21231 | H7: =(G7-'8.6'!G7)/'8.6'!G7 -> -0.13342857 | I7: =(1/G7-1/'8.6'!G7)*1000000 -> 6.2846108 | J7: 18365 | K7: =(J7-'8.6'!J7)/'8.6'!J7 -> 0.13364198 | L7: =(1/J7-1/'8.6'!J7)*1000000 -> -7.2769929
A8: T3 | B8: AI/AO/Local Logging | C8: Interrupts | D8: 33003 | E8: =(D8-'8.6'!D8)/'8.6'!D8 -> 0.057788462 | F8: =(1/D8-1/'8.6'!D8)*1000000 -> -1.7510063 | G8: 19940 | H8: =(G8-'8.6'!G8)/'8.6'!G8 -> -0.041346154 | I8: =(1/G8-1/'8.6'!G8)*1000000 -> 2.0735283 | J8: 18993 | K8: =(J8-'8.6'!J8)/'8.6'!J8 -> 0.33753521 | L8: =(1/J8-1/'8.6'!J8)*1000000 -> -17.771559
A9: T4 | B9: AI/AO/Host communication | C9: Interrupts | D9: 30817 | E9: =(D9-'8.6'!D9)/'8.6'!D9 -> -0.15437807 | F9: =(1/D9-1/'8.6'!D9)*1000000 -> 5.00951 | G9: 10106 | H9: =(G9-'8.6'!G9)/'8.6'!G9 -> -0.56988424 | I9: =(1/G9-1/'8.6'!G9)*1000000 -> 56.390682 | J9: 8234 | K9: =(J9-'8.6'!J9)/'8.6'!J9 -> -0.46228695 | L9: =(1/J9-1/'8.6'!J9)*1000000 -> 56.143666
G10: Std Dev > 5000 | J10: Std Dev > 3000
A11: LV RT 2009 Single-Point Benchmark Results
A12: PXI-8110, LV RT 2009, NI-DAQmx 8.9.5 (PXI-6259 and PXI-6723) With SMP support (and CPU0 loaded)
A13: Test | B13: Description | C13: I/O Mode | D13: Rate 1 Channel | E13: Compared to LV 8.6 8196 | F13: Additonal Jitter (us) | G13: Rate 4 Channel | H13: Compared to LV 8.6 8196 | I13: Additonal Jitter (us) | J13: Rate 16 Channel | K13: Compared to LV 8.6 8196 | L13: Additonal Jitter (us)
A14: T1 | B14: AI / AO | C14: Polling | D14: 91324 | E14: =(D14-'8.6'!D5)/'8.6'!D5 -> -0.036666667 | F14: =(1/D14-1/'8.6'!D5)*1000000 -> 0.40150088 | G14: 62500 | H14: =(G14-'8.6'!G5)/'8.6'!G5 -> 0.043405676 | I14: =(1/G14-1/'8.6'!G5)*1000000 -> -0.69449082 | J14: 30166 | K14: =(J14-'8.6'!J5)/'8.6'!J5 -> 0.065936396 | L14: =(1/J14-1/'8.6'!J5)*1000000 -> -2.1857852
A15: T2a | B15: AI/PID/AO | C15: Polling | D15: 86207 | E15: =(D15-'8.6'!D6)/'8.6'!D6 -> -0.06464493 | F15: =(1/D15-1/'8.6'!D6)*1000000 -> 0.74988029 | G15: 53619 | H15: =(G15-'8.6'!G6)/'8.6'!G6 -> -0.021551095 | I15: =(1/G15-1/'8.6'!G6)*1000000 -> 0.40193019 | J15: 27322 | K15: =(J15-'8.6'!J6)/'8.6'!J6 -> 0.034924242 | L15: =(1/J15-1/'8.6'!J6)*1000000 -> -1.2782462
A16: T2b | B16: AI/PID/AO | C16: Interrupts | D16: 27322 | E16: =(D16-'8.6'!D7)/'8.6'!D7 -> -0.3083038 | F16: =(1/D16-1/'8.6'!D7)*1000000 -> 11.284086 | G16: 23557 | H16: =(G16-'8.6'!G7)/'8.6'!G7 -> -0.038489796 | I16: =(1/G16-1/'8.6'!G7)*1000000 -> 1.6339006 | J16: 14085 | K16: =(J16-'8.6'!J7)/'8.6'!J7 -> -0.13055556 | L16: =(1/J16-1/'8.6'!J7)*1000000 -> 9.26912
A17: T3 | B17: AI/AO/Local Logging | C17: Interrupts | D17: 73801 | E17: =(D17-'8.6'!D8)/'8.6'!D8 -> 1.3654167 | F17: =(1/D17-1/'8.6'!D8)*1000000 -> -18.50133 | G17: 31898 | H17: =(G17-'8.6'!G8)/'8.6'!G8 -> 0.53355769 | I17: =(1/G17-1/'8.6'!G8)*1000000 -> -16.726995 | J17: 8032 | K17: =(J17-'8.6'!J8)/'8.6'!J8 -> -0.4343662 | L17: =(1/J17-1/'8.6'!J8)*1000000 -> 54.079457
A18: T4 | B18: AI/AO/Host communication | C18: Interrupts | D18: 82644 | E18: =(D18-'8.6'!D9)/'8.6'!D9 -> 1.2677606 | F18: =(1/D18-1/'8.6'!D9)*1000000 -> -15.34002 | G18: 51282 | H18: =(G18-'8.6'!G9)/'8.6'!G9 -> 1.1825843 | I18: =(1/G18-1/'8.6'!G9)*1000000 -> -23.060416 | J18: 20387 | K18: =(J18-'8.6'!J9)/'8.6'!J9 -> 0.33135245 | L18: =(1/J18-1/'8.6'!J9)*1000000 -> -16.253124
A20: LV RT 2009 Single-Point Benchmark Results
A21: PXI-8110, LV RT 2009, NI-DAQmx 9.0 (PXI-6259 and PXI-6723) No SMP support
A22: Test | B22: Description | C22: I/O Mode | D22: Rate 1 Channel | E22: Compared to DAQ 8.95 | F22: Additonal Jitter (us) | G22: Rate 4 Channel | H22: Compared to DAQ 8.95 | I22: Additonal Jitter (us) | J22: Rate 16 Channel | K22: Compared to DAQ 8.95 | L22: Additonal Jitter (us)
A23: T1 | B23: AI / AO | C23: Polling | D23: 144928 | E23: =(D23-D5)/D5 -> -0.0072404699 | F23: =(1/D23-1/D5)*1000000 -> 0.049959083 | G23: 80000 | H23: =(G23-G5)/G5 -> 0.036001036 | I23: =(1/G23-1/G5)*1000000 -> -0.45001295 | J23: 32415 | K23: =(J23-J5)/J5 -> -0.01134596 | L23: =(1/J23-1/J5)*1000000 -> 0.35002191
A24: T2a | B24: AI/PID/AO | C24: Polling | D24: 135135 | E24: =(D24-D6)/D6 -> -0.01351233 | F24: =(1/D24-1/D6)*1000000 -> 0.09999134 | G24: 70423 | H24: =(G24-G6)/G6 -> 0.007049907 | I24: =(1/G24-1/G6)*1000000 -> -0.10010802 | J24: 30722 | K24: =(J24-J6)/J6 -> 0 | L24: =(1/J24-1/J6)*1000000 -> 0
A25: T2b | B25: AI/PID/AO | C25: Interrupts | D25: 34542 | E25: =(D25-D7)/D7 -> -0.015560876 | F25: =(1/D25-1/D7)*1000000 -> 0.45049145 | G25: 21231 | H25: =(G25-G7)/G7 -> 0 | I25: =(1/G25-1/G7)*1000000 -> 0 | J25: 18365 | K25: =(J25-J7)/J7 -> 0 | L25: =(1/J25-1/J7)*1000000 -> 0
A26: T3 | B26: AI/AO/Local Logging | C26: Interrupts | D26: 33389 | E26: =(D26-D8)/D8 -> 0.011695906 | F26: =(1/D26-1/D8)*1000000 -> -0.35029221 | G26: 20284 | H26: =(G26-G8)/G8 -> 0.017251755 | I26: =(1/G26-1/G8)*1000000 -> -0.85051051 | J26: 18002 | K26: =(J26-J8)/J8 -> -0.052177118 | L26: =(1/J26-1/J8)*1000000 -> 2.8984067
A27: T4 | B27: AI/AO/Host communication | C27: Interrupts | D27: 31447 | E27: =(D27-D9)/D9 -> 0.020443262 | F27: =(1/D27-1/D9)*1000000 -> -0.65008624 | G27: 20284 | H27: =(G27-G9)/G9 -> 1.0071245 | I27: =(1/G27-1/G9)*1000000 -> -49.651177 | J27: 17652 | K27: =(J27-J9)/J9 -> 1.143794 | L27: =(1/J27-1/J9)*1000000 -> -64.796852
A29: LV RT 2009 Single-Point Benchmark Results
A30: PXI-8110, LV RT 2009, NI-DAQmx 9.0 (PXI-6259 and PXI-6723) With SMP support (and CPU0 loaded)
A31: Test | B31: Description | C31: I/O Mode | D31: Rate 1 Channel | E31: Compared to DAQ 8.95 | F31: Additonal Jitter (us) | G31: Rate 4 Channel | H31: Compared to DAQ 8.95 | I31: Additonal Jitter (us) | J31: Rate 16 Channel | K31: Compared to DAQ 8.95 | L31: Additonal Jitter (us)
A32: T1 | B32: AI / AO | C32: Polling | D32: 94787 | E32: =(D32-D14)/D14 -> 0.037919933 | F32: =(1/D32-1/D14)*1000000 -> -0.40005416 | G32: 65147 | H32: =(G32-G14)/G14 -> 0.042352 | I32: =(1/G32-1/G14)*1000000 -> -0.65009901 | J32: 30166 | K32: =(J32-J14)/J14 -> 0 | L32: =(1/J32-1/J14)*1000000 -> 0
A33: T2a | B33: AI/PID/AO | C33: Polling | D33: 88496 | E33: =(D33-D15)/D15 -> 0.026552368 | F33: =(1/D33-1/D15)*1000000 -> -0.30004032 | G33: 59880 | H33: =(G33-G15)/G15 -> 0.11676831 | I33: =(1/G33-1/G15)*1000000 -> -1.9500386 | J33: 28209 | K33: =(J33-J15)/J15 -> 0.03246468 | L33: =(1/J33-1/J15)*1000000 -> -1.1508625
A34: T2b | B34: AI/PID/AO | C34: Interrupts | D34: 27322 | E34: =(D34-D16)/D16 -> 0 | F34: =(1/D34-1/D16)*1000000 -> 0 | G34: 23337 | H34: =(G34-G16)/G16 -> -0.00933905 | I34: =(1/G34-1/G16)*1000000 -> 0.40018211 | J34: 14503 | K34: =(J34-J16)/J16 -> 0.029676961 | L34: =(1/J34-1/J16)*1000000 -> -2.0462636
A35: T3 | B35: AI/AO/Local Logging | C35: Interrupts | D35: 75472 | E35: =(D35-D17)/D17 -> 0.02264197 | F35: =(1/D35-1/D17)*1000000 -> -0.3000049 | G35: 31898 | H35: =(G35-G17)/G17 -> 0 | I35: =(1/G35-1/G17)*1000000 -> 0 | J35: 8032 | K35: =(J35-J17)/J17 -> 0 | L35: =(1/J35-1/J17)*1000000 -> 0
A36: T4 | B36: AI/AO/Host communication | C36: Interrupts | D36: 82000 | E36: =(D36-D18)/D18 -> -0.0077924592 | F36: =(1/D36-1/D18)*1000000 -> 0.095029991 | G36: 59701 | H36: =(G36-G18)/G18 -> 0.16417066 | I36: =(1/G36-1/G18)*1000000 -> -2.7498813 | J36: 20387 | K36: =(J36-J18)/J18 -> 0 | L36: =(1/J36-1/J18)*1000000 -> 0
D37: T4: Omitted single outlier (69930) | J37: Omitted single outlier (2843)
A39: LV RT 2009 Single-Point Benchmark Results
A40: PXIe-8108, LV RT 2009, NI-DAQmx 9.0 (PXIe-6361 and PXI-6723) No SMP support
A41: Test | B41: Description | C41: I/O Mode | D41: Rate 1 Channel | E41: Compared to 8110 | F41: Additional Jitter (us) | G41: Rate 4 Channel | H41: Compared to 8110 | I41: Additional Jitter (us) | J41: Rate 16 Channel | K41: Compared to 8110 | L41: Additional Jitter (us)
A42: T1 | B42: AI / AO | C42: Polling | D42: 109769 | E42: =(D42-D23)/D23 -> -0.24259632 | F42: =(1/D42-1/D23)*1000000 -> 2.2100623 | G42: 81301 | H42: =(G42-G23)/G23 -> 0.0162625 | I42: =(1/G42-1/G23)*1000000 -> -0.20002829 | J42: 33245 | K42: =(J42-J23)/J23 -> 0.02560543 | L42: =(1/J42-1/J23)*1000000 -> -0.77020393
A43: T2a | B43: AI/PID/AO | C43: Polling | D43: 105485 | E43: =(D43-D24)/D24 -> -0.21941022 | F43: =(1/D43-1/D24)*1000000 -> 2.0800135 | G43: 72993 | H43: =(G43-G24)/G24 -> 0.036493759 | I43: =(1/G43-1/G24)*1000000 -> -0.49996245 | J43: 30553 | K43: =(J43-J24)/J24 -> -0.0055009439 | L43: =(1/J43-1/J24)*1000000 -> 0.18004595
A44: T2b | B44: AI/PID/AO | C44: Interrupts | D44: 39262 | E44: =(D44-D25)/D25 -> 0.13664524 | F44: =(1/D44-1/D25)*1000000 -> -3.4803434 | G44: 36846 | H44: =(G44-G25)/G25 -> 0.73548114 | I44: =(1/G44-1/G25)*1000000 -> -19.960949 | J44: 33245 | K44: =(J44-J25)/J25 -> 0.81023686 | L44: =(1/J44-1/J25)*1000000 -> -24.371691
...

Sheet 2010
A1: LV RT 2010b29 Single-Point Benchmark Results
A2: PXI-8110, LV RT 2010, NI-DAQmx 9.1.0 (PXI-6071E and PXI-6723) No SMP support
A3: Test | B3: Description | C3: I/O Mode | D3: Rate 1 Channel | E3: Compared to LV 2009 SP1 | F3: Additonal Jitter (us) | G3: Rate 4 Channel | H3: Compared to LV 2009 SP1 | I3: Additonal Jitter (us) | J3: Rate 16 Channel | K3: Compared to LV 2009 SP1 | L3: Additonal Jitter (us)
A4: T1 | B4: AI / AO | C4: Polling | D4: 148148 | E4: =(D4-'2009'!D81)/'2009'!D81 -> 0.051851326 | G4: 79051 | H4: =(G4-'2009'!G81)/'2009'!G81 -> #DIV/0! | J4: 33389 | K4: =(J4-'2009'!J81)/'2009'!J81 -> #DIV/0!
A5: T2a | B5: AI/PID/AO | C5: Polling | D5: 131579 | E5: =(D5-'2009'!D82)/'2009'!D82 -> #DIV/0! | G5: 70671 | H5: =(G5-'2009'!G82)/'2009'!G82 -> -0.014145219 | J5: 31696 | K5: =(J5-'2009'!J82)/'2009'!J82 -> #DIV/0!
A6: T2b | B6: AI/PID/AO | C6: Interrupts | D6: 38095 | E6: =(D6-'2009'!D83)/'2009'!D83 -> #DIV/0! | G6: 23557 | H6: =(G6-'2009'!G83)/'2009'!G83 -> #DIV/0! | J6: 20284 | K6: =(J6-'2009'!J83)/'2009'!J83 -> 0.017251755
A7: T3 | B7: AI/AO/Local Logging | C7: Interrupts | D7: 35714 | E7: =(D7-'2009'!D84)/'2009'!D84 -> -0.021427006 | G7: 23557 | H7: =(G7-'2009'!G84)/'2009'!G84 -> #DIV/0! | J7: 20921 | K7: =(J7-'2009'!J84)/'2009'!J84 -> #DIV/0!
A8: T4 | B8: AI/AO/Host communication | C8: Interrupts | D8: 35087 | E8: =(D8-'2009'!D85)/'2009'!D85 -> #DIV/0! | G8: 22573 | H8: =(G8-'2009'!G85)/'2009'!G85 -> 0 | J8: 20202 | K8: =(J8-'2009'!J85)/'2009'!J85 -> #DIV/0!
A10: LV RT 2010b29 Single-Point Benchmark Results
A11: PXI-8110, LV RT 2010, NI-DAQmx 9.1.0 (PXI-6071E and PXI-6723) With SMP support (CPU0 loaded)
A12: Test | B12: Description | C12: I/O Mode | D12: Rate 1 Channel | E12: Compared to LV 2009 SP1 | F12: Additonal Jitter (us) | G12: Rate 4 Channel | H12: Compared to LV 2009 SP1 | I12: Additonal Jitter (us) | J12: Rate 16 Channel | K12: Compared to LV 2009 SP1 | L12: Additonal Jitter (us)
A13: T1 | B13: AI / AO | C13: Polling | D13: 161290 | E13: =(D13-'2009'!D32)/'2009'!D32 -> 0.70160465 | G13: 80972 | H13: =(G13-'2009'!G32)/'2009'!G32 -> 0.24291218 | J13: 34542 | K13: =(J13-'2009'!J32)/'2009'!J32 -> 0.14506398
A14: T2a | B14: AI/PID/AO | C14: Polling | D14: 148148 | E14: =(D14-'2009'!D33)/'2009'!D33 -> 0.67406436 | G14: 84746 | H14: =(G14-'2009'!G33)/'2009'!G33 -> 0.41526386 | J14: 33389 | K14: =(J14-'2009'!J33)/'2009'!J33 -> 0.18362934
A15: T2b | B15: AI/PID/AO | C15: Interrupts | D15: 31696 | E15: =(D15-'2009'!D34)/'2009'!D34 -> 0.16009077 | G15: 27322 | H15: =(G15-'2009'!G34)/'2009'!G34 -> 0.17075888 | J15: 17376 | K15: =(J15-'2009'!J34)/'2009'!J34 -> 0.19809695
A16: T3 | B16: AI/AO/Local Logging | C16: Interrupts | D16: 123457 | E16: =(D16-'2009'!D35)/'2009'!D35 -> 0.63579871 | G16: 42463 | H16: =(G16-'2009'!G35)/'2009'!G35 -> 0.33121199 | J16: 10309 | K16: =(J16-'2009'!J35)/'2009'!J35 -> 0.28349104
A17: T4 | B17: AI/AO/Host communication | C17: Interrupts | D17: 127389 | E17: =(D17-'2009'!D36)/'2009'!D36 -> 0.55352439 | G17: 72464 | H17: =(G17-'2009'!G36)/'2009'!G36 -> 0.21378201 | J17: 22497 | K17: =(J17-'2009'!J36)/'2009'!J36 -> 0.10349733
A19: LV RT 2010rc8 Single-Point Benchmark Results
A20: PXIe-8108, LV RT 2010, NI-DAQmx 9.1.5 (PXIe-6361 and PXIe-6363) No SMP support
A21: Test | B21: Description | C21: I/O Mode | D21: Rate 1 Channel | E21: Vs. LV09SP1, Dmx9.02 | F21: Additonal Jitter (us) | G21: Rate 4 Channel | H21: Vs. LV09SP1, Dmx9.02 | I21: Additonal Jitter (us) | J21: Rate 16 Channel
A22: T1 | B22: AI / AO | C22: Polling | D22: 160256 | E22: =(D22-'2009'!D62)/'2009'!D62 -> 0.0080071454 | G22: 99305 | H22: =(G22-'2009'!G62)/'2009'!G62 -> -0.010926077
A23: T2a | B23: AI/PID/AO | C23: Polling | D23: 152439 | E23: =(D23-'2009'!D63)/'2009'!D63 -> 0.0060984061 | G23: 84746 | H23: =(G23-'2009'!G63)/'2009'!G63 -> -0.065253359
A24: T2b | B24: AI/PID/AO | C24: Interrupts | D24: 85034 | E24: =(D24-'2009'!D64)/'2009'!D64 -> -0.0042507348 | G24: 56497 | H24: =(G24-'2009'!G64)/'2009'!G64 -> 0
A25: T3 | B25: AI/AO/Local Logging | C25: Interrupts | D25: 78370 | E25: =(D25-'2009'!D65)/'2009'!D65 -> -0.068177495 | G25: 55494 | H25: =(G25-'2009'!G65)/'2009'!G65 -> -0.066590416
A26: T4 | B26: AI/AO/Host communication | C26: Interrupts | D26: 77519 | E26: =(D26-'2009'!D66)/'2009'!D66 -> -0.058149566 | G26: 51546 | H26: =(G26-'2009'!G66)/'2009'!G66 -> -0.14742222
A28: LV RT 2010rc2 Single-Point Benchmark Results
A29: PXIe-8108, LV RT 2010, NI-DAQmx 9.1.5 (PXIe-6361 and PXIe-6363) With SMP support
A30: Test | B30: Description | C30: I/O Mode | D30: Rate 1 Channel | E30: Vs. LV09SP1, Dmx9.02 | F30: Additonal Jitter (us) | G30: Rate 4 Channel | H30: Vs. LV09SP1, Dmx9.02 | I30: Additonal Jitter (us) | J30: Rate 16 Channel
A31: T1 | B31: AI / AO | C31: Polling | D31: 156495 | E31: =(D31-'2009'!D71)/'2009'!D71 -> 0.054775962 | G31: 101937 | H31: =(G31-'2009'!G71)/'2009'!G71 -> -0.0061132561
A32: T2a | B32: AI/PID/AO | C32: Polling | D32: 153139 | E32: =(D32-'2009'!D72)/'2009'!D72 -> 0.27258449 | G32: 95057 | H32: =(G32-'2009'!G72)/'2009'!G72 -> -0.0095030687
A33: T2b | B33: AI/PID/AO | C33: Interrupts | D33: 60096 | E33: =(D33-'2009'!D73)/'2009'!D73 -> 0.060099843 | G33: 43611 | H33: =(G33-'2009'!G73)/'2009'!G73 -> 0.015271796
A34: T3 | B34: AI/AO/Local Logging | C34: Interrupts | D34: 125313 | E34: =(D34-'2009'!D74)/'2009'!D74 -> -0.0576482 | G34: 94162 | H34: =(G34-'2009'!G74)/'2009'!G74 -> 0.057441576
A35: T4 | B35: AI/AO/Host communication | C35: Interrupts | D35: 145349 | E35: =(D35-'2009'!D75)/'2009'!D75 -> 0.10174643 | G35: 82102 | H35: =(G35-'2009'!G75)/'2009'!G75 -> 0.078005803
A37: LV RT 2010rc2 Single-Point Benchmark Results
A38: PXI-8110, LV RT 2010, NI-DAQmx 9.1.5 (PXI-6071E and PXI-6723) No SMP support
A39: Test | B39: Description | C39: I/O Mode | D39: Rate 1 Channel | E39: Vs. LV09, Dmx9.0 | F39: Additonal Jitter (us) | G39: Rate 4 Channel | H39: Vs. LV09, Dmx9.0 | I39: Additonal Jitter (us) | J39: Rate 16 Channel | K39: Vs. LV09, Dmx9.0 | L39: Additonal Jitter (us)
A40: T1 | B40: AI / AO | C40: Polling | D40: 161290 | E40: =(D40-'2009'!D23)/'2009'!D23 -> 0.11289744 | G40: 80972 | H40: =(G40-'2009'!G23)/'2009'!G23 -> 0.01215 | J40: 31299 | K40: =(J40-'2009'!J23)/'2009'!J23 -> -0.034428505
A41: T2a | B41: AI/PID/AO | C41: Polling | D41: 150376 | E41: =(D41-'2009'!D24)/'2009'!D24 -> 0.11278351 | G41: 76046 | H41: =(G41-'2009'!G24)/'2009'!G24 -> 0.079846073 | J41: 32258 | K41: =(J41-'2009'!J24)/'2009'!J24 -> 0.049996745
A42: T2b | B42: AI/PID/AO | C42: Interrupts | D42: 45045 | E42: =(D42-'2009'!D25)/'2009'!D25 -> 0.30406462 | G42: 30166 | H42: =(G42-'2009'!G25)/'2009'!G25 -> 0.42084687 | J42: 24155 | K42: =(J42-'2009'!J25)/'2009'!J25 -> 0.31527362
A43: T3 | B43: AI/AO/Local Logging | C43: Interrupts | D43: 41494 | E43: =(D43-'2009'!D26)/'2009'!D26 -> 0.24274462 | G43: 28209 | H43: =(G43-'2009'!G26)/'2009'!G26 -> 0.39070203 | J43: 21231 | K43: =(J43-'2009'!J26)/'2009'!J26 -> 0.17936896
A44: T4 | B44: AI/AO/Host communication | C44: Interrupts | D44: 40984 | E44: =(D44-'2009'!D27)/'2009'!D27 -> 0.30327217 | G44: 29197 | H44: =(G44-'2009'!G27)/'2009'!G27 -> 0.43941037 | J44: 21053 | K44: =(J44-'2009'!J27)/'2009'!J27 -> 0.19266939
...

Sheet 2011
A1: LV RT 2011 Single-Point Benchmark Results
A2: PXIe-8108, LV RT 2011b103, NI-DAQmx 9.3.5b16 (PXIe-6361 and PXIe-6363) With SMP support
A3: Test | B3: Description | C3: I/O Mode | D3: Rate 1ch Min | E3: Vs. LV10.1, Dmx9.1.5 | F3: Additonal Jitter (us) | G3: Rate 4ch Min | H3: Vs. LV10.1, Dmx9.1.5 | I3: Additonal Jitter (us) | J3: Rate 16ch Min | K3: Vs. LV10.1, Dmx9.1.5
A4: T1 | B4: AI / AO | C4: Polling | D4: 145773 | E4: =(D4-'2010'!D68)/'2010'!D68 -> 0.0087468601 | G4: 101420 | H4: =(G4-'2010'!G68)/'2010'!G68 -> -0.09431873 | J4: 37523 | K4: =(J4-'2010'!J68)/'2010'!J68 -> 0.023987556
A5: T2a | B5: AI/PID/AO | C5: Polling | D5: 150602 | E5: =(D5-'2010'!D69)/'2010'!D69 -> 0.046683115 | G5: 101626 | H5: =(G5-'2010'!G69)/'2010'!G69 -> -0.042682065 | J5: 35112 | K5: =(J5-'2010'!J69)/'2010'!J69 -> 0.09338897
A6: T2b | B6: AI/PID/AO | C6: Interrupts | D6: 56529 | E6: =(D6-'2010'!D70)/'2010'!D70 -> -0.13623653 | G6: 49554 | H6: =(G6-'2010'!G70)/'2010'!G70 -> -0.12289148 | J6: 26240 | K6: =(J6-'2010'!J70)/'2010'!J70 -> -0.06871096
A7: T3 | B7: AI/AO/Local Logging | C7: Polling | D7: 144509 | E7: =(D7-'2010'!D71)/'2010'!D71 -> -0.070801183 | G7: 101010 | H7: =(G7-'2010'!G71)/'2010'!G71 -> -0.062621801 | J7: 35804 | K7: =(J7-'2010'!J71)/'2010'!J71 -> 0.0093310405
A8: T4 | B8: AI/AO/Host communication | C8: Polling | D8: 139665 | E8: =(D8-'2010'!D72)/'2010'!D72 -> -0.013964686 | G8: 96899 | H8: =(G8-'2010'!G72)/'2010'!G72 -> -0.042632442 | J8: 36010 | K8: =(J8-'2010'!J72)/'2010'!J72 -> -0.012586032
A10: LV RT 2011 Single-Point Benchmark Results
A11: PXIe-8108, LV RT 2011b103, NI-DAQmx 9.3.5b16 (PXIe-6361 and PXIe-6363) No SMP support
A12: Test | B12: Description | C12: I/O Mode | D12: Rate 1 Channel | E12: Vs. LV10.1, Dmx9.1.5 | F12: Additonal Jitter (us) | G12: Rate 4 Channel | H12: Vs. LV10.1, Dmx9.1.5 | I12: Additonal Jitter (us) | J12: DAQmx Rate 16 Channel | K12: Vs. LV10.1, Dmx9.1.5
A13: T1 | B13: AI / AO | C13: Polling | D13: 150602 | E13: =(D13-'2010'!D78)/'2010'!D78 -> -0.034639693 | G13: 103627 | H13: =(G13-'2010'!G78)/'2010'!G78 -> -0.039378911 | J13: 36470 | K13: =(J13-'2010'!J78)/'2010'!J78 -> -0.010204636
A14: T2a | B14: AI/PID/AO | C14: Polling | D14: 144092 | E14: =(D14-'2010'!D79)/'2010'!D79 -> -0.020175576 | G14: 93197 | H14: =(G14-'2010'!G79)/'2010'!G79 -> -0.071761519 | J14: 33944 | K14: =(J14-'2010'!J79)/'2010'!J79 -> -0.032245189
A15: T2b | B15: AI/PID/AO | C15: Interrupts | D15: 83752 | E15: =(D15-'2010'!D80)/'2010'!D80 -> -0.094641487 | G15: 72254 | H15: =(G15-'2010'!G80)/'2010'!G80 -> -0.088151037 | J15: 31676 | K15: =(J15-'2010'!J80)/'2010'!J80 -> -0.03450378
A16: T3 | B16: AI/AO/Local Logging | C16: Interrupts | D16: 74129 | E16: =(D16-'2010'!D81)/'2010'!D81 -> -0.080798562 | G16: 67797 | H16: =(G16-'2010'!G81)/'2010'!G81 -> -0.091521835 | J16: 32113 | K16: =(J16-'2010'!J81)/'2010'!J81 -> 0
A17: T4 | B17: AI/AO/Host communication | C17: Interrupts | D17: 71073 | E17: =(D17-'2010'!D82)/'2010'!D82 -> -0.10803077 | G17: 66711 | H17: =(G17-'2010'!G82)/'2010'!G82 -> -0.074049913 | J17: 31536 | K17: =(J17-'2010'!J82)/'2010'!J82 -> -0.017661901
A20: LV RT 2011 SP1 Single-Point Benchmark Results
A21: PXIe-8108, LV RT 2011.1a1, NI-DAQmx 9.4.0 (PXIe-6361 and PXIe-6363) With SMP support
A22: Test | B22: Description | C22: I/O Mode | D22: Rate 1 Channel | E22: Vs. LV10.1, Dmx9.1.5 | F22: Vs. LV11, Dmx9.3.5 | G22: Rate 4 Channel | H22: Vs. LV10.1, Dmx9.1.5 | I22: Vs. LV11, Dmx9.3.5 | J22: Rate 16 Channel | K22: Vs. LV10.1, Dmx9.1.5 | L22: Vs. LV11, Dmx9.3.5
A23: T1 | B23: AI / AO | C23: Polling | D23: 169779 | E23: =(D23-'2010'!D68)/'2010'!D68 -> 0.174868 | F23: =(D23-D4)/D4 -> 0.1646807 | G23: 112486 | H23: =(G23-'2010'!G68)/'2010'!G68 -> 0.0045007233 | I23: =(G23-G4)/G4 -> 0.10911063 | J23: 37523 | K23: =(J23-'2010'!J68)/'2010'!J68 -> 0.023987556 | L23: =(J23-J4)/J4 -> 0
A24: T2a | B24: AI/PID/AO | C24: Polling | D24: 144509 | E24: =(D24-'2010'!D69)/'2010'!D69 -> 0.0043367967 | F24: =(D24-D5)/D5 -> -0.04045763 | G24: 103520 | H24: =(G24-'2010'!G69)/'2010'!G69 -> -0.024840566 | I24: =(G24-G5)/G5 -> 0.018636963 | J24: 36166 | K24: =(J24-'2010'!J69)/'2010'!J69 -> 0.12621057 | L24: =(J24-J5)/J5 -> 0.030018227
A25: T2b | B25: AI/PID/AO | C25: Interrupts | D25: 61312 | E25: =(D25-'2010'!D70)/'2010'!D70 -> -0.063152265 | F25: =(D25-D6)/D6 -> 0.084611438 | G25: 54585 | H25: =(G25-'2010'!G70)/'2010'!G70 -> -0.033842505 | I25: =(G25-G6)/G6 -> 0.10152561 | J25: 27181 | K25: =(J25-'2010'!J70)/'2010'!J70 -> -0.035313742 | L25: =(J25-J6)/J6 -> 0.03586128
A26: T3 | B26: AI/AO/Local Logging | C26: Polling | D26: 143266 | E26: =(D26-'2010'!D71)/'2010'!D71 -> -0.078793724 | F26: =(D26-D7)/D7 -> -0.0086015404 | G26: 106157 | H26: =(G26-'2010'!G71)/'2010'!G71 -> -0.014857366 | I26: =(G26-G7)/G7 -> 0.050955351 | J26: 35651 | K26: =(J26-'2010'!J71)/'2010'!J71 -> 0.0050179009 | L26: =(J26-J7)/J7 -> -0.0042732656
A27: T4 | B27: AI/AO/Host communication | C27: Polling | D27: 139470 | E27: =(D27-'2010'!D72)/'2010'!D72 -> -0.015341386 | F27: =(D27-D8)/D8 -> -0.001396198 | G27: 100200 | H27: =(G27-'2010'!G72)/'2010'!G72 -> -0.010018377 | I27: =(G27-G8)/G8 -> 0.034066399 | J27: 33289 | K27: =(J27-'2010'!J72)/'2010'!J72 -> -0.087197346 | L27: =(J27-J8)/J8 -> -0.075562344
A29: LV RT 2011 SP1 Single-Point Benchmark Results
A30: PXIe-8108, LV RT 2011.1a1, NI-DAQmx 9.4.0 (PXIe-6361 and PXIe-6363) No SMP support
A31: Test | B31: Description | C31: I/O Mode | D31: Rate 1 Channel | E31: Vs. LV10.1, Dmx9.1.5 | F31: Vs. LV11, Dmx9.3.5 | G31: Rate 4 Channel | H31: Vs. LV10.1, Dmx9.1.5 | I31: Vs. LV11, Dmx9.3.5 | J31: DAQmx Rate 16 Channel | K31: Vs. LV10.1, Dmx9.1.5 | L31: Vs. LV11, Dmx9.3.5
A32: T1 | B32: AI / AO | C32: Polling | D32: 154083 | E32: =(D32-'2010'!D78)/'2010'!D78 -> -0.012326449 | F32: =(D32-D13)/D13 -> 0.023113903 | G32: 102041 | H32: =(G32-'2010'!G78)/'2010'!G78 -> -0.054081112 | I32: =(G32-G13)/G13 -> -0.015304892 | J32: 36166 | K32: =(J32-'2010'!J78)/'2010'!J78 -> -0.018455192 | L32: =(J32-J13)/J13 -> -0.0083356183
A33: T2a | B33: AI/PID/AO | C33: Polling | D33: 148810 | E33: =(D33-'2010'!D79)/'2010'!D79 -> 0.011906786 | F33: =(D33-D14)/D14 -> 0.03274297 | G33: 94073 | H33: =(G33-'2010'!G79)/'2010'!G79 -> -0.063036593 | I33: =(G33-G14)/G14 -> 0.0093994442 | J33: 34518 | K33: =(J33-'2010'!J79)/'2010'!J79 -> -0.015880257 | L33: =(J33-J14)/J14 -> 0.016910205
A34: T2b | B34: AI/PID/AO | C34: Interrupts | D34: 85690 | E34: =(D34-'2010'!D80)/'2010'!D80 -> -0.073691721 | F34: =(D34-D15)/D15 -> 0.023139746 | G34: 72569 | H34: =(G34-'2010'!G80)/'2010'!G80 -> -0.084175722 | I34: =(G34-G15)/G15 -> 0.0043596202 | J34: 31676 | K34: =(J34-'2010'!J80)/'2010'!J80 -> -0.03450378 | L34: =(J34-J15)/J15 -> 0
A35: T3 | B35: AI/AO/Local Logging | C35: Interrupts | D35: 73910 | E35: =(D35-'2010'!D81)/'2010'!D81 -> -0.083514167 | F35: =(D35-D16)/D16 -> -0.0029543094 | G35: 66711 | H35: =(G35-'2010'!G81)/'2010'!G81 -> -0.10607421 | I35: =(G35-G16)/G16 -> -0.016018408 | J35: 31114 | K35: =(J35-'2010'!J81)/'2010'!J81 -> -0.031108897 | L35: =(J35-J16)/J16 -> -0.031108897
A36: T4 | B36: AI/AO/Host communication | C36: Interrupts | D36: 72833 | E36: =(D36-'2010'!D82)/'2010'!D82 -> -0.085942697 | F36: =(D36-D17)/D17 -> 0.024763272 | G36: 68446 | H36: =(G36-'2010'!G82)/'2010'!G82 -> -0.049968076 | I36: =(G36-G17)/G17 -> 0.026007705 | J36: 32531 | K36: =(J36-'2010'!J82)/'2010'!J82 -> 0.013332087 | L36: =(J36-J17)/J17 -> 0.031551243

Sheet 2012
A1: PXIe-8108, LV RT 2012a11, NI-DAQmx 9.4.0 (PXIe-6361 and PXIe-6363) With SMP support
A2: Test | B2: Description | C2: I/O Mode | D2: Rate 1ch Min | E2: vs. LV11.1, Dmx9.4 | F2: vs. LV11, Dmx9.3.5 | G2: Rate 1ch Max | H2: Rate 4ch Min | I2: vs. LV11.1, Dmx9.4 | J2: vs. LV11, Dmx9.3.5 | K2: Rate 4ch Max | L2: Rate 16ch Min | M2: vs. LV11.1, Dmx9.4 | N2: vs. LV11, Dmx9.3.5 | O2: Rate 16ch Max
A3: T1 | B3: AI / AO | C3: Polling | D3: 144509 | E3: =(D3-'2011'!D23)/'2011'!D23 -> -0.14884055 | F3: =(D3-'2011'!D4)/'2011'!D4 -> -0.0086710159 | G3: 173913 | H3: 111234 | I3: =(H3-'2011'!G23)/'2011'!G23 -> -0.011130274 | J3: =(H3-'2011'!G4)/'2011'!G4 -> 0.096765924 | K3: 113766 | L3: 37161 | M3: =(L3-'2011'!J23)/'2011'!J23 -> -0.0096474163 | N3: =(L3-'2011'!J4)/'2011'!J4 -> -0.0096474163 | O3: 37836
A4: T2a | B4: AI/PID/AO | C4: Polling | D4: 168634 | E4: =(D4-'2011'!D24)/'2011'!D24 -> 0.16694462 | F4: =(D4-'2011'!D5)/'2011'!D5 -> 0.11973281 | G4: 171527 | H4: 103842 | I4: =(H4-'2011'!G24)/'2011'!G24 -> 0.00311051 | J4: =(H4-'2011'!G5)/'2011'!G5 -> 0.021805443 | K4: 105597 | L4: 36166 | M4: =(L4-'2011'!J24)/'2011'!J24 -> 0 | N4: =(L4-'2011'!J5)/'2011'!J5 -> 0.030018227 | O4: 36470
A5: T2b | B5: AI/PID/AO | C5: Interrupts | D5: 68681 | E5: =(D5-'2011'!D25)/'2011'!D25 -> 0.12018854 | F5: =(D5-'2011'!D6)/'2011'!D6 -> 0.21496931 | G5: 69638 | H5: 57670 | I5: =(H5-'2011'!G25)/'2011'!G25 -> 0.056517358 | J5: =(H5-'2011'!G6)/'2011'!G6 -> 0.16378093 | K5: 60533 | L5: 28177 | M5: =(L5-'2011'!J25)/'2011'!J25 -> 0.036643243 | N5: =(L5-'2011'!J6)/'2011'!J6 -> 0.073818598 | O5: 29283
A6: T3 | B6: AI/AO/Local Logging | C6: Polling | D6: 135501 | E6: =(D6-'2011'!D26)/'2011'!D26 -> -0.05419988 | F6: =(D6-'2011'!D7)/'2011'!D7 -> -0.062335218 | G6: 162338 | H6: 104603 | I6: =(H6-'2011'!G26)/'2011'!G26 -> -0.014638696 | J6: =(H6-'2011'!G7)/'2011'!G7 -> 0.035570736 | K6: 108932 | L6: 35650 | M6: =(L6-'2011'!J26)/'2011'!J26 -> -2.8049704e-05 | N6: =(L6-'2011'!J7)/'2011'!J7 -> -0.0043011954 | O6: 36643
A7: T4 | B7: AI/AO/Host communication | C7: Polling | D7: 121507 | E7: =(D7-'2011'!D27)/'2011'!D27 -> -0.12879472 | F7: =(D7-'2011'!D8)/'2011'!D8 -> -0.1300111 | G7: 138504 | H7: 102669 | I7: =(H7-'2011'!G27)/'2011'!G27 -> 0.024640719 | J7: =(H7-'2011'!G8)/'2011'!G8 -> 0.059546538 | K7: 103842 | L7: 36470 | M7: =(L7-'2011'!J27)/'2011'!J27 -> 0.095557091 | N7: =(L7-'2011'!J8)/'2011'!J8 -> 0.012774229 | O7: 37679
A9: PXIe-8108, LV RT 2012a11, NI-DAQmx 9.4.0 (PXIe-6361 and PXIe-6363) No SMP support
A10: Test | B10: Description | C10: I/O Mode | D10: Rate 1ch Min | E10: vs. LV11.1, Dmx9.4 | F10: vs. LV11, Dmx9.3.5 | G10: Rate 1ch Max | H10: Rate 4ch Min | I10: vs. LV11.1, Dmx9.4 | J10: vs. LV11, Dmx9.3.5 | K10: Rate 4ch Max | L10: Rate 16ch Min | M10: vs. LV11.1, Dmx9.4 | N10: vs. LV11, Dmx9.3.5 | O10: Rate 16ch Max
A11: T1 | B11: AI / AO | C11: Polling | D11: 151515 | E11: =(D11-'2011'!D32)/'2011'!D32 -> -0.016666342 | F11: =(D11-'2011'!D13)/'2011'!D13 -> 0.0060623365 | G11: 154083 | H11: 102669 | I11: =(H11-'2011'!G32)/'2011'!G32 -> 0.0061543889 | J11: =(H11-'2011'!G13)/'2011'!G13 -> -0.0092446949 | K11: 104603 | L11: 36166 | M11: =(L11-'2011'!J32)/'2011'!J32 -> 0 | N11: =(L11-'2011'!J13)/'2011'!J13 -> -0.0083356183 | O11: 36643
A12: T2a | B12: AI/PID/AO | C12: Polling | D12: 147059 | E12: =(D12-'2011'!D33)/'2011'!D33 -> -0.011766682 | F12: =(D12-'2011'!D14)/'2011'!D14 -> 0.020591011 | G12: 151515 | H12: 95785 | I12: =(H12-'2011'!G33)/'2011'!G33 -> 0.018198633 | J12: =(H12-'2011'!G14)/'2011'!G14 -> 0.027769134 | K12: 96712 | L12: 34376 | M12: =(L12-'2011'!J33)/'2011'!J33 -> -0.0041137957 | N12: =(L12-'2011'!J14)/'2011'!J14 -> 0.012726844 | O12: 34941
A13: T2b | B13: AI/PID/AO | C13: Interrupts | D13: 85470 | E13: =(D13-'2011'!D34)/'2011'!D34 -> -0.0025673941 | F13: =(D13-'2011'!D15)/'2011'!D15 -> 0.020512943 | G13: 87108 | H13: 71276 | I13: =(H13-'2011'!G34)/'2011'!G34 -> -0.017817525 | J13: =(H13-'2011'!G15)/'2011'!G15 -> -0.013535583 | K13: 73801 | L13: 31676 | M13: =(L13-'2011'!J34)/'2011'!J34 -> 0 | N13: =(L13-'2011'!J15)/'2011'!J15 -> 0 | O13: 32669
A14: T3 | B14: AI/AO/Local Logging | C14: Interrupts | D14: 73206 | E14: =(D14-'2011'!D35)/'2011'!D35 -> -0.0095250981 | F14: =(D14-'2011'!D16)/'2011'!D16 -> -0.012451267 | G14: 74184 | H14: 66269 | I14: =(H14-'2011'!G35)/'2011'!G35 -> -0.006625594 | J14: =(H14-'2011'!G16)/'2011'!G16 -> -0.02253787 | K14: 66800 | L14: 31114 | M14: =(L14-'2011'!J35)/'2011'!J35 -> 0 | N14: =(L14-'2011'!J16)/'2011'!J16 -> -0.031108897 | O14: 31546
A15: T4 | B15: AI/AO/Host communication | C15: Interrupts | D15: 71839 | E15: =(D15-'2011'!D36)/'2011'!D36 -> -0.01364766 | F15: =(D15-'2011'!D17)/'2011'!D17 -> 0.010777651 | G15: 76336 | H15: 62189 | I15: =(H15-'2011'!G36)/'2011'!G36 -> -0.09141513 | J15: =(H15-'2011'!G17)/'2011'!G17 -> -0.067784923 | K15: 68027
A17: PXIe-8108, LV RT 2012a40, NI-DAQmx 9.4.0 (PXIe-6361 and PXIe-6363) With SMP support
A18: Test | B18: Description | C18: I/O Mode | D18: Rate 1ch Min | E18: vs. LV11.1, Dmx9.4 | F18: vs. LV11, Dmx9.3.5 | G18: Rate 1ch Max | H18: Rate 4ch Min | I18: vs. LV11.1, Dmx9.4 | J18: vs. LV11, Dmx9.3.5 | K18: Rate 4ch Max | L18: Rate 16ch Min | M18: vs. LV11.1, Dmx9.4 | N18: vs. LV11, Dmx9.3.5 | O18: Rate 16ch Max
A19: T1 | B19: AI / AO | C19: Polling | D19: 169779 | E19: =(D19-'2011'!D23)/'2011'!D23 -> 0 | F19: =(D19-'2011'!D4)/'2011'!D4 -> 0.1646807 | G19: 174216 | H19: 109649 | I19: =(H19-'2011'!G23)/'2011'!G23 -> -0.025220916 | J19: =(H19-'2011'!G4)/'2011'!G4 -> 0.081137843 | K19: 112108 | L19: 38565 | M19: =(L19-'2011'!J23)/'2011'!J23 -> 0.027769635 | N19: =(L19-'2011'!J4)/'2011'!J4 -> 0.027769635 | O19: 38926
A20: T2a | B20: AI/PID/AO | C20: Polling | D20: 168919 | E20: =(D20-'2011'!D24)/'2011'!D24 -> 0.16891681 | F20: =(D20-'2011'!D5)/'2011'!D5 -> 0.12162521 | G20: 169204 | H20: CAR 333189 | I20: =(H20-'2011'!G24)/'2011'!G24 -> #VALUE! | J20: =(H20-'2011'!G5)/'2011'!G5 -> #VALUE! | M20: =(L20-'2011'!J24)/'2011'!J24 -> -1 | N20: =(L20-'2011'!J5)/'2011'!J5 -> -1
A21: T2b | B21: AI/PID/AO | C21: Interrupts | D21: 57803 | E21: =(D21-'2011'!D25)/'2011'!D25 -> -0.057231863 | F21: =(D21-'2011'!D6)/'2011'!D6 -> 0.022537105 | G21: 59312 | I21: =(H21-'2011'!G25)/'2011'!G25 -> -1 | J21: =(H21-'2011'!G6)/'2011'!G6 -> -1 | M21: =(L21-'2011'!J25)/'2011'!J25 -> -1 | N21: =(L21-'2011'!J6)/'2011'!J6 -> -1
A22: T3 | B22: AI/AO/Local Logging | C22: Polling | D22: 144092 | E22: =(D22-'2011'!D26)/'2011'!D26 -> 0.0057654991 | F22: =(D22-'2011'!D7)/'2011'!D7 -> -0.0028856334 | G22: 154799 | I22: =(H22-'2011'!G26)/'2011'!G26 -> -1 | J22: =(H22-'2011'!G7)/'2011'!G7 -> -1 | M22: =(L22-'2011'!J26)/'2011'!J26 -> -1 | N22: =(L22-'2011'!J7)/'2011'!J7 -> -1
A23: T4 | B23: AI/AO/Host communication | C23: Polling | D23: 137741 | E23: =(D23-'2011'!D27)/'2011'!D27 -> -0.012396931 | F23: =(D23-'2011'!D8)/'2011'!D8 -> -0.013775821 | G23: 140252 | H23: 84818 | I23: =(H23-'2011'!G27)/'2011'!G27 -> -0.15351297 | J23: =(H23-'2011'!G8)/'2011'!G8 -> -0.12467621 | K23: 104603 | L23: 36996 | M23: =(L23-'2011'!J27)/'2011'!J27 -> 0.11135811 | N23: =(L23-'2011'!J8)/'2011'!J8 -> 0.027381283 | O23: 37397
A25: PXIe-8108, LV RT 2012a40, NI-DAQmx 9.4.0 (PXIe-6361 and PXIe-6363) No SMP support
A26: Test | B26: Description | C26: I/O Mode | D26: Rate 1ch Min | E26: vs. LV11.1, Dmx9.4 | F26: vs. LV11, Dmx9.3.5 | G26: Rate 1ch Max | H26: Rate 4ch Min | I26: vs. LV11.1, Dmx9.4 | J26: vs. LV11, Dmx9.3.5 | K26: Rate 4ch Max | L26: Rate 16ch Min | M26: vs. LV11.1, Dmx9.4 | N26: vs. LV11, Dmx9.3.5 | O26: Rate 16ch Max
A27: T1 | B27: AI / AO | C27: Polling | E27: =(D27-'2011'!D32)/'2011'!D32 -> -1 | F27: =(D27-'2011'!D13)/'2011'!D13 -> -1 | I27: =(H27-'2011'!G32)/'2011'!G32 -> -1 | J27: =(H27-'2011'!G13)/'2011'!G13 -> -1 | M27: =(L27-'2011'!J32)/'2011'!J32 -> -1 | N27: =(L27-'2011'!J13)/'2011'!J13 -> -1
A28: T2a | B28: AI/PID/AO | C28: Polling | E28: =(D28-'2011'!D33)/'2011'!D33 -> -1 | F28: =(D28-'2011'!D14)/'2011'!D14 -> -1 | I28: =(H28-'2011'!G33)/'2011'!G33 -> -1 | J28: =(H28-'2011'!G14)/'2011'!G14 -> -1 | M28: =(L28-'2011'!J33)/'2011'!J33 -> -1 | N28: =(L28-'2011'!J14)/'2011'!J14 -> -1
A29: T2b | B29: AI/PID/AO | C29: Interrupts | E29: =(D29-'2011'!D34)/'2011'!D34 -> -1 | F29: =(D29-'2011'!D15)/'2011'!D15 -> -1 | I29: =(H29-'2011'!G34)/'2011'!G34 -> -1 | J29: =(H29-'2011'!G15)/'2011'!G15 -> -1 | M29: =(L29-'2011'!J34)/'2011'!J34 -> -1 | N29: =(L29-'2011'!J15)/'2011'!J15 -> -1
A30: T3 | B30: AI/AO/Local Logging | C30: Interrupts | E30: =(D30-'2011'!D35)/'2011'!D35 -> -1 | F30: =(D30-'2011'!D16)/'2011'!D16 -> -1 | I30: =(H30-'2011'!G35)/'2011'!G35 -> -1 | J30: =(H30-'2011'!G16)/'2011'!G16 -> -1 | M30: =(L30-'2011'!J35)/'2011'!J35 -> -1 | N30: =(L30-'2011'!J16)/'2011'!J16 -> -1
A31: T4 | B31: AI/AO/Host communication | C31: Interrupts | E31: =(D31-'2011'!D36)/'2011'!D36 -> -1 | F31: =(D31-'2011'!D17)/'2011'!D17 -> -1 | I31: =(H31-'2011'!G36)/'2011'!G36 -> -1 | J31: =(H31-'2011'!G17)/'2011'!G17 -> -1 | M31: =(L31-'2011'!J36)/'2011'!J36 -> -1 | N31: =(L31-'2011'!J17)/'2011'!J17 -> -1
A33: PXIe-8108, LV RT 2012b82, NI-DAQmx 9.5.5 (PXIe-6361 and PXIe-6363) With SMP support
A34: Test | B34: Description | C34: I/O Mode | D34: Rate 1ch Min | E34: vs. LV11.1, Dmx9.4 | F34: vs. LV11, Dmx9.3.5 | G34: Rate 1ch Max | H34: Rate 4ch Min | I34: vs. LV11.1, Dmx9.4 | J34: vs. LV11, Dmx9.3.5 | K34: Rate 4ch Max | L34: Rate 16ch Min | M34: vs. LV11.1, Dmx9.4 | N34: vs. LV11, Dmx9.3.5 | O34: Rate 16ch Max | P34: Avg:
A35: T1 | B35: AI / AO | C35: Polling | D35: 155280 | E35: =(D35-'2011'!D23)/'2011'!D23 -> -0.085399254 | F35: =(D35-'2011'!D4)/'2011'!D4 -> 0.065217839 | G35: 174216 | H35: 108578 | I35: =(H35-'2011'!G23)/'2011'!G23 -> -0.034742101 | J35: =(H35-'2011'!G4)/'2011'!G4 -> 0.070577795 | K35: 113122 | L35: 38095 | M35: =(L35-'2011'!J23)/'2011'!J23 -> 0.015243984 | N35: =(L35-'2011'!J4)/'2011'!J4 -> 0.015243984 | O35: 39108 | P35: =AVERAGE(E35:F35,I35:J35,M35:N35) -> 0.0076903743
A36: T2a | B36: AI/PID/AO | C36: Polling | D36: 162602 | E36: =(D36-'2011'!D24)/'2011'!D24 -> 0.12520327 | F36: =(D36-'2011'!D5)/'2011'!D5 -> 0.079680217 | G36: 170648 | H36: 98912 | I36: =(H36-'2011'!G24)/'2011'!G24 -> -0.044513138 | J36: =(H36-'2011'!G5)/'2011'!G5 -> -0.026705764 | K36: 105485 | L36: 36178 | M36: =(L36-'2011'!J24)/'2011'!J24 -> 0.00033180335 | N36: =(L36-'2011'!J5)/'2011'!J5 -> 0.030359991 | O36: 36873 | P36: =AVERAGE(E36:F36,I36:J36,M36:N36) -> 0.027392731
A37: T2b | B37: AI/PID/AO | C37: Interrupts | D37: 65531 | E37: =(D37-'2011'!D25)/'2011'!D25 -> 0.068811978 | F37: =(D37-'2011'!D6)/'2011'!D6 -> 0.1592457 | G37: 66534 | H37: 59952 | I37: =(H37-'2011'!G25)/'2011'!G25 -> 0.098323715 | J37: =(H37-'2011'!G6)/'2011'!G6 -> 0.2098317 | K37: 61350 | L37: 29291 | M37: =(L37-'2011'!J25)/'2011'!J25 -> 0.077627755 | N37: =(L37-'2011'!J6)/'2011'!J6 -> 0.11627287 | O37: 29595 | P37: =AVERAGE(E37:F37,I37:J37,M37:N37) -> 0.12168562
A38: T3 | B38: AI/AO/Local Logging | C38: Polling | D38: 126743 | E38: =(D38-'2011'!D26)/'2011'!D26 -> -0.11533092 | F38: =(D38-'2011'!D7)/'2011'!D7 -> -0.12294044 | G38: 148148 | H38: 99602 | I38: =(H38-'2011'!G26)/'2011'!G26 -> -0.061748165 | J38: =(H38-'2011'!G7)/'2011'!G7 -> -0.013939214 | K38: 102041 | L38: 36364 | M38: =(L38-'2011'!J26)/'2011'!J26 -> 0.019999439 | N38: =(L38-'2011'!J7)/'2011'!J7 -> 0.015640711 | O38: 37216 | P38: =AVERAGE(E38:F38,I38:J38,M38:N38) -> -0.046386432
A39: T4 | B39: AI/AO/Host communication | C39: Polling | D39: 123305 | E39: =(D39-'2011'!D27)/'2011'!D27 -> -0.11590306 | F39: =(D39-'2011'!D8)/'2011'!D8 -> -0.11713744 | G39: 136986 | H39: 95057 | I39: =(H39-'2011'!G27)/'2011'!G27 -> -0.051327345 | J39: =(H39-'2011'!G8)/'2011'!G8 -> -0.019009484 | K39: 102880 | L39: 36996 | M39: =IF(L39="","",(L39-'2011'!J27)/'2011'!J27) -> 0.11135811 | N39: =IF(L39="","",(L39-'2011'!J8)/'2011'!J8) -> 0.027381283 | O39: 38095 | P39: =AVERAGE(E39:F39,I39:J39,M39:N39) -> -0.027439656
P40: =AVERAGE(P35:P39) -> 0.016588527
D41: 1 Channel | H41: 4 Channel | L41: 16 Channel
A42: Test | B42: Description | C42: I/O Mode | D42: LV 2012, Dmx 9.5.5 | E42: LV 2011.1 Dmx 9.4 | F42: LV 2011, Dmx 9.3.5 | G42: 2012 Max | H42: LV 2012, Dmx 9.5.5 | I42: LV 2011.1 Dmx 9.4 | J42: LV 2011, Dmx 9.3.5 | K42: 2012 Max | L42: LV 2012, Dmx 9.5.5 | M42: LV 2011.1 Dmx 9.4 | N42: LV 2011, Dmx 9.3.5 | O42: 2012 Max
A43: T1 | B43: AI / AO | C43: Polling | D43: 155280 | E43: ='2011'!D23 -> 169779 | F43: ='2011'!D4 -> 145773 | G43: 174216 | H43: 108578 | I43: ='2011'!G23 -> 112486 | J43: ='2011'!G4 -> 101420 | K43: 113122 | L43: 38095 | M43: ='2011'!J23 -> 37523 | N43: ='2011'!J4 -> 37523 | O43: 39108
A44: T2a | B44: AI/PID/AO | C44: Polling | D44: 162602 | E44: ='2011'!D24 -> 144509 | F44: ='2011'!D5 -> 150602 | G44: 170648 | H44: 98912 | I44: ='2011'!G24 -> 103520 | J44: ='2011'!G5 -> 101626 | K44: 105485 | L44: 36178 | M44: ='2011'!J24 -> 36166 | N44: ='2011'!J5 -> 35112 | O44: 36873
...

Sheet 2013
A1: PXIe-8108, LV RT 2013, NI-DAQmx 9.5.5 (PXIe-6361 and PXIe-6363) With SMP support
A2: Test | B2: Description | C2: I/O Mode | D2: Rate 1ch Min | E2: vs. LV11.1, Dmx9.4 | F2: vs. LV12.1, Dmx9.5.5 | G2: Rate 1ch Max | H2: Rate 4ch Min | I2: vs. LV11.1, Dmx9.4 | J2: vs. LV12.1, Dmx9.5.5 | K2: Rate 4ch Max | L2: Rate 16ch Min | M2: vs. LV11.1, Dmx9.4 | N2: vs. LV12.1, Dmx9.5.5 | O2: Rate 16ch Max
A3: T1 | B3: AI / AO | C3: Polling | D3: 148368 | E3: =(D3-'2011'!D23)/'2011'!D23 -> -0.126111 | F3: =(D3-'2012'!D78)/'2012'!D78 -> -0.086055021 | G3: 176056 | H3: 111607 | I3: =(H3-'2011'!G23)/'2011'!G23 -> -0.0078143058 | J3: =(H3-'2012'!H78)/'2012'!H78 -> 0.034595597 | K3: 113636 | L3: 38745 | M3: =(L3-'2011'!J23)/'2011'!J23 -> 0.032566692 | N3: =(L3-'2012'!L78)/'2012'!L78 -> 0.028291621 | O3: 39093
A4: T2a | B4: AI/PID/AO | C4: Polling | D4: 143678 | E4: =(D4-'2011'!D24)/'2011'!D24 -> -0.0057505069 | F4: =(D4-'2012'!D79)/'2012'!D79 -> -0.03448693 | G4: 171233 | H4: 101626 | I4: =(H4-'2011'!G24)/'2011'!G24 -> -0.018295981 | J4: =(H4-'2012'!H79)/'2012'!H79 -> 0.049801147 | K4: 106724 | L4: 35336 | M4: =(L4-'2011'!J24)/'2011'!J24 -> -0.022949732 | N4: =(L4-'2012'!L79)/'2012'!L79 -> 0.023697781 | O4: 37397
A5: T2b | B5: AI/PID/AO | C5: Interrupts | D5: 63573 | E5: =(D5-'2011'!D25)/'2011'!D25 -> 0.036876957 | F5: =(D5-'2012'!D80)/'2012'!D80 -> 0.054033889 | G5: 63939 | H5: 57937 | I5: =(H5-'2011'!G25)/'2011'!G25 -> 0.061408812 | J5: =(H5-'2012'!H80)/'2012'!H80 -> 0.017956602 | K5: 59880 | L5: 28433 | M5: =(L5-'2011'!J25)/'2011'!J25 -> 0.046061587 | N5: =(L5-'2012'!L80)/'2012'!L80 -> 0.018738803 | O5: 28994
A6: T3 | B6: AI/AO/Local Logging | C6: Polling | D6: 121212 | E6: =(D6-'2011'!D26)/'2011'!D26 -> -0.15393743 | F6: =(D6-'2012'!D81)/'2012'!D81 -> -0.086061557 | G6: 163399 | H6: 107875 | I6: =(H6-'2011'!G26)/'2011'!G26 -> 0.016183577 | J6: =(H6-'2012'!H81)/'2012'!H81 -> 0.075512707 | K6: 109529 | L6: 37369 | M6: =(L6-'2011'!J26)/'2011'!J26 -> 0.048189392 | N6: =(L6-'2012'!L81)/'2012'!L81 -> 0.047454872 | O6: 37397
A7: T4 | B7: AI/AO/Host communication | C7: Polling | D7: 134590 | E7: =(D7-'2011'!D27)/'2011'!D27 -> -0.034989603 | F7: =(D7-'2012'!D82)/'2012'!D82 -> 0.018849357 | G7: 141844 | H7: 82576 | I7: =(H7-'2011'!G27)/'2011'!G27 -> -0.17588822 | J7: =(H7-'2012'!H82)/'2012'!H82 -> -0.1544196 | K7: 95057 | L7: 35436 | M7: =(L7-'2011'!J27)/'2011'!J27 -> 0.064495779 | N7: =(L7-'2012'!L82)/'2012'!L82 -> 0.018773539 | O7: 36219
A8: Worst of 3 | C8: http://us-aus-rtweb1/Reports/RT/2013/performance/pharlap/rtperf-8108/sp_online_poll_smp/2012-12-18_20-28-52/HTML/2012-12-18_20-36-14_SinglePointBenchmarks_ATS.html
A9: Average: | B9: =AVERAGE(F3:F7,J3:J7,N3:N7) -> 0.0017788541
A10: PXIe-8108, LV RT 2013, NI-DAQmx 9.5.5 (PXIe-6361 and PXIe-6363) No SMP support
A11: Test | B11: Description | C11: I/O Mode | D11: Rate 1ch Min | E11: vs. LV11.1, Dmx9.4 | F11: vs. LV12.1, Dmx9.5.5 | G11: Rate 1ch Max | H11: Rate 4ch Min | I11: vs. LV11.1, Dmx9.4 | J11: vs. LV12.1, Dmx9.5.5 | K11: Rate 4ch Max | L11: Rate 16ch Min | M11: vs. LV11.1, Dmx9.4 | N11: vs. LV12.1, Dmx9.5.5 | O11: Rate 16ch Max
A12: T1 | B12: AI / AO | C12: Polling | D12: 157729 | E12: =(D12-'2011'!D32)/'2011'!D32 -> 0.023662571 | F12: =(D12-'2012'!D86)/'2012'!D86 -> 0.083601264 | G12: 160000 | H12: 104493 | I12: =(H12-'2011'!G32)/'2011'!G32 -> 0.024029557 | J12: =(H12-'2012'!H86)/'2012'!H86 -> 0.016716127 | K12: 105374 | L12: 37369 | M12: =(L12-'2011'!J32)/'2011'!J32 -> 0.033263286 | N12: =(L12-'2012'!L86)/'2012'!L86 -> 0.018312124 | O12: 37552
A13: T2a | B13: AI/PID/AO | C13: Polling | D13: 152905 | E13: =(D13-'2011'!D33)/'2011'!D33 -> 0.027518312 | F13: =(D13-'2012'!D87)/'2012'!D87 -> 0.091741875 | G13: 155763 | H13: 97087 | I13: =(H13-'2011'!G33)/'2011'!G33 -> 0.032038948 | J13: =(H13-'2012'!H87)/'2012'!H87 -> 0.055339363 | K13: 97087 | L13: 35174 | M13: =(L13-'2011'!J33)/'2011'!J33 -> 0.019004577 | N13: =(L13-'2012'!L87)/'2012'!L87 -> 0.040435413 | O13: 35753
A14: T2b | B14: AI/PID/AO | C14: Interrupts | D14: 89047 | E14: =(D14-'2011'!D34)/'2011'!D34 -> 0.0391761 | F14: =(D14-'2012'!D88)/'2012'!D88 -> 0.072132055 | G14: 90744 | H14: 72886 | I14: =(H14-'2011'!G34)/'2011'!G34 -> 0.0043682564 | J14: =(H14-'2012'!H88)/'2012'!H88 -> 0.085275242 | K14: 75301 | L14: 33167 | M14: =(L14-'2011'!J34)/'2011'!J34 -> 0.047070337 | N14: =(L14-'2012'!L88)/'2012'!L88 -> 0.042757883 | O14: 33167
A15: T3 | B15: AI/AO/Local Logging | C15: Interrupts | D15: 75245 | E15: =(D15-'2011'!D35)/'2011'!D35 -> 0.018062508 | F15: =(D15-'2012'!D89)/'2012'!D89 -> 0.045156541 | G15: 77042 | H15: 70126 | I15: =(H15-'2011'!G35)/'2011'!G35 -> 0.051190958 | J15: =(H15-'2012'!H89)/'2012'!H89 -> 0.055399202 | K15: 70621 | L15: 32404 | M15: =(L15-'2011'!J35)/'2011'!J35 -> 0.041460436 | N15: =(L15-'2012'!L89)/'2012'!L89 -> 0.016851288 | O15: 32520
A16: T4 | B16: AI/AO/Host communication | C16: Interrupts | D16: 74906 | E16: =(D16-'2011'!D36)/'2011'!D36 -> 0.028462373 | F16: =(D16-'2012'!D90)/'2012'!D90 -> 0.060676003 | G16: 75529 | H16: 52854 | I16: =(H16-'2011'!G36)/'2011'!G36 -> -0.22780002 | J16: =(H16-'2012'!H90)/'2012'!H90 -> -0.19503503 | K16: 53419 | L16: 30703 | M16: =(L16-'2011'!J36)/'2011'!J36 -> -0.056192555 | N16: =(L16-'2012'!L90)/'2012'!L90 -> -0.056192555 | O16: 32268 | P16: Had a 14k outlier but haven't been able to reproduce in another 20 runs.
A17: Worst of 3 | C17: http://us-aus-rtweb1/Reports/RT/2013/performance/pharlap/rtperf-8108/sp_online_poll_nosmp/2012-12-18_10-13-27/HTML/2012-12-18_10-18-37_SinglePointBenchmarks_ATS.html
A18: Average: | B18: =AVERAGE(F12:F16,J12:J16,N12:N16) -> 0.028877786
C20: Reruns: | D20: 2012 | E20: 2013
C21: T1 1 | D21: 154559 | E21: 159236
C22: T3 1 | D22: 114548 | E22: 129701
C23: T4 4 | D23: 99404 | E23: 103413
C24: T4 4 (noSMP) | E24: 67613
A26: PXIe-8108, LV RT 2013b75, NI-DAQmx 9.5.5 (PXIe-6361 and PXIe-6363) With SMP support
A27: Test | B27: Description | C27: I/O Mode | D27: Rate 1ch Min | E27: vs. LV11.1, Dmx9.4 | F27: vs. LV12.1, Dmx9.5.5 | G27: Rate 1ch Max | H27: Rate 4ch Min | I27: vs. LV11.1, Dmx9.4 | J27: vs. LV12.1, Dmx9.5.5 | K27: Rate 4ch Max | L27: Rate 16ch Min | M27: vs. LV11.1, Dmx9.4 | N27: vs. LV12.1, Dmx9.5.5 | O27: Rate 16ch Max
A28: T1 | B28: AI / AO | C28: Polling | D28: 173611 | E28: =(D28-'2011'!D23)/'2011'!D23 -> 0.022570518 | F28: =(D28-'2012'!D78)/'2012'!D78 -> 0.069441536 | G28: 179211 | H28: 108696 | I28: =(H28-'2011'!G23)/'2011'!G23 -> -0.033693082 | J28: =(H28-'2012'!H78)/'2012'!H78 -> 0.0076106605 | K28: 114025 | L28: 39277 | M28: =(L28-'2011'!J23)/'2011'!J23 -> 0.046744663 | N28: =(L28-'2012'!L78)/'2012'!L78 -> 0.042410892 | O28: 39463
A29: T2a | B29: AI/PID/AO | C29: Polling | D29: 171821 | E29: =(D29-'2011'!D24)/'2011'!D24 -> 0.18899861 | F29: =(D29-'2012'!D79)/'2012'!D79 -> 0.15463343 | G29: 172414 | H29: 103199 | I29: =(H29-'2011'!G24)/'2011'!G24 -> -0.0031008501 | J29: =(H29-'2012'!H79)/'2012'!H79 -> 0.066050307 | K29: 107411 | L29: 37216 | M29: =(L29-'2011'!J24)/'2011'!J24 -> 0.029032793 | N29: =(L29-'2012'!L79)/'2012'!L79 -> 0.078162118 | O29: 37552
A30: T2b | B30: AI/PID/AO | C30: Interrupts | D30: 64061 | E30: =(D30-'2011'!D25)/'2011'!D25 -> 0.044836247 | F30: =(D30-'2012'!D80)/'2012'!D80 -> 0.06212488 | G30: 66534 | H30: 57937 | I30: =(H30-'2011'!G25)/'2011'!G25 -> 0.061408812 | J30: =(H30-'2012'!H80)/'2012'!H80 -> 0.017956602 | K30: 59880 | L30: 29394 | M30: =(L30-'2011'!J25)/'2011'!J25 -> 0.081417166 | N30: =(L30-'2012'!L80)/'2012'!L80 -> 0.053170906 | O30: 29429
A31: T3 | B31: AI/AO/Local Logging | C31: Polling | D31: 152207 | E31: =(D31-'2011'!D26)/'2011'!D26 -> 0.062408387 | F31: =(D31-'2012'!D81)/'2012'!D81 -> 0.14764073 | G31: 159744 | H31: 100000 | I31: =(H31-'2011'!G26)/'2011'!G26 -> -0.057999001 | J31: =(H31-'2012'!H81)/'2012'!H81 -> -0.0030009671 | K31: 107411 | L31: 36023 | M31: =(L31-'2011'!J26)/'2011'!J26 -> 0.01043449 | N31: =(L31-'2012'!L81)/'2012'!L81 -> 0.0097264267 | O31: 38095
A32: T4 | B32: AI/AO/Host communication | C32: Polling | E32: =(D32-'2011'!D27)/'2011'!D27 -> -1 | F32: =(D32-'2012'!D82)/'2012'!D82 -> -1 | I32: =(H32-'2011'!G27)/'2011'!G27 -> -1 | J32: =(H32-'2012'!H82)/'2012'!H82 -> -1 | M32: =(L32-'2011'!J27)/'2011'!J27 -> -1 | N32: =(L32-'2012'!L82)/'2012'!L82 -> -1
A33: Worst of 3 | C33: http://us-aus-rtweb1.natinst.com/Reports/RT/2013/performance/pharlap/rtperf-8108/sp_online_poll_smp/2013-04-12_18-18-20/HTML/2013-04-12_18-25-44_SinglePointBenchmarks_ATS.html
A34: Average: | B34: =AVERAGE(F28:F32,J28:J32,N28:N32) -> -0.15293817
A35: PXIe-8108, LV RT 2013b75, NI-DAQmx 9.5.5 (PXIe-6361 and PXIe-6363) No SMP support
A36: Test | B36: Description | C36: I/O Mode | D36: Rate 1ch Min | E36: vs. LV11.1, Dmx9.4 | F36: vs. LV12.1, Dmx9.5.5 | G36: Rate 1ch Max | H36: Rate 4ch Min | I36: vs. LV11.1, Dmx9.4 | J36: vs. LV12.1, Dmx9.5.5 | K36: Rate 4ch Max | L36: Rate 16ch Min | M36: vs. LV11.1, Dmx9.4 | N36: vs. LV12.1, Dmx9.5.5 | O36: Rate 16ch Max
A37: T1 | B37: AI / AO | C37: Polling | D37: 154799 | E37: =(D37-'2011'!D32)/'2011'!D32 -> 0.0046468462 | F37: =(D37-'2012'!D86)/'2012'!D86 -> 0.063472108 | G37: 157233 | H37: 100402 | I37: =(H37-'2011'!G32)/'2011'!G32 -> -0.016062171 | J37: =(H37-'2012'!H86)/'2012'!H86 -> -0.023089273 | K37: 104932 | L37: 37216 | M37: =(L37-'2011'!J32)/'2011'!J32 -> 0.029032793 | N37: =(L37-'2012'!L86)/'2012'!L86 -> 0.014142845 | O37: 37552
A38: T2a | B38: AI/PID/AO | C38: Polling | D38: 151976 | E38: =(D38-'2011'!D33)/'2011'!D33 -> 0.021275452 | F38: =(D38-'2012'!D87)/'2012'!D87 -> 0.085108814 | G38: 153374 | H38: 94073 | I38: =(H38-'2011'!G33)/'2011'!G33 -> 0 | J38: =(H38-'2012'!H87)/'2012'!H87 -> 0.022577069 | K38: 97087 | L38: 35398 | M38: =(L38-'2011'!J33)/'2011'!J33 -> 0.025493945 | N38: =(L38-'2012'!L87)/'2012'!L87 -> 0.04706126 | O38: 35753
A39: T2b | B39: AI/PID/AO | C39: Interrupts | D39: 85837 | E39: =(D39-'2011'!D34)/'2011'!D34 -> 0.0017154861 | F39: =(D39-'2012'!D88)/'2012'!D88 -> 0.033483433 | G39: 87951 | H39: 70077 | I39: =(H39-'2011'!G34)/'2011'!G34 -> -0.034339732 | J39: =(H39-'2012'!H88)/'2012'!H88 -> 0.043449128 | K39: 73965 | L39: 32478 | M39: =(L39-'2011'!J34)/'2011'!J34 -> 0.025318853 | N39: =(L39-'2012'!L88)/'2012'!L88 -> 0.021095985 | O39: 33289
A40: T3 | B40: AI/AO/Local Logging | C40: Interrupts | D40: 76278 | E40: =(D40-'2011'!D35)/'2011'!D35 -> 0.032038966 | F40: =(D40-'2012'!D89)/'2012'!D89 -> 0.059504959 | G40: 76628 | H40: 69252 | I40: =(H40-'2011'!G35)/'2011'!G35 -> 0.03808967 | J40: =(H40-'2012'!H89)/'2012'!H89 -> 0.042245466 | K40: 69930 | L40: 32584 | M40: =(L40-'2011'!J35)/'2011'!J35 -> 0.047245613 | N40: =(L40-'2012'!L89)/'2012'!L89 -> 0.022499765 | O40: 32723
A41: T4 | B41: AI/AO/Host communication | C41: Interrupts | E41: =(D41-'2011'!D36)/'2011'!D36 -> -1 | F41: =(D41-'2012'!D90)/'2012'!D90 -> -1 | I41: =(H41-'2011'!G36)/'2011'!G36 -> -1 | J41: =(H41-'2012'!H90)/'2012'!H90 -> -1 | M41: =(L41-'2011'!J36)/'2011'!J36 -> -1 | N41: =(L41-'2012'!L90)/'2012'!L90 -> -1
A42: Worst of 3 | C42: http://us-aus-rtweb1.natinst.com/Reports/RT/2013/performance/pharlap/rtperf-8108/sp_online_poll_nosmp/2013-04-12_08-38-40/HTML/2013-04-12_08-45-28_SinglePointBenchmarks_ATS.html
...

Sheet 2014
A1: PXIe-8108, LV RT 2014a10, NI-DAQmx 9.8 (PXIe-6361 and PXIe-6363) With SMP support
A2: Test | B2: Description | C2: I/O Mode | D2: Rate 1ch Min | E2: vs. LV13.1, Dmx9.8 | F2: vs. LV12.1, Dmx9.5.5 | G2: Rate 1ch Max | H2: Rate 4ch Min | I2: vs. LV13.1, Dmx9.8 | J2: vs. LV12.1, Dmx9.5.5 | K2: Rate 4ch Max | L2: Rate 16ch Min | M2: vs. LV13.1, Dmx9.8 | N2: vs. LV12.1, Dmx9.5.5 | O2: Rate 16ch Max
A3: T1 | B3: AI / AO | C3: Polling | D3: 165017 | E3: =(D3-'2013'!D82)/'2013'!D82 -> -0.0098999802 | F3: =(D3-'2012'!D78)/'2012'!D78 -> 0.016502606 | G3: 171821 | H3: 110619 | I3: =(H3-'2013'!H82)/'2013'!H82 -> -0.0033246837 | J3: =(H3-'2012'!H78)/'2012'!H78 -> 0.025436848 | K3: 112108 | L3: 38775 | M3: =(L3-'2013'!L82)/'2013'!L82 -> 0.010476116 | N3: =(L3-'2012'!L78)/'2012'!L78 -> 0.029087821 | O3: 38926
A4: T2a | B4: AI/PID/AO | C4: Polling | D4: 165837 | E4: =(D4-'2013'!D83)/'2013'!D83 -> -0.008294264 | F4: =(D4-'2012'!D79)/'2012'!D79 -> 0.11442107 | G4: 167785 | H4: 104493 | I4: =(H4-'2013'!H83)/'2013'!H83 -> 0.032386504 | J4: =(H4-'2012'!H79)/'2012'!H79 -> 0.079417385 | K4: 105042 | L4: 35855 | M4: =(L4-'2013'!L83)/'2013'!L83 -> -0.013617607 | N4: =(L4-'2012'!L79)/'2012'!L79 -> 0.038733414 | O4: 37037
A5: T2b | B5: AI/PID/AO | C5: Interrupts | D5: 65833 | E5: =(D5-'2013'!D84)/'2013'!D84 -> 0.012503845 | F5: =(D5-'2012'!D80)/'2012'!D80 -> 0.09150446 | G5: 66225 | H5: 58005 | I5: =(H5-'2013'!H84)/'2013'!H84 -> 0.013931618 | J5: =(H5-'2012'!H80)/'2012'!H80 -> 0.019151366 | K5: 58480 | L5: 28777 | M5: =(L5-'2013'!L84)/'2013'!L84 -> 0.0031722792 | N5: =(L5-'2012'!L80)/'2012'!L80 -> 0.031064135 | O5: 29163
A6: T3 | B6: AI/AO/Local Logging | C6: Polling | D6: 156006 | E6: =(D6-'2013'!D85)/'2013'!D85 -> 0.077999972 | F6: =(D6-'2012'!D81)/'2012'!D81 -> 0.17628519 | G6: 161031 | H6: 104932 | I6: =(H6-'2013'!H85)/'2013'!H85 -> 0.083952275 | J6: =(H6-'2012'!H81)/'2012'!H81 -> 0.046171025 | K6: 108342 | L6: 37722 | M6: =(L6-'2013'!L85)/'2013'!L85 -> 0.02753943 | N6: =(L6-'2012'!L81)/'2012'!L81 -> 0.057349479 | O6: 38095
A7: T4 | B7: AI/AO/Host communication | C7: Polling | D7: 137552 | E7: =(D7-'2013'!D86)/'2013'!D86 -> 0.041271764 | F7: =(D7-'2012'!D82)/'2012'!D82 -> 0.041271764 | G7: 139470 | H7: 99405 | I7: =(H7-'2013'!H86)/'2013'!H86 -> -0.044715447 | J7: =(H7-'2012'!H82)/'2012'!H82 -> 0.017909806 | K7: 105485 | L7: 36914 | M7: =(L7-'2013'!L86)/'2013'!L86 -> 0.0092410324 | N7: =(L7-'2012'!L82)/'2012'!L82 -> 0.061265561 | O7: 37764
A8: Worst of 3 | C8: http://us-aus-rtweb1/Reports/RT/2014/performance/pharlap/rtperf-8108/sp_online_poll_smp/2013-11-23_03-01-57/HTML/2013-11-23_03-10-00_SinglePointBenchmarks_ATS.html
A10: PXIe-8108, LV RT 2014a10, NI-DAQmx 9.8 (PXIe-6361 and PXIe-6363) No SMP support
A11: Test | B11: Description | C11: I/O Mode | D11: Rate 1ch Min | E11: vs. LV13.1, Dmx9.8 | F11: vs. LV12.1, Dmx9.5.5 | G11: Rate 1ch Max | H11: Rate 4ch Min | I11: vs. LV13.1, Dmx9.8 | J11: vs. LV12.1, Dmx9.5.5 | K11: Rate 4ch Max | L11: Rate 16ch Min | M11: vs. LV13.1, Dmx9.8 | N11: vs. LV12.1, Dmx9.5.5 | O11: Rate 16ch Max
A12: T1 | B12: AI / AO | C12: Polling | D12: 152672 | E12: =(D12-'2013'!D90)/'2013'!D90 -> 0.029008951 | F12: =(D12-'2012'!D86)/'2012'!D86 -> 0.048859577 | G12: 154083 | H12: 100806 | I12: =(H12-'2013'!H90)/'2013'!H90 -> -0.015123981 | J12: =(H12-'2012'!H86)/'2012'!H86 -> -0.019158356 | K12: 103627 | L12: 36873 | M12: =(L12-'2013'!L90)/'2013'!L90 -> -0.014011819 | N12: =(L12-'2012'!L86)/'2012'!L86 -> 0.0047960324 | O12: 37552
A13: T2a | B13: AI/PID/AO | C13: Polling | D13: 144928 | E13: =(D13-'2013'!D91)/'2013'!D91 -> -0.0086936299 | F13: =(D13-'2012'!D87)/'2012'!D87 -> 0.034786086 | G13: 147492 | H13: 95057 | I13: =(H13-'2013'!H91)/'2013'!H91 -> 0.0047565191 | J13: =(H13-'2012'!H87)/'2012'!H87 -> 0.033273186 | K13: 95420 | L13: 35174 | M13: =(L13-'2013'!L91)/'2013'!L91 -> 0.0066683838 | N13: =(L13-'2012'!L87)/'2012'!L87 -> 0.040435413 | O13: 35286
A14: T2b | B14: AI/PID/AO | C14: Interrupts | D14: 82508 | E14: =(D14-'2013'!D92)/'2013'!D92 -> -0.036301626 | F14: =(D14-'2012'!D88)/'2012'!D88 -> -0.006597958 | G14: 86059 | H14: 71073 | I14: =(H14-'2013'!H92)/'2013'!H92 -> -0.0042730253 | J14: =(H14-'2012'!H88)/'2012'!H88 -> 0.058279605 | K14: 73099 | L14: 32680 | M14: =(L14-'2013'!L92)/'2013'!L92 -> -0.0062036249 | N14: =(L14-'2012'!L88)/'2012'!L88 -> 0.027446788 | O14: 32884
A15: T3 | B15: AI/AO/Local Logging | C15: Interrupts | D15: 75131 | E15: =(D15-'2013'!D93)/'2013'!D93 -> -0.015037101 | F15: =(D15-'2012'!D89)/'2012'!D89 -> 0.043573076 | G15: 76982 | H15: 69784 | I15: =(H15-'2013'!H93)/'2013'!H93 -> 0 | J15: =(H15-'2012'!H89)/'2012'!H89 -> 0.050252088 | K15: 69930 | L15: 32425 | M15: =(L15-'2013'!L93)/'2013'!L93 -> 0 | N15: =(L15-'2012'!L89)/'2012'!L89 -> 0.017510277 | O15: 32584
A16: T4 | B16: AI/AO/Host communication | C16: Interrupts | D16: 73801 | E16: =(D16-'2013'!D94)/'2013'!D94 -> -0.019190644 | F16: =(D16-'2012'!D90)/'2012'!D90 -> 0.045029099 | G16: 73855 | H16: 67751 | I16: =(H16-'2013'!H94)/'2013'!H94 -> -0.0047448365 | J16: =(H16-'2012'!H90)/'2012'!H90 -> 0.031845873 | K16: 70077 | L16: 32830 | M16: =(L16-'2013'!L94)/'2013'!L94 -> 0.0075497177 | N16: =(L16-'2012'!L90)/'2012'!L90 -> 0.009191233 | O16: 33156
A17: Worst of 3 | C17: http://us-aus-rtweb1/Reports/RT/2014/performance/pharlap/rtperf-8108/sp_online_poll_nosmp/2013-11-22_18-06-46/HTML/2013-11-22_18-14-41_SinglePointBenchmarks_ATS.html
A19: PXIe-8108, LV RT 2014b22, NI-DAQmx 9.8 (PXIe-6361 and PXIe-6363) With SMP support
A20: Test | B20: Description | C20: I/O Mode | D20: Rate 1ch Min | E20: vs. LV13.1, Dmx9.8 | F20: vs. LV12.1, Dmx9.5.5 | G20: Rate 1ch Max | H20: Rate 4ch Min | I20: vs. LV13.1, Dmx9.8 | J20: vs. LV12.1, Dmx9.5.5 | K20: Rate 4ch Max | L20: Rate 16ch Min | M20: vs. LV13.1, Dmx9.8 | N20: vs. LV12.1, Dmx9.5.5 | O20: Rate 16ch Max
A21: T1 | B21: AI / AO | C21: Polling | D21: 166667 | E21: =(D21-'2013'!D82)/'2013'!D82 -> 0 | F21: =(D21-'2012'!D78)/'2012'!D78 -> 0.026666585 | G21: 168634 | H21: 110132 | I21: =(H21-'2013'!H82)/'2013'!H82 -> -0.0077125455 | J21: =(H21-'2012'!H78)/'2012'!H78 -> 0.020922364 | K21: 112108 | L21: 38595 | M21: =(L21-'2013'!L82)/'2013'!L82 -> 0.0057853178 | N21: =(L21-'2012'!L78)/'2012'!L78 -> 0.024310624 | O21: 38775
A22: T2a | B22: AI/PID/AO | C22: Polling | D22: 159236 | E22: =(D22-'2013'!D83)/'2013'!D83 -> -0.047768263 | F22: =(D22-'2012'!D79)/'2012'!D79 -> 0.070062496 | G22: 162866 | H22: 104493 | I22: =(H22-'2013'!H83)/'2013'!H83 -> 0.032386504 | J22: =(H22-'2012'!H79)/'2012'!H79 -> 0.079417385 | K22: 105374 | L22: 36711 | M22: =(L22-'2013'!L83)/'2013'!L83 -> 0.0099312242 | N22: =(L22-'2012'!L79)/'2012'!L79 -> 0.06353207 | O22: 37037
A23: T2b | B23: AI/PID/AO | C23: Interrupts | D23: 64516 | E23: =(D23-'2013'!D84)/'2013'!D84 -> -0.0077514611 | F23: =(D23-'2012'!D80)/'2012'!D80 -> 0.069668734 | G23: 58480 | H23: 58479 | I23: =(H23-'2013'!H84)/'2013'!H84 -> 0.022217172 | J23: =(H23-'2012'!H80)/'2012'!H80 -> 0.027479575 | K23: 59952 | L23: 31566 | M23: =(L23-'2013'!L84)/'2013'!L84 -> 0.10039741 | N23: =(L23-'2012'!L80)/'2012'!L80 -> 0.13099248 | O23: 31847
A24: T3 | B24: AI/AO/Local Logging | C24: Polling | D24: 130208 | E24: =(D24-'2013'!D85)/'2013'!D85 -> -0.10026396 | F24: =(D24-'2012'!D81)/'2012'!D81 -> -0.018231719 | G24: 156250 | H24: 105374 | I24: =(H24-'2013'!H85)/'2013'!H85 -> 0.088518155 | J24: =(H24-'2012'!H81)/'2012'!H81 -> 0.050577761 | K24: 106724 | L24: 36377 | M24: =(L24-'2013'!L85)/'2013'!L85 -> -0.0090980905 | N24: =(L24-'2012'!L81)/'2012'!L81 -> 0.019649064 | O24: 37397
A25: T4 | B25: AI/AO/Host communication | C25: Polling | D25: 136612 | E25: =(D25-'2013'!D86)/'2013'!D86 -> 0.034155942 | F25: =(D25-'2012'!D82)/'2012'!D82 -> 0.034155942 | G25: 139665 | H25: 99108 | I25: =(H25-'2013'!H86)/'2013'!H86 -> -0.047569625 | J25: =(H25-'2012'!H82)/'2012'!H82 -> 0.014868518 | K25: 105485 | L25: 37580 | M25: =(L25-'2013'!L86)/'2013'!L86 -> 0.027449694 | N25: =(L25-'2012'!L82)/'2012'!L82 -> 0.080412845 | O25: 37951
A26: Worst of 3 | C26: http://us-aus-rtweb1.natinst.com/Reports/RT/2014/performance/pharlap/rtperf-8108/sp_online_poll_smp/2014-02-04_17-04-29/HTML/2014-02-04_17-12-41_SinglePointBenchmarks_ATS.html | D26: T3 an outlier
A28: PXIe-8108, LV RT 2014b22, NI-DAQmx 9.8 (PXIe-6361 and PXIe-6363) No SMP support
