Workbook
Name _9033_with_UI: Test_Data_9033_UI_2017a17!$A$1:$N$83
Name test: Test_Data_9033_UI_2017!$A$1:$N$85

Sheet x64_ui  Regression
B1: Average CPU Usage (%)
A2: Loop Rate (Hz) | B2: 2014rc | C2: 2015b26 | D2: 2014a | E2: 2015b64 | F2: 2015rc1 | G2: 2016.0b59 | H2: 2016 | I2: 2017a17 | J2: 2017b6 | K2: 2017 | L2: 2018b10 | M2: 2018rc1 | N2: ='Test_Data_9033_UI_2020 B78'!P1 -> 2020 B78
A3: 100 | B3: 13.19 | C3: 12.82 | D3: 5.305 | E3: 12.34 | F3: 0.995 | G3: 11.43 | H3: 11.965 | I3: 12.14 | J3: 11.725 | K3: 11.42 | L3: 10.8 | M3: 10.955 | N3: ='Test_Data_9033_UI_2020 B78'!Q2 -> 13.95
A4: 200 | B4: 15.185 | C4: 14.705 | D4: 7.95 | E4: 14.305 | F4: 13.28 | G4: 13.185 | H4: 13.025 | I4: 13.72 | J4: 13.255 | K4: 13.025 | L4: 12.635 | M4: 12.48 | N4: ='Test_Data_9033_UI_2020 B78'!Q3 -> 15.39
A5: 300 | B5: 16.56 | C5: 16.205 | D5: 10.755 | E5: 16.155 | F5: 14.35 | G5: 14.525 | H5: 14.49 | I5: 14.765 | J5: 14.71 | K5: 13.93 | L5: 14.035 | M5: 13.64 | N5: ='Test_Data_9033_UI_2020 B78'!Q4 -> 16.305
A6: 400 | B6: 18.425 | C6: 18.835 | D6: 13.615 | E6: 18.13 | F6: 16.18 | G6: 16.16 | H6: 15.865 | I6: 16.715 | J6: 16.245 | K6: 15.65 | L6: 15.235 | M6: 15.11 | N6: ='Test_Data_9033_UI_2020 B78'!Q5 -> 17.89
A7: 500 | B7: 19.975 | C7: 20.075 | D7: 16.58 | E7: 19.75 | F7: 17.585 | G7: 17.895 | H7: 17.415 | I7: 18.285 | J7: 17.585 | K7: 16.925 | L7: 16.31 | M7: 16.45 | N7: ='Test_Data_9033_UI_2020 B78'!Q6 -> 19.285
A8: 600 | B8: 21.68 | C8: 21.58 | D8: 18.995 | E8: 20.755 | F8: 19.35 | G8: 18.89 | H8: 18.66 | I8: 19.475 | J8: 18.83 | K8: 18.04 | L8: 17.27 | M8: 17.765 | N8: ='Test_Data_9033_UI_2020 B78'!Q7 -> 20.5
A9: 700 | B9: 23.23 | C9: 23.32 | D9: 21.715 | E9: 22.66 | F9: 21.47 | G9: 20.43 | H9: 19.98 | I9: 20.79 | J9: 19.76 | K9: 19.605 | L9: 18.88 | M9: 19.195 | N9: ='Test_Data_9033_UI_2020 B78'!Q8 -> 21.95
A10: 800 | B10: 24.975 | C10: 24.9 | D10: 23.42 | E10: 24.525 | F10: 22.055 | G10: 21.73 | H10: 22 | I10: 22.7 | J10: 20.795 | K10: 20.785 | L10: 20.7 | M10: 20.25 | N10: ='Test_Data_9033_UI_2020 B78'!Q9 -> 23.21
A11: 900 | B11: 26.21 | C11: 26.445 | D11: 27.545 | E11: 25.685 | F11: 23.11 | G11: 23.145 | H11: 22.5 | I11: 23.2 | J11: 22.24 | K11: 22.135 | L11: 22.015 | M11: 21.605 | N11: ='Test_Data_9033_UI_2020 B78'!Q10 -> 25.065
A12: 1000 | B12: 27.755 | C12: 27.625 | D12: 30.295 | E12: 27.235 | F12: 24.36 | G12: 25.04 | H12: 24.29 | I12: 24.645 | J12: 23.41 | K12: 23.235 | L12: 22.8 | M12: 22.785 | N12: ='Test_Data_9033_UI_2020 B78'!Q11 -> 26.62
A13: 1100 | B13: 29.505 | C13: 29.22 | D13: 29.14 | E13: 28.72 | F13: 25.78 | G13: 26.17 | H13: 26.345 | I13: 25.91 | J13: 24.395 | K13: 24.51 | L13: 24.39 | M13: 24.51 | N13: ='Test_Data_9033_UI_2020 B78'!Q12 -> 28.115
A14: 1200 | B14: 31.585 | C14: 31.32 | D14: 32.115 | E14: 30.72 | F14: 27.73 | G14: 27.75 | H14: 29.075 | I14: 27.345 | J14: 26.08 | K14: 25.985 | L14: 25.845 | M14: 25.92 | N14: ='Test_Data_9033_UI_2020 B78'!Q13 -> 29.705
... A20: 1800 | B20: 40.825 | C20: 41.16 | D20: 45.865 | E20: 40.915 | F20: 35.35 | G20: 36.395 | H20: 35.615 | I20: 35.885 | J20: 33.805 | K20: 34.005 | L20: 33.785 | M20: 33.995 | N20: ='Test_Data_9033_UI_2020 B78'!Q19 -> 36.825
A21: 1900 | B21: 42.515 | C21: 42.725 | D21: 44.11 | E21: 42.765 | F21: 37.205 | G21: 37.6 | H21: 37.3 | I21: 37.225 | J21: 36.155 | K21: 34.945 | N21: ='Test_Data_9033_UI_2020 B78'!Q20 -> 38.51
A22: 2000 | B22: 44.26 | C22: 44.325 | D22: 49.93 | E22: 44.48 | F22: 39.07 | G22: 39.31 | H22: 38.915 | I22: 38.505 | J22: 36.865 | K22: 35.315 | N22: ='Test_Data_9033_UI_2020 B78'!Q21 -> 40.46
A23: =A22+100 -> 2100 | B23: 46.51 | C23: 46.045 | E23: 45.685 | F23: 40.08 | G23: 41.01 | I23: 39.155 | J23: 38.1 | K23: 37.585 | N23: ='Test_Data_9033_UI_2020 B78'!Q22 -> 41.11
A24: =A23+100 -> 2200 | B24: 47.59 | C24: 46.995 | E24: 46.94 | F24: 41.03 | G24: 42.205 | I24: 41.245 | J24: 38.845 | K24: 37.805 | N24: ='Test_Data_9033_UI_2020 B78'!Q23 -> 43.575
A25: =A24+100 -> 2300 | B25: 49.485 | C25: 50.225 | E25: 48.81 | F25: 41.56 | G25: 43.665 | I25: 42.705 | J25: 40.68 | K25: 40.19 | N25: ='Test_Data_9033_UI_2020 B78'!Q24 -> 45.49
A26: =A25+100 -> 2400 | B26: 51.235 | C26: 52.21 | E26: 50.635 | F26: 44.25 | G26: 45.325 | I26: 43.93 | J26: 42.335 | K26: 41.84 | N26: ='Test_Data_9033_UI_2020 B78'!Q25 -> 45.025
A27: =A26+100 -> 2500 | B27: 53.02 | C27: 52.71 | E27: 52.345 | F27: 45.995 | G27: 47.165 | I27: 43.585 | J27: 43.395 | K27: 42.595 | N27: ='Test_Data_9033_UI_2020 B78'!Q26 -> 47.18
A28: =A27+100 -> 2600 | B28: 54.54 | C28: 54.045 | E28: 53.68 | F28: 47.14 | G28: 48.06 | I28: 47.24 | K28: 42.97
A29: =A28+100 -> 2700 | B29: 55.83 | C29: 55.585 | E29: 55.315 | F29: 48.14 | G29: 49.575 | I29: 45.725 | K29: 46.03
A30: =A29+100 -> 2800 | B30: 57.08 | C30: 57.185 | E30: 56.985 | F30: 50.425 | G30: 51.355 | K30: 45.55
A31: 2900 | C31: 59.535 | E31: 59.435 | F31: 51.805 | G31: 53.055
A32: 3000 | C32: 61.665 | E32: 61.24 | F32: 52.905 | G32: 54.01

Sheet Test_Data_9033_UI_2020 B78
A1: Core | B1: Rate | C1: ISRs (Min) | D1: ISRs (Max) | E1: ISRs (Max) | F1: TL (min) | G1: TL (max) | H1: TL (Mean) | I1: Other (Min) | J1: Other (Max) | K1: Other (Mean) | L1: Total (min) | M1: Total (max) | N1: Total (Mean) | P1: 2020 B78 | Q1: Total (Mean)
A2: 0 | B2: 100 | C2: 1.56 | D2: 1.85 | E2: 1.68 | F2: 1.01 | G2: 1.07 | H2: 1.04 | I2: 17.98 | J2: 29.01 | K2: 23.47 | L2: 20.85 | M2: 31.84 | N2: 26.2 | P2: 100 | Q2: =AVERAGE(N2:N3) -> 13.95
A3: 1 | B3: 100 | C3: 0.07 | D3: 0.39 | E3: 0.14 | F3: 1.55 | G3: 1.59 | H3: 1.56 | I3: 0 | J3: 0.02 | K3: 0 | L3: 1.62 | M3: 1.95 | N3: 1.7 | P3: =P2+100 -> 200 | Q3: =AVERAGE(N4:N5) -> 15.39
A4: 0 | B4: 200 | C4: 1.66 | D4: 2.06 | E4: 1.77 | F4: 1.57 | G4: 1.61 | H4: 1.59 | I4: 20.41 | J4: 28.71 | K4: 24.09 | L4: 23.64 | M4: 32.09 | N4: 27.45 | P4: =P3+100 -> 300 | Q4: =AVERAGE(N6:N7) -> 16.305
A5: 1 | B5: 200 | C5: 0.09 | D5: 0.4 | E5: 0.16 | F5: 3.15 | G5: 3.22 | H5: 3.17 | I5: 0 | J5: 0.06 | K5: 0 | L5: 3.26 | M5: 3.68 | N5: 3.33 | P5: =P4+100 -> 400 | Q5: =AVERAGE(N8:N9) -> 17.89
A6: 0 | B6: 300 | C6: 1.68 | D6: 1.99 | E6: 1.78 | F6: 2.07 | G6: 2.18 | H6: 2.13 | I6: 19.96 | J6: 31.13 | K6: 23.88 | L6: 23.88 | M6: 35.13 | N6: 27.78 | P6: =P5+100 -> 500 | Q6: =AVERAGE(N10:N11) -> 19.285
A7: 1 | B7: 300 | C7: 0.08 | D7: 0.45 | E7: 0.17 | F7: 4.64 | G7: 4.69 | H7: 4.66 | I7: 0 | J7: 0 | K7: 0 | L7: 4.73 | M7: 5.13 | N7: 4.83 | P7: =P6+100 -> 600 | Q7: =AVERAGE(N12:N13) -> 20.5
A8: 0 | B8: 400 | C8: 1.76 | D8: 2.2 | E8: 1.86 | F8: 2.65 | G8: 2.75 | H8: 2.71 | I8: 21.13 | J8: 34.01 | K8: 24.83 | L8: 25.66 | M8: 38.94 | N8: 29.4 | P8: =P7+100 -> 700 | Q8: =AVERAGE(N14:N15) -> 21.95
A9: 1 | B9: 400 | C9: 0.1 | D9: 0.43 | E9: 0.19 | F9: 6.16 | G9: 6.25 | H9: 6.19 | I9: 0 | J9: 0.07 | K9: 0 | L9: 6.27 | M9: 6.63 | N9: 6.38 | P9: =P8+100 -> 800 | Q9: =AVERAGE(N16:N17) -> 23.21
A10: 0 | B10: 500 | C10: 1.86 | D10: 2.27 | E10: 1.95 | F10: 3.2 | G10: 3.35 | H10: 3.27 | I10: 21.77 | J10: 32.48 | K10: 25.45 | L10: 26.98 | M10: 37.82 | N10: 30.66 | P10: =P9+100 -> 900 | Q10: =AVERAGE(N18:N19) -> 25.065
A11: 1 | B11: 500 | C11: 0.1 | D11: 0.43 | E11: 0.19 | F11: 7.7 | G11: 7.8 | H11: 7.72 | I11: 0 | J11: 0.01 | K11: 0 | L11: 7.8 | M11: 8.16 | N11: 7.91 | P11: =P10+100 -> 1000 | Q11: =AVERAGE(N20:N21) -> 26.62
A12: 0 | B12: 600 | C12: 1.91 | D12: 2.35 | E12: 2.02 | F12: 3.73 | G12: 3.88 | H12: 3.82 | I12: 21.53 | J12: 33.51 | K12: 25.69 | L12: 27.28 | M12: 39.41 | N12: 31.53 | P12: =P11+100 -> 1100 | Q12: =AVERAGE(N22:N23) -> 28.115
A13: 1 | B13: 600 | C13: 0.09 | D13: 0.44 | E13: 0.19 | F13: 9.25 | G13: 9.34 | H13: 9.28 | I13: 0 | J13: 0.01 | K13: 0 | L13: 9.35 | M13: 9.73 | N13: 9.47 | P13: =P12+100 -> 1200 | Q13: =AVERAGE(N24:N25) -> 29.705
A14: 0 | B14: 700 | C14: 1.99 | D14: 2.41 | E14: 2.11 | F14: 4.36 | G14: 4.49 | H14: 4.41 | I14: 22.42 | J14: 32.66 | K14: 26.32 | L14: 28.84 | M14: 39.3 | N14: 32.84 | P14: =P13+100 -> 1300 | Q14: =AVERAGE(N26:N27) -> 30.855
A15: 1 | B15: 700 | C15: 0.1 | D15: 0.43 | E15: 0.19 | F15: 10.82 | G15: 10.91 | H15: 10.86 | I15: 0 | J15: 0.06 | K15: 0 | L15: 10.94 | M15: 11.35 | N15: 11.06 | P15: =P14+100 -> 1400 | Q15: =AVERAGE(N28:N29) -> 32.245
A16: 0 | B16: 800 | C16: 2.04 | D16: 2.46 | E16: 2.2 | F16: 4.91 | G16: 5.06 | H16: 4.97 | I16: 22.42 | J16: 34.05 | K16: 26.7 | L16: 29.49 | M16: 41.3 | N16: 33.87 | P16: =P15+100 -> 1500 | Q16: =AVERAGE(N30:N31) -> 33.68
A17: 1 | B17: 800 | C17: 0.09 | D17: 0.44 | E17: 0.2 | F17: 12.3 | G17: 12.42 | H17: 12.35 | I17: 0 | J17: 0.08 | K17: 0 | L17: 12.41 | M17: 12.87 | N17: 12.55 | P17: =P16+100 -> 1600 | Q17: =AVERAGE(N32:N33) -> 34.975
A18: 0 | B18: 900 | C18: 2.12 | D18: 2.52 | E18: 2.21 | F18: 5.45 | G18: 5.6 | H18: 5.52 | I18: 24.28 | J18: 36.44 | K18: 28.19 | L18: 31.91 | M18: 44.26 | N18: 35.93 | P18: =P17+100 -> 1700 | Q18: =AVERAGE(N34:N35) -> 35.03
A19: 1 | B19: 900 | C19: 0.1 | D19: 0.43 | E19: 0.2 | F19: 13.97 | G19: 14.06 | H19: 14.01 | I19: 0 | J19: 0.01 | K19: 0 | L19: 14.07 | M19: 14.47 | N19: 14.2 | P19: =P18+100 -> 1800 | Q19: =AVERAGE(N36:N37) -> 36.825
A20: 0 | B20: 1000 | C20: 2.13 | D20: 2.53 | E20: 2.28 | F20: 5.96 | G20: 6.21 | H20: 6.09 | I20: 24.53 | J20: 34.67 | K20: 29.35 | L20: 32.72 | M20: 43.08 | N20: 37.72 | P20: =P19+100 -> 1900 | Q20: =AVERAGE(N38:N39) -> 38.51
A21: 1 | B21: 1000 | C21: 0.01 | D21: 0.31 | E21: 0.1 | F21: 15.37 | G21: 15.52 | H21: 15.43 | I21: 0 | J21: 0.02 | K21: 0 | L21: 15.4 | M21: 15.78 | N21: 15.52 | P21: =P20+100 -> 2000 | Q21: =AVERAGE(N40:N41) -> 40.46
A22: 0 | B22: 1100 | C22: 2.22 | D22: 2.61 | E22: 2.34 | F22: 6.63 | G22: 6.79 | H22: 6.7 | I22: 26.39 | J22: 39.06 | K22: 30.21 | L22: 35.4 | M22: 48.22 | N22: 39.25 | P22: =P21+100 -> 2100 | Q22: =AVERAGE(N42:N43) -> 41.11
A23: 1 | B23: 1100 | C23: 0.01 | D23: 0.32 | E23: 0.07 | F23: 16.87 | G23: 16.97 | H23: 16.91 | I23: 0 | J23: 0.01 | K23: 0 | L23: 16.88 | M23: 17.29 | N23: 16.98 | P23: =P22+100 -> 2200 | Q23: =AVERAGE(N44:N45) -> 43.575
A24: 0 | B24: 1200 | C24: 2.24 | D24: 2.62 | E24: 2.39 | F24: 7.23 | G24: 7.4 | H24: 7.3 | I24: 27.11 | J24: 39.46 | K24: 31.07 | L24: 36.76 | M24: 49.29 | N24: 40.76 | P24: =P23+100 -> 2300 | Q24: =AVERAGE(N46:N47) -> 45.49
A25: 1 | B25: 1200 | C25: 0.01 | D25: 0.33 | E25: 0.1 | F25: 18.51 | G25: 18.61 | H25: 18.55 | I25: 0 | J25: 0.01 | K25: 0 | L25: 18.53 | M25: 18.91 | N25: 18.65 | P25: =P24+100 -> 2400 | Q25: =AVERAGE(N48:N49) -> 45.025
A26: 0 | B26: 1300 | C26: 2.32 | D26: 2.79 | E26: 2.46 | F26: 7.72 | G26: 7.92 | H26: 7.79 | I26: 27.41 | J26: 38.65 | K26: 31.4 | L26: 37.58 | M26: 49.01 | N26: 41.65 | P26: =P25+100 -> 2500 | Q26: =AVERAGE(N50:N51) -> 47.18
A27: 1 | B27: 1300 | C27: 0 | D27: 0.27 | E27: 0.05 | F27: 19.96 | G27: 20.06 | H27: 20.01 | I27: 0 | J27: 0 | K27: 0 | L27: 19.97 | M27: 20.3 | N27: 20.06 | P27: =P26+100 -> 2600 | Q27: =AVERAGE(N52:N53) -> #DIV/0!
A28: 0 | B28: 1400 | C28: 2.38 | D28: 2.77 | E28: 2.52 | F28: 8.35 | G28: 8.57 | H28: 8.45 | I28: 27.6 | J28: 37.66 | K28: 31.83 | L28: 38.53 | M28: 48.67 | N28: 42.8 | P28: =P27+100 -> 2700 | Q28: =AVERAGE(N54:N55) -> #DIV/0!
A29: 1 | B29: 1400 | C29: 0 | D29: 0.42 | E29: 0.09 | F29: 21.54 | G29: 21.71 | H29: 21.6 | I29: 0 | J29: 0.02 | K29: 0 | L29: 21.56 | M29: 22.05 | N29: 21.69 | P29: =P28+100 -> 2800 | Q29: =AVERAGE(N56:N57) -> #DIV/0!
A30: 0 | B30: 1500 | C30: 2.46 | D30: 2.84 | E30: 2.61 | F30: 8.8 | G30: 9.08 | H30: 8.94 | I30: 28.45 | J30: 40.04 | K30: 32.59 | L30: 40.09 | M30: 51.63 | N30: 44.13 | P30: 2900 | Q30: =AVERAGE(N58:N59) -> #DIV/0!
A31: 1 | B31: 1500 | C31: 0.01 | D31: 0.32 | E31: 0.09 | F31: 23.09 | G31: 23.22 | H31: 23.14 | I31: 0 | J31: 0.02 | K31: 0 | L31: 23.1 | M31: 23.47 | N31: 23.23 | P31: 3000 | Q31: =AVERAGE(N60:N61) -> #DIV/0!
A32: 0 | B32: 1600 | C32: 2.55 | D32: 2.92 | E32: 2.68 | F32: 9.49 | G32: 9.77 | H32: 9.62 | I32: 28.79 | J32: 38.71 | K32: 32.92 | L32: 40.95 | M32: 51.38 | N32: 45.22
A33: 1 | B33: 1600 | C33: 0 | D33: 0.41 | E33: 0.08 | F33: 24.6 | G33: 24.73 | H33: 24.65 | I33: 0 | J33: 0.01 | K33: 0 | L33: 24.63 | M33: 25.14 | N33: 24.73
A34: 0 | B34: 1700 | C34: 2.56 | D34: 2.95 | E34: 2.75 | F34: 9.83 | G34: 10.11 | H34: 9.97 | I34: 27.73 | J34: 38.77 | K34: 31.5 | L34: 40.43 | M34: 51.59 | N34: 44.22
A35: 1 | B35: 1700 | C35: 0 | D35: 0.33 | E35: 0.09 | F35: 25.67 | G35: 25.83 | H35: 25.75 | I35: 0 | J35: 0.05 | K35: 0 | L35: 25.69 | M35: 26.14 | N35: 25.84
A36: 0 | B36: 1800 | C36: 2.66 | D36: 3.07 | E36: 2.81 | F36: 10.43 | G36: 10.69 | H36: 10.59 | I36: 28.31 | J36: 39.34 | K36: 32.67 | L36: 41.65 | M36: 52.87 | N36: 46.07
A37: 1 | B37: 1800 | C37: 0.02 | D37: 0.44 | E37: 0.14 | F37: 27.33 | G37: 27.52 | H37: 27.44 | I37: 0 | J37: 0 | K37: 0 | L37: 27.37 | M37: 27.93 | N37: 27.58
A38: 0 | B38: 1900 | C38: 2.7 | D38: 3.12 | E38: 2.86 | F38: 11.24 | G38: 11.55 | H38: 11.38 | I38: 29.16 | J38: 46.53 | K38: 33.24 | L38: 43.3 | M38: 60.9 | N38: 47.47
A39: 1 | B39: 1900 | C39: 0.01 | D39: 0.44 | E39: 0.11 | F39: 29.34 | G39: 29.61 | H39: 29.44 | I39: 0 | J39: 0.01 | K39: 0 | L39: 29.38 | M39: 29.98 | N39: 29.55
A40: 0 | B40: 2000 | C40: 2.8 | D40: 3.2 | E40: 2.94 | F40: 11.59 | G40: 12.05 | H40: 11.81 | I40: 30.5 | J40: 57.7 | K40: 35.43 | L40: 45.11 | M40: 72.64 | N40: 50.18
...

Sheet Test_Data_9033_UI_2018rc1
A1: Core | B1: Rate | C1: ISRs (Min) | D1: ISRs (Max) | E1: ISRs (Max) | F1: TL (min) | G1: TL (max) | H1: TL (Mean) | I1: Other (Min) | J1: Other (Max) | K1: Other (Mean) | L1: Total (min) | M1: Total (max) | N1: Total (Mean) | Q1: Total (Mean)
A2: 0 | B2: 100 | C2: 0.17 | D2: 0.21 | E2: 0.19 | F2: 1.08 | G2: 1.14 | H2: 1.11 | I2: 14.39 | J2: 23.06 | K2: 18.93 | L2: 15.69 | M2: 24.4 | N2: 20.23 | P2: 100 | Q2: =AVERAGE(N2:N3) -> 10.955
A3: 1 | B3: 100 | C3: 0.08 | D3: 0.13 | E3: 0.1 | F3: 1.56 | G3: 1.58 | H3: 1.57 | I3: 0 | J3: 0 | K3: 0 | L3: 1.65 | M3: 1.72 | N3: 1.68 | P3: =P2+100 -> 200 | Q3: =AVERAGE(N4:N5) -> 12.48
A4: 0 | B4: 200 | C4: 0.18 | D4: 0.22 | E4: 0.2 | F4: 1.71 | G4: 1.75 | H4: 1.73 | I4: 17.82 | J4: 25.91 | K4: 19.8 | L4: 19.73 | M4: 27.84 | N4: 21.72 | P4: =P3+100 -> 300 | Q4: =AVERAGE(N6:N7) -> 13.64
A5: 1 | B5: 200 | C5: 0.09 | D5: 0.16 | E5: 0.11 | F5: 3.11 | G5: 3.14 | H5: 3.13 | I5: 0 | J5: 0 | K5: 0 | L5: 3.21 | M5: 3.29 | N5: 3.24 | P5: =P4+100 -> 400 | Q5: =AVERAGE(N8:N9) -> 15.11
A6: 0 | B6: 300 | C6: 0.18 | D6: 0.23 | E6: 0.2 | F6: 2.36 | G6: 2.41 | H6: 2.38 | I6: 17.88 | J6: 22.58 | K6: 19.95 | L6: 20.47 | M6: 25.16 | N6: 22.54 | P6: =P5+100 -> 500 | Q6: =AVERAGE(N10:N11) -> 16.45
A7: 1 | B7: 300 | C7: 0.09 | D7: 0.14 | E7: 0.11 | F7: 4.62 | G7: 4.66 | H7: 4.64 | I7: 0 | J7: 0 | K7: 0 | L7: 4.71 | M7: 4.78 | N7: 4.74 | P7: =P6+100 -> 600 | Q7: =AVERAGE(N12:N13) -> 17.765
A8: 0 | B8: 400 | C8: 0.17 | D8: 0.26 | E8: 0.21 | F8: 2.92 | G8: 2.98 | H8: 2.95 | I8: 18.64 | J8: 23.77 | K8: 20.79 | L8: 21.78 | M8: 26.93 | N8: 23.95 | P8: =P7+100 -> 700 | Q8: =AVERAGE(N14:N15) -> 19.195
A9: 1 | B9: 400 | C9: 0.09 | D9: 0.15 | E9: 0.11 | F9: 6.14 | G9: 6.27 | H9: 6.16 | I9: 0 | J9: 0 | K9: 0 | L9: 6.23 | M9: 6.38 | N9: 6.27 | P9: =P8+100 -> 800 | Q9: =AVERAGE(N16:N17) -> 20.25
A10: 0 | B10: 500 | C10: 0.2 | D10: 0.24 | E10: 0.22 | F10: 3.55 | G10: 3.61 | H10: 3.58 | I10: 19.26 | J10: 27.88 | K10: 21.31 | L10: 23.04 | M10: 31.7 | N10: 25.1 | P10: =P9+100 -> 900 | Q10: =AVERAGE(N18:N19) -> 21.605
A11: 1 | B11: 500 | C11: 0.08 | D11: 0.14 | E11: 0.11 | F11: 7.68 | G11: 7.74 | H11: 7.7 | I11: 0 | J11: 0 | K11: 0 | L11: 7.77 | M11: 7.83 | N11: 7.8 | P11: =P10+100 -> 1000 | Q11: =AVERAGE(N20:N21) -> 22.785
A12: 0 | B12: 600 | C12: 0.18 | D12: 0.27 | E12: 0.23 | F12: 4.12 | G12: 4.22 | H12: 4.17 | I12: 19.91 | J12: 25.73 | K12: 21.8 | L12: 24.28 | M12: 30.15 | N12: 26.2 | P12: =P11+100 -> 1100 | Q12: =AVERAGE(N22:N23) -> 24.51
A13: 1 | B13: 600 | C13: 0.08 | D13: 0.13 | E13: 0.1 | F13: 9.17 | G13: 9.35 | H13: 9.23 | I13: 0 | J13: 0 | K13: 0 | L13: 9.27 | M13: 9.45 | N13: 9.33 | P13: =P12+100 -> 1200 | Q13: =AVERAGE(N24:N25) -> 25.92
A14: 0 | B14: 700 | C14: 0.19 | D14: 0.26 | E14: 0.23 | F14: 4.75 | G14: 4.87 | H14: 4.8 | I14: 20.56 | J14: 25.25 | K14: 22.51 | L14: 25.62 | M14: 30.28 | N14: 27.54 | P14: =P13+100 -> 1300 | Q14: =AVERAGE(N26:N27) -> 27.235
A15: 1 | B15: 700 | C15: 0.08 | D15: 0.15 | E15: 0.1 | F15: 10.71 | G15: 10.84 | H15: 10.75 | I15: 0 | J15: 0.01 | K15: 0 | L15: 10.8 | M15: 10.95 | N15: 10.85 | P15: =P14+100 -> 1400 | Q15: =AVERAGE(N28:N29) -> 28.605
A16: 0 | B16: 800 | C16: 0.19 | D16: 0.3 | E16: 0.24 | F16: 5.38 | G16: 5.49 | H16: 5.43 | I16: 20.29 | J16: 25.82 | K16: 22.46 | L16: 25.94 | M16: 31.49 | N16: 28.13 | P16: =P15+100 -> 1500 | Q16: =AVERAGE(N30:N31) -> 30.11
A17: 1 | B17: 800 | C17: 0.08 | D17: 0.13 | E17: 0.1 | F17: 12.22 | G17: 12.38 | H17: 12.27 | I17: 0 | J17: 0.01 | K17: 0 | L17: 12.31 | M17: 12.51 | N17: 12.37 | P17: =P16+100 -> 1600 | Q17: =AVERAGE(N32:N33) -> 31.805
A18: 0 | B18: 900 | C18: 0.17 | D18: 0.23 | E18: 0.2 | F18: 6 | G18: 6.1 | H18: 6.05 | I18: 20.75 | J18: 31.48 | K18: 22.97 | L18: 27.02 | M18: 37.8 | N18: 29.23 | P18: =P17+100 -> 1700 | Q18: =AVERAGE(N34:N35) -> 33.055
A19: 1 | B19: 900 | C19: 0.08 | D19: 0.14 | E19: 0.11 | F19: 13.77 | G19: 13.94 | H19: 13.87 | I19: 0 | J19: 0.02 | K19: 0 | L19: 13.88 | M19: 14.06 | N19: 13.98 | P19: =P18+100 -> 1800 | Q19: =AVERAGE(N36:N37) -> 33.995
A20: 0 | B20: 1000 | C20: 0.15 | D20: 0.24 | E20: 0.19 | F20: 6.59 | G20: 6.78 | H20: 6.67 | I20: 21.23 | J20: 26.02 | K20: 23.34 | L20: 28.05 | M20: 32.89 | N20: 30.19 | P20: =P19+100 -> 1900
A21: 1 | B21: 1000 | C21: 0.09 | D21: 0.12 | E21: 0.1 | F21: 15.22 | G21: 15.37 | H21: 15.28 | I21: 0 | J21: 0 | K21: 0 | L21: 15.32 | M21: 15.49 | N21: 15.38 | P21: =P20+100 -> 2000
A22: 0 | B22: 1100 | C22: 0.14 | D22: 0.22 | E22: 0.19 | F22: 7.18 | G22: 7.31 | H22: 7.24 | I22: 22.54 | J22: 28.24 | K22: 24.52 | L22: 29.96 | M22: 35.7 | N22: 31.95 | P22: =P21+100 -> 2100
A23: 1 | B23: 1100 | C23: 0.07 | D23: 0.13 | E23: 0.1 | F23: 16.92 | G23: 17.06 | H23: 16.97 | I23: 0 | J23: 0.02 | K23: 0 | L23: 17.01 | M23: 17.17 | N23: 17.07 | P23: =P22+100 -> 2200
A24: 0 | B24: 1200 | C24: 0.13 | D24: 0.24 | E24: 0.18 | F24: 7.93 | G24: 8.09 | H24: 7.98 | I24: 23.4 | J24: 31.77 | K24: 25.55 | L24: 31.51 | M24: 40.05 | N24: 33.71 | P24: =P23+100 -> 2300
A25: 1 | B25: 1200 | C25: 0.05 | D25: 0.1 | E25: 0.07 | F25: 18.02 | G25: 18.14 | H25: 18.06 | I25: 0 | J25: 0 | K25: 0 | L25: 18.08 | M25: 18.22 | N25: 18.13 | P25: =P24+100 -> 2400
A26: 0 | B26: 1300 | C26: 0.15 | D26: 0.22 | E26: 0.19 | F26: 8.43 | G26: 8.55 | H26: 8.49 | I26: 23.76 | J26: 29.83 | K26: 26.21 | L26: 32.4 | M26: 38.53 | N26: 34.88 | P26: =P25+100 -> 2500
A27: 1 | B27: 1300 | C27: 0.05 | D27: 0.11 | E27: 0.07 | F27: 19.49 | G27: 19.58 | H27: 19.52 | I27: 0 | J27: 0 | K27: 0 | L27: 19.55 | M27: 19.67 | N27: 19.59 | P27: =P26+100 -> 2600
A28: 0 | B28: 1400 | C28: 0.12 | D28: 0.24 | E28: 0.18 | F28: 9.12 | G28: 9.28 | H28: 9.19 | I28: 24.78 | J28: 33.68 | K28: 26.69 | L28: 34.11 | M28: 43.08 | N28: 36.06 | P28: =P27+100 -> 2700
A29: 1 | B29: 1400 | C29: 0.05 | D29: 0.12 | E29: 0.08 | F29: 21 | G29: 21.2 | H29: 21.07 | I29: 0 | J29: 0 | K29: 0 | L29: 21.06 | M29: 21.3 | N29: 21.15 | P29: =P28+100 -> 2800
A30: 0 | B30: 1500 | C30: 0.14 | D30: 0.22 | E30: 0.18 | F30: 9.62 | G30: 9.94 | H30: 9.76 | I30: 24.87 | J30: 36.24 | K30: 27.62 | L30: 34.81 | M30: 46.22 | N30: 37.56 | P30: 2900
A31: 1 | B31: 1500 | C31: 0.05 | D31: 0.12 | E31: 0.08 | F31: 22.51 | G31: 22.72 | H31: 22.59 | I31: 0 | J31: 0.01 | K31: 0 | L31: 22.56 | M31: 22.83 | N31: 22.66 | P31: 3000
A32: 0 | B32: 1600 | C32: 0.13 | D32: 0.25 | E32: 0.18 | F32: 10.44 | G32: 10.62 | H32: 10.52 | I32: 26.22 | J32: 36.87 | K32: 28.75 | L32: 36.92 | M32: 47.65 | N32: 39.45
A33: 1 | B33: 1600 | C33: 0.05 | D33: 0.15 | E33: 0.09 | F33: 23.99 | G33: 24.21 | H33: 24.07 | I33: 0 | J33: 0.01 | K33: 0 | L33: 24.06 | M33: 24.31 | N33: 24.16
A34: 0 | B34: 1700 | C34: 0.14 | D34: 0.24 | E34: 0.18 | F34: 10.91 | G34: 11.11 | H34: 11.01 | I34: 25.81 | J34: 36.49 | K34: 29.2 | L34: 36.89 | M34: 47.79 | N34: 40.39
A35: 1 | B35: 1700 | C35: 0.05 | D35: 0.14 | E35: 0.1 | F35: 25.56 | G35: 25.78 | H35: 25.63 | I35: 0 | J35: 0 | K35: 0 | L35: 25.64 | M35: 25.89 | N35: 25.72
A36: 0 | B36: 1800 | C36: 0.15 | D36: 0.23 | E36: 0.19 | F36: 11.52 | G36: 11.73 | H36: 11.61 | I36: 27.41 | J36: 35.52 | K36: 29.48 | L36: 39.21 | M36: 47.4 | N36: 41.28
A37: 1 | B37: 1800 | C37: 0.04 | D37: 0.09 | E37: 0.07 | F37: 26.59 | G37: 26.68 | H37: 26.64 | I37: 0 | J37: 0 | K37: 0 | L37: 26.66 | M37: 26.77 | N37: 26.71
A38: 0 | B38: 1900 | C38: 0.14 | D38: 0.22 | E38: 0.18 | F38: 12.17 | G38: 12.48 | H38: 12.31 | I38: 27.08 | J38: 34.89 | K38: 29.72 | L38: 39.51 | M38: 47.48 | N38: 42.22
A39: 1 | B39: 1900 | C39: 0.06 | D39: 0.15 | E39: 0.1 | F39: 28.49 | G39: 28.72 | H39: 28.58 | I39: 0 | J39: 0.01 | K39: 0 | L39: 28.58 | M39: 28.82 | N39: 28.68
A40: 0 | B40: 2000 | C40: 0.15 | D40: 0.23 | E40: 0.19 | F40: 12.64 | G40: 12.98 | H40: 12.77 | I40: 27 | J40: 34.5 | K40: 29.59 | L40: 39.91 | M40: 47.55 | N40: 42.55
...

Sheet Test_Data_9033_UI_2018b10
A1: Core | B1: Rate | C1: ISRs (Min) | D1: ISRs (Max) | E1: ISRs (Max) | F1: TL (min) | G1: TL (max) | H1: TL (Mean) | I1: Other (Min) | J1: Other (Max) | K1: Other (Mean) | L1: Total (min) | M1: Total (max) | N1: Total (Mean) | Q1: Total (Mean)
A2: 0 | B2: 100 | C2: 0.16 | D2: 0.2 | E2: 0.17 | F2: 1.09 | G2: 1.15 | H2: 1.13 | I2: 15.45 | J2: 26.79 | K2: 18.62 | L2: 16.77 | M2: 28.07 | N2: 19.93 | P2: 100 | Q2: =AVERAGE(N2:N3) -> 10.8
A3: 1 | B3: 100 | C3: 0.08 | D3: 0.26 | E3: 0.11 | F3: 1.54 | G3: 1.57 | H3: 1.56 | I3: 0 | J3: 0 | K3: 0 | L3: 1.63 | M3: 1.82 | N3: 1.67 | P3: =P2+100 -> 200 | Q3: =AVERAGE(N4:N5) -> 12.635
A4: 0 | B4: 200 | C4: 0.17 | D4: 0.19 | E4: 0.18 | F4: 1.74 | G4: 1.78 | H4: 1.76 | I4: 17.29 | J4: 31.54 | K4: 20.12 | L4: 19.24 | M4: 33.49 | N4: 22.06 | P4: =P3+100 -> 300 | Q4: =AVERAGE(N6:N7) -> 14.035
A5: 1 | B5: 200 | C5: 0.09 | D5: 0.27 | E5: 0.12 | F5: 3.08 | G5: 3.11 | H5: 3.09 | I5: 0 | J5: 0 | K5: 0 | L5: 3.18 | M5: 3.37 | N5: 3.21 | P5: =P4+100 -> 400 | Q5: =AVERAGE(N8:N9) -> 15.235
A6: 0 | B6: 300 | C6: 0.17 | D6: 0.2 | E6: 0.19 | F6: 2.35 | G6: 2.41 | H6: 2.38 | I6: 17.33 | J6: 30.92 | K6: 20.75 | L6: 19.89 | M6: 33.52 | N6: 23.32 | P6: =P5+100 -> 500 | Q6: =AVERAGE(N10:N11) -> 16.31
A7: 1 | B7: 300 | C7: 0.08 | D7: 0.27 | E7: 0.12 | F7: 4.61 | G7: 4.65 | H7: 4.63 | I7: 0 | J7: 0 | K7: 0 | L7: 4.7 | M7: 4.92 | N7: 4.75 | P7: =P6+100 -> 600 | Q7: =AVERAGE(N12:N13) -> 17.27
A8: 0 | B8: 400 | C8: 0.11 | D8: 0.22 | E8: 0.19 | F8: 2.96 | G8: 3.04 | H8: 2.99 | I8: 18.33 | J8: 31.33 | K8: 21.08 | L8: 21.51 | M8: 34.55 | N8: 24.27 | P8: =P7+100 -> 700 | Q8: =AVERAGE(N14:N15) -> 18.88
A9: 1 | B9: 400 | C9: 0.09 | D9: 0.28 | E9: 0.12 | F9: 6.05 | G9: 6.17 | H9: 6.08 | I9: 0 | J9: 0.01 | K9: 0 | L9: 6.15 | M9: 6.39 | N9: 6.2 | P9: =P8+100 -> 800 | Q9: =AVERAGE(N16:N17) -> 20.7
A10: 0 | B10: 500 | C10: 0.19 | D10: 0.23 | E10: 0.2 | F10: 3.62 | G10: 3.69 | H10: 3.66 | I10: 18.63 | J10: 28.29 | K10: 21.03 | L10: 22.49 | M10: 32.16 | N10: 24.89 | P10: =P9+100 -> 900 | Q10: =AVERAGE(N18:N19) -> 22.015
A11: 1 | B11: 500 | C11: 0.09 | D11: 0.26 | E11: 0.12 | F11: 7.59 | G11: 7.64 | H11: 7.61 | I11: 0 | J11: 0.01 | K11: 0 | L11: 7.68 | M11: 7.89 | N11: 7.73 | P11: =P10+100 -> 1000 | Q11: =AVERAGE(N20:N21) -> 22.8
A12: 0 | B12: 600 | C12: 0.17 | D12: 0.24 | E12: 0.21 | F12: 4.18 | G12: 4.26 | H12: 4.22 | I12: 18.7 | J12: 24.7 | K12: 20.87 | L12: 23.14 | M12: 29.16 | N12: 25.3 | P12: =P11+100 -> 1100 | Q12: =AVERAGE(N22:N23) -> 24.39
A13: 1 | B13: 600 | C13: 0.08 | D13: 0.26 | E13: 0.12 | F13: 9.1 | G13: 9.19 | H13: 9.12 | I13: 0 | J13: 0 | K13: 0 | L13: 9.19 | M13: 9.42 | N13: 9.24 | P13: =P12+100 -> 1200 | Q13: =AVERAGE(N24:N25) -> 25.845
A14: 0 | B14: 700 | C14: 0.17 | D14: 0.26 | E14: 0.22 | F14: 4.85 | G14: 4.93 | H14: 4.88 | I14: 19.75 | J14: 31.39 | K14: 21.92 | L14: 24.85 | M14: 36.54 | N14: 27.02 | P14: =P13+100 -> 1300 | Q14: =AVERAGE(N26:N27) -> 27.095
A15: 1 | B15: 700 | C15: 0.08 | D15: 0.27 | E15: 0.12 | F15: 10.59 | G15: 10.7 | H15: 10.62 | I15: 0 | J15: 0 | K15: 0 | L15: 10.68 | M15: 10.96 | N15: 10.74 | P15: =P14+100 -> 1400 | Q15: =AVERAGE(N28:N29) -> 28.455
A16: 0 | B16: 800 | C16: 0.16 | D16: 0.27 | E16: 0.22 | F16: 5.47 | G16: 5.61 | H16: 5.54 | I16: 21.27 | J16: 25.66 | K16: 23.29 | L16: 27.02 | M16: 31.47 | N16: 29.06 | P16: =P15+100 -> 1500 | Q16: =AVERAGE(N30:N31) -> 29.81
A17: 1 | B17: 800 | C17: 0.08 | D17: 0.28 | E17: 0.12 | F17: 12.18 | G17: 12.36 | H17: 12.22 | I17: 0 | J17: 0 | K17: 0 | L17: 12.28 | M17: 12.62 | N17: 12.34 | P17: =P16+100 -> 1600 | Q17: =AVERAGE(N32:N33) -> 31.37
A18: 0 | B18: 900 | C18: 0.19 | D18: 0.22 | E18: 0.2 | F18: 6.18 | G18: 6.27 | H18: 6.21 | I18: 21.59 | J18: 27.31 | K18: 23.91 | L18: 27.99 | M18: 33.72 | N18: 30.32 | P18: =P17+100 -> 1700 | Q18: =AVERAGE(N34:N35) -> 32.69
A19: 1 | B19: 900 | C19: 0.06 | D19: 0.27 | E19: 0.1 | F19: 13.58 | G19: 13.63 | H19: 13.6 | I19: 0 | J19: 0.02 | K19: 0 | L19: 13.65 | M19: 13.88 | N19: 13.71 | P19: =P18+100 -> 1800 | Q19: =AVERAGE(N36:N37) -> 33.785
A20: 0 | B20: 1000 | C20: 0.14 | D20: 0.2 | E20: 0.17 | F20: 6.73 | G20: 6.91 | H20: 6.81 | I20: 20.96 | J20: 40.17 | K20: 23.25 | L20: 27.92 | M20: 47.26 | N20: 30.24 | P20: =P19+100 -> 1900
A21: 1 | B21: 1000 | C21: 0.08 | D21: 0.28 | E21: 0.11 | F21: 15.2 | G21: 15.35 | H21: 15.25 | I21: 0 | J21: 0 | K21: 0 | L21: 15.3 | M21: 15.57 | N21: 15.36 | P21: =P20+100 -> 2000
A22: 0 | B22: 1100 | C22: 0.12 | D22: 0.21 | E22: 0.18 | F22: 7.35 | G22: 7.44 | H22: 7.39 | I22: 22.08 | J22: 27.85 | K22: 24.2 | L22: 29.62 | M22: 35.42 | N22: 31.76 | P22: =P21+100 -> 2100
A23: 1 | B23: 1100 | C23: 0.08 | D23: 0.28 | E23: 0.12 | F23: 16.87 | G23: 16.98 | H23: 16.9 | I23: 0 | J23: 0.02 | K23: 0 | L23: 16.97 | M23: 17.25 | N23: 17.02 | P23: =P22+100 -> 2200
A24: 0 | B24: 1200 | C24: 0.17 | D24: 0.2 | E24: 0.18 | F24: 8.02 | G24: 8.23 | H24: 8.11 | I24: 22.98 | J24: 28.7 | K24: 25.06 | L24: 31.22 | M24: 37 | N24: 33.35 | P24: =P23+100 -> 2300
A25: 1 | B25: 1200 | C25: 0.09 | D25: 0.27 | E25: 0.12 | F25: 18.16 | G25: 18.3 | H25: 18.22 | I25: 0 | J25: 0 | K25: 0 | L25: 18.26 | M25: 18.51 | N25: 18.34 | P25: =P24+100 -> 2400
A26: 0 | B26: 1300 | C26: 0.12 | D26: 0.22 | E26: 0.17 | F26: 8.56 | G26: 8.78 | H26: 8.66 | I26: 23.67 | J26: 28.4 | K26: 25.73 | L26: 32.48 | M26: 37.21 | N26: 34.56 | P26: =P25+100 -> 2500
A27: 1 | B27: 1300 | C27: 0.06 | D27: 0.24 | E27: 0.09 | F27: 19.48 | G27: 19.64 | H27: 19.54 | I27: 0 | J27: 0.01 | K27: 0 | L27: 19.55 | M27: 19.83 | N27: 19.63 | P27: =P26+100 -> 2600
A28: 0 | B28: 1400 | C28: 0.12 | D28: 0.2 | E28: 0.17 | F28: 9.23 | G28: 9.42 | H28: 9.33 | I28: 24.18 | J28: 29.03 | K28: 26.32 | L28: 33.68 | M28: 38.53 | N28: 35.82 | P28: =P27+100 -> 2700
A29: 1 | B29: 1400 | C29: 0.05 | D29: 0.25 | E29: 0.09 | F29: 20.92 | G29: 21.13 | H29: 21 | I29: 0 | J29: 0.01 | K29: 0 | L29: 20.98 | M29: 21.38 | N29: 21.09 | P29: =P28+100 -> 2800
A30: 0 | B30: 1500 | C30: 0.11 | D30: 0.2 | E30: 0.17 | F30: 9.74 | G30: 10.11 | H30: 9.92 | I30: 24.38 | J30: 32.04 | K30: 26.92 | L30: 34.48 | M30: 42.24 | N30: 37.01 | P30: 2900
A31: 1 | B31: 1500 | C31: 0.05 | D31: 0.26 | E31: 0.1 | F31: 22.45 | G31: 22.65 | H31: 22.51 | I31: 0 | J31: 0.01 | K31: 0 | L31: 22.5 | M31: 22.86 | N31: 22.61 | P31: 3000
A32: 0 | B32: 1600 | C32: 0.13 | D32: 0.22 | E32: 0.17 | F32: 10.58 | G32: 10.74 | H32: 10.65 | I32: 25.06 | J32: 31.6 | K32: 27.76 | L32: 35.84 | M32: 42.51 | N32: 38.58
A33: 1 | B33: 1600 | C33: 0.05 | D33: 0.24 | E33: 0.09 | F33: 23.99 | G33: 24.19 | H33: 24.07 | I33: 0 | J33: 0.01 | K33: 0 | L33: 24.07 | M33: 24.38 | N33: 24.16
A34: 0 | B34: 1700 | C34: 0.11 | D34: 0.21 | E34: 0.17 | F34: 11.17 | G34: 11.39 | H34: 11.27 | I34: 25.73 | J34: 31.89 | K34: 28.16 | L34: 37.2 | M34: 43.42 | N34: 39.6
A35: 1 | B35: 1700 | C35: 0.05 | D35: 0.22 | E35: 0.09 | F35: 25.61 | G35: 25.78 | H35: 25.69 | I35: 0 | J35: 0.02 | K35: 0 | L35: 25.68 | M35: 26 | N35: 25.78
A36: 0 | B36: 1800 | C36: 0.14 | D36: 0.18 | E36: 0.17 | F36: 11.86 | G36: 12 | H36: 11.93 | I36: 26.17 | J36: 31.04 | K36: 28.22 | L36: 38.23 | M36: 43.16 | N36: 40.31
A37: 1 | B37: 1800 | C37: 0.06 | D37: 0.25 | E37: 0.1 | F37: 27.11 | G37: 27.24 | H37: 27.16 | I37: 0 | J37: 0 | K37: 0 | L37: 27.18 | M37: 27.49 | N37: 27.26
A40: Software | B40: Version
A41: CompactRIO Support | B41: 18
A42: Hardware Configuration Web Support | B42: 16.0.0
...

Sheet Test_Data_9033_UI_2017
A1: Core | B1: Rate | C1: ISRs (Min) | D1: ISRs (Max) | E1: ISRs (Max) | F1: TL (min) | G1: TL (max) | H1: TL (Mean) | I1: Other (Min) | J1: Other (Max) | K1: Other (Mean) | L1: Total (min) | M1: Total (max) | N1: Total (Mean) | Q1: Total (Mean)
A2: 0 | B2: 100 | C2: 0.13 | D2: 0.29 | E2: 0.19 | F2: 1.05 | G2: 1.11 | H2: 1.1 | I2: 16.61 | J2: 23.92 | K2: 19.9 | L2: 17.88 | M2: 25.17 | N2: 21.19 | P2: 100 | Q2: =AVERAGE(N2:N3) -> 11.42
A3: 1 | B3: 100 | C3: 0.08 | D3: 0.22 | E3: 0.13 | F3: 1.5 | G3: 1.53 | H3: 1.52 | I3: 0 | J3: 0.01 | K3: 0 | L3: 1.58 | M3: 1.75 | N3: 1.65 | P3: =P2+100 -> 200 | Q3: =AVERAGE(N4:N5) -> 13.025
A4: 0 | B4: 200 | C4: 0.13 | D4: 0.29 | E4: 0.19 | F4: 1.67 | G4: 1.71 | H4: 1.68 | I4: 18.87 | J4: 24.57 | K4: 21.02 | L4: 20.76 | M4: 26.43 | N4: 22.89 | P4: =P3+100 -> 300 | Q4: =AVERAGE(N6:N7) -> 13.93
A5: 1 | B5: 200 | C5: 0.08 | D5: 0.22 | E5: 0.15 | F5: 2.99 | G5: 3.03 | H5: 3.01 | I5: 0 | J5: 0.03 | K5: 0 | L5: 3.09 | M5: 3.24 | N5: 3.16 | P5: =P4+100 -> 400 | Q5: =AVERAGE(N8:N9) -> 15.65
A6: 0 | B6: 300 | C6: 0.14 | D6: 0.27 | E6: 0.19 | F6: 2.26 | G6: 2.31 | H6: 2.28 | I6: 18.03 | J6: 23 | K6: 20.73 | L6: 20.52 | M6: 25.45 | N6: 23.19 | P6: =P5+100 -> 500 | Q6: =AVERAGE(N10:N11) -> 16.925
A7: 1 | B7: 300 | C7: 0.09 | D7: 0.23 | E7: 0.16 | F7: 4.48 | G7: 4.62 | H7: 4.51 | I7: 0 | J7: 0.07 | K7: 0 | L7: 4.57 | M7: 4.79 | N7: 4.67 | P7: =P6+100 -> 600 | Q7: =AVERAGE(N12:N13) -> 18.04
A8: 0 | B8: 400 | C8: 0.16 | D8: 0.25 | E8: 0.19 | F8: 2.87 | G8: 2.94 | H8: 2.89 | I8: 19.91 | J8: 24.89 | K8: 22.07 | L8: 23.03 | M8: 28.02 | N8: 25.15 | P8: =P7+100 -> 700 | Q8: =AVERAGE(N14:N15) -> 19.605
A9: 1 | B9: 400 | C9: 0.1 | D9: 0.23 | E9: 0.17 | F9: 5.96 | G9: 6.02 | H9: 5.98 | I9: 0 | J9: 0.01 | K9: 0 | L9: 6.07 | M9: 6.23 | N9: 6.15 | P9: =P8+100 -> 800 | Q9: =AVERAGE(N16:N17) -> 20.785
A10: 0 | B10: 500 | C10: 0.15 | D10: 0.29 | E10: 0.2 | F10: 3.44 | G10: 3.55 | H10: 3.49 | I10: 20.13 | J10: 25.71 | K10: 22.55 | L10: 23.78 | M10: 29.42 | N10: 26.24 | P10: =P9+100 -> 900 | Q10: =AVERAGE(N18:N19) -> 22.135
A11: 1 | B11: 500 | C11: 0.08 | D11: 0.22 | E11: 0.16 | F11: 7.42 | G11: 7.5 | H11: 7.45 | I11: 0 | J11: 0.06 | K11: 0 | L11: 7.51 | M11: 7.71 | N11: 7.61 | P11: =P10+100 -> 1000 | Q11: =AVERAGE(N20:N21) -> 23.235
A12: 0 | B12: 600 | C12: 0.17 | D12: 0.27 | E12: 0.2 | F12: 4.09 | G12: 4.16 | H12: 4.12 | I12: 20.51 | J12: 26.65 | K12: 22.65 | L12: 24.8 | M12: 31.02 | N12: 26.97 | P12: =P11+100 -> 1100 | Q12: =AVERAGE(N22:N23) -> 24.51
A13: 1 | B13: 600 | C13: 0.1 | D13: 0.24 | E13: 0.16 | F13: 8.93 | G13: 8.97 | H13: 8.95 | I13: 0 | J13: 0.01 | K13: 0 | L13: 9.04 | M13: 9.21 | N13: 9.11 | P13: =P12+100 -> 1200 | Q13: =AVERAGE(N24:N25) -> 25.985
A14: 0 | B14: 700 | C14: 0.17 | D14: 0.26 | E14: 0.21 | F14: 4.68 | G14: 4.79 | H14: 4.72 | I14: 21.54 | J14: 28.69 | K14: 23.64 | L14: 26.45 | M14: 33.63 | N14: 28.57 | P14: =P13+100 -> 1300 | Q14: =AVERAGE(N26:N27) -> 27.105
A15: 1 | B15: 700 | C15: 0.11 | D15: 0.24 | E15: 0.17 | F15: 10.45 | G15: 10.51 | H15: 10.47 | I15: 0 | J15: 0.05 | K15: 0 | L15: 10.56 | M15: 10.73 | N15: 10.64 | P15: =P14+100 -> 1400 | Q15: =AVERAGE(N28:N29) -> 28.615
A16: 0 | B16: 800 | C16: 0.15 | D16: 0.32 | E16: 0.21 | F16: 5.3 | G16: 5.43 | H16: 5.37 | I16: 21.59 | J16: 29.64 | K16: 23.9 | L16: 27.1 | M16: 35.24 | N16: 29.48 | P16: =P15+100 -> 1500 | Q16: =AVERAGE(N30:N31) -> 29.715
A17: 1 | B17: 800 | C17: 0.1 | D17: 0.23 | E17: 0.16 | F17: 11.89 | G17: 12.1 | H17: 11.92 | I17: 0 | J17: 0.01 | K17: 0 | L17: 12.01 | M17: 12.32 | N17: 12.09 | P17: =P16+100 -> 1600 | Q17: =AVERAGE(N32:N33) -> 31.165
A18: 0 | B18: 900 | C18: 0.18 | D18: 0.3 | E18: 0.24 | F18: 5.94 | G18: 6.01 | H18: 5.97 | I18: 22.53 | J18: 31.72 | K18: 24.79 | L18: 28.73 | M18: 37.98 | N18: 31.01 | P18: =P17+100 -> 1700 | Q18: =AVERAGE(N34:N35) -> 32.43
A19: 1 | B19: 900 | C19: 0.05 | D19: 0.1 | E19: 0.07 | F19: 13.15 | G19: 13.3 | H19: 13.18 | I19: 0 | J19: 0 | K19: 0 | L19: 13.21 | M19: 13.39 | N19: 13.26 | P19: =P18+100 -> 1800 | Q19: =AVERAGE(N36:N37) -> 34.005
A20: 0 | B20: 1000 | C20: 0.15 | D20: 0.28 | E20: 0.22 | F20: 6.41 | G20: 6.57 | H20: 6.47 | I20: 22.58 | J20: 28.97 | K20: 25.03 | L20: 29.24 | M20: 35.72 | N20: 31.72 | P20: =P19+100 -> 1900 | Q20: =AVERAGE(N38:N39) -> 34.945
A21: 1 | B21: 1000 | C21: 0.06 | D21: 0.22 | E21: 0.1 | F21: 14.61 | G21: 14.76 | H21: 14.65 | I21: 0 | J21: 0.01 | K21: 0 | L21: 14.7 | M21: 14.95 | N21: 14.75 | P21: =P20+100 -> 2000 | Q21: =AVERAGE(N40:N41) -> 35.315
A22: 0 | B22: 1100 | C22: 0.14 | D22: 0.31 | E22: 0.22 | F22: 7.07 | G22: 7.18 | H22: 7.12 | I22: 23.36 | J22: 29.49 | K22: 25.49 | L22: 30.66 | M22: 36.9 | N22: 32.83 | P22: =P21+100 -> 2100 | Q22: =AVERAGE(N42:N43) -> 37.585
A23: 1 | B23: 1100 | C23: 0.04 | D23: 0.18 | E23: 0.08 | F23: 16.06 | G23: 16.21 | H23: 16.11 | I23: 0 | J23: 0 | K23: 0 | L23: 16.12 | M23: 16.33 | N23: 16.19 | P23: =P22+100 -> 2200 | Q23: =AVERAGE(N44:N45) -> 37.805
A24: 0 | B24: 1200 | C24: 0.14 | D24: 0.3 | E24: 0.22 | F24: 7.77 | G24: 7.92 | H24: 7.86 | I24: 23.65 | J24: 30.57 | K24: 26.16 | L24: 31.69 | M24: 38.64 | N24: 34.24 | P24: =P23+100 -> 2300 | Q24: =AVERAGE(N46:N47) -> 40.19
A25: 1 | B25: 1200 | C25: 0.05 | D25: 0.18 | E25: 0.08 | F25: 17.6 | G25: 17.77 | H25: 17.65 | I25: 0 | J25: 0 | K25: 0 | L25: 17.67 | M25: 17.95 | N25: 17.73 | P25: =P24+100 -> 2400 | Q25: =AVERAGE(N48:N49) -> 41.84
A26: 0 | B26: 1300 | C26: 0.13 | D26: 0.28 | E26: 0.21 | F26: 8.26 | G26: 8.45 | H26: 8.35 | I26: 24.31 | J26: 29.26 | K26: 26.45 | L26: 32.95 | M26: 37.86 | N26: 35.01 | P26: =P25+100 -> 2500 | Q26: =AVERAGE(N50:N51) -> 42.595
A27: 1 | B27: 1300 | C27: 0.05 | D27: 0.21 | E27: 0.1 | F27: 19.06 | G27: 19.23 | H27: 19.1 | I27: 0 | J27: 0 | K27: 0 | L27: 19.12 | M27: 19.43 | N27: 19.2 | P27: =P26+100 -> 2600 | Q27: =AVERAGE(N52:N53) -> 42.97
A28: 0 | B28: 1400 | C28: 0.15 | D28: 0.29 | E28: 0.22 | F28: 8.91 | G28: 9.09 | H28: 9 | I28: 25.36 | J28: 30.91 | K28: 27.44 | L28: 34.6 | M28: 40.16 | N28: 36.66 | P28: =P27+100 -> 2700 | Q28: =AVERAGE(N54:N55) -> 46.03
A29: 1 | B29: 1400 | C29: 0.06 | D29: 0.16 | E29: 0.08 | F29: 20.44 | G29: 20.58 | H29: 20.49 | I29: 0 | J29: 0 | K29: 0 | L29: 20.51 | M29: 20.68 | N29: 20.57 | P29: =P28+100 -> 2800 | Q29: =AVERAGE(N56:N57) -> 45.55
A30: 0 | B30: 1500 | C30: 0.08 | D30: 0.28 | E30: 0.21 | F30: 9.45 | G30: 9.73 | H30: 9.59 | I30: 25.22 | J30: 33.55 | K30: 27.58 | L30: 35.18 | M30: 43.43 | N30: 37.38 | P30: 2900 | Q30: =AVERAGE(N58:N59) -> #DIV/0!
A31: 1 | B31: 1500 | C31: 0.05 | D31: 0.19 | E31: 0.08 | F31: 21.9 | G31: 22.09 | H31: 21.97 | I31: 0 | J31: 0.01 | K31: 0 | L31: 21.95 | M31: 22.26 | N31: 22.05 | P31: 3000 | Q31: =AVERAGE(N60:N61) -> #DIV/0!
A32: 0 | B32: 1600 | C32: 0.16 | D32: 0.3 | E32: 0.22 | F32: 10.17 | G32: 10.38 | H32: 10.25 | I32: 25.92 | J32: 37.69 | K32: 28.27 | L32: 36.34 | M32: 48.34 | N32: 38.74
A33: 1 | B33: 1600 | C33: 0.05 | D33: 0.12 | E33: 0.08 | F33: 23.41 | G33: 23.63 | H33: 23.51 | I33: 0 | J33: 0 | K33: 0 | L33: 23.48 | M33: 23.71 | N33: 23.59
A34: 0 | B34: 1700 | C34: 0.15 | D34: 0.3 | E34: 0.22 | F34: 10.75 | G34: 11.02 | H34: 10.9 | I34: 25.56 | J34: 32.85 | K34: 28.61 | L34: 36.65 | M34: 44.08 | N34: 39.73
A35: 1 | B35: 1700 | C35: 0.04 | D35: 0.2 | E35: 0.09 | F35: 24.95 | G35: 25.18 | H35: 25.04 | I35: 0 | J35: 0 | K35: 0 | L35: 25.02 | M35: 25.27 | N35: 25.13
A36: 0 | B36: 1800 | C36: 0.15 | D36: 0.3 | E36: 0.22 | F36: 11.54 | G36: 11.81 | H36: 11.7 | I36: 27.02 | J36: 34.82 | K36: 29.37 | L36: 39.04 | M36: 46.88 | N36: 41.28
A37: 1 | B37: 1800 | C37: 0.05 | D37: 0.24 | E37: 0.1 | F37: 26.54 | G37: 26.78 | H37: 26.64 | I37: 0 | J37: 0 | K37: 0 | L37: 26.62 | M37: 26.94 | N37: 26.73
A38: 0 | B38: 1900 | C38: 0.13 | D38: 0.3 | E38: 0.22 | F38: 12.14 | G38: 12.38 | H38: 12.24 | I38: 27.79 | J38: 33.72 | K38: 29.81 | L38: 40.17 | M38: 46.21 | N38: 42.27
A39: 1 | B39: 1900 | C39: 0.06 | D39: 0.2 | E39: 0.09 | F39: 27.45 | G39: 27.64 | H39: 27.53 | I39: 0 | J39: 0 | K39: 0 | L39: 27.53 | M39: 27.83 | N39: 27.62
A40: 0 | B40: 2000 | C40: 0.13 | D40: 0.3 | E40: 0.23 | F40: 12.19 | G40: 12.49 | H40: 12.34 | I40: 26.66 | J40: 40.65 | K40: 28.9 | L40: 39.18 | M40: 53.32 | N40: 41.46
...

Sheet Test_Data_9033_UI_2017b6
A1: Core | B1: Rate | C1: ISRs (Min) | D1: ISRs (Max) | E1: ISRs (Max) | F1: TL (min) | G1: TL (max) | H1: TL (Mean) | I1: Other (Min) | J1: Other (Max) | K1: Other (Mean) | L1: Total (min) | M1: Total (max) | N1: Total (Mean) | Q1: Total (Mean)
A2: 0 | B2: 100 | C2: 0.15 | D2: 0.26 | E2: 0.18 | F2: 1.06 | G2: 1.14 | H2: 1.1 | I2: 17.18 | J2: 26.79 | K2: 20.47 | L2: 18.44 | M2: 28.02 | N2: 21.74 | P2: 100 | Q2: =AVERAGE(N2:N3) -> 11.725
A3: 1 | B3: 100 | C3: 0.07 | D3: 0.21 | E3: 0.14 | F3: 1.54 | G3: 1.59 | H3: 1.56 | I3: 0 | J3: 0.06 | K3: 0 | L3: 1.62 | M3: 1.8 | N3: 1.71 | P3: =P2+100 -> 200 | Q3: =AVERAGE(N4:N5) -> 13.255
A4: 0 | B4: 200 | C4: 0.16 | D4: 0.26 | E4: 0.18 | F4: 1.66 | G4: 1.7 | H4: 1.68 | I4: 18.7 | J4: 27.82 | K4: 21.39 | L4: 20.6 | M4: 29.77 | N4: 23.26 | P4: =P3+100 -> 300 | Q4: =AVERAGE(N6:N7) -> 14.71
A5: 1 | B5: 200 | C5: 0.08 | D5: 0.21 | E5: 0.15 | F5: 3.08 | G5: 3.12 | H5: 3.1 | I5: 0 | J5: 0.02 | K5: 0 | L5: 3.16 | M5: 3.32 | N5: 3.25 | P5: =P4+100 -> 400 | Q5: =AVERAGE(N8:N9) -> 16.245
A6: 0 | B6: 300 | C6: 0.16 | D6: 0.25 | E6: 0.18 | F6: 2.23 | G6: 2.29 | H6: 2.26 | I6: 19.27 | J6: 28.69 | K6: 22.24 | L6: 21.76 | M6: 31.16 | N6: 24.68 | P6: =P5+100 -> 500 | Q6: =AVERAGE(N10:N11) -> 17.585
A7: 1 | B7: 300 | C7: 0.08 | D7: 0.2 | E7: 0.15 | F7: 4.56 | G7: 4.6 | H7: 4.58 | I7: 0 | J7: 0.03 | K7: 0 | L7: 4.65 | M7: 4.8 | N7: 4.74 | P7: =P6+100 -> 600 | Q7: =AVERAGE(N12:N13) -> 18.83
A8: 0 | B8: 400 | C8: 0.16 | D8: 0.26 | E8: 0.19 | F8: 2.86 | G8: 2.93 | H8: 2.89 | I8: 20.42 | J8: 33.93 | K8: 23.17 | L8: 23.49 | M8: 37.05 | N8: 26.25 | P8: =P7+100 -> 700 | Q8: =AVERAGE(N14:N15) -> 19.76
A9: 1 | B9: 400 | C9: 0.08 | D9: 0.2 | E9: 0.14 | F9: 6.07 | G9: 6.15 | H9: 6.1 | I9: 0 | J9: 0.03 | K9: 0 | L9: 6.15 | M9: 6.34 | N9: 6.24 | P9: =P8+100 -> 800 | Q9: =AVERAGE(N16:N17) -> 20.795
A10: 0 | B10: 500 | C10: 0.13 | D10: 0.28 | E10: 0.2 | F10: 3.46 | G10: 3.57 | H10: 3.5 | I10: 19.9 | J10: 37.99 | K10: 23.71 | L10: 23.57 | M10: 41.71 | N10: 27.41 | P10: =P9+100 -> 900 | Q10: =AVERAGE(N18:N19) -> 22.24
A11: 1 | B11: 500 | C11: 0.08 | D11: 0.2 | E11: 0.15 | F11: 7.56 | G11: 7.75 | H11: 7.61 | I11: 0 | J11: 0.01 | K11: 0 | L11: 7.64 | M11: 7.94 | N11: 7.76 | P11: =P10+100 -> 1000 | Q11: =AVERAGE(N20:N21) -> 23.41
A12: 0 | B12: 600 | C12: 0.14 | D12: 0.27 | E12: 0.19 | F12: 4.01 | G12: 4.16 | H12: 4.07 | I12: 20.68 | J12: 38.85 | K12: 24.11 | L12: 24.94 | M12: 43.12 | N12: 28.38 | P12: =P11+100 -> 1100 | Q12: =AVERAGE(N22:N23) -> 24.395
A13: 1 | B13: 600 | C13: 0.09 | D13: 0.21 | E13: 0.16 | F13: 9.07 | G13: 9.31 | H13: 9.12 | I13: 0 | J13: 0.07 | K13: 0 | L13: 9.17 | M13: 9.49 | N13: 9.28 | P13: =P12+100 -> 1200 | Q13: =AVERAGE(N24:N25) -> 26.08
A14: 0 | B14: 700 | C14: 0.15 | D14: 0.27 | E14: 0.2 | F14: 4.65 | G14: 4.74 | H14: 4.68 | I14: 21.07 | J14: 32.95 | K14: 23.86 | L14: 25.99 | M14: 37.88 | N14: 28.75 | P14: =P13+100 -> 1300 | Q14: =AVERAGE(N26:N27) -> 27.61
A15: 1 | B15: 700 | C15: 0.08 | D15: 0.2 | E15: 0.16 | F15: 10.56 | G15: 10.73 | H15: 10.62 | I15: 0 | J15: 0.06 | K15: 0 | L15: 10.65 | M15: 10.93 | N15: 10.77 | P15: =P14+100 -> 1400 | Q15: =AVERAGE(N28:N29) -> 28.815
A16: 0 | B16: 800 | C16: 0.14 | D16: 0.29 | E16: 0.21 | F16: 5.27 | G16: 5.36 | H16: 5.31 | I16: 21.61 | J16: 26.59 | K16: 23.85 | L16: 27.13 | M16: 32.18 | N16: 29.37 | P16: =P15+100 -> 1500 | Q16: =AVERAGE(N30:N31) -> 29.915
A17: 1 | B17: 800 | C17: 0.07 | D17: 0.2 | E17: 0.15 | F17: 12.03 | G17: 12.21 | H17: 12.07 | I17: 0 | J17: 0.02 | K17: 0 | L17: 12.13 | M17: 12.39 | N17: 12.22 | P17: =P16+100 -> 1600 | Q17: =AVERAGE(N32:N33) -> 31.335
A18: 0 | B18: 900 | C18: 0.14 | D18: 0.31 | E18: 0.25 | F18: 5.83 | G18: 5.98 | H18: 5.87 | I18: 21.66 | J18: 41.52 | K18: 24.85 | L18: 27.81 | M18: 47.78 | N18: 30.97 | P18: =P17+100 -> 1700 | Q18: =AVERAGE(N34:N35) -> 32.605
A19: 1 | B19: 900 | C19: 0.05 | D19: 0.16 | E19: 0.08 | F19: 13.4 | G19: 13.45 | H19: 13.42 | I19: 0 | J19: 0.01 | K19: 0 | L19: 13.45 | M19: 13.59 | N19: 13.51 | P19: =P18+100 -> 1800 | Q19: =AVERAGE(N36:N37) -> 33.805
A20: 0 | B20: 1000 | C20: 0.11 | D20: 0.27 | E20: 0.22 | F20: 6.52 | G20: 6.71 | H20: 6.59 | I20: 22.16 | J20: 27.75 | K20: 24.85 | L20: 28.91 | M20: 34.72 | N20: 31.65 | P20: =P19+100 -> 1900 | Q20: =AVERAGE(N38:N39) -> 36.155
A21: 1 | B21: 1000 | C21: 0.05 | D21: 0.16 | E21: 0.08 | F21: 15.02 | G21: 15.24 | H21: 15.09 | I21: 0 | J21: 0.01 | K21: 0 | L21: 15.08 | M21: 15.36 | N21: 15.17 | P21: =P20+100 -> 2000 | Q21: =AVERAGE(N40:N41) -> 36.865
A22: 0 | B22: 1100 | C22: 0.13 | D22: 0.28 | E22: 0.17 | F22: 7 | G22: 7.1 | H22: 7.04 | I22: 22.43 | J22: 28.59 | K22: 24.79 | L22: 29.62 | M22: 35.85 | N22: 32 | P22: =P21+100 -> 2100 | Q22: =AVERAGE(N42:N43) -> 38.1
A23: 1 | B23: 1100 | C23: 0.09 | D23: 0.21 | E23: 0.16 | F23: 16.58 | G23: 16.74 | H23: 16.63 | I23: 0 | J23: 0.02 | K23: 0 | L23: 16.68 | M23: 16.94 | N23: 16.79 | P23: =P22+100 -> 2200 | Q23: =AVERAGE(N44:N45) -> 38.845
A24: 0 | B24: 1200 | C24: 0.11 | D24: 0.27 | E24: 0.21 | F24: 7.72 | G24: 7.85 | H24: 7.78 | I24: 23.5 | J24: 30.64 | K24: 26.1 | L24: 31.46 | M24: 38.7 | N24: 34.09 | P24: =P23+100 -> 2300 | Q24: =AVERAGE(N46:N47) -> 40.68
A25: 1 | B25: 1200 | C25: 0.05 | D25: 0.18 | E25: 0.09 | F25: 17.89 | G25: 18.04 | H25: 17.98 | I25: 0 | J25: 0.01 | K25: 0 | L25: 17.96 | M25: 18.21 | N25: 18.07 | P25: =P24+100 -> 2400 | Q25: =AVERAGE(N48:N49) -> 42.335
A26: 0 | B26: 1300 | C26: 0.1 | D26: 0.28 | E26: 0.22 | F26: 8.22 | G26: 8.47 | H26: 8.29 | I26: 24.14 | J26: 48.8 | K26: 27.06 | L26: 32.66 | M26: 57.51 | N26: 35.57 | P26: =P25+100 -> 2500 | Q26: =AVERAGE(N50:N51) -> 43.395
A27: 1 | B27: 1300 | C27: 0.04 | D27: 0.2 | E27: 0.08 | F27: 19.48 | G27: 19.71 | H27: 19.57 | I27: 0 | J27: 0.01 | K27: 0 | L27: 19.53 | M27: 19.82 | N27: 19.65 | P27: =P26+100 -> 2600 | Q27: =AVERAGE(N52:N53) -> #DIV/0!
A28: 0 | B28: 1400 | C28: 0.09 | D28: 0.28 | E28: 0.21 | F28: 8.97 | G28: 9.08 | H28: 9.03 | I28: 24.54 | J28: 33.69 | K28: 27.39 | L28: 33.76 | M28: 42.85 | N28: 36.62 | P28: =P27+100 -> 2700 | Q28: =AVERAGE(N54:N55) -> #DIV/0!
A29: 1 | B29: 1400 | C29: 0.04 | D29: 0.21 | E29: 0.08 | F29: 20.82 | G29: 21.07 | H29: 20.92 | I29: 0 | J29: 0.02 | K29: 0 | L29: 20.88 | M29: 21.27 | N29: 21.01 | P29: =P28+100 -> 2800 | Q29: =AVERAGE(N56:N57) -> #DIV/0!
A30: 0 | B30: 1500 | C30: 0.11 | D30: 0.28 | E30: 0.22 | F30: 9.36 | G30: 9.69 | H30: 9.48 | I30: 25.33 | J30: 35.74 | K30: 27.73 | L30: 35.08 | M30: 45.56 | N30: 37.43 | P30: 2900 | Q30: =AVERAGE(N58:N59) -> #DIV/0!
A31: 1 | B31: 1500 | C31: 0.04 | D31: 0.2 | E31: 0.07 | F31: 22.23 | G31: 22.44 | H31: 22.33 | I31: 0 | J31: 0.01 | K31: 0 | L31: 22.28 | M31: 22.58 | N31: 22.4 | P31: 3000 | Q31: =AVERAGE(N60:N61) -> #DIV/0!
A32: 0 | B32: 1600 | C32: 0.1 | D32: 0.3 | E32: 0.22 | F32: 10.12 | G32: 10.28 | H32: 10.2 | I32: 25.69 | J32: 32.78 | K32: 28.28 | L32: 36.12 | M32: 43.26 | N32: 38.7
A33: 1 | B33: 1600 | C33: 0.04 | D33: 0.19 | E33: 0.08 | F33: 23.79 | G33: 24.05 | H33: 23.89 | I33: 0 | J33: 0.01 | K33: 0 | L33: 23.86 | M33: 24.19 | N33: 23.97
A34: 0 | B34: 1700 | C34: 0.15 | D34: 0.3 | E34: 0.22 | F34: 10.7 | G34: 11 | H34: 10.8 | I34: 25.58 | J34: 44.77 | K34: 28.92 | L34: 36.56 | M34: 56.05 | N34: 39.94
A35: 1 | B35: 1700 | C35: 0.04 | D35: 0.1 | E35: 0.07 | F35: 25.13 | G35: 25.34 | H35: 25.2 | I35: 0 | J35: 0.01 | K35: 0 | L35: 25.18 | M35: 25.41 | N35: 25.27
A36: 0 | B36: 1800 | C36: 0.17 | D36: 0.29 | E36: 0.24 | F36: 11.2 | G36: 11.41 | H36: 11.3 | I36: 26.61 | J36: 37.45 | K36: 29.28 | L36: 38.11 | M36: 49.05 | N36: 40.82
A37: 1 | B37: 1800 | C37: 0.07 | D37: 0.1 | E37: 0.09 | F37: 26.67 | G37: 26.75 | H37: 26.71 | I37: 0 | J37: 0.01 | K37: 0 | L37: 26.74 | M37: 26.84 | N37: 26.79
A38: 0 | B38: 1900 | C38: 0.15 | D38: 0.31 | E38: 0.23 | F38: 12.08 | G38: 12.3 | H38: 12.19 | I38: 28.21 | J38: 38.53 | K38: 31.4 | L38: 40.68 | M38: 51.1 | N38: 43.82
A39: 1 | B39: 1900 | C39: 0.04 | D39: 0.1 | E39: 0.07 | F39: 28.32 | G39: 28.55 | H39: 28.42 | I39: 0 | J39: 0.01 | K39: 0 | L39: 28.38 | M39: 28.63 | N39: 28.49
A40: 0 | B40: 2000 | C40: 0.11 | D40: 0.29 | E40: 0.22 | F40: 12.51 | G40: 13.05 | H40: 12.67 | I40: 27.92 | J40: 49.71 | K40: 30.86 | L40: 40.79 | M40: 62.94 | N40: 43.75
...

Sheet Test_Data_9033_UI_2017a17
A1: Core | B1: Rate | C1: ISRs (Min) | D1: ISRs (Max) | E1: ISRs (Max) | F1: TL (min) | G1: TL (max) | H1: TL (Mean) | I1: Other (Min) | J1: Other (Max) | K1: Other (Mean) | L1: Total (min) | M1: Total (max) | N1: Total (Mean) | P1: Total (Mean)
A2: 0 | B2: 100 | C2: 0.19 | D2: 0.29 | E2: 0.22 | F2: 1.06 | G2: 1.12 | H2: 1.1 | I2: 17.52 | J2: 26.85 | K2: 21.14 | L2: 18.84 | M2: 28.17 | N2: 22.46 | O2: 100 | P2: =AVERAGE(N2:N3) -> 12.14
A3: 1 | B3: 100 | C3: 0.11 | D3: 0.28 | E3: 0.19 | F3: 1.62 | G3: 1.65 | H3: 1.63 | I3: 0 | J3: 0.01 | K3: 0 | L3: 1.72 | M3: 1.92 | N3: 1.82 | O3: 200 | P3: =AVERAGE(N4:N5) -> 13.72
A4: 0 | B4: 200 | C4: 0.13 | D4: 0.32 | E4: 0.21 | F4: 1.7 | G4: 1.77 | H4: 1.72 | I4: 19.48 | J4: 25.92 | K4: 22.1 | L4: 21.48 | M4: 27.82 | N4: 24.04 | O4: 300 | P4: =AVERAGE(N6:N7) -> 14.765
A5: 1 | B5: 200 | C5: 0.12 | D5: 0.27 | E5: 0.19 | F5: 3.19 | G5: 3.23 | H5: 3.21 | I5: 0 | J5: 0.06 | K5: 0 | L5: 3.32 | M5: 3.5 | N5: 3.4 | O5: 400 | P5: =AVERAGE(N8:N9) -> 16.715
A6: 0 | B6: 300 | C6: 0.19 | D6: 0.33 | E6: 0.23 | F6: 2.27 | G6: 2.37 | H6: 2.32 | I6: 19.09 | J6: 25.89 | K6: 22.02 | L6: 21.64 | M6: 28.43 | N6: 24.57 | O6: 500 | P6: =AVERAGE(N10:N11) -> 18.285
A7: 1 | B7: 300 | C7: 0.12 | D7: 0.26 | E7: 0.19 | F7: 4.75 | G7: 4.79 | H7: 4.77 | I7: 0 | J7: 0.01 | K7: 0 | L7: 4.89 | M7: 5.05 | N7: 4.96 | O7: 600 | P7: =AVERAGE(N12:N13) -> 19.475
A8: 0 | B8: 400 | C8: 0.21 | D8: 0.32 | E8: 0.24 | F8: 2.92 | G8: 2.98 | H8: 2.94 | I8: 20.83 | J8: 32.88 | K8: 23.67 | L8: 24.01 | M8: 36.11 | N8: 26.84 | O8: 700 | P8: =AVERAGE(N14:N15) -> 20.79
A9: 1 | B9: 400 | C9: 0.12 | D9: 0.29 | E9: 0.2 | F9: 6.37 | G9: 6.56 | H9: 6.39 | I9: 0 | J9: 0.06 | K9: 0 | L9: 6.5 | M9: 6.71 | N9: 6.59 | O9: 800 | P9: =AVERAGE(N16:N17) -> 22.7
A10: 0 | B10: 500 | C10: 0.18 | D10: 0.35 | E10: 0.24 | F10: 3.52 | G10: 3.63 | H10: 3.56 | I10: 21.53 | J10: 35.19 | K10: 24.52 | L10: 25.32 | M10: 39.01 | N10: 28.32 | O10: 900 | P10: =AVERAGE(N18:N19) -> 23.2
A11: 1 | B11: 500 | C11: 0.13 | D11: 0.28 | E11: 0.2 | F11: 8 | G11: 8.22 | H11: 8.05 | I11: 0 | J11: 0.06 | K11: 0 | L11: 8.14 | M11: 8.39 | N11: 8.25 | O11: 1000 | P11: =AVERAGE(N20:N21) -> 24.645
A12: 0 | B12: 600 | C12: 0.18 | D12: 0.32 | E12: 0.24 | F12: 4.13 | G12: 4.26 | H12: 4.19 | I12: 21.93 | J12: 36.23 | K12: 24.82 | L12: 26.39 | M12: 40.67 | N12: 29.25 | O12: 1100 | P12: =AVERAGE(N22:N23) -> 25.91
A13: 1 | B13: 600 | C13: 0.13 | D13: 0.29 | E13: 0.2 | F13: 9.45 | G13: 9.65 | H13: 9.5 | I13: 0 | J13: 0.03 | K13: 0 | L13: 9.6 | M13: 9.89 | N13: 9.7 | O13: 1200 | P13: =AVERAGE(N24:N25) -> 27.345
A14: 0 | B14: 700 | C14: 0.16 | D14: 0.31 | E14: 0.25 | F14: 4.77 | G14: 4.89 | H14: 4.83 | I14: 22.73 | J14: 28.15 | K14: 25.21 | L14: 27.81 | M14: 33.23 | N14: 30.28 | O14: 1300 | P14: =AVERAGE(N26:N27) -> 28.875
A15: 1 | B15: 700 | C15: 0.12 | D15: 0.28 | E15: 0.19 | F15: 11.06 | G15: 11.28 | H15: 11.11 | I15: 0 | J15: 0.01 | K15: 0 | L15: 11.2 | M15: 11.49 | N15: 11.3 | O15: 1400 | P15: =AVERAGE(N28:N29) -> 30.25
A16: 0 | B16: 800 | C16: 0.18 | D16: 0.35 | E16: 0.25 | F16: 5.55 | G16: 5.68 | H16: 5.62 | I16: 23.97 | J16: 39.27 | K16: 26.69 | L16: 29.82 | M16: 45.19 | N16: 32.56 | O16: 1500 | P16: =AVERAGE(N30:N31) -> 30.57
A17: 1 | B17: 800 | C17: 0.13 | D17: 0.28 | E17: 0.2 | F17: 12.57 | G17: 12.86 | H17: 12.64 | I17: 0 | J17: 0.05 | K17: 0 | L17: 12.72 | M17: 13.1 | N17: 12.84 | O17: 1600 | P17: =AVERAGE(N32:N33) -> 32.775
A18: 0 | B18: 900 | C18: 0.17 | D18: 0.41 | E18: 0.28 | F18: 6.02 | G18: 6.15 | H18: 6.09 | I18: 23.55 | J18: 33.23 | K18: 26.15 | L18: 29.85 | M18: 39.73 | N18: 32.51 | O18: 1700 | P18: =AVERAGE(N34:N35) -> 34.26
A19: 1 | B19: 900 | C19: 0.06 | D19: 0.25 | E19: 0.09 | F19: 13.76 | G19: 13.92 | H19: 13.8 | I19: 0 | J19: 0.01 | K19: 0 | L19: 13.82 | M19: 14.15 | N19: 13.89 | O19: 1800 | P19: =AVERAGE(N36:N37) -> 35.885
A20: 0 | B20: 1000 | C20: 0.18 | D20: 0.35 | E20: 0.27 | F20: 6.63 | G20: 6.84 | H20: 6.71 | I20: 24.33 | J20: 29.74 | K20: 26.96 | L20: 31.26 | M20: 36.65 | N20: 33.94 | O20: 1900 | P20: =AVERAGE(N38:N39) -> 37.225
A21: 1 | B21: 1000 | C21: 0.07 | D21: 0.14 | E21: 0.09 | F21: 15.19 | G21: 15.4 | H21: 15.25 | I21: 0 | J21: 0.01 | K21: 0 | L21: 15.27 | M21: 15.54 | N21: 15.35 | O21: 2000 | P21: =AVERAGE(N40:N41) -> 38.505
A22: 0 | B22: 1100 | C22: 0.18 | D22: 0.34 | E22: 0.26 | F22: 7.3 | G22: 7.42 | H22: 7.35 | I22: 24.5 | J22: 31.2 | K22: 27.35 | L22: 32.1 | M22: 38.83 | N22: 34.96 | O22: 2100 | P22: =AVERAGE(N42:N43) -> 39.155
A23: 1 | B23: 1100 | C23: 0.06 | D23: 0.14 | E23: 0.1 | F23: 16.71 | G23: 16.92 | H23: 16.77 | I23: 0 | J23: 0.01 | K23: 0 | L23: 16.78 | M23: 17.04 | N23: 16.86 | O23: 2200 | P23: =AVERAGE(N44:N45) -> 41.245
A24: 0 | B24: 1200 | C24: 0.22 | D24: 0.34 | E24: 0.26 | F24: 7.95 | G24: 8.15 | H24: 8.03 | I24: 25.13 | J24: 31.83 | K24: 27.96 | L24: 33.33 | M24: 40.11 | N24: 36.26 | O24: 2300 | P24: =AVERAGE(N46:N47) -> 42.705
A25: 1 | B25: 1200 | C25: 0.06 | D25: 0.1 | E25: 0.07 | F25: 18.33 | G25: 18.39 | H25: 18.36 | I25: 0 | J25: 0 | K25: 0 | L25: 18.4 | M25: 18.48 | N25: 18.43 | O25: 2400 | P25: =AVERAGE(N48:N49) -> 43.93
A26: 0 | B26: 1300 | C26: 0.18 | D26: 0.36 | E26: 0.27 | F26: 8.56 | G26: 8.7 | H26: 8.64 | I26: 25.78 | J26: 32.26 | K26: 28.82 | L26: 34.64 | M26: 41.25 | N26: 37.72 | O26: 2500 | P26: =AVERAGE(N50:N51) -> 43.585
A27: 1 | B27: 1300 | C27: 0.06 | D27: 0.27 | E27: 0.1 | F27: 19.86 | G27: 20.08 | H27: 19.93 | I27: 0 | J27: 0.02 | K27: 0 | L27: 19.93 | M27: 20.35 | N27: 20.03 | O27: 2600 | P27: =AVERAGE(N52:N53) -> 47.24
A28: 0 | B28: 1400 | C28: 0.18 | D28: 0.38 | E28: 0.27 | F28: 9.23 | G28: 9.37 | H28: 9.29 | I28: 26.52 | J28: 34.02 | K28: 29.45 | L28: 36.04 | M28: 43.65 | N28: 39.01 | O28: 2700 | P28: =AVERAGE(N54:N55) -> 45.725
A29: 1 | B29: 1400 | C29: 0.05 | D29: 0.14 | E29: 0.09 | F29: 21.33 | G29: 21.56 | H29: 21.4 | I29: 0 | J29: 0 | K29: 0 | L29: 21.4 | M29: 21.68 | N29: 21.49
A30: 0 | B30: 1500 | C30: 0.15 | D30: 0.39 | E30: 0.21 | F30: 9.49 | G30: 9.87 | H30: 9.69 | I30: 25.24 | J30: 31.93 | K30: 28.07 | L30: 35.28 | M30: 41.89 | N30: 37.98
A31: 1 | B31: 1500 | C31: 0.12 | D31: 0.27 | E31: 0.2 | F31: 22.67 | G31: 23.51 | H31: 22.96 | I31: 0 | J31: 0.02 | K31: 0 | L31: 22.85 | M31: 23.71 | N31: 23.16
A32: 0 | B32: 1600 | C32: 0.18 | D32: 0.35 | E32: 0.26 | F32: 10.57 | G32: 10.75 | H32: 10.65 | I32: 27.52 | J32: 33.87 | K32: 30.17 | L32: 38.36 | M32: 44.81 | N32: 41.08
A33: 1 | B33: 1600 | C33: 0.06 | D33: 0.21 | E33: 0.1 | F33: 24.31 | G33: 24.55 | H33: 24.37 | I33: 0 | J33: 0 | K33: 0 | L33: 24.37 | M33: 24.76 | N33: 24.47
A34: 0 | B34: 1700 | C34: 0.15 | D34: 0.34 | E34: 0.25 | F34: 11.08 | G34: 11.28 | H34: 11.16 | I34: 28.48 | J34: 34.82 | K34: 31.07 | L34: 39.86 | M34: 46.3 | N34: 42.48
A35: 1 | B35: 1700 | C35: 0.06 | D35: 0.22 | E35: 0.11 | F35: 25.84 | G35: 26.07 | H35: 25.93 | I35: 0 | J35: 0 | K35: 0 | L35: 25.93 | M35: 26.29 | N35: 26.04
A36: 0 | B36: 1800 | C36: 0.2 | D36: 0.37 | E36: 0.27 | F36: 11.8 | G36: 11.98 | H36: 11.88 | I36: 28.62 | J36: 36.48 | K36: 31.87 | L36: 40.77 | M36: 48.69 | N36: 44.02
A37: 1 | B37: 1800 | C37: 0.05 | D37: 0.1 | E37: 0.07 | F37: 27.62 | G37: 27.73 | H37: 27.67 | I37: 0 | J37: 0 | K37: 0 | L37: 27.68 | M37: 27.8 | N37: 27.75
A38: 0 | B38: 1900 | C38: 0.15 | D38: 0.35 | E38: 0.25 | F38: 12.44 | G38: 12.76 | H38: 12.6 | I38: 29.7 | J38: 42.47 | K38: 32.34 | L38: 42.47 | M38: 55.33 | N38: 45.18
A39: 1 | B39: 1900 | C39: 0.06 | D39: 0.24 | E39: 0.11 | F39: 29.06 | G39: 29.34 | H39: 29.16 | I39: 0 | J39: 0.01 | K39: 0 | L39: 29.12 | M39: 29.51 | N39: 29.27
A40: 0 | B40: 2000 | C40: 0.18 | D40: 0.36 | E40: 0.27 | F40: 12.84 | G40: 13.35 | H40: 13.11 | I40: 30.17 | J40: 37.84 | K40: 33.12 | L40: 43.6 | M40: 51.29 | N40: 46.5
...

Sheet Test_Data_9033_UI_16.0
A1: Core | B1: Rate | C1: ISRs (Min) | D1: ISRs (Max) | E1: ISRs (Max) | F1: TL (min) | G1: TL (max) | H1: TL (Mean) | I1: Other (Min) | J1: Other (Max) | K1: Other (Mean) | L1: Total (min) | M1: Total (max) | N1: Total (Mean) | Q1: Total (Mean)
A2: 0 | B2: 100 | C2: 0.16 | D2: 0.23 | E2: 0.18 | F2: 1.09 | G2: 1.15 | H2: 1.13 | I2: 17.5 | J2: 28.09 | K2: 20.88 | L2: 18.81 | M2: 29.42 | N2: 22.19 | P2: 100 | Q2: =AVERAGE(N2:N3) -> 11.965
A3: 1 | B3: 100 | C3: 0.13 | D3: 0.2 | E3: 0.16 | F3: 1.58 | G3: 1.59 | H3: 1.58 | I3: 0 | J3: 0 | K3: 0 | L3: 1.71 | M3: 1.79 | N3: 1.74 | P3: =P2+100 -> 200 | Q3: =AVERAGE(N4:N5) -> 13.025
A4: 0 | B4: 200 | C4: 0.17 | D4: 0.21 | E4: 0.19 | F4: 1.71 | G4: 1.75 | H4: 1.73 | I4: 17.94 | J4: 27.73 | K4: 20.89 | L4: 19.84 | M4: 29.69 | N4: 22.81 | P4: =P3+100 -> 300 | Q4: =AVERAGE(N6:N7) -> 14.49
A5: 1 | B5: 200 | C5: 0.14 | D5: 0.18 | E5: 0.16 | F5: 3.07 | G5: 3.09 | H5: 3.08 | I5: 0 | J5: 0 | K5: 0 | L5: 3.21 | M5: 3.26 | N5: 3.24 | P5: =P4+100 -> 400 | Q5: =AVERAGE(N8:N9) -> 15.865
A6: 0 | B6: 300 | C6: 0.1 | D6: 0.3 | E6: 0.19 | F6: 2.35 | G6: 2.44 | H6: 2.39 | I6: 18.3 | J6: 37.97 | K6: 21.52 | L6: 20.91 | M6: 40.58 | N6: 24.1 | P6: =P5+100 -> 500 | Q6: =AVERAGE(N10:N11) -> 17.415
A7: 1 | B7: 300 | C7: 0.13 | D7: 0.19 | E7: 0.16 | F7: 4.68 | G7: 4.83 | H7: 4.72 | I7: 0 | J7: 0 | K7: 0 | L7: 4.83 | M7: 4.99 | N7: 4.88 | P7: =P6+100 -> 600 | Q7: =AVERAGE(N12:N13) -> 18.66
A8: 0 | B8: 400 | C8: 0.15 | D8: 0.29 | E8: 0.21 | F8: 3 | G8: 3.09 | H8: 3.03 | I8: 18.48 | J8: 28.2 | K8: 22.14 | L8: 21.74 | M8: 31.48 | N8: 25.38 | P8: =P7+100 -> 700 | Q8: =AVERAGE(N14:N15) -> 19.98
A9: 1 | B9: 400 | C9: 0.12 | D9: 0.18 | E9: 0.16 | F9: 6.15 | G9: 6.33 | H9: 6.2 | I9: 0 | J9: 0 | K9: 0 | L9: 6.29 | M9: 6.48 | N9: 6.35 | P9: =P8+100 -> 800 | Q9: =AVERAGE(N16:N17) -> 22
A10: 0 | B10: 500 | C10: 0.15 | D10: 0.27 | E10: 0.21 | F10: 3.62 | G10: 3.76 | H10: 3.67 | I10: 19.47 | J10: 32.25 | K10: 23.05 | L10: 23.38 | M10: 36.17 | N10: 26.94 | P10: =P9+100 -> 900 | Q10: =AVERAGE(N18:N19) -> 22.5
A11: 1 | B11: 500 | C11: 0.13 | D11: 0.18 | E11: 0.16 | F11: 7.69 | G11: 7.87 | H11: 7.73 | I11: 0 | J11: 0 | K11: 0 | L11: 7.84 | M11: 8.03 | N11: 7.89 | P11: =P10+100 -> 1000 | Q11: =AVERAGE(N20:N21) -> 24.29
A12: 0 | B12: 600 | C12: 0.09 | D12: 0.32 | E12: 0.22 | F12: 4.23 | G12: 4.36 | H12: 4.29 | I12: 19.88 | J12: 30.75 | K12: 23.4 | L12: 24.38 | M12: 35.35 | N12: 27.9 | P12: =P11+100 -> 1100 | Q12: =AVERAGE(N22:N23) -> 26.345
A13: 1 | B13: 600 | C13: 0.13 | D13: 0.18 | E13: 0.16 | F13: 9.21 | G13: 9.38 | H13: 9.25 | I13: 0 | J13: 0 | K13: 0 | L13: 9.35 | M13: 9.54 | N13: 9.42 | P13: =P12+100 -> 1200 | Q13: =AVERAGE(N24:N25) -> 29.075
A14: 0 | B14: 700 | C14: 0.12 | D14: 0.29 | E14: 0.22 | F14: 4.91 | G14: 5.02 | H14: 4.96 | I14: 20.49 | J14: 29.33 | K14: 23.85 | L14: 25.65 | M14: 34.54 | N14: 29.03 | P14: =P13+100 -> 1300 | Q14: =AVERAGE(N26:N27) -> 29.335
A15: 1 | B15: 700 | C15: 0.13 | D15: 0.18 | E15: 0.16 | F15: 10.68 | G15: 10.85 | H15: 10.76 | I15: 0 | J15: 0 | K15: 0 | L15: 10.83 | M15: 11 | N15: 10.93 | P15: =P14+100 -> 1400 | Q15: =AVERAGE(N28:N29) -> 30.16
A16: 0 | B16: 800 | C16: 0.12 | D16: 0.32 | E16: 0.23 | F16: 5.61 | G16: 5.74 | H16: 5.67 | I16: 22.08 | J16: 30.95 | K16: 25.18 | L16: 27.95 | M16: 36.89 | N16: 31.08 | P16: =P15+100 -> 1500 | Q16: =AVERAGE(N30:N31) -> 32.115
A17: 1 | B17: 800 | C17: 0.13 | D17: 0.19 | E17: 0.17 | F17: 12.7 | G17: 12.9 | H17: 12.75 | I17: 0 | J17: 0 | K17: 0 | L17: 12.86 | M17: 13.07 | N17: 12.92 | P17: =P16+100 -> 1600 | Q17: =AVERAGE(N32:N33) -> 33.08
A18: 0 | B18: 900 | C18: 0.18 | D18: 0.29 | E18: 0.23 | F18: 6.15 | G18: 6.37 | H18: 6.2 | I18: 21.29 | J18: 42.76 | K18: 24.27 | L18: 27.7 | M18: 49.4 | N18: 30.71 | P18: =P17+100 -> 1700 | Q18: =AVERAGE(N34:N35) -> 34.345
A19: 1 | B19: 900 | C19: 0.14 | D19: 0.19 | E19: 0.17 | F19: 14.08 | G19: 14.16 | H19: 14.12 | I19: 0 | J19: 0 | K19: 0 | L19: 14.25 | M19: 14.34 | N19: 14.29 | P19: =P18+100 -> 1800 | Q19: =AVERAGE(N36:N37) -> 35.615
A20: 0 | B20: 1000 | C20: 0.17 | D20: 0.35 | E20: 0.25 | F20: 6.79 | G20: 7.03 | H20: 6.87 | I20: 22.19 | J20: 39.97 | K20: 25.55 | L20: 29.22 | M20: 47.25 | N20: 32.67 | P20: =P19+100 -> 1900 | Q20: =AVERAGE(N38:N39) -> 37.3
A21: 1 | B21: 1000 | C21: 0.1 | D21: 0.18 | E21: 0.15 | F21: 15.7 | G21: 15.89 | H21: 15.76 | I21: 0 | J21: 0 | K21: 0 | L21: 15.81 | M21: 16.04 | N21: 15.91 | P21: =P20+100 -> 2000 | Q21: =AVERAGE(N40:N41) -> 38.915
A22: 0 | B22: 1100 | C22: 0.11 | D22: 0.3 | E22: 0.23 | F22: 7.48 | G22: 7.64 | H22: 7.56 | I22: 24.1 | J22: 35.76 | K22: 27.36 | L22: 31.85 | M22: 43.55 | N22: 35.15 | P22: =P21+100 -> 2100 | Q22: =AVERAGE(N42:N43) -> #DIV/0!
A23: 1 | B23: 1100 | C23: 0.11 | D23: 0.15 | E23: 0.13 | F23: 17.36 | G23: 17.55 | H23: 17.42 | I23: 0 | J23: 0 | K23: 0 | L23: 17.48 | M23: 17.68 | N23: 17.54 | P23: =P22+100 -> 2200 | Q23: =AVERAGE(N44:N45) -> #DIV/0!
A24: 0 | B24: 1200 | C24: 0.17 | D24: 0.24 | E24: 0.21 | F24: 8.18 | G24: 8.71 | H24: 8.26 | I24: 25.43 | J24: 84.3 | K24: 30.57 | L24: 33.87 | M24: 93.18 | N24: 39.03 | P24: =P23+100 -> 2300 | Q24: =AVERAGE(N46:N47) -> #DIV/0!
A25: 1 | B25: 1200 | C25: 0.12 | D25: 0.17 | E25: 0.14 | F25: 18.95 | G25: 19.04 | H25: 18.98 | I25: 0 | J25: 0 | K25: 0 | L25: 19.08 | M25: 19.18 | N25: 19.12 | P25: =P24+100 -> 2400 | Q25: =AVERAGE(N48:N49) -> #DIV/0!
A26: 0 | B26: 1300 | C26: 0.13 | D26: 0.25 | E26: 0.19 | F26: 8.72 | G26: 9.04 | H26: 8.84 | I26: 24.81 | J26: 55.43 | K26: 28.93 | L26: 33.74 | M26: 64.64 | N26: 37.95 | P26: =P25+100 -> 2500 | Q26: =AVERAGE(N50:N51) -> #DIV/0!
A27: 1 | B27: 1300 | C27: 0.11 | D27: 0.15 | E27: 0.13 | F27: 20.51 | G27: 20.71 | H27: 20.59 | I27: 0 | J27: 0 | K27: 0 | L27: 20.62 | M27: 20.86 | N27: 20.72 | P27: =P26+100 -> 2600 | Q27: =AVERAGE(N52:N53) -> #DIV/0!
A28: 0 | B28: 1400 | C28: 0.12 | D28: 0.29 | E28: 0.2 | F28: 9.53 | G28: 9.76 | H28: 9.66 | I28: 25.19 | J28: 34.4 | K28: 28.17 | L28: 35.03 | M28: 44.4 | N28: 38.03 | P28: =P27+100 -> 2700 | Q28: =AVERAGE(N54:N55) -> #DIV/0!
A29: 1 | B29: 1400 | C29: 0.11 | D29: 0.15 | E29: 0.13 | F29: 22.09 | G29: 22.29 | H29: 22.16 | I29: 0 | J29: 0 | K29: 0 | L29: 22.21 | M29: 22.43 | N29: 22.29 | P29: =P28+100 -> 2800 | Q29: =AVERAGE(N56:N57) -> #DIV/0!
A30: 0 | B30: 1500 | C30: 0.09 | D30: 0.31 | E30: 0.19 | F30: 9.93 | G30: 10.5 | H30: 10.17 | I30: 27.14 | J30: 53.34 | K30: 30.06 | L30: 37.43 | M30: 64 | N30: 40.43 | P30: 2900 | Q30: =AVERAGE(N58:N59) -> #DIV/0!
A31: 1 | B31: 1500 | C31: 0.1 | D31: 0.18 | E31: 0.14 | F31: 23.58 | G31: 23.86 | H31: 23.66 | I31: 0 | J31: 0 | K31: 0 | L31: 23.7 | M31: 24.01 | N31: 23.8 | P31: 3000 | Q31: =AVERAGE(N60:N61) -> #DIV/0!
A32: 0 | B32: 1600 | C32: 0.13 | D32: 0.32 | E32: 0.2 | F32: 10.77 | G32: 11.08 | H32: 10.91 | I32: 25.88 | J32: 36.95 | K32: 29.45 | L32: 36.94 | M32: 48.14 | N32: 40.56
A33: 1 | B33: 1600 | C33: 0.11 | D33: 0.17 | E33: 0.14 | F33: 25.34 | G33: 25.61 | H33: 25.46 | I33: 0 | J33: 0 | K33: 0 | L33: 25.47 | M33: 25.76 | N33: 25.6
A34: 0 | B34: 1700 | C34: 0.1 | D34: 0.31 | E34: 0.19 | F34: 11.4 | G34: 11.73 | H34: 11.53 | I34: 26.68 | J34: 52.65 | K34: 30.4 | L34: 38.35 | M34: 64.55 | N34: 42.13
A35: 1 | B35: 1700 | C35: 0.11 | D35: 0.18 | E35: 0.15 | F35: 26.3 | G35: 26.54 | H35: 26.41 | I35: 0 | J35: 0 | K35: 0 | L35: 26.45 | M35: 26.7 | N35: 26.56
