Workbook
Name _8108_1: rawdata_8108!$V$28:$AA$28
Name test: rawdata_8108!$V$30:$AA$53

Sheet 8108 Regression
B1: Average CPU Usage (%)
A2: Loop Rate (Hz) | B2: 2012 | C2: 2013 | D2: 2014b | E2: 2014rc | F2: 2015b26 | G2: 2015b35 | H2: 2015b64 | I2: 2015rc1 | J2: 2016 | K2: 2017a17 | L2: 2017b8 | M2: 2017 | N2: 2018b13 | O2: 2018 | P2: =rawdata_8108!V58 -> 2019 | Q2: =rawdata_8108!H86 -> 2020 B3 | R2: =rawdata_8108!O86 -> 2020 B78
A3: 500 | B3: 3.47 | C3: 3.58 | D3: 3.6 | E3: 3.6 | F3: 3.72 | G3: 3.69 | H3: 3.71 | I3: 3.74 | J3: 3.6 | K3: 3.66 | L3: 3.61 | M3: 3.63 | N3: 3.59 | O3: 3.64 | P3: =rawdata_8108!AA60 -> 3.65 | Q3: =rawdata_8108!M88 -> 3.68 | R3: =rawdata_8108!T88 -> 3.64
A4: =A3+500 -> 1000 | B4: 6.93 | C4: 7.07 | D4: 7.11 | E4: 7.14 | F4: 7.37 | G4: 7.33 | H4: 7.34 | I4: 7.37 | J4: 7.17 | K4: 7.18 | L4: 7.15 | M4: 7.18 | N4: 7.1 | O4: 7.17 | P4: =rawdata_8108!AA61 -> 7.19 | Q4: =rawdata_8108!M89 -> 7.33 | R4: =rawdata_8108!T89 -> 7.24
A5: =A4+500 -> 1500 | B5: 10.32 | C5: 10.63 | D5: 10.67 | E5: 10.69 | F5: 11.05 | G5: 11 | H5: 11.01 | I5: 11.11 | J5: 10.77 | K5: 10.81 | L5: 10.78 | M5: 10.78 | N5: 10.69 | O5: 10.75 | P5: =rawdata_8108!AA62 -> 10.78 | Q5: =rawdata_8108!M90 -> 10.98 | R5: =rawdata_8108!T90 -> 10.83
A6: =A5+500 -> 2000 | B6: 13.76 | C6: 14.15 | D6: 14.22 | E6: 14.23 | F6: 14.78 | G6: 14.62 | H6: 14.69 | I6: 14.76 | J6: 14.37 | K6: 14.37 | L6: 14.34 | M6: 14.42 | N6: 14.2 | O6: 14.37 | P6: =rawdata_8108!AA63 -> 14.39 | Q6: =rawdata_8108!M91 -> 14.71 | R6: =rawdata_8108!T91 -> 14.47
A7: =A6+500 -> 2500 | B7: 17.2 | C7: 17.68 | D7: 17.79 | E7: 17.84 | F7: 18.45 | G7: 18.3 | H7: 18.38 | I7: 18.47 | J7: 17.97 | K7: 17.99 | L7: 17.96 | M7: 18.04 | N7: 17.88 | O7: 17.98 | P7: =rawdata_8108!AA64 -> 18 | Q7: =rawdata_8108!M92 -> 18.32 | R7: =rawdata_8108!T92 -> 18.09
A8: =A7+500 -> 3000 | B8: 20.67 | C8: 21.27 | D8: 21.38 | E8: 21.45 | F8: 22.14 | G8: 21.96 | H8: 22.12 | I8: 22.16 | J8: 21.61 | K8: 21.63 | L8: 21.48 | M8: 21.63 | N8: 21.37 | O8: 21.6 | P8: =rawdata_8108!AA65 -> 21.64 | Q8: =rawdata_8108!M93 -> 22.01 | R8: =rawdata_8108!T93 -> 21.72
A9: =A8+500 -> 3500 | B9: 24.04 | C9: 24.76 | D9: 24.96 | E9: 24.98 | F9: 25.92 | G9: 25.64 | H9: 25.77 | I9: 25.83 | J9: 25.09 | K9: 25.23 | L9: 25.16 | M9: 25.24 | N9: 24.88 | O9: 25.26 | P9: =rawdata_8108!AA66 -> 25.21 | Q9: =rawdata_8108!M94 -> 25.6 | R9: =rawdata_8108!T94 -> 25.29
A10: =A9+500 -> 4000 | B10: 27.5 | C10: 28.27 | D10: 28.61 | E10: 28.51 | F10: 29.56 | G10: 29.29 | H10: 29.41 | I10: 29.51 | J10: 28.63 | K10: 28.64 | L10: 28.57 | M10: 28.76 | N10: 28.51 | O10: 28.75 | P10: =rawdata_8108!AA67 -> 28.72 | Q10: =rawdata_8108!M95 -> 29.16 | R10: =rawdata_8108!T95 -> 28.91
A11: =A10+500 -> 4500 | B11: 30.96 | C11: 31.86 | D11: 32.07 | E11: 32.17 | F11: 33.19 | G11: 32.94 | H11: 33.05 | I11: 33.23 | J11: 32.25 | K11: 32.27 | L11: 32.18 | M11: 32.34 | N11: 32.04 | O11: 32.26 | P11: =rawdata_8108!AA68 -> 32.39 | Q11: =rawdata_8108!M96 -> 32.89 | R11: =rawdata_8108!T96 -> 32.63
A12: =A11+500 -> 5000 | B12: 34.39 | C12: 35.33 | D12: 35.69 | E12: 35.64 | F12: 36.97 | G12: 36.62 | H12: 36.74 | I12: 36.91 | J12: 35.98 | K12: 35.9 | L12: 35.76 | M12: 35.88 | N12: 35.69 | O12: 35.75 | P12: =rawdata_8108!AA69 -> 35.9 | Q12: =rawdata_8108!M97 -> 36.46 | R12: =rawdata_8108!T97 -> 36.16
A13: =A12+500 -> 5500 | B13: 37.86 | C13: 38.97 | D13: 39.23 | E13: 39.2 | F13: 40.69 | G13: 40.19 | H13: 40.54 | I13: 40.64 | J13: 39.48 | K13: 39.43 | L13: 39.41 | M13: 39.51 | N13: 39.18 | O13: 39.5 | P13: =rawdata_8108!AA70 -> 39.52 | Q13: =rawdata_8108!M98 -> 40.21 | R13: =rawdata_8108!T98 -> 39.65
A14: =A13+500 -> 6000 | B14: 41.36 | C14: 42.51 | D14: 42.85 | E14: 42.88 | F14: 44.41 | G14: 43.88 | H14: 44.09 | I14: 44.22 | J14: 43.02 | K14: 43 | L14: 42.95 | M14: 43.16 | N14: 42.75 | O14: 43.04 | P14: =rawdata_8108!AA71 -> 43.04 | Q14: =rawdata_8108!M99 -> 43.8 | R14: =rawdata_8108!T99 -> 43.3
A15: =A14+500 -> 6500 | B15: 44.7 | C15: 46.03 | D15: 46.37 | E15: 46.45 | F15: 48.05 | G15: 47.59 | H15: 47.88 | I15: 47.99 | J15: 46.57 | K15: 46.57 | L15: 46.45 | M15: 46.82 | N15: 46.32 | O15: 46.59 | P15: =rawdata_8108!AA72 -> 46.6 | Q15: =rawdata_8108!M100 -> 47.45 | R15: =rawdata_8108!T100 -> 46.87
... A24: =A23+500 -> 11000 | B24: 75.78 | C24: 78.07 | D24: 78.66 | E24: 78.62 | F24: 81.62 | G24: 80.51 | H24: 81.11 | I24: 81.47 | J24: 78.9 | K24: 78.89 | L24: 78.72 | M24: 79.14 | N24: 78.79 | O24: 78.97 | P24: =rawdata_8108!AA81 -> 79.1 | Q24: =rawdata_8108!M109 -> 80.43 | R24: =rawdata_8108!T109 -> 79.62
A25: =A24+500 -> 11500 | B25: 79.23 | C25: 81.72 | D25: 82.2 | E25: 82.1 | F25: 85.35 | G25: 84.31 | H25: 84.92 | J25: 82.33 | K25: 82.63 | L25: 82.27 | M25: 82.7 | O25: 82.52 | P25: =rawdata_8108!AA82 -> 82.71 | Q25: =rawdata_8108!M110 -> 84.1 | R25: =rawdata_8108!T110 -> 83.07
A26: =A25+500 -> 12000 | B26: 82.66 | C26: 85.28 | D26: 85.8 | E26: 85.76 | G26: 88.39 | J26: 86.03 | K26: 86.3 | L26: 85.96 | O26: 86.27 | Q26: =rawdata_8108!M111 -> 87.82 | R26: =rawdata_8108!T111 -> 86.98
A27: =A26+500 -> 12500 | C27: 88.88 | D27: 89.48 | E27: 89.45 | G27: 91.75 | J27: 89.74 | K27: 89.63 | L27: 89.46 | O27: 90.01 | Q27: =rawdata_8108!M112 -> 91.82 | R27: =rawdata_8108!T112 -> 90.35
D28: 0.2

Sheet rawdata_8108
A1: 2015b26 | H1: 2015b35 | O1: 2015rc1 | V1: 2016
A2: Sleep | B2: Rate | C2: ISRs | D2: TL | E2: Other | F2: Total | H2: Sleep | I2: Rate | J2: ISRs | K2: TL | L2: Other | M2: Total | O2: Sleep | P2: Rate | Q2: ISRs | R2: TL | S2: Other | T2: Total | V2: Sleep | W2: Rate | X2: ISRs | Y2: TL | Z2: Other | AA2: Total
A3: 0 | B3: 500 | C3: 0 | D3: 3.72 | E3: 0 | F3: 3.72 | H3: 0 | I3: 500 | J3: 0 | K3: 3.69 | L3: 0 | M3: 3.69 | O3: 0 | P3: 500 | Q3: 0 | R3: 3.74 | S3: 0 | T3: 3.74 | V3: 0 | W3: 500 | X3: 0 | Y3: 3.6 | Z3: 0 | AA3: 3.6
A4: 0 | B4: 1000 | C4: 0 | D4: 7.37 | E4: 0 | F4: 7.37 | H4: 0 | I4: 1000 | J4: 0 | K4: 7.33 | L4: 0 | M4: 7.33 | O4: 0 | P4: 1000 | Q4: 0 | R4: 7.37 | S4: 0 | T4: 7.37 | V4: 0 | W4: 1000 | X4: 0 | Y4: 7.17 | Z4: 0 | AA4: 7.17
A5: 0 | B5: 1500 | C5: 0 | D5: 11.05 | E5: 0 | F5: 11.05 | H5: 0 | I5: 1500 | J5: 0 | K5: 11 | L5: 0 | M5: 11 | O5: 0 | P5: 1500 | Q5: 0 | R5: 11.11 | S5: 0 | T5: 11.11 | V5: 0 | W5: 1500 | X5: 0 | Y5: 10.77 | Z5: 0 | AA5: 10.77
A6: 0 | B6: 2000 | C6: 0 | D6: 14.78 | E6: 0 | F6: 14.78 | H6: 0 | I6: 2000 | J6: 0 | K6: 14.62 | L6: 0 | M6: 14.62 | O6: 0 | P6: 2000 | Q6: 0 | R6: 14.76 | S6: 0 | T6: 14.76 | V6: 0 | W6: 2000 | X6: 0 | Y6: 14.37 | Z6: 0 | AA6: 14.37
A7: 0 | B7: 2500 | C7: 0 | D7: 18.45 | E7: 0 | F7: 18.45 | H7: 0 | I7: 2500 | J7: 0 | K7: 18.3 | L7: 0 | M7: 18.3 | O7: 0 | P7: 2500 | Q7: 0 | R7: 18.47 | S7: 0 | T7: 18.47 | V7: 0 | W7: 2500 | X7: 0 | Y7: 17.97 | Z7: 0 | AA7: 17.97
A8: 0 | B8: 3000 | C8: 0 | D8: 22.14 | E8: 0 | F8: 22.14 | H8: 0 | I8: 3000 | J8: 0 | K8: 21.96 | L8: 0 | M8: 21.96 | O8: 0 | P8: 3000 | Q8: 0 | R8: 22.16 | S8: 0 | T8: 22.16 | V8: 0 | W8: 3000 | X8: 0 | Y8: 21.61 | Z8: 0 | AA8: 21.61
A9: 0 | B9: 3500 | C9: 0 | D9: 25.92 | E9: 0 | F9: 25.92 | H9: 0 | I9: 3500 | J9: 0 | K9: 25.64 | L9: 0 | M9: 25.64 | O9: 0 | P9: 3500 | Q9: 0 | R9: 25.83 | S9: 0 | T9: 25.83 | V9: 0 | W9: 3500 | X9: 0 | Y9: 25.08 | Z9: 0 | AA9: 25.09
A10: 0 | B10: 4000 | C10: 0 | D10: 29.56 | E10: 0 | F10: 29.56 | H10: 0 | I10: 4000 | J10: 0 | K10: 29.29 | L10: 0 | M10: 29.29 | O10: 0 | P10: 4000 | Q10: 0 | R10: 29.5 | S10: 0 | T10: 29.51 | V10: 0 | W10: 4000 | X10: 0 | Y10: 28.63 | Z10: 0 | AA10: 28.63
A11: 0 | B11: 4500 | C11: 0 | D11: 33.19 | E11: 0 | F11: 33.19 | H11: 0 | I11: 4500 | J11: 0 | K11: 32.94 | L11: 0 | M11: 32.94 | O11: 0 | P11: 4500 | Q11: 0 | R11: 33.23 | S11: 0 | T11: 33.23 | V11: 0 | W11: 4500 | X11: 0 | Y11: 32.25 | Z11: 0 | AA11: 32.25
A12: 0 | B12: 5000 | C12: 0 | D12: 36.97 | E12: 0 | F12: 36.97 | H12: 0 | I12: 5000 | J12: 0 | K12: 36.61 | L12: 0 | M12: 36.62 | O12: 0 | P12: 5000 | Q12: 0 | R12: 36.91 | S12: 0 | T12: 36.91 | V12: 0 | W12: 5000 | X12: 0 | Y12: 35.98 | Z12: 0 | AA12: 35.98
A13: 0 | B13: 5500 | C13: 0 | D13: 40.69 | E13: 0 | F13: 40.69 | H13: 0 | I13: 5500 | J13: 0 | K13: 40.19 | L13: 0 | M13: 40.19 | O13: 0 | P13: 5500 | Q13: 0 | R13: 40.64 | S13: 0 | T13: 40.64 | V13: 0 | W13: 5500 | X13: 0 | Y13: 39.48 | Z13: 0 | AA13: 39.48
A14: 0 | B14: 6000 | C14: 0 | D14: 44.41 | E14: 0 | F14: 44.41 | H14: 0 | I14: 6000 | J14: 0 | K14: 43.88 | L14: 0 | M14: 43.88 | O14: 0 | P14: 6000 | Q14: 0 | R14: 44.22 | S14: 0 | T14: 44.22 | V14: 0 | W14: 6000 | X14: 0 | Y14: 43.02 | Z14: 0 | AA14: 43.02
... A24: 0 | B24: 11000 | C24: 0 | D24: 81.62 | E24: 0 | F24: 81.62 | H24: 0 | I24: 11000 | J24: 0 | K24: 80.51 | L24: 0 | M24: 80.51 | O24: 0 | P24: 11000 | Q24: 0 | R24: 81.47 | S24: 0 | T24: 81.47 | V24: 0 | W24: 11000 | X24: 0 | Y24: 78.9 | Z24: 0 | AA24: 78.9
A25: 0 | B25: 11500 | C25: 0 | D25: 85.34 | E25: 0 | F25: 85.35 | H25: 0 | I25: 11500 | J25: 0 | K25: 84.31 | L25: 0 | M25: 84.31 | V25: 0 | W25: 11500 | X25: 0 | Y25: 82.33 | Z25: 0 | AA25: 82.33
H26: 0 | I26: 12000 | J26: 0 | K26: 88.39 | L26: 0 | M26: 88.39 | V26: 0 | W26: 12000 | X26: 0 | Y26: 86.03 | Z26: 0 | AA26: 86.03
H27: 0 | I27: 12500 | J27: 0 | K27: 91.75 | L27: 0 | M27: 91.75 | V27: 0 | W27: 12500 | X27: 0 | Y27: 89.74 | Z27: 0 | AA27: 89.74
A29: Software | H29: 2017a17 | O29: 2017b8 | V29: 2017
H30: Sleep | I30: Rate | J30: ISRs | K30: TL | L30: Other | M30: Total | O30: Sleep | P30: Rate | Q30: ISRs | R30: TL | S30: Other | T30: Total | V30: Sleep | W30: Rate | X30: ISRs | Y30: TL | Z30: Other | AA30: Total
H31: 0 | I31: 500 | J31: 0 | K31: 3.66 | L31: 0 | M31: 3.66 | O31: 0 | P31: 500 | Q31: 0 | R31: 3.61 | S31: 0 | T31: 3.61 | V31: 0 | W31: 500 | X31: 0 | Y31: 3.63 | Z31: 0 | AA31: 3.63
H32: 0 | I32: 1000 | J32: 0 | K32: 7.18 | L32: 0 | M32: 7.18 | O32: 0 | P32: 1000 | Q32: 0 | R32: 7.15 | S32: 0 | T32: 7.15 | V32: 0 | W32: 1000 | X32: 0 | Y32: 7.18 | Z32: 0 | AA32: 7.18
H33: 0 | I33: 1500 | J33: 0 | K33: 10.81 | L33: 0 | M33: 10.81 | O33: 0 | P33: 1500 | Q33: 0 | R33: 10.78 | S33: 0 | T33: 10.78 | V33: 0 | W33: 1500 | X33: 0 | Y33: 10.78 | Z33: 0 | AA33: 10.78
H34: 0 | I34: 2000 | J34: 0 | K34: 14.37 | L34: 0 | M34: 14.37 | O34: 0 | P34: 2000 | Q34: 0 | R34: 14.34 | S34: 0 | T34: 14.34 | V34: 0 | W34: 2000 | X34: 0 | Y34: 14.42 | Z34: 0 | AA34: 14.42
H35: 0 | I35: 2500 | J35: 0 | K35: 17.99 | L35: 0 | M35: 17.99 | O35: 0 | P35: 2500 | Q35: 0 | R35: 17.96 | S35: 0 | T35: 17.96 | V35: 0 | W35: 2500 | X35: 0 | Y35: 18.04 | Z35: 0 | AA35: 18.04
H36: 0 | I36: 3000 | J36: 0 | K36: 21.63 | L36: 0 | M36: 21.63 | O36: 0 | P36: 3000 | Q36: 0 | R36: 21.48 | S36: 0 | T36: 21.48 | V36: 0 | W36: 3000 | X36: 0 | Y36: 21.63 | Z36: 0 | AA36: 21.63
H37: 0 | I37: 3500 | J37: 0 | K37: 25.23 | L37: 0 | M37: 25.23 | O37: 0 | P37: 3500 | Q37: 0 | R37: 25.16 | S37: 0 | T37: 25.16 | V37: 0 | W37: 3500 | X37: 0 | Y37: 25.24 | Z37: 0 | AA37: 25.24
H38: 0 | I38: 4000 | J38: 0 | K38: 28.64 | L38: 0 | M38: 28.64 | O38: 0 | P38: 4000 | Q38: 0 | R38: 28.57 | S38: 0 | T38: 28.57 | V38: 0 | W38: 4000 | X38: 0 | Y38: 28.76 | Z38: 0 | AA38: 28.76
H39: 0 | I39: 4500 | J39: 0 | K39: 32.27 | L39: 0 | M39: 32.27 | O39: 0 | P39: 4500 | Q39: 0 | R39: 32.18 | S39: 0 | T39: 32.18 | V39: 0 | W39: 4500 | X39: 0 | Y39: 32.33 | Z39: 0 | AA39: 32.34
H40: 0 | I40: 5000 | J40: 0 | K40: 35.9 | L40: 0 | M40: 35.9 | O40: 0 | P40: 5000 | Q40: 0 | R40: 35.75 | S40: 0 | T40: 35.76 | V40: 0 | W40: 5000 | X40: 0 | Y40: 35.88 | Z40: 0 | AA40: 35.88
H41: 0 | I41: 5500 | J41: 0 | K41: 39.42 | L41: 0 | M41: 39.43 | O41: 0 | P41: 5500 | Q41: 0 | R41: 39.41 | S41: 0 | T41: 39.41 | V41: 0 | W41: 5500 | X41: 0 | Y41: 39.51 | Z41: 0 | AA41: 39.51
H42: 0 | I42: 6000 | J42: 0 | K42: 43 | L42: 0 | M42: 43 | O42: 0 | P42: 6000 | Q42: 0 | R42: 42.95 | S42: 0 | T42: 42.95 | V42: 0 | W42: 6000 | X42: 0 | Y42: 43.16 | Z42: 0 | AA42: 43.16
... H53: 0 | I53: 11500 | J53: 0 | K53: 82.62 | L53: 0 | M53: 82.63 | O53: 0 | P53: 11500 | Q53: 0 | R53: 82.27 | S53: 0 | T53: 82.27 | V53: 0 | W53: 11500 | X53: 0 | Y53: 82.7 | Z53: 0 | AA53: 82.7
H54: 0 | I54: 12000 | J54: 0.01 | K54: 86.29 | L54: 0 | M54: 86.3 | O54: 0 | P54: 12000 | Q54: 0 | R54: 85.96 | S54: 0 | T54: 85.96
H55: 0 | I55: 12500 | J55: 0 | K55: 89.63 | L55: 0 | M55: 89.63 | O55: 0 | P55: 12500 | Q55: 0 | R55: 89.46 | S55: 0 | T55: 89.46
O56: 0 | P56: 13000 | Q56: 0 | R56: 0 | S56: 0 | T56: 0
H58: 2018b13 | O58: 2018 | V58: 2019
H59: Sleep | I59: Rate | J59: ISRs | K59: TL | L59: Other | M59: Total | O59: Sleep | P59: Rate | Q59: ISRs | R59: TL | S59: Other | T59: Total | V59: Sleep | W59: Rate | X59: ISRs | Y59: TL | Z59: Other | AA59: Total
H60: 0 | I60: 500 | J60: 0 | K60: 3.59 | L60: 0 | M60: 3.59 | O60: 0 | P60: 500 | Q60: 0 | R60: 3.64 | S60: 0 | T60: 3.64 | V60: 0 | W60: 500 | X60: 0 | Y60: 3.65 | Z60: 0 | AA60: 3.65
H61: 0 | I61: 1000 | J61: 0 | K61: 7.1 | L61: 0 | M61: 7.1 | O61: 0 | P61: 1000 | Q61: 0 | R61: 7.17 | S61: 0 | T61: 7.17 | V61: 0 | W61: 1000 | X61: 0 | Y61: 7.19 | Z61: 0 | AA61: 7.19
...
