Workbook
Name _9068: Test_Data_2017a17!$A$1:$N$61

Sheet 9068 Regression
B1: Average CPU Usage (%)
A2: Loop Rate (Hz) | B2: 2012 | C2: 2013 | D2: 2014a | E2: 2014rc | F2: 2014 | G2: 2015b64 | H2: 2015rc1 | I2: 2016b55 | J2: 2016b59 | K2: 2016 | L2: 2017a17 | M2: 2017b6 | N2: 2017 | O2: 2018b10 | P2: 2018rc1 | Q2: 2019b27 | R2: 2019 | S2: ='20.0b14 mean calculation'!P1 -> 2020 b14 | T2: ='20.0b78 mean calculation'!P1 -> 2020 b78
A3: 100 | B3: 4.975 | C3: 5.5 | D3: 5.305 | E3: 10.88 | F3: 8.14 | G3: 7.665 | H3: 9.39 | I3: 8.835 | J3: 7.955 | K3: 7.305 | L3: 9.295 | M3: 7.915 | N3: 13.75 | O3: 8.755 | P3: 8.56 | Q3: 9.215 | R3: 9.585 | S3: ='20.0b14 mean calculation'!Q2 -> 10.4 | T3: ='20.0b78 mean calculation'!Q2 -> 8.765
A4: =A3+100 -> 200 | B4: 8.27 | C4: 8.495 | D4: 7.95 | E4: 11.56 | F4: 12.2 | G4: 9.23 | H4: 9.82 | I4: 10.06 | J4: 9.92 | K4: 9.75 | L4: 11.105 | M4: 9.725 | N4: 10.285 | O4: 9.17 | P4: 9.325 | Q4: 10.115 | R4: 10.15 | S4: ='20.0b14 mean calculation'!Q3 -> 10.81 | T4: ='20.0b78 mean calculation'!Q3 -> 10.18
A5: =A4+100 -> 300 | B5: 10.75 | C5: 11.595 | D5: 10.755 | E5: 14.355 | F5: 14.085 | G5: 11.25 | H5: 11.595 | I5: 12.44 | J5: 12.1 | K5: 11.72 | L5: 14.01 | M5: 11.98 | N5: 12.245 | O5: 11.295 | P5: 11.525 | Q5: 12.245 | R5: 12.33 | S5: ='20.0b14 mean calculation'!Q4 -> 13.03 | T5: ='20.0b78 mean calculation'!Q4 -> 12.33
A6: =A5+100 -> 400 | B6: 14.605 | C6: 14.83 | D6: 13.615 | E6: 17.925 | F6: 16.46 | G6: 13.285 | H6: 13.7 | I6: 14.695 | J6: 14.78 | K6: 13.63 | L6: 16.12 | M6: 14.2 | N6: 14.155 | O6: 13.27 | P6: 13.275 | Q6: 14.22 | R6: 14.435 | S6: ='20.0b14 mean calculation'!Q5 -> 15.405 | T6: ='20.0b78 mean calculation'!Q5 -> 14.315
A7: =A6+100 -> 500 | B7: 17.805 | C7: 17.975 | D7: 16.58 | E7: 18.94 | F7: 17.965 | G7: 16.775 | H7: 15.84 | I7: 17.12 | J7: 16.8 | K7: 17.04 | L7: 18.305 | M7: 16.505 | N7: 16.44 | O7: 16.005 | P7: 16.605 | Q7: 16.78 | R7: 17.09 | S7: ='20.0b14 mean calculation'!Q6 -> 17.975 | T7: ='20.0b78 mean calculation'!Q6 -> 16.43
A8: =A7+100 -> 600 | B8: 21.04 | C8: 19.59 | D8: 18.995 | E8: 22.6 | F8: 20.245 | G8: 17.775 | H8: 17.995 | I8: 19.35 | J8: 20.77 | K8: 19.115 | L8: 20.955 | M8: 18.835 | N8: 18.71 | O8: 18.145 | P8: 18.22 | Q8: 19.255 | R8: 19.345 | S8: ='20.0b14 mean calculation'!Q7 -> 20.875 | T8: ='20.0b78 mean calculation'!Q7 -> 19.535
A9: =A8+100 -> 700 | B9: 24.195 | C9: 24.23 | D9: 21.715 | E9: 23.46 | F9: 22.79 | G9: 19.83 | H9: 20.22 | I9: 22.65 | J9: 23.14 | K9: 20.69 | L9: 22.29 | M9: 20.985 | N9: 20.745 | O9: 20.655 | P9: 21.385 | Q9: 21.595 | R9: 21.745 | S9: ='20.0b14 mean calculation'!Q8 -> 22.26 | T9: ='20.0b78 mean calculation'!Q8 -> 22.09
A10: =A9+100 -> 800 | B10: 27.605 | C10: 27.37 | D10: 23.42 | E10: 27.285 | F10: 25.43 | G10: 22.425 | H10: 22.22 | I10: 24.14 | J10: 23.79 | K10: 23.115 | L10: 24.935 | M10: 23.17 | N10: 23.205 | O10: 22.485 | P10: 22.78 | Q10: 23.755 | R10: 23.77 | S10: ='20.0b14 mean calculation'!Q9 -> 24.88 | T10: ='20.0b78 mean calculation'!Q9 -> 24.2
A11: =A10+100 -> 900 | B11: 29.565 | C11: 30.305 | D11: 27.545 | E11: 29.435 | F11: 27.535 | G11: 24.06 | H11: 24.4 | I11: 26.51 | J11: 26.3 | K11: 25.175 | L11: 26.46 | M11: 25.365 | N11: 25.48 | O11: 24.48 | P11: 25.45 | Q11: 26.075 | R11: 26 | S11: ='20.0b14 mean calculation'!Q10 -> 26.71 | T11: ='20.0b78 mean calculation'!Q10 -> 26.46
A12: =A11+100 -> 1000 | B12: 30.525 | C12: 30.115 | D12: 30.295 | E12: 32.18 | F12: 30.2 | G12: 25.885 | H12: 26.495 | I12: 28.97 | J12: 28.37 | K12: 26.74 | L12: 28.755 | M12: 27.41 | N12: 27.355 | O12: 26.625 | P12: 27.565 | Q12: 28.27 | R12: 28.16 | S12: ='20.0b14 mean calculation'!Q11 -> 28.935 | T12: ='20.0b78 mean calculation'!Q11 -> 28.27
A13: =A12+100 -> 1100 | B13: 32.01 | C13: 32.74 | D13: 29.14 | E13: 32.47 | F13: 33.36 | G13: 28.435 | H13: 30.25 | I13: 31.07 | J13: 30.855 | K13: 29.85 | L13: 30.93 | M13: 29.83 | N13: 29.85 | O13: 28.85 | P13: 29.52 | Q13: 29.995 | R13: 30.22 | S13: ='20.0b14 mean calculation'!Q12 -> 31.05 | T13: ='20.0b78 mean calculation'!Q12 -> 30.605
A14: =A13+100 -> 1200 | B14: 34.925 | C14: 35.505 | D14: 32.115 | E14: 37.365 | F14: 36.03 | G14: 30.765 | H14: 30.93 | I14: 33.895 | J14: 35.215 | K14: 32.01 | L14: 33.705 | M14: 32.155 | N14: 31.965 | O14: 31.21 | P14: 31.995 | Q14: 32.27 | R14: 32.775 | S14: ='20.0b14 mean calculation'!Q13 -> 33.395 | T14: ='20.0b78 mean calculation'!Q13 -> 32.835
A15: =A14+100 -> 1300 | B15: 37.55 | C15: 37.935 | D15: 34.68 | E15: 39.61 | F15: 37.975 | G15: 32.75 | H15: 34.63 | I15: 36.04 | J15: 38.455 | K15: 33.82 | L15: 36.01 | M15: 33.5 | N15: 34.155 | O15: 33.415 | P15: 33.71 | Q15: 34.39 | R15: 35.215 | S15: ='20.0b14 mean calculation'!Q14 -> 35.61 | T15: ='20.0b78 mean calculation'!Q14 -> 35.34
... A18: =A17+100 -> 1600 | B18: 46.125 | C18: 46.905 | D18: 41.27 | E18: 48.33 | F18: 46.52 | G18: 38.345 | H18: 41.41 | I18: 43.965 | J18: 43.06 | K18: 41.445 | L18: 42.675 | M18: 41.01 | N18: 43.08 | O18: 40.52 | P18: 42.285 | Q18: 40.92 | R18: 42.19 | S18: ='20.0b14 mean calculation'!Q17 -> 43.09 | T18: ='20.0b78 mean calculation'!Q17 -> 41.975
A19: =A18+100 -> 1700 | B19: 49.08 | C19: 49.485 | D19: 45.275 | E19: 50.16 | F19: 53.27 | G19: 41.705 | H19: 43.835 | J19: 46.665 | K19: 43.19 | L19: 44.5 | M19: 42.26 | N19: 44.79 | O19: 42.625 | P19: 42.705 | Q19: 43.075 | R19: 44.59 | S19: ='20.0b14 mean calculation'!Q18 -> 44.335 | T19: ='20.0b78 mean calculation'!Q18 -> 43.375
A20: =A19+100 -> 1800 | C20: 49.15 | D20: 45.865 | E20: 51.545 | F20: 50.32 | G20: 44.105 | H20: 45.14 | J20: 48.22 | K20: 45.95 | M20: 46.105 | N20: 46.87 | O20: 44.55 | P20: 44.59 | Q20: 45.03 | R20: 46.725 | S20: ='20.0b14 mean calculation'!Q19 -> 48.265 | T20: ='20.0b78 mean calculation'!Q19 -> 46.46
A21: =A20+100 -> 1900 | D21: 44.11 | E21: 55.925 | F21: 53.57 | G21: 46.395 | H21: 47.295 | J21: 49.765 | K21: 49.165 | M21: 48.815 | N21: 46.605 | O21: 47.44 | Q21: 48.265 | R21: 49.715 | S21: ='20.0b14 mean calculation'!Q20 -> 49.71 | T21: ='20.0b78 mean calculation'!Q20 -> 49.76
A22: =A21+100 -> 2000 | D22: 49.93 | F22: 60.43 | G22: 48.24 | H22: 48.085 | M22: 50.13 | N22: 51.09 | Q22: 50 | S22: ='20.0b14 mean calculation'!Q21 -> 52.33
A23: =A22+100 -> 2100 | N23: 53.805 | Q23: 53.17 | S23: ='20.0b14 mean calculation'!Q22 -> 54.665
A24: =A23+100 -> 2200 | Q24: 55.79 | S24: ='20.0b14 mean calculation'!Q23 -> 56.32
A25: =A24+100 -> 2300 | Q25: 57.98 | S25: ='20.0b14 mean calculation'!Q24 -> 59.525
A26: =A25+100 -> 2400 | Q26: 60.69 | S26: ='20.0b14 mean calculation'!Q25 -> 62.935
A27: =A26+100 -> 2500 | S27: ='20.0b14 mean calculation'!Q26 -> 66.435
A28: =A27+100 -> 2600 | S28: ='20.0b14 mean calculation'!Q27 -> 61.915
A29: =A28+100 -> 2700 | S29: ='20.0b14 mean calculation'!Q28 -> 69.48
A30: =A29+100 -> 2800 | S30: ='20.0b14 mean calculation'!Q29 -> 73.14
A31: 2900 | S31: ='20.0b14 mean calculation'!Q30 -> 76.555

Sheet 20.0b78 mean calculation
A1: Core | B1: Rate | C1: ISRs (Min) | D1: ISRs (Max) | E1: ISRs (Max) | F1: TL (min) | G1: TL (max) | H1: TL (Mean) | I1: Other (Min) | J1: Other (Max) | K1: Other (Mean) | L1: Total (min) | M1: Total (max) | N1: Total (Mean) | P1: 2020 b78 | Q1: Total (Mean)
A2: 0 | B2: 100 | C2: 1.47 | D2: 3.43 | E2: 1.82 | F2: 1.82 | G2: 2.13 | H2: 1.93 | I2: 5.34 | J2: 94.86 | K2: 9.24 | L2: 8.8 | M2: 100 | N2: 12.99 | P2: 100 | Q2: =AVERAGE(N2:N3) -> 8.765
A3: 1 | B3: 100 | C3: 1.18 | D3: 2.09 | E3: 1.77 | F3: 2.54 | G3: 4.19 | H3: 2.77 | I3: 0 | J3: 0.13 | K3: 0 | L3: 3.72 | M3: 5.66 | N3: 4.54 | P3: =P2+100 -> 200 | Q3: =AVERAGE(N4:N5) -> 10.18
A4: 0 | B4: 200 | C4: 1.56 | D4: 2.99 | E4: 2.37 | F4: 3.03 | G4: 3.11 | H4: 3.07 | I4: 7.76 | J4: 15.89 | K4: 8.22 | L4: 12.62 | M4: 21.95 | N4: 13.66 | P4: =P3+100 -> 300 | Q4: =AVERAGE(N6:N7) -> 12.33
A5: 1 | B5: 200 | C5: 1.07 | D5: 2.27 | E5: 1.61 | F5: 5.04 | G5: 5.16 | H5: 5.09 | I5: 0 | J5: 0.07 | K5: 0 | L5: 6.13 | M5: 7.38 | N5: 6.7 | P5: =P4+100 -> 400 | Q5: =AVERAGE(N8:N9) -> 14.315
A6: 0 | B6: 300 | C6: 1.65 | D6: 2.6 | E6: 2.01 | F6: 4.22 | G6: 4.33 | H6: 4.27 | I6: 8.49 | J6: 18.77 | K6: 8.86 | L6: 14.49 | M6: 25.13 | N6: 15.13 | P6: =P5+100 -> 500 | Q6: =AVERAGE(N10:N11) -> 16.43
A7: 1 | B7: 300 | C7: 1.51 | D7: 2.41 | E7: 2.07 | F7: 7.35 | G7: 7.73 | H7: 7.45 | I7: 0 | J7: 0.1 | K7: 0.01 | L7: 8.87 | M7: 10.03 | N7: 9.53 | P7: =P6+100 -> 600 | Q7: =AVERAGE(N12:N13) -> 19.535
A8: 0 | B8: 400 | C8: 2.89 | D8: 3.41 | E8: 3.14 | F8: 5.37 | G8: 5.55 | H8: 5.44 | I8: 8.87 | J8: 11.69 | K8: 9.15 | L8: 17.34 | M8: 20.41 | N8: 17.73 | P8: =P7+100 -> 700 | Q8: =AVERAGE(N14:N15) -> 22.09
A9: 1 | B9: 400 | C9: 0.97 | D9: 1.43 | E9: 1.18 | F9: 9.62 | G9: 9.81 | H9: 9.72 | I9: 0 | J9: 0.04 | K9: 0 | L9: 10.6 | M9: 11.18 | N9: 10.9 | P9: =P8+100 -> 800 | Q9: =AVERAGE(N16:N17) -> 24.2
A10: 0 | B10: 500 | C10: 2.81 | D10: 3.41 | E10: 3.12 | F10: 6.61 | G10: 6.8 | H10: 6.69 | I10: 9.31 | J10: 20.18 | K10: 9.67 | L10: 18.96 | M10: 30.11 | N10: 19.48 | P10: =P9+100 -> 900 | Q10: =AVERAGE(N18:N19) -> 26.46
A11: 1 | B11: 500 | C11: 1.12 | D11: 1.65 | E11: 1.37 | F11: 11.9 | G11: 12.55 | H11: 12 | I11: 0 | J11: 0.05 | K11: 0 | L11: 13.09 | M11: 14.02 | N11: 13.38 | P11: =P10+100 -> 1000 | Q11: =AVERAGE(N20:N21) -> 28.27
A12: 0 | B12: 600 | C12: 2.58 | D12: 3.59 | E12: 2.94 | F12: 7.89 | G12: 8.11 | H12: 7.98 | I12: 11.34 | J12: 22.25 | K12: 11.66 | L12: 22.05 | M12: 33.93 | N12: 22.59 | P12: =P11+100 -> 1100 | Q12: =AVERAGE(N22:N23) -> 30.605
A13: 1 | B13: 600 | C13: 1.45 | D13: 2.1 | E13: 1.76 | F13: 14.55 | G13: 15.37 | H13: 14.71 | I13: 0 | J13: 0.09 | K13: 0.01 | L13: 16.16 | M13: 16.86 | N13: 16.48 | P13: =P12+100 -> 1200 | Q13: =AVERAGE(N24:N25) -> 32.835
A14: 0 | B14: 700 | C14: 2.92 | D14: 3.61 | E14: 3.2 | F14: 9.08 | G14: 9.32 | H14: 9.15 | I14: 12.18 | J14: 25.17 | K14: 12.9 | L14: 24.28 | M14: 37.73 | N14: 25.25 | P14: =P13+100 -> 1300 | Q14: =AVERAGE(N26:N27) -> 35.34
A15: 1 | B15: 700 | C15: 1.47 | D15: 1.99 | E15: 1.74 | F15: 17 | G15: 17.5 | H15: 17.17 | I15: 0 | J15: 0.06 | K15: 0.01 | L15: 18.64 | M15: 19.42 | N15: 18.93 | P15: =P14+100 -> 1400 | Q15: =AVERAGE(N28:N29) -> 37.655
A16: 0 | B16: 800 | C16: 3.12 | D16: 3.58 | E16: 3.34 | F16: 10.48 | G16: 10.7 | H16: 10.57 | I16: 12.99 | J16: 22.59 | K16: 13.54 | L16: 26.8 | M16: 36.79 | N16: 27.45 | P16: =P15+100 -> 1500 | Q16: =AVERAGE(N30:N31) -> 40.02
A17: 1 | B17: 800 | C17: 1.52 | D17: 1.94 | E17: 1.73 | F17: 18.99 | G17: 19.84 | H17: 19.23 | I17: 0 | J17: 0.03 | K17: 0 | L17: 20.56 | M17: 21.7 | N17: 20.95 | P17: =P16+100 -> 1600 | Q17: =AVERAGE(N32:N33) -> 41.975
A18: 0 | B18: 900 | C18: 1.7 | D18: 2.6 | E18: 2.08 | F18: 11.55 | G18: 11.8 | H18: 11.66 | I18: 13.46 | J18: 48.85 | K18: 14.39 | L18: 26.93 | M18: 62.99 | N18: 28.13 | P18: =P17+100 -> 1700 | Q18: =AVERAGE(N34:N35) -> 43.375
A19: 1 | B19: 900 | C19: 2.72 | D19: 3.74 | E19: 3.15 | F19: 21.31 | G19: 22.61 | H19: 21.62 | I19: 0 | J19: 0.23 | K19: 0.02 | L19: 24.25 | M19: 26.59 | N19: 24.79 | P19: =P18+100 -> 1800 | Q19: =AVERAGE(N36:N37) -> 46.46
A20: 0 | B20: 1000 | C20: 2.69 | D20: 3.71 | E20: 3.17 | F20: 12.75 | G20: 13.12 | H20: 12.87 | I20: 13.74 | J20: 27.23 | K20: 14.45 | L20: 29.64 | M20: 43.71 | N20: 30.49 | P20: =P19+100 -> 1900 | Q20: =AVERAGE(N38:N39) -> 49.76
A21: 1 | B21: 1000 | C21: 1.87 | D21: 2.62 | E21: 2.16 | F21: 23.65 | G21: 25.01 | H21: 23.88 | I21: 0 | J21: 0.05 | K21: 0.01 | L21: 25.64 | M21: 27.17 | N21: 26.05 | P21: =P20+100 -> 2000 | Q21: =AVERAGE(N40:N41) -> #DIV/0!
A22: 0 | B22: 1100 | C22: 3 | D22: 3.48 | E22: 3.23 | F22: 14.34 | G22: 14.56 | H22: 14.44 | I22: 15.2 | J22: 17.91 | K22: 15.51 | L22: 32.74 | M22: 35.82 | N22: 33.17 | P22: =P21+100 -> 2100 | Q22: =AVERAGE(N42:N43) -> #DIV/0!
A23: 1 | B23: 1100 | C23: 1.91 | D23: 2.43 | E23: 2.15 | F23: 25.68 | G23: 26.21 | H23: 25.88 | I23: 0 | J23: 0.09 | K23: 0.01 | L23: 27.59 | M23: 28.41 | N23: 28.04 | P23: =P22+100 -> 2200 | Q23: =AVERAGE(N44:N45) -> #DIV/0!
A24: 0 | B24: 1200 | C24: 3.05 | D24: 3.54 | E24: 3.31 | F24: 15.52 | G24: 15.76 | H24: 15.62 | I24: 16.14 | J24: 22.49 | K24: 16.48 | L24: 35.01 | M24: 41.69 | N24: 35.4 | P24: =P23+100 -> 2300 | Q24: =AVERAGE(N46:N47) -> #DIV/0!
A25: 1 | B25: 1200 | C25: 1.9 | D25: 2.38 | E25: 2.15 | F25: 28.01 | G25: 28.34 | H25: 28.11 | I25: 0 | J25: 0.05 | K25: 0.01 | L25: 29.96 | M25: 30.59 | N25: 30.27 | P25: =P24+100 -> 2400 | Q25: =AVERAGE(N48:N49) -> #DIV/0!
A26: 0 | B26: 1300 | C26: 3.05 | D26: 3.5 | E26: 3.26 | F26: 16.75 | G26: 17.16 | H26: 16.94 | I26: 16.83 | J26: 29.08 | K26: 17.26 | L26: 36.9 | M26: 49.67 | N26: 37.45 | P26: =P25+100 -> 2500 | Q26: =AVERAGE(N50:N51) -> #DIV/0!
A27: 1 | B27: 1300 | C27: 2.16 | D27: 2.72 | E27: 2.43 | F27: 30.53 | G27: 31.67 | H27: 30.79 | I27: 0 | J27: 0.09 | K27: 0.01 | L27: 32.77 | M27: 34 | N27: 33.23 | P27: =P26+100 -> 2600 | Q27: =AVERAGE(N52:N53) -> #DIV/0!
A28: 0 | B28: 1400 | C28: 3.13 | D28: 3.6 | E28: 3.4 | F28: 18.19 | G28: 18.49 | H28: 18.34 | I28: 17.65 | J28: 23.62 | K28: 18.03 | L28: 39.25 | M28: 45.51 | N28: 39.76 | P28: =P27+100 -> 2700 | Q28: =AVERAGE(N54:N55) -> #DIV/0!
A29: 1 | B29: 1400 | C29: 2.25 | D29: 2.79 | E29: 2.51 | F29: 32.82 | G29: 33.45 | H29: 33.04 | I29: 0 | J29: 0.06 | K29: 0.01 | L29: 35.16 | M29: 36.14 | N29: 35.55 | P29: =P28+100 -> 2800 | Q29: =AVERAGE(N56:N57) -> #DIV/0!
A30: 0 | B30: 1500 | C30: 2.86 | D30: 3.53 | E30: 3.21 | F30: 19.44 | G30: 20.01 | H30: 19.7 | I30: 18.47 | J30: 31.13 | K30: 18.95 | L30: 41.19 | M30: 54.52 | N30: 41.86 | P30: 2900 | Q30: =AVERAGE(N58:N59) -> #DIV/0!
A31: 1 | B31: 1500 | C31: 2.48 | D31: 3.21 | E31: 2.84 | F31: 35.08 | G31: 36.54 | H31: 35.34 | I31: 0 | J31: 0.09 | K31: 0.01 | L31: 37.7 | M31: 39.41 | N31: 38.18
A32: 0 | B32: 1600 | C32: 3.26 | D32: 3.68 | E32: 3.47 | F32: 20.78 | G32: 21.12 | H32: 20.99 | I32: 18.87 | J32: 29.63 | K32: 19.37 | L32: 43.23 | M32: 54.34 | N32: 43.82
A33: 1 | B33: 1600 | C33: 2.46 | D33: 3 | E33: 2.73 | F33: 37.15 | G33: 38.01 | H33: 37.39 | I33: 0 | J33: 0.06 | K33: 0.01 | L33: 39.65 | M33: 40.71 | N33: 40.13
A34: 0 | B34: 1700 | C34: 2.74 | D34: 3.49 | E34: 3.11 | F34: 21.54 | G34: 21.91 | H34: 21.7 | I34: 18.44 | J34: 26.63 | K34: 19.04 | L34: 43.02 | M34: 51.79 | N34: 43.84
A35: 1 | B35: 1700 | C35: 2.8 | D35: 3.56 | E35: 3.15 | F35: 39.51 | G35: 40.39 | H35: 39.75 | I35: 0 | J35: 0.06 | K35: 0.01 | L35: 42.5 | M35: 43.71 | N35: 42.91
A36: 0 | B36: 1800 | C36: 2.01 | D36: 2.82 | E36: 2.38 | F36: 23.14 | G36: 23.6 | H36: 23.31 | I36: 19.99 | J36: 35.21 | K36: 20.62 | L36: 45.37 | M36: 61.35 | N36: 46.31
A37: 1 | B37: 1800 | C37: 3.88 | D37: 4.72 | E37: 4.3 | F37: 41.98 | G37: 43.93 | H37: 42.29 | I37: 0 | J37: 0.15 | K37: 0.02 | L37: 46.25 | M37: 48.69 | N37: 46.61
A38: 0 | B38: 1900 | C38: 3.2 | D38: 3.76 | E38: 3.42 | F38: 25.26 | G38: 25.66 | H38: 25.42 | I38: 21.61 | J38: 36.23 | K38: 22.27 | L38: 50.33 | M38: 65.57 | N38: 51.12
A39: 1 | B39: 1900 | C39: 3.2 | D39: 3.8 | E39: 3.46 | F39: 44.63 | G39: 45.62 | H39: 44.93 | I39: 0 | J39: 0.07 | K39: 0.01 | L39: 47.88 | M39: 49.26 | N39: 48.4
A40: 0 | B40: 2000 | C40: 0 | D40: 0 | E40: NaN | F40: 0 | G40: 0 | H40: NaN | I40: 0 | J40: 0 | K40: NaN | L40: 0 | M40: 0 | N40: NaN
...

Sheet 20.0b14 mean calculation
A1: Core | B1: Rate | C1: ISRs (Min) | D1: ISRs (Max) | E1: ISRs (Max) | F1: TL (min) | G1: TL (max) | H1: TL (Mean) | I1: Other (Min) | J1: Other (Max) | K1: Other (Mean) | L1: Total (min) | M1: Total (max) | N1: Total (Mean) | P1: 2020 b14 | Q1: Total (Mean)
A2: 0 | B2: 100 | C2: 0.23 | D2: 3.21 | E2: 2.75 | F2: 1.79 | G2: 89.96 | H2: 2.67 | I2: 5.63 | J2: 95.97 | K2: 12.37 | L2: 8.99 | M2: 99.98 | N2: 17.79 | P2: 100 | Q2: =AVERAGE(N2:N3) -> 10.4
A3: 1 | B3: 100 | C3: 0.05 | D3: 0.4 | E3: 0.26 | F3: 0.07 | G3: 4.35 | H3: 2.75 | I3: 0 | J3: 0.02 | K3: 0 | L3: 0.11 | M3: 4.72 | N3: 3.01 | P3: =P2+100 -> 200 | Q3: =AVERAGE(N4:N5) -> 10.81
A4: 0 | B4: 200 | C4: 2.95 | D4: 3.83 | E4: 3.06 | F4: 2.99 | G4: 3.09 | H4: 3.03 | I4: 9.34 | J4: 32.77 | K4: 10.14 | L4: 15.33 | M4: 39.36 | N4: 16.22 | P4: =P3+100 -> 300 | Q4: =AVERAGE(N6:N7) -> 13.03
A5: 1 | B5: 200 | C5: 0.2 | D5: 0.33 | E5: 0.26 | F5: 5.09 | G5: 5.49 | H5: 5.13 | I5: 0 | J5: 0.01 | K5: 0 | L5: 5.32 | M5: 5.75 | N5: 5.4 | P5: =P4+100 -> 400 | Q5: =AVERAGE(N8:N9) -> 15.405
A6: 0 | B6: 300 | C6: 3.16 | D6: 3.94 | E6: 3.31 | F6: 4.19 | G6: 4.34 | H6: 4.24 | I6: 10.25 | J6: 16.76 | K6: 10.74 | L6: 17.65 | M6: 24.56 | N6: 18.29 | P6: =P5+100 -> 500 | Q6: =AVERAGE(N10:N11) -> 17.975
A7: 1 | B7: 300 | C7: 0.22 | D7: 0.34 | E7: 0.27 | F7: 7.43 | G7: 7.62 | H7: 7.51 | I7: 0 | J7: 0 | K7: 0 | L7: 7.66 | M7: 7.97 | N7: 7.77 | P7: =P6+100 -> 600 | Q7: =AVERAGE(N12:N13) -> 20.875
A8: 0 | B8: 400 | C8: 3.3 | D8: 4.38 | E8: 3.42 | F8: 5.3 | G8: 5.49 | H8: 5.35 | I8: 10.96 | J8: 44.12 | K8: 11.98 | L8: 19.63 | M8: 53.72 | N8: 20.74 | P8: =P7+100 -> 700 | Q8: =AVERAGE(N14:N15) -> 22.26
A9: 1 | B9: 400 | C9: 0.22 | D9: 0.34 | E9: 0.27 | F9: 9.71 | G9: 10.57 | H9: 9.8 | I9: 0 | J9: 0 | K9: 0 | L9: 9.94 | M9: 10.89 | N9: 10.07 | P9: =P8+100 -> 800 | Q9: =AVERAGE(N16:N17) -> 24.88
A10: 0 | B10: 500 | C10: 3.6 | D10: 4.18 | E10: 3.71 | F10: 6.47 | G10: 6.89 | H10: 6.52 | I10: 11.84 | J10: 71.46 | K10: 13.2 | L10: 22.01 | M10: 82.52 | N10: 23.44 | P10: =P9+100 -> 900 | Q10: =AVERAGE(N18:N19) -> 26.71
A11: 1 | B11: 500 | C11: 0.19 | D11: 0.35 | E11: 0.27 | F11: 12.07 | G11: 15.98 | H11: 12.24 | I11: 0 | J11: 0.02 | K11: 0 | L11: 12.33 | M11: 16.33 | N11: 12.51 | P11: =P10+100 -> 1000 | Q11: =AVERAGE(N20:N21) -> 28.935
A12: 0 | B12: 600 | C12: 3.8 | D12: 5.01 | E12: 3.98 | F12: 7.71 | G12: 8.02 | H12: 7.8 | I12: 12.6 | J12: 56.27 | K12: 15.01 | L12: 24.26 | M12: 68.52 | N12: 26.79 | P12: =P11+100 -> 1100 | Q12: =AVERAGE(N22:N23) -> 31.05
A13: 1 | B13: 600 | C13: 0.19 | D13: 0.35 | E13: 0.27 | F13: 14.49 | G13: 17.61 | H13: 14.69 | I13: 0 | J13: 0 | K13: 0 | L13: 14.73 | M13: 17.93 | N13: 14.96 | P13: =P12+100 -> 1200 | Q13: =AVERAGE(N24:N25) -> 33.395
A14: 0 | B14: 700 | C14: 4.01 | D14: 4.56 | E14: 4.18 | F14: 8.92 | G14: 9.11 | H14: 9.02 | I14: 13.54 | J14: 19.85 | K14: 14.12 | L14: 26.65 | M14: 33.26 | N14: 27.31 | P14: =P13+100 -> 1300 | Q14: =AVERAGE(N26:N27) -> 35.61
A15: 1 | B15: 700 | C15: 0.17 | D15: 0.33 | E15: 0.27 | F15: 16.82 | G15: 17.3 | H15: 16.94 | I15: 0 | J15: 0 | K15: 0 | L15: 17.07 | M15: 17.59 | N15: 17.21 | P15: =P14+100 -> 1400 | Q15: =AVERAGE(N28:N29) -> 38.865
A16: 0 | B16: 800 | C16: 4.19 | D16: 5.13 | E16: 4.45 | F16: 10.13 | G16: 10.42 | H16: 10.22 | I16: 14.19 | J16: 49.38 | K16: 15.76 | L16: 28.68 | M16: 64.93 | N16: 30.42 | P16: =P15+100 -> 1500 | Q16: =AVERAGE(N30:N31) -> 40.445
A17: 1 | B17: 800 | C17: 0.14 | D17: 0.33 | E17: 0.24 | F17: 18.85 | G17: 20.45 | H17: 19.1 | I17: 0 | J17: 0.01 | K17: 0 | L17: 19.08 | M17: 20.65 | N17: 19.34 | P17: =P16+100 -> 1600 | Q17: =AVERAGE(N32:N33) -> 43.09
A18: 0 | B18: 900 | C18: 4.35 | D18: 4.78 | E18: 4.52 | F18: 11.49 | G18: 11.66 | H18: 11.56 | I18: 14.81 | J18: 26.28 | K18: 15.5 | L18: 30.75 | M18: 42.63 | N18: 31.59 | P18: =P17+100 -> 1700 | Q18: =AVERAGE(N34:N35) -> 44.335
A19: 1 | B19: 900 | C19: 0.21 | D19: 0.35 | E19: 0.28 | F19: 21.4 | G19: 22.29 | H19: 21.55 | I19: 0 | J19: 0.02 | K19: 0 | L19: 21.63 | M19: 22.63 | N19: 21.83 | P19: =P18+100 -> 1800 | Q19: =AVERAGE(N36:N37) -> 48.265
A20: 0 | B20: 1000 | C20: 4.42 | D20: 5.57 | E20: 4.62 | F20: 12.5 | G20: 12.82 | H20: 12.63 | I20: 15.75 | J20: 53.17 | K20: 17.24 | L20: 32.83 | M20: 71.26 | N20: 34.49 | P20: =P19+100 -> 1900 | Q20: =AVERAGE(N38:N39) -> 49.71
A21: 1 | B21: 1000 | C21: 0.01 | D21: 0.33 | E21: 0.1 | F21: 23.09 | G21: 24.75 | H21: 23.28 | I21: 0 | J21: 0.02 | K21: 0 | L21: 23.13 | M21: 24.96 | N21: 23.38 | P21: =P20+100 -> 2000 | Q21: =AVERAGE(N40:N41) -> 52.33
A22: 0 | B22: 1100 | C22: 4.56 | D22: 5.13 | E22: 4.77 | F22: 13.99 | G22: 14.19 | H22: 14.08 | I22: 16.58 | J22: 28.49 | K22: 17.41 | L22: 35.27 | M22: 47.55 | N22: 36.26 | P22: =P21+100 -> 2100 | Q22: =AVERAGE(N42:N43) -> 54.665
A23: 1 | B23: 1100 | C23: 0.01 | D23: 0.33 | E23: 0.14 | F23: 25.53 | G23: 26.51 | H23: 25.7 | I23: 0 | J23: 0 | K23: 0 | L23: 25.56 | M23: 26.63 | N23: 25.84 | P23: =P22+100 -> 2200 | Q23: =AVERAGE(N44:N45) -> 56.32
A24: 0 | B24: 1200 | C24: 4.72 | D24: 5.52 | E24: 4.92 | F24: 15.24 | G24: 15.56 | H24: 15.39 | I24: 17.28 | J24: 41.24 | K24: 18.42 | L24: 37.29 | M24: 62.02 | N24: 38.72 | P24: =P23+100 -> 2300 | Q24: =AVERAGE(N46:N47) -> 59.525
A25: 1 | B25: 1200 | C25: 0.02 | D25: 0.32 | E25: 0.13 | F25: 27.68 | G25: 28.94 | H25: 27.94 | I25: 0 | J25: 0.01 | K25: 0 | L25: 27.72 | M25: 29.25 | N25: 28.07 | P25: =P24+100 -> 2400 | Q25: =AVERAGE(N48:N49) -> 62.935
A26: 0 | B26: 1300 | C26: 5.03 | D26: 5.95 | E26: 5.19 | F26: 16.16 | G26: 16.94 | H26: 16.36 | I26: 17.44 | J26: 77.03 | K26: 18.75 | L26: 38.81 | M26: 99.84 | N26: 40.3 | P26: =P25+100 -> 2500 | Q26: =AVERAGE(N50:N51) -> 66.435
A27: 1 | B27: 1300 | C27: 0.19 | D27: 0.32 | E27: 0.24 | F27: 30.47 | G27: 35 | H27: 30.69 | I27: 0 | J27: 0.02 | K27: 0 | L27: 30.72 | M27: 35.32 | N27: 30.92 | P27: =P26+100 -> 2600 | Q27: =AVERAGE(N52:N53) -> 61.915
A28: 0 | B28: 1400 | C28: 5.07 | D28: 6.4 | E28: 5.34 | F28: 17.8 | G28: 18.45 | H28: 18.08 | I28: 19.04 | J28: 57.08 | K28: 21.57 | L28: 42.3 | M28: 81.42 | N28: 44.98 | P28: =P27+100 -> 2700 | Q28: =AVERAGE(N54:N55) -> 69.48
A29: 1 | B29: 1400 | C29: 0 | D29: 0.3 | E29: 0.08 | F29: 32.38 | G29: 34.11 | H29: 32.67 | I29: 0 | J29: 0.01 | K29: 0 | L29: 32.4 | M29: 34.16 | N29: 32.75 | P29: =P28+100 -> 2800 | Q29: =AVERAGE(N56:N57) -> 73.14
A30: 0 | B30: 1500 | C30: 5.41 | D30: 6.16 | E30: 5.58 | F30: 19.06 | G30: 19.58 | H30: 19.33 | I30: 19.87 | J30: 31.23 | K30: 20.96 | L30: 44.46 | M30: 56.68 | N30: 45.86 | P30: 2900 | Q30: =AVERAGE(N58:N59) -> 76.555
A31: 1 | B31: 1500 | C31: 0.01 | D31: 0.32 | E31: 0.07 | F31: 34.71 | G31: 35.59 | H31: 34.96 | I31: 0 | J31: 0.01 | K31: 0 | L31: 34.73 | M31: 35.8 | N31: 35.03
A32: 0 | B32: 1600 | C32: 5.44 | D32: 6.6 | E32: 5.66 | F32: 20.71 | G32: 21.21 | H32: 20.85 | I32: 20.59 | J32: 53.88 | K32: 22.22 | L32: 46.89 | M32: 81.52 | N32: 48.73
A33: 1 | B33: 1600 | C33: 0.01 | D33: 0.34 | E33: 0.11 | F33: 37.08 | G33: 39.01 | H33: 37.33 | I33: 0 | J33: 0.01 | K33: 0 | L33: 37.12 | M33: 39.06 | N33: 37.45
A34: 0 | B34: 1700 | C34: 5.72 | D34: 6.52 | E34: 5.89 | F34: 21.61 | G34: 22.08 | H34: 21.83 | I34: 20.92 | J34: 31.65 | K34: 21.74 | L34: 48.54 | M34: 59.9 | N34: 49.46
A35: 1 | B35: 1700 | C35: 0.02 | D35: 0.32 | E35: 0.13 | F35: 38.86 | G35: 39.63 | H35: 39.08 | I35: 0 | J35: 0.01 | K35: 0 | L35: 38.9 | M35: 39.77 | N35: 39.21
A36: 0 | B36: 1800 | C36: 5.97 | D36: 7.12 | E36: 6.22 | F36: 23.01 | G36: 23.84 | H36: 23.22 | I36: 21.76 | J36: 69.16 | K36: 25.26 | L36: 50.91 | M36: 99.93 | N36: 54.69
A37: 1 | B37: 1800 | C37: 0.01 | D37: 0.34 | E37: 0.06 | F37: 41.25 | G37: 46.58 | H37: 41.77 | I37: 0 | J37: 0.01 | K37: 0 | L37: 41.29 | M37: 46.9 | N37: 41.84
A38: 0 | B38: 1900 | C38: 5.98 | D38: 6.71 | E38: 6.17 | F38: 25.23 | G38: 25.94 | H38: 25.61 | I38: 22.98 | J38: 35.84 | K38: 23.84 | L38: 54.57 | M38: 67.88 | N38: 55.62
A39: 1 | B39: 1900 | C39: 0.01 | D39: 0.33 | E39: 0.12 | F39: 43.26 | G39: 44.98 | H39: 43.67 | I39: 0 | J39: 0.01 | K39: 0 | L39: 43.3 | M39: 45.18 | N39: 43.8
A40: 0 | B40: 2000 | C40: 6.37 | D40: 7.45 | E40: 6.54 | F40: 25.79 | G40: 26.49 | H40: 26.08 | I40: 23.88 | J40: 52.76 | K40: 25.31 | L40: 56.32 | M40: 86.37 | N40: 57.93
...

Sheet 19.0 mean calculation
A1: Total (Mean) | B1: Mean | R1: 19.0release
A2: 14.67 | B2: 9.585 | R2: Core | S2: Rate | T2: ISRs (Min) | U2: ISRs (Max) | V2: ISRs (Max) | W2: TL (min) | X2: TL (max) | Y2: TL (Mean) | Z2: Other (Min) | AA2: Other (Max) | AB2: Other (Mean) | AC2: Total (min) | AD2: Total (max) | AE2: Total (Mean)
A3: 4.5 | R3: 0 | S3: 100 | T3: 0.31 | U3: 3.69 | V3: 1.78 | W3: 1.19 | X3: 89.57 | Y3: 2.64 | Z3: 4.86 | AA3: 95.69 | AB3: 10.25 | AC3: 7.44 | AD3: 100 | AE3: 14.67
A4: 13.78 | B4: 10.15 | R4: 1 | S4: 100 | T4: 0.91 | U4: 2.36 | V4: 1.81 | W4: 2.25 | X4: 3.87 | Y4: 2.69 | Z4: 0 | AA4: 0.03 | AB4: 0 | AC4: 3.55 | AD4: 5.19 | AE4: 4.5
A5: 6.52 | R5: 0 | S5: 200 | T5: 1.93 | U5: 2.9 | V5: 2.39 | W5: 2.98 | X5: 3.11 | Y5: 3.02 | Z5: 8.01 | AA5: 18.27 | AB5: 8.37 | AC5: 13.03 | AD5: 23.99 | AE5: 13.78
A6: 15.18 | B6: 12.33 | R6: 1 | S6: 200 | T6: 1.02 | U6: 1.99 | V6: 1.48 | W6: 4.96 | X6: 5.31 | Y6: 5.04 | Z6: 0 | AA6: 0.03 | AB6: 0 | AC6: 6.01 | AD6: 6.98 | AE6: 6.52
A7: 9.48 | R7: 0 | S7: 300 | T7: 1.52 | U7: 2.59 | V7: 1.93 | W7: 4.15 | X7: 4.24 | Y7: 4.19 | Z7: 8.72 | AA7: 15.47 | AB7: 9.06 | AC7: 14.62 | AD7: 21.96 | AE7: 15.18
A8: 18.12 | B8: 14.435 | R8: 1 | S8: 300 | T8: 1.46 | U8: 2.57 | V8: 2.12 | W8: 7.28 | X8: 7.42 | Y8: 7.35 | Z8: 0 | AA8: 0.08 | AB8: 0.01 | AC8: 8.75 | AD8: 9.97 | AE8: 9.48
A9: 10.75 | R9: 0 | S9: 400 | T9: 2.82 | U9: 3.43 | V9: 3.1 | W9: 5.29 | X9: 5.43 | Y9: 5.35 | Z9: 9.11 | AA9: 28.21 | AB9: 9.66 | AC9: 17.43 | AD9: 37.02 | AE9: 18.12
A10: 20.56 | B10: 17.09 | R10: 1 | S10: 400 | T10: 0.97 | U10: 1.41 | V10: 1.14 | W10: 9.51 | X10: 9.96 | Y10: 9.6 | Z10: 0 | AA10: 0.03 | AB10: 0 | AC10: 10.52 | AD10: 11.17 | AE10: 10.75
A11: 13.62 | R11: 0 | S11: 500 | T11: 2.69 | U11: 3.34 | V11: 2.96 | W11: 6.49 | X11: 6.75 | Y11: 6.61 | Z11: 10.69 | AA11: 12.9 | AB11: 10.98 | AC11: 20.07 | AD11: 22.85 | AE11: 20.56
A12: 21.81 | B12: 19.345 | R12: 1 | S12: 500 | T12: 1.22 | U12: 1.75 | V12: 1.46 | W12: 11.99 | X12: 12.43 | Y12: 12.16 | Z12: 0 | AA12: 0.04 | AB12: 0.01 | AC12: 13.3 | AD12: 13.97 | AE12: 13.62
A13: 16.88 | R13: 0 | S13: 600 | T13: 1.82 | U13: 2.62 | V13: 2.2 | W13: 7.72 | X13: 7.96 | Y13: 7.82 | Z13: 11.48 | AA13: 12.32 | AB13: 11.79 | AC13: 21.36 | AD13: 22.34 | AE13: 21.81
A14: 24.91 | B14: 21.745 | R14: 1 | S14: 600 | T14: 1.86 | U14: 2.78 | V14: 2.41 | W14: 14.33 | X14: 14.78 | Y14: 14.46 | Z14: 0 | AA14: 0.05 | AB14: 0.01 | AC14: 16.35 | AD14: 17.25 | AE14: 16.88
A15: 18.58 | R15: 0 | S15: 700 | T15: 2.89 | U15: 3.39 | V15: 3.14 | W15: 8.99 | X15: 9.22 | Y15: 9.1 | Z15: 12.37 | AA15: 23.97 | AB15: 12.68 | AC15: 24.51 | AD15: 36.32 | AE15: 24.91
A16: 26.96 | B16: 23.77 | R16: 1 | S16: 700 | T16: 1.49 | U16: 1.91 | V16: 1.68 | W16: 16.73 | X16: 17.65 | Y16: 16.89 | Z16: 0 | AA16: 0.06 | AB16: 0.01 | AC16: 18.35 | AD16: 19.5 | AE16: 18.58
A17: 20.58 | R17: 0 | S17: 800 | T17: 3.06 | U17: 3.45 | V17: 3.28 | W17: 10.27 | X17: 10.43 | Y17: 10.34 | Z17: 13.08 | AA17: 13.61 | AB17: 13.33 | AC17: 26.66 | AD17: 27.29 | AE17: 26.96
A18: 27.76 | B18: 26 | R18: 1 | S18: 800 | T18: 1.46 | U18: 1.96 | V18: 1.67 | W18: 18.73 | X18: 19.34 | Y18: 18.9 | Z18: 0 | AA18: 0.04 | AB18: 0 | AC18: 20.3 | AD18: 21.11 | AE18: 20.58
A19: 24.24 | R19: 0 | S19: 900 | T19: 1.54 | U19: 2.28 | V19: 1.82 | W19: 11.36 | X19: 11.8 | Y19: 11.52 | Z19: 13.55 | AA19: 65.19 | AB19: 14.42 | AC19: 26.8 | AD19: 78.97 | AE19: 27.76
A20: 31.08 | B20: 28.16 | R20: 1 | S20: 900 | T20: 3.01 | U20: 3.9 | V20: 3.29 | W20: 20.77 | X20: 22.4 | Y20: 20.92 | Z20: 0 | AA20: 0.35 | AB20: 0.02 | AC20: 23.88 | AD20: 26.64 | AE20: 24.24
A21: 25.24 | R21: 0 | S21: 1000 | T21: 2.89 | U21: 3.82 | V21: 3.19 | W21: 12.75 | X21: 13.09 | Y21: 12.9 | Z21: 14.55 | AA21: 18.58 | AB21: 14.99 | AC21: 30.48 | AD21: 35.43 | AE21: 31.08
A22: 32.86 | B22: 30.22 | R22: 1 | S22: 1000 | T22: 1.63 | U22: 2.09 | V22: 1.88 | W22: 23.13 | X22: 23.71 | Y22: 23.36 | Z22: 0 | AA22: 0.02 | AB22: 0 | AC22: 24.85 | AD22: 25.79 | AE22: 25.24
A23: 27.58 | R23: 0 | S23: 1100 | T23: 3.03 | U23: 3.4 | V23: 3.22 | W23: 13.98 | X23: 14.18 | Y23: 14.09 | Z23: 15.28 | AA23: 15.89 | AB23: 15.55 | AC23: 32.56 | AD23: 33.13 | AE23: 32.86
A24: 35.03 | B24: 32.775 | R24: 1 | S24: 1100 | T24: 1.82 | U24: 2.3 | V24: 2.04 | W24: 25.32 | X24: 25.85 | Y24: 25.53 | Z24: 0 | AA24: 0.06 | AB24: 0.01 | AC24: 27.28 | AD24: 28.11 | AE24: 27.58
A25: 30.52 | R25: 0 | S25: 1200 | T25: 3.12 | U25: 3.53 | V25: 3.29 | W25: 15.34 | X25: 15.83 | Y25: 15.53 | Z25: 15.89 | AA25: 27.42 | AB25: 16.22 | AC25: 34.58 | AD25: 46.54 | AE25: 35.03
A26: 37.13 | B26: 35.215 | R26: 1 | S26: 1200 | T26: 2.03 | U26: 2.49 | V26: 2.26 | W26: 28.05 | X26: 28.97 | Y26: 28.24 | Z26: 0 | AA26: 0.08 | AB26: 0.02 | AC26: 30.19 | AD26: 31.28 | AE26: 30.52
A27: 33.3 | R27: 0 | S27: 1300 | T27: 2.62 | U27: 3.19 | V27: 2.91 | W27: 16.76 | X27: 16.99 | Y27: 16.88 | Z27: 17.09 | AA27: 17.79 | AB27: 17.35 | AC27: 36.78 | AD27: 37.5 | AE27: 37.13
A28: 39.6 | B28: 37.46 | R28: 1 | S28: 1300 | T28: 2.42 | U28: 3.15 | V28: 2.78 | W28: 30.28 | X28: 30.78 | Y28: 30.51 | Z28: 0 | AA28: 0.06 | AB28: 0.01 | AC28: 32.8 | AD28: 33.79 | AE28: 33.3
A29: 35.32 | R29: 0 | S29: 1400 | T29: 3.09 | U29: 3.51 | V29: 3.28 | W29: 18.02 | X29: 18.3 | Y29: 18.15 | Z29: 17.8 | AA29: 29.97 | AB29: 18.18 | AC29: 39.25 | AD29: 51.65 | AE29: 39.6
A30: 37.66 | B30: 36.975 | R30: 1 | S30: 1400 | T30: 2.21 | U30: 2.67 | V30: 2.46 | W30: 32.58 | X30: 33.92 | Y30: 32.86 | Z30: 0 | AA30: 0.04 | AB30: 0 | AC30: 34.79 | AD30: 36.49 | AE30: 35.32
A31: 36.29 | R31: 0 | S31: 1500 | T31: 3.16 | U31: 3.6 | V31: 3.4 | W31: 18.56 | X31: 19.04 | Y31: 18.79 | Z31: 15.12 | AA31: 15.84 | AB31: 15.47 | AC31: 37.24 | AD31: 38.13 | AE31: 37.66
A32: 44.46 | B32: 42.19 | R32: 1 | S32: 1500 | T32: 2.14 | U32: 2.59 | V32: 2.35 | W32: 33.75 | X32: 34.27 | Y32: 33.94 | Z32: 0 | AA32: 0.05 | AB32: 0.01 | AC32: 36.01 | AD32: 36.76 | AE32: 36.29
A33: 39.92 | R33: 0 | S33: 1600 | T33: 3.25 | U33: 3.66 | V33: 3.47 | W33: 21.01 | X33: 21.51 | Y33: 21.26 | Z33: 19.48 | AA33: 20.05 | AB33: 19.74 | AC33: 43.92 | AD33: 44.91 | AE33: 44.46
A34: 46.34 | B34: 44.59 | R34: 1 | S34: 1600 | T34: 2.32 | U34: 2.88 | V34: 2.56 | W34: 37.08 | X34: 37.75 | Y34: 37.36 | Z34: 0 | AA34: 0.03 | AB34: 0 | AC34: 39.48 | AD34: 40.41 | AE34: 39.92
A35: 42.84 | R35: 0 | S35: 1700 | T35: 2.91 | U35: 3.49 | V35: 3.11 | W35: 22.09 | X35: 22.65 | Y35: 22.3 | Z35: 20.22 | AA35: 42.7 | AB35: 20.93 | AC35: 45.53 | AD35: 68.84 | AE35: 46.34
A36: 47.25 | B36: 46.725 | R36: 1 | S36: 1700 | T36: 2.68 | U36: 3.29 | V36: 2.99 | W36: 39.5 | X36: 41.18 | Y36: 39.84 | Z36: 0 | AA36: 0.12 | AB36: 0.02 | AC36: 42.36 | AD36: 44.36 | AE36: 42.84
A37: 46.2 | R37: 0 | S37: 1800 | T37: 1.94 | U37: 2.8 | V37: 2.33 | W37: 23.47 | X37: 23.79 | Y37: 23.62 | Z37: 20.92 | AA37: 23.39 | AB37: 21.31 | AC37: 46.59 | AD37: 49.57 | AE37: 47.25
A38: 50.99 | B38: 49.715 | R38: 1 | S38: 1800 | T38: 3.89 | U38: 4.7 | V38: 4.21 | W38: 41.64 | X38: 42.42 | Y38: 41.96 | Z38: 0 | AA38: 0.08 | AB38: 0.02 | AC38: 45.64 | AD38: 46.92 | AE38: 46.2
A39: 48.44 | R39: 0 | S39: 1900 | T39: 3.08 | U39: 3.6 | V39: 3.3 | W39: 24.92 | X39: 25.44 | Y39: 25.15 | Z39: 22.02 | AA39: 35.2 | AB39: 22.54 | AC39: 50.38 | AD39: 64.06 | AE39: 50.99
A40: NaN | R40: 1 | S40: 1900 | T40: 3.33 | U40: 4.01 | V40: 3.65 | W40: 44.5 | X40: 46.03 | Y40: 44.78 | Z40: 0 | AA40: 0.06 | AB40: 0.01 | AC40: 47.9 | AD40: 49.65 | AE40: 48.44
...

Sheet b27 mean calculation
A1: Total (Mean) | B1: Mean
A2: 15.46 | B2: =AVERAGE(A2:A3) -> 9.215
A3: 2.97
A4: 15.01 | B4: =AVERAGE(A4:A5) -> 10.115
A5: 5.22
A6: 16.92 | B6: =AVERAGE(A6:A7) -> 12.245
A7: 7.57
A8: 18.55 | B8: =AVERAGE(A8:A9) -> 14.22
A9: 9.89
A10: 21.05 | B10: =AVERAGE(A10:A11) -> 16.78
A11: 12.51
A12: 23.63 | B12: =AVERAGE(A12:A13) -> 19.255
A13: 14.88
A14: 25.98 | B14: =AVERAGE(A14:A15) -> 21.595
A15: 17.21
A16: 28.32 | B16: =AVERAGE(A16:A17) -> 23.755
A17: 19.19
A18: 30.29 | B18: =AVERAGE(A18:A19) -> 26.075
A19: 21.86
A20: 32.11 | B20: =AVERAGE(A20:A21) -> 28.27
A21: 24.43
A22: 34.14 | B22: =AVERAGE(A22:A23) -> 29.995
A23: 25.85
A24: 36.4 | B24: =AVERAGE(A24:A25) -> 32.27
A25: 28.14
A26: 38.33 | B26: =AVERAGE(A26:A27) -> 34.39
A27: 30.45
A28: 40.46 | B28: =AVERAGE(A28:A29) -> 36.685
A29: 32.91
A30: 42.88 | B30: =AVERAGE(A30:A31) -> 39.065
A31: 35.25
A32: 44.61 | B32: =AVERAGE(A32:A33) -> 40.92
A33: 37.23
A34: 46.71 | B34: =AVERAGE(A34:A35) -> 43.075
A35: 39.44
A36: 48.34 | B36: =AVERAGE(A36:A37) -> 45.03
A37: 41.72
A38: 52.09 | B38: =AVERAGE(A38:A39) -> 48.265
A39: 44.44
A40: 53.14 | B40: =AVERAGE(A40:A41) -> 50
...

Sheet Test_data_2019b27
A1: Core | B1: Rate | C1: ISRs (Min) | D1: ISRs (Max) | E1: ISRs (Max) | F1: TL (min) | G1: TL (max) | H1: TL (Mean) | I1: Other (Min) | J1: Other (Max) | K1: Other (Mean) | L1: Total (min) | M1: Total (max) | N1: Total (Mean)
A2: 0 | B2: 100 | C2: 1.43 | D2: 3.29 | E2: 2.55 | F2: 1.78 | G2: 3.37 | H2: 1.89 | I2: 5.7 | J2: 93.94 | K2: 11.01 | L2: 8.96 | M2: 99.96 | N2: 15.46
A3: 1 | B3: 100 | C3: 0.15 | D3: 0.46 | E3: 0.26 | F3: 2.57 | G3: 3.83 | H3: 2.71 | I3: 0 | J3: 0 | K3: 0 | L3: 2.81 | M3: 4.25 | N3: 2.97
A4: 0 | B4: 200 | C4: 2.7 | D4: 2.91 | E4: 2.78 | F4: 2.88 | G4: 2.97 | H4: 2.92 | I4: 8.92 | J4: 18.44 | K4: 9.3 | L4: 14.59 | M4: 24.28 | N4: 15.01
A5: 1 | B5: 200 | C5: 0.2 | D5: 0.34 | E5: 0.26 | F5: 4.93 | G5: 5.18 | H5: 4.96 | I5: 0 | J5: 0 | K5: 0 | L5: 5.13 | M5: 5.46 | N5: 5.22
A6: 0 | B6: 300 | C6: 2.87 | D6: 3.07 | E6: 2.96 | F6: 4 | G6: 4.08 | H6: 4.03 | I6: 9.44 | J6: 11.3 | K6: 9.92 | L6: 16.39 | M6: 18.41 | N6: 16.92
A7: 1 | B7: 300 | C7: 0.21 | D7: 0.35 | E7: 0.27 | F7: 7.25 | G7: 7.37 | H7: 7.3 | I7: 0 | J7: 0 | K7: 0 | L7: 7.46 | M7: 7.71 | N7: 7.57
A8: 0 | B8: 400 | C8: 3 | D8: 3.3 | E8: 3.12 | F8: 5.11 | G8: 5.27 | H8: 5.16 | I8: 9.99 | J8: 19.89 | K8: 10.27 | L8: 18.21 | M8: 28.38 | N8: 18.55
A9: 1 | B9: 400 | C9: 0.19 | D9: 0.35 | E9: 0.27 | F9: 9.56 | G9: 10.02 | H9: 9.62 | I9: 0 | J9: 0 | K9: 0 | L9: 9.77 | M9: 10.33 | N9: 9.89
A10: 0 | B10: 500 | C10: 3.22 | D10: 3.52 | E10: 3.33 | F10: 6.37 | G10: 6.49 | H10: 6.42 | I10: 11.05 | J10: 12.92 | K10: 11.29 | L10: 20.76 | M10: 22.77 | N10: 21.05
A11: 1 | B11: 500 | C11: 0.18 | D11: 0.37 | E11: 0.27 | F11: 12.15 | G11: 12.45 | H11: 12.24 | I11: 0 | J11: 0 | K11: 0 | L11: 12.39 | M11: 12.73 | N11: 12.51
A12: 0 | B12: 600 | C12: 3.47 | D12: 3.69 | E12: 3.57 | F12: 7.41 | G12: 7.6 | H12: 7.49 | I12: 12.33 | J12: 13.77 | K12: 12.57 | L12: 23.36 | M12: 24.93 | N12: 23.63
A13: 1 | B13: 600 | C13: 0.14 | D13: 0.36 | E13: 0.27 | F13: 14.49 | G13: 14.85 | H13: 14.6 | I13: 0 | J13: 0 | K13: 0 | L13: 14.74 | M13: 15.08 | N13: 14.88
... A49: 1 | B49: 2400 | C49: 0.08 | D49: 0.37 | E49: 0.22 | F49: 56.76 | G49: 57.32 | H49: 57.01 | I49: 0 | J49: 0 | K49: 0 | L49: 56.89 | M49: 57.51 | N49: 57.24
A50: 0 | B50: 2500 | C50: 0 | D50: 0 | E50: NaN | F50: 0 | G50: 0 | H50: NaN | I50: 0 | J50: 0 | K50: NaN | L50: 0 | M50: 0 | N50: NaN
A51: 1 | B51: 2500 | C51: 0 | D51: 0 | E51: NaN | F51: 0 | G51: 0 | H51: NaN | I51: 0 | J51: 0 | K51: NaN | L51: 0 | M51: 0 | N51: NaN

Sheet Test_Data_2018rc1
A1: Core | B1: Rate | C1: ISRs (Min) | D1: ISRs (Max) | E1: ISRs (Max) | F1: TL (min) | G1: TL (max) | H1: TL (Mean) | I1: Other (Min) | J1: Other (Max) | K1: Other (Mean) | L1: Total (min) | M1: Total (max) | N1: Total (Mean) | Q1: Total Mean
A2: 0 | B2: 100 | C2: 0.05 | D2: 1.9 | E2: 0.7 | F2: 1.16 | G2: 89.82 | H2: 2.64 | I2: 3.65 | J2: 87.07 | K2: 9.6 | L2: 5.04 | M2: 99.98 | N2: 12.94 | P2: 100 | Q2: =AVERAGE(N2:N3) -> 8.56
A3: 1 | B3: 100 | C3: 0.61 | D3: 2.05 | E3: 1.56 | F3: 2.23 | G3: 3.73 | H3: 2.61 | I3: 0 | J3: 0.14 | K3: 0.01 | L3: 3.27 | M3: 5.59 | N3: 4.18 | P3: =P2+100 -> 200 | Q3: =AVERAGE(N4:N5) -> 9.325
A4: 0 | B4: 200 | C4: 0.5 | D4: 1.76 | E4: 1.19 | F4: 2.95 | G4: 3.07 | H4: 2.99 | I4: 7.82 | J4: 17.3 | K4: 8.24 | L4: 11.55 | M4: 21.7 | N4: 12.42 | P4: =P3+100 -> 300 | Q4: =AVERAGE(N6:N7) -> 11.525
A5: 1 | B5: 200 | C5: 0.73 | D5: 1.95 | E5: 1.33 | F5: 4.8 | G5: 5.09 | H5: 4.9 | I5: 0 | J5: 0.2 | K5: 0 | L5: 5.63 | M5: 6.82 | N5: 6.23 | P5: =P4+100 -> 400 | Q5: =AVERAGE(N8:N9) -> 13.275
A6: 0 | B6: 300 | C6: 0.42 | D6: 1.27 | E6: 0.79 | F6: 4.12 | G6: 4.23 | H6: 4.18 | I6: 8.48 | J6: 19.14 | K6: 8.99 | L6: 13.23 | M6: 24.38 | N6: 13.97 | P6: =P5+100 -> 500 | Q6: =AVERAGE(N10:N11) -> 16.605
A7: 1 | B7: 300 | C7: 1.43 | D7: 2.3 | E7: 1.92 | F7: 7.1 | G7: 7.55 | H7: 7.16 | I7: 0 | J7: 0.07 | K7: 0.01 | L7: 8.53 | M7: 9.56 | N7: 9.08 | P7: =P6+100 -> 600 | Q7: =AVERAGE(N12:N13) -> 18.22
A8: 0 | B8: 400 | C8: 1.6 | D8: 1.99 | E8: 1.82 | F8: 5.24 | G8: 5.4 | H8: 5.3 | I8: 8.86 | J8: 12.52 | K8: 9.09 | L8: 15.86 | M8: 19.72 | N8: 16.22 | P8: =P7+100 -> 700 | Q8: =AVERAGE(N14:N15) -> 21.385
A9: 1 | B9: 400 | C9: 0.85 | D9: 1.28 | E9: 1.06 | F9: 9.19 | G9: 9.38 | H9: 9.26 | I9: 0 | J9: 0.04 | K9: 0 | L9: 10.03 | M9: 10.65 | N9: 10.33 | P9: =P8+100 -> 800 | Q9: =AVERAGE(N16:N17) -> 22.78
A10: 0 | B10: 500 | C10: 1.45 | D10: 2.18 | E10: 1.79 | F10: 6.52 | G10: 6.78 | H10: 6.6 | I10: 9.99 | J10: 33.35 | K10: 11.76 | L10: 18.3 | M10: 41.9 | N10: 20.15 | P10: =P9+100 -> 900 | Q10: =AVERAGE(N18:N19) -> 25.45
A11: 1 | B11: 500 | C11: 1.04 | D11: 1.83 | E11: 1.32 | F11: 11.57 | G11: 12.24 | H11: 11.74 | I11: 0 | J11: 0.08 | K11: 0 | L11: 12.73 | M11: 14.03 | N11: 13.06 | P11: =P10+100 -> 1000 | Q11: =AVERAGE(N20:N21) -> 27.565
A12: 0 | B12: 600 | C12: 0.95 | D12: 1.7 | E12: 1.33 | F12: 7.63 | G12: 7.86 | H12: 7.74 | I12: 10.92 | J12: 19.97 | K12: 11.43 | L12: 19.75 | M12: 29.21 | N12: 20.51 | P12: =P11+100 -> 1100 | Q12: =AVERAGE(N22:N23) -> 29.52
A13: 1 | B13: 600 | C13: 1.55 | D13: 2.37 | E13: 1.93 | F13: 13.82 | G13: 14.29 | H13: 14 | I13: 0 | J13: 0.07 | K13: 0.01 | L13: 15.61 | M13: 16.51 | N13: 15.93 | P13: =P12+100 -> 1200 | Q13: =AVERAGE(N24:N25) -> 31.995
A14: 0 | B14: 700 | C14: 1.79 | D14: 2.51 | E14: 1.99 | F14: 8.98 | G14: 9.3 | H14: 9.11 | I14: 11.55 | J14: 35.64 | K14: 13.84 | L14: 22.42 | M14: 47.16 | N14: 24.95 | P14: =P13+100 -> 1300 | Q14: =AVERAGE(N26:N27) -> 33.71
A15: 1 | B15: 700 | C15: 1.27 | D15: 1.66 | E15: 1.46 | F15: 16.13 | G15: 17.34 | H15: 16.35 | I15: 0 | J15: 0.06 | K15: 0 | L15: 17.52 | M15: 18.78 | N15: 17.82 | P15: =P14+100 -> 1400 | Q15: =AVERAGE(N28:N29) -> 35.835
A16: 0 | B16: 800 | C16: 1.73 | D16: 2.19 | E16: 1.95 | F16: 10.16 | G16: 10.39 | H16: 10.3 | I16: 12.51 | J16: 29.38 | K16: 13.29 | L16: 24.61 | M16: 41.83 | N16: 25.53 | P16: =P15+100 -> 1500 | Q16: =AVERAGE(N30:N31) -> 40.4
A17: 1 | B17: 800 | C17: 1.45 | D17: 1.89 | E17: 1.65 | F17: 18.15 | G17: 19.09 | H17: 18.38 | I17: 0 | J17: 0.04 | K17: 0 | L17: 19.71 | M17: 20.79 | N17: 20.03 | P17: =P16+100 -> 1600 | Q17: =AVERAGE(N32:N33) -> 42.285
A18: 0 | B18: 900 | C18: 0.42 | D18: 1.11 | E18: 0.76 | F18: 11.37 | G18: 11.76 | H18: 11.58 | I18: 13.22 | J18: 42.61 | K18: 14.77 | L18: 25.29 | M18: 55.06 | N18: 27.11 | P18: =P17+100 -> 1700 | Q18: =AVERAGE(N34:N35) -> 42.705
A19: 1 | B19: 900 | C19: 2.61 | D19: 3.48 | E19: 3.03 | F19: 20.35 | G19: 21.87 | H19: 20.72 | I19: 0 | J19: 0.36 | K19: 0.03 | L19: 23.34 | M19: 25.72 | N19: 23.79 | P19: =P18+100 -> 1800 | Q19: =AVERAGE(N36:N37) -> 44.59
A20: 0 | B20: 1000 | C20: 1.54 | D20: 2.22 | E20: 1.85 | F20: 12.72 | G20: 13.16 | H20: 12.84 | I20: 13.75 | J20: 45.41 | K20: 15.8 | L20: 28.13 | M20: 60.79 | N20: 30.48 | P20: 1900 | Q20: =AVERAGE(N38:N39) -> #DIV/0!
A21: 1 | B21: 1000 | C21: 1.66 | D21: 2.24 | E21: 1.94 | F21: 22.47 | G21: 23.87 | H21: 22.7 | I21: 0 | J21: 0.08 | K21: 0.01 | L21: 24.32 | M21: 25.96 | N21: 24.65
A22: 0 | B22: 1100 | C22: 1.63 | D22: 2.15 | E22: 1.89 | F22: 13.86 | G22: 14.35 | H22: 14.06 | I22: 14.21 | J22: 47.4 | K22: 15.82 | L22: 30.1 | M22: 63.89 | N22: 31.77
A23: 1 | B23: 1100 | C23: 1.84 | D23: 2.39 | E23: 2.09 | F23: 24.96 | G23: 26.31 | H23: 25.17 | I23: 0 | J23: 0.11 | K23: 0.01 | L23: 26.88 | M23: 28.73 | N23: 27.27
A24: 0 | B24: 1200 | C24: 1.77 | D24: 2.44 | E24: 1.99 | F24: 15.41 | G24: 15.93 | H24: 15.61 | I24: 15.27 | J24: 49.93 | K24: 16.85 | L24: 32.7 | M24: 68.3 | N24: 34.45
A25: 1 | B25: 1200 | C25: 1.95 | D25: 2.29 | E25: 2.11 | F25: 27.25 | G25: 28.82 | H25: 27.42 | I25: 0 | J25: 0.05 | K25: 0.01 | L25: 29.28 | M25: 31.16 | N25: 29.54
A26: 0 | B26: 1300 | C26: 1.56 | D26: 2.02 | E26: 1.79 | F26: 16.56 | G26: 16.98 | H26: 16.76 | I26: 15.85 | J26: 34.31 | K26: 16.73 | L26: 34.26 | M26: 53.14 | N26: 35.27
A27: 1 | B27: 1300 | C27: 2.29 | D27: 2.73 | E27: 2.48 | F27: 29.43 | G27: 30.8 | H27: 29.66 | I27: 0 | J27: 0.07 | K27: 0.01 | L27: 31.76 | M27: 33.49 | N27: 32.15
A28: 0 | B28: 1400 | C28: 1.55 | D28: 2.03 | E28: 1.8 | F28: 17.8 | G28: 18.28 | H28: 17.95 | I28: 16.55 | J28: 38.98 | K28: 17.39 | L28: 36.01 | M28: 59.08 | N28: 37.14
A29: 1 | B29: 1400 | C29: 2.47 | D29: 3 | E29: 2.71 | F29: 31.57 | G29: 33.03 | H29: 31.81 | I29: 0 | J29: 0.07 | K29: 0.01 | L29: 34.23 | M29: 35.77 | N29: 34.53
A30: 0 | B30: 1500 | C30: 1.48 | D30: 2.2 | E30: 1.77 | F30: 19.04 | G30: 19.76 | H30: 19.41 | I30: 17.3 | J30: 46.83 | K30: 22.51 | L30: 38.14 | M30: 68.37 | N30: 43.69
A31: 1 | B31: 1500 | C31: 2.6 | D31: 3.39 | E31: 2.93 | F31: 33.6 | G31: 35.48 | H31: 34.16 | I31: 0 | J31: 0.18 | K31: 0.02 | L31: 36.41 | M31: 38.9 | N31: 37.11
A32: 0 | B32: 1600 | C32: 1.95 | D32: 2.53 | E32: 2.2 | F32: 20.74 | G32: 21.64 | H32: 21.01 | I32: 18.32 | J32: 54.13 | K32: 22.41 | L32: 41.32 | M32: 78.23 | N32: 45.62
... A37: 1 | B37: 1800 | C37: 3.64 | D37: 4.46 | E37: 4.07 | F37: 40.03 | G37: 41.66 | H37: 40.39 | I37: 0 | J37: 0.4 | K37: 0.07 | L37: 43.7 | M37: 46.34 | N37: 44.53
A40: Software | B40: Version
A41: CompactRIO Support | B41: 18
A42: Hardware Configuration Web Support | B42: 18.0.0
A43: LabVIEW Real-Time | B43: 18.0.0
A44: Network Configuration Web Support | B44: 18.0.0
A45: Network Streams | B45: 18
A46: NI System Configuration | B46: 18.0.0
...

Sheet Test_Data_2018b10
A1: Core | B1: Rate | C1: ISRs (Min) | D1: ISRs (Max) | E1: ISRs (Max) | F1: TL (min) | G1: TL (max) | H1: TL (Mean) | I1: Other (Min) | J1: Other (Max) | K1: Other (Mean) | L1: Total (min) | M1: Total (max) | N1: Total (Mean) | Q1: Total Mean
A2: 0 | B2: 100 | C2: 0 | D2: 2.58 | E2: 0.77 | F2: 1.15 | G2: 94.81 | H2: 2.59 | I2: 3.53 | J2: 86.44 | K2: 9.98 | L2: 5.24 | M2: 99.97 | N2: 13.34 | P2: 100 | Q2: =AVERAGE(N2:N3) -> 8.755
A3: 1 | B3: 100 | C3: 0.71 | D3: 2.06 | E3: 1.54 | F3: 2.27 | G3: 3.73 | H3: 2.62 | I3: 0 | J3: 0.25 | K3: 0 | L3: 3.04 | M3: 5.65 | N3: 4.17 | P3: =P2+100 -> 200 | Q3: =AVERAGE(N4:N5) -> 9.17
A4: 0 | B4: 200 | C4: 0.42 | D4: 1.72 | E4: 1.19 | F4: 2.88 | G4: 2.98 | H4: 2.93 | I4: 7.6 | J4: 16.6 | K4: 7.91 | L4: 11.27 | M4: 21.01 | N4: 12.04 | P4: =P3+100 -> 300 | Q4: =AVERAGE(N6:N7) -> 11.295
A5: 1 | B5: 200 | C5: 0.86 | D5: 2.09 | E5: 1.37 | F5: 4.85 | G5: 5.15 | H5: 4.93 | I5: 0 | J5: 0.09 | K5: 0 | L5: 5.71 | M5: 7.04 | N5: 6.3 | P5: =P4+100 -> 400 | Q5: =AVERAGE(N8:N9) -> 13.27
A6: 0 | B6: 300 | C6: 0.35 | D6: 1.06 | E6: 0.73 | F6: 4.02 | G6: 4.19 | H6: 4.07 | I6: 8.35 | J6: 8.85 | K6: 8.54 | L6: 12.8 | M6: 13.92 | N6: 13.34 | P6: =P5+100 -> 500 | Q6: =AVERAGE(N10:N11) -> 16.005
A7: 1 | B7: 300 | C7: 1.68 | D7: 2.41 | E7: 1.98 | F7: 7.16 | G7: 7.49 | H7: 7.26 | I7: 0 | J7: 0.09 | K7: 0.01 | L7: 8.88 | M7: 9.64 | N7: 9.25 | P7: =P6+100 -> 600 | Q7: =AVERAGE(N12:N13) -> 18.145
A8: 0 | B8: 400 | C8: 1.5 | D8: 2.07 | E8: 1.84 | F8: 5.13 | G8: 5.29 | H8: 5.2 | I8: 8.56 | J8: 30.78 | K8: 9.01 | L8: 15.47 | M8: 38.14 | N8: 16.04 | P8: =P7+100 -> 700 | Q8: =AVERAGE(N14:N15) -> 20.655
A9: 1 | B9: 400 | C9: 0.86 | D9: 1.44 | E9: 1.1 | F9: 9.31 | G9: 9.82 | H9: 9.38 | I9: 0 | J9: 0.13 | K9: 0.01 | L9: 10.22 | M9: 11.26 | N9: 10.5 | P9: =P8+100 -> 800 | Q9: =AVERAGE(N16:N17) -> 22.485
A10: 0 | B10: 500 | C10: 1.5 | D10: 1.99 | E10: 1.8 | F10: 6.45 | G10: 6.63 | H10: 6.54 | I10: 9.98 | J10: 19.84 | K10: 10.42 | L10: 18.2 | M10: 28.32 | N10: 18.75 | P10: =P9+100 -> 900 | Q10: =AVERAGE(N18:N19) -> 24.48
A11: 1 | B11: 500 | C11: 1.14 | D11: 1.58 | E11: 1.36 | F11: 11.76 | G11: 12.74 | H11: 11.89 | I11: 0 | J11: 0.07 | K11: 0.01 | L11: 13.02 | M11: 14.2 | N11: 13.26 | P11: =P10+100 -> 1000 | Q11: =AVERAGE(N20:N21) -> 26.625
A12: 0 | B12: 600 | C12: 0.72 | D12: 1.74 | E12: 1.4 | F12: 7.55 | G12: 7.81 | H12: 7.66 | I12: 10.83 | J12: 28.05 | K12: 11.19 | L12: 19.34 | M12: 37.6 | N12: 20.25 | P12: =P11+100 -> 1100 | Q12: =AVERAGE(N22:N23) -> 28.85
A13: 1 | B13: 600 | C13: 1.55 | D13: 2.6 | E13: 1.95 | F13: 13.91 | G13: 14.51 | H13: 14.08 | I13: 0 | J13: 0.09 | K13: 0.01 | L13: 15.69 | M13: 16.55 | N13: 16.04 | P13: =P12+100 -> 1200 | Q13: =AVERAGE(N24:N25) -> 31.21
A14: 0 | B14: 700 | C14: 1.62 | D14: 2.33 | E14: 1.89 | F14: 8.89 | G14: 9.18 | H14: 8.98 | I14: 11.53 | J14: 53.14 | K14: 12.32 | L14: 22.22 | M14: 64.65 | N14: 23.18 | P14: =P13+100 -> 1300 | Q14: =AVERAGE(N26:N27) -> 33.415
A15: 1 | B15: 700 | C15: 1.42 | D15: 1.88 | E15: 1.63 | F15: 16.36 | G15: 17.91 | H15: 16.5 | I15: 0 | J15: 0.05 | K15: 0.01 | L15: 17.84 | M15: 19.75 | N15: 18.13 | P15: =P14+100 -> 1400 | Q15: =AVERAGE(N28:N29) -> 35.68
A16: 0 | B16: 800 | C16: 1.87 | D16: 2.21 | E16: 2.04 | F16: 10.09 | G16: 10.27 | H16: 10.16 | I16: 12.34 | J16: 15.38 | K16: 12.67 | L16: 24.48 | M16: 27.81 | N16: 24.87 | P16: =P15+100 -> 1500 | Q16: =AVERAGE(N30:N31) -> 37.755
A17: 1 | B17: 800 | C17: 1.44 | D17: 1.81 | E17: 1.63 | F17: 18.29 | G17: 18.88 | H17: 18.47 | I17: 0 | J17: 0.02 | K17: 0 | L17: 19.83 | M17: 20.59 | N17: 20.1 | P17: =P16+100 -> 1600 | Q17: =AVERAGE(N32:N33) -> 40.52
A18: 0 | B18: 900 | C18: 0.61 | D18: 1.08 | E18: 0.8 | F18: 11.26 | G18: 11.55 | H18: 11.4 | I18: 12.87 | J18: 13.32 | K18: 13.09 | L18: 24.96 | M18: 25.7 | N18: 25.28 | P18: =P17+100 -> 1700 | Q18: =AVERAGE(N34:N35) -> 42.625
A19: 1 | B19: 900 | C19: 2.64 | D19: 3.32 | E19: 3.02 | F19: 20.53 | G19: 20.74 | H19: 20.64 | I19: 0 | J19: 0.11 | K19: 0.02 | L19: 23.28 | M19: 24.02 | N19: 23.68 | P19: =P18+100 -> 1800 | Q19: =AVERAGE(N36:N37) -> 44.55
A20: 0 | B20: 1000 | C20: 1.66 | D20: 2.13 | E20: 1.93 | F20: 12.53 | G20: 12.97 | H20: 12.7 | I20: 13.52 | J20: 23.77 | K20: 13.88 | L20: 28.02 | M20: 38.58 | N20: 28.51 | P20: 1900 | Q20: =AVERAGE(N38:N39) -> 47.44
A21: 1 | B21: 1000 | C21: 1.71 | D21: 2.16 | E21: 1.9 | F21: 22.6 | G21: 23.58 | H21: 22.83 | I21: 0 | J21: 0.05 | K21: 0.01 | L21: 24.32 | M21: 25.53 | N21: 24.74
A22: 0 | B22: 1100 | C22: 1.43 | D22: 1.95 | E22: 1.69 | F22: 13.84 | G22: 14.07 | H22: 13.95 | I22: 14.34 | J22: 17.86 | K22: 14.59 | L22: 29.91 | M22: 33.48 | N22: 30.23
A23: 1 | B23: 1100 | C23: 2.13 | D23: 2.64 | E23: 2.4 | F23: 24.91 | G23: 25.39 | H23: 25.07 | I23: 0 | J23: 0.07 | K23: 0.01 | L23: 27.13 | M23: 27.86 | N23: 27.47
A24: 0 | B24: 1200 | C24: 1.69 | D24: 2.12 | E24: 1.9 | F24: 15.22 | G24: 15.5 | H24: 15.33 | I24: 15.07 | J24: 25.74 | K24: 15.4 | L24: 32.06 | M24: 43.07 | N24: 32.63
A25: 1 | B25: 1200 | C25: 2.09 | D25: 2.51 | E25: 2.33 | F25: 27.28 | G25: 28.41 | H25: 27.45 | I25: 0 | J25: 0.07 | K25: 0.01 | L25: 29.42 | M25: 30.85 | N25: 29.79
A26: 0 | B26: 1300 | C26: 1.68 | D26: 2.19 | E26: 1.91 | F26: 16.45 | G26: 16.72 | H26: 16.58 | I26: 15.65 | J26: 19.37 | K26: 16.03 | L26: 34.02 | M26: 37.85 | N26: 34.52
A27: 1 | B27: 1300 | C27: 2.33 | D27: 2.77 | E27: 2.55 | F27: 29.51 | G27: 30.13 | H27: 29.75 | I27: 0 | J27: 0.05 | K27: 0.01 | L27: 31.94 | M27: 32.69 | N27: 32.31
A28: 0 | B28: 1400 | C28: 1.79 | D28: 2.12 | E28: 1.97 | F28: 17.74 | G28: 17.97 | H28: 17.85 | I28: 16.61 | J28: 17.19 | K28: 16.83 | L28: 36.38 | M28: 36.94 | N28: 36.65
A29: 1 | B29: 1400 | C29: 2.43 | D29: 2.9 | E29: 2.66 | F29: 31.82 | G29: 32.33 | H29: 32.04 | I29: 0 | J29: 0.04 | K29: 0 | L29: 34.39 | M29: 34.96 | N29: 34.71
A30: 0 | B30: 1500 | C30: 1.56 | D30: 2.21 | E30: 1.91 | F30: 18.86 | G30: 19.41 | H30: 19.13 | I30: 16.9 | J30: 27.94 | K30: 17.27 | L30: 37.83 | M30: 49.23 | N30: 38.31
A31: 1 | B31: 1500 | C31: 2.61 | D31: 3.33 | E31: 2.87 | F31: 34.1 | G31: 35.37 | H31: 34.32 | I31: 0 | J31: 0.07 | K31: 0.01 | L31: 36.77 | M31: 38.23 | N31: 37.2
A32: 0 | B32: 1600 | C32: 1.99 | D32: 2.43 | E32: 2.17 | F32: 20.47 | G32: 20.87 | H32: 20.64 | I32: 18 | J32: 32.91 | K32: 18.52 | L32: 40.72 | M32: 55.72 | N32: 41.33
... A39: 1 | B39: 1900 | C39: 3.19 | D39: 3.74 | E39: 3.49 | F39: 43.68 | G39: 44.28 | H39: 43.92 | I39: 0 | J39: 0.06 | K39: 0.01 | L39: 47.03 | M39: 47.83 | N39: 47.42
A42: Software | B42: Version
A43: CompactRIO Support | B43: 18
A44: Hardware Configuration Web Support | B44: 16.0.0
A45: LabVIEW Real-Time | B45: 18.0.0
A46: Network Configuration Web Support | B46: 16.0.0
A47: Network Streams | B47: 18
A48: NI System Configuration | B48: 17.5.0
...

Sheet Test_Data_2017
A1: Core | B1: Rate | C1: ISRs (Min) | D1: ISRs (Max) | E1: ISRs (Max) | F1: TL (min) | G1: TL (max) | H1: TL (Mean) | I1: Other (Min) | J1: Other (Max) | K1: Other (Mean) | L1: Total (min) | M1: Total (max) | N1: Total (Mean) | Q1: Total Mean
A2: 0 | B2: 100 | C2: 0.08 | D2: 2.79 | E2: 1.12 | F2: 1.26 | G2: 94.38 | H2: 2.69 | I2: 5.53 | J2: 96.53 | K2: 19.44 | L2: 9.5 | M2: 100 | N2: 23.25 | P2: 100 | Q2: =AVERAGE(N2:N3) -> 13.75
A3: 1 | B3: 100 | C3: 0.56 | D3: 1.88 | E3: 1.32 | F3: 2.45 | G3: 4.36 | H3: 2.92 | I3: 0 | J3: 0.12 | K3: 0.01 | L3: 3.3 | M3: 6.12 | N3: 4.25 | P3: =P2+100 -> 200 | Q3: =AVERAGE(N4:N5) -> 10.285
A4: 0 | B4: 200 | C4: 0.92 | D4: 1.95 | E4: 1.52 | F4: 2.98 | G4: 3.13 | H4: 3.02 | I4: 8.17 | J4: 43.48 | K4: 9.73 | L4: 12.26 | M4: 48.36 | N4: 14.27 | P4: =P3+100 -> 300 | Q4: =AVERAGE(N6:N7) -> 12.245
A5: 1 | B5: 200 | C5: 0.73 | D5: 1.64 | E5: 1.06 | F5: 5.16 | G5: 5.88 | H5: 5.24 | I5: 0 | J5: 0.04 | K5: 0 | L5: 5.96 | M5: 7.48 | N5: 6.3 | P5: =P4+100 -> 400 | Q5: =AVERAGE(N8:N9) -> 14.155
A6: 0 | B6: 300 | C6: 0.71 | D6: 1.53 | E6: 1.14 | F6: 4.16 | G6: 4.33 | H6: 4.21 | I6: 8.94 | J6: 33.66 | K6: 9.89 | L6: 14 | M6: 39.3 | N6: 15.23 | P6: =P5+100 -> 500 | Q6: =AVERAGE(N10:N11) -> 16.44
A7: 1 | B7: 300 | C7: 1.21 | D7: 2.06 | E7: 1.58 | F7: 7.57 | G7: 8.32 | H7: 7.67 | I7: 0 | J7: 0.12 | K7: 0.01 | L7: 8.9 | M7: 10.19 | N7: 9.26 | P7: =P6+100 -> 600 | Q7: =AVERAGE(N12:N13) -> 18.71
A8: 0 | B8: 400 | C8: 1.3 | D8: 1.91 | E8: 1.68 | F8: 5.28 | G8: 5.52 | H8: 5.35 | I8: 9.58 | J8: 13.02 | K8: 9.94 | L8: 16.48 | M8: 20.26 | N8: 16.97 | P8: =P7+100 -> 700 | Q8: =AVERAGE(N14:N15) -> 20.745
A9: 1 | B9: 400 | C9: 0.97 | D9: 1.57 | E9: 1.18 | F9: 10.03 | G9: 10.57 | H9: 10.17 | I9: 0 | J9: 0.03 | K9: 0 | L9: 11.06 | M9: 11.65 | N9: 11.34 | P9: =P8+100 -> 800 | Q9: =AVERAGE(N16:N17) -> 23.205
A10: 0 | B10: 500 | C10: 1.47 | D10: 1.95 | E10: 1.71 | F10: 6.4 | G10: 6.71 | H10: 6.56 | I10: 10.34 | J10: 13.69 | K10: 10.78 | L10: 18.49 | M10: 22.13 | N10: 19.04 | P10: =P9+100 -> 900 | Q10: =AVERAGE(N18:N19) -> 25.48
A11: 1 | B11: 500 | C11: 1.14 | D11: 1.6 | E11: 1.34 | F11: 12.36 | G11: 12.83 | H11: 12.49 | I11: 0 | J11: 0.05 | K11: 0 | L11: 13.53 | M11: 14.22 | N11: 13.84 | P11: =P10+100 -> 1000 | Q11: =AVERAGE(N20:N21) -> 27.355
A12: 0 | B12: 600 | C12: 1.2 | D12: 1.86 | E12: 1.61 | F12: 7.73 | G12: 7.92 | H12: 7.83 | I12: 11.05 | J12: 19.69 | K12: 11.55 | L12: 20.34 | M12: 29.23 | N12: 20.98 | P12: =P11+100 -> 1100 | Q12: =AVERAGE(N22:N23) -> 29.85
A13: 1 | B13: 600 | C13: 1.32 | D13: 2.02 | E13: 1.59 | F13: 14.72 | G13: 15.4 | H13: 14.84 | I13: 0 | J13: 0.06 | K13: 0 | L13: 16.14 | M13: 17.07 | N13: 16.44 | P13: =P12+100 -> 1200 | Q13: =AVERAGE(N24:N25) -> 31.965
A14: 0 | B14: 700 | C14: 1.49 | D14: 1.94 | E14: 1.75 | F14: 8.94 | G14: 9.1 | H14: 9.01 | I14: 11.69 | J14: 15.14 | K14: 11.98 | L14: 22.28 | M14: 26.02 | N14: 22.74 | P14: =P13+100 -> 1300 | Q14: =AVERAGE(N26:N27) -> 34.155
A15: 1 | B15: 700 | C15: 1.35 | D15: 1.94 | E15: 1.61 | F15: 17 | G15: 17.49 | H15: 17.14 | I15: 0 | J15: 0.04 | K15: 0 | L15: 18.53 | M15: 19.2 | N15: 18.75 | P15: =P14+100 -> 1400 | Q15: =AVERAGE(N28:N29) -> 34.58
A16: 0 | B16: 800 | C16: 1.74 | D16: 2.2 | E16: 1.97 | F16: 10.2 | G16: 10.38 | H16: 10.29 | I16: 12.49 | J16: 18.8 | K16: 13.22 | L16: 24.6 | M16: 31.38 | N16: 25.48 | P16: =P15+100 -> 1500 | Q16: =AVERAGE(N30:N31) -> 38.885
A17: 1 | B17: 800 | C17: 1.37 | D17: 1.75 | E17: 1.56 | F17: 19.18 | G17: 19.91 | H17: 19.37 | I17: 0 | J17: 0.03 | K17: 0 | L17: 20.64 | M17: 21.37 | N17: 20.93 | P17: =P16+100 -> 1600 | Q17: =AVERAGE(N32:N33) -> 43.08
A18: 0 | B18: 900 | C18: 0.74 | D18: 1.28 | E18: 0.95 | F18: 11.46 | G18: 11.68 | H18: 11.55 | I18: 13.13 | J18: 41.21 | K18: 13.98 | L18: 25.46 | M18: 53.9 | N18: 26.48 | P18: =P17+100 -> 1700 | Q18: =AVERAGE(N34:N35) -> 44.79
A19: 1 | B19: 900 | C19: 2.42 | D19: 3.07 | E19: 2.7 | F19: 21.47 | G19: 22.72 | H19: 21.78 | I19: 0 | J19: 0.09 | K19: 0.01 | L19: 24.02 | M19: 25.86 | N19: 24.48 | P19: =P18+100 -> 1800 | Q19: =AVERAGE(N36:N37) -> 46.87
A20: 0 | B20: 1000 | C20: 1.61 | D20: 2.09 | E20: 1.84 | F20: 12.35 | G20: 13.05 | H20: 12.61 | I20: 13.75 | J20: 19.73 | K20: 14.56 | L20: 28.08 | M20: 34.27 | N20: 29.01 | P20: 1900 | Q20: =AVERAGE(N38:N39) -> 46.605
A21: 1 | B21: 1000 | C21: 1.6 | D21: 2.16 | E21: 1.86 | F21: 23.64 | G21: 24.26 | H21: 23.84 | I21: 0 | J21: 0.04 | K21: 0.01 | L21: 25.32 | M21: 26.14 | N21: 25.7 | P21: 2000 | Q21: =AVERAGE(N40:N41) -> 51.09
A22: 0 | B22: 1100 | C22: 1.72 | D22: 2.09 | E22: 1.94 | F22: 14.15 | G22: 14.34 | H22: 14.24 | I22: 14.54 | J22: 24.94 | K22: 15.18 | L22: 30.65 | M22: 41.35 | N22: 31.36 | P22: 2100 | Q22: =AVERAGE(N42:N43) -> 53.805
A23: 1 | B23: 1100 | C23: 1.72 | D23: 2.23 | E23: 1.96 | F23: 26.18 | G23: 27.4 | H23: 26.37 | I23: 0 | J23: 0.05 | K23: 0 | L23: 28.01 | M23: 29.23 | N23: 28.34
A24: 0 | B24: 1200 | C24: 1.89 | D24: 2.24 | E24: 2.06 | F24: 15.42 | G24: 15.62 | H24: 15.5 | I24: 15 | J24: 19.5 | K24: 15.73 | L24: 32.44 | M24: 37.28 | N24: 33.29
A25: 1 | B25: 1200 | C25: 1.91 | D25: 2.2 | E25: 2.04 | F25: 28.45 | G25: 28.85 | H25: 28.6 | I25: 0 | J25: 0.03 | K25: 0 | L25: 30.43 | M25: 30.94 | N25: 30.64
A26: 0 | B26: 1300 | C26: 1.73 | D26: 2.2 | E26: 1.98 | F26: 16.51 | G26: 16.81 | H26: 16.64 | I26: 15.8 | J26: 23.03 | K26: 16.5 | L26: 34.34 | M26: 41.84 | N26: 35.12
A27: 1 | B27: 1300 | C27: 1.98 | D27: 2.46 | E27: 2.24 | F27: 30.68 | G27: 31.56 | H27: 30.95 | I27: 0 | J27: 0.03 | K27: 0.01 | L27: 32.91 | M27: 33.87 | N27: 33.19
A28: 0 | B28: 1400 | C28: 1.94 | D28: 2.34 | E28: 2.13 | F28: 17.52 | G28: 17.81 | H28: 17.69 | I28: 14.19 | J28: 21.3 | K28: 14.85 | L28: 33.92 | M28: 41.41 | N28: 34.66
A29: 1 | B29: 1400 | C29: 1.97 | D29: 2.34 | E29: 2.17 | F29: 32.12 | G29: 32.76 | H29: 32.32 | I29: 0 | J29: 0.03 | K29: 0 | L29: 34.1 | M29: 35.1 | N29: 34.5
A30: 0 | B30: 1500 | C30: 2.06 | D30: 2.64 | E30: 2.26 | F30: 18.54 | G30: 19.37 | H30: 18.87 | I30: 16.18 | J30: 45.34 | K30: 18.8 | L30: 37.03 | M30: 67.25 | N30: 39.92
A31: 1 | B31: 1500 | C31: 1.95 | D31: 2.42 | E31: 2.19 | F31: 35.19 | G31: 37.33 | H31: 35.66 | I31: 0 | J31: 0.06 | K31: 0.01 | L31: 37.32 | M31: 39.71 | N31: 37.85
A32: 0 | B32: 1600 | C32: 1.95 | D32: 2.56 | E32: 2.22 | F32: 20.46 | G32: 21.09 | H32: 20.73 | I32: 17.61 | J32: 45.04 | K32: 22.6 | L32: 40.31 | M32: 68.44 | N32: 45.55
A33: 1 | B33: 1600 | C33: 2.34 | D33: 2.77 | E33: 2.52 | F33: 37.61 | G33: 39.61 | H33: 38.08 | I33: 0 | J33: 0.16 | K33: 0.02 | L33: 40.02 | M33: 42.47 | N33: 40.61
A34: 0 | B34: 1700 | C34: 1.78 | D34: 2.39 | E34: 2.03 | F34: 22.21 | G34: 22.82 | H34: 22.49 | I34: 18.87 | J34: 52.66 | K34: 21.58 | L34: 43.19 | M34: 77.87 | N34: 46.1
... A43: 1 | B43: 2100 | C43: 3.33 | D43: 3.82 | E43: 3.53 | F43: 50.62 | G43: 53.14 | H43: 50.98 | I43: 0 | J43: 0.08 | K43: 0.01 | L43: 53.97 | M43: 56.79 | N43: 54.52
A44: 0 | B44: 2200 | C44: 0 | D44: 0 | E44: NaN | F44: 0 | G44: 0 | H44: NaN | I44: 0 | J44: 0 | K44: NaN | L44: 0 | M44: 0 | N44: NaN
A45: 1 | B45: 2200 | C45: 0 | D45: 0 | E45: NaN | F45: 0 | G45: 0 | H45: NaN | I45: 0 | J45: 0 | K45: NaN | L45: 0 | M45: 0 | N45: NaN

Sheet Test_Data_2017b6
A1: Core | B1: Rate | C1: ISRs (Min) | D1: ISRs (Max) | E1: ISRs (Max) | F1: TL (min) | G1: TL (max) | H1: TL (Mean) | I1: Other (Min) | J1: Other (Max) | K1: Other (Mean) | L1: Total (min) | M1: Total (max) | N1: Total (Mean) | Q1: Total Mean
A2: 0 | B2: 100 | C2: 0.25 | D2: 1.98 | E2: 0.87 | F2: 1.19 | G2: 2.62 | H2: 1.91 | I2: 3.86 | J2: 76.15 | K2: 8.92 | L2: 6.06 | M2: 79.68 | N2: 11.69 | P2: 100 | Q2: =AVERAGE(N2:N3) -> 7.915
A3: 1 | B3: 100 | C3: 0.56 | D3: 1.96 | E3: 1.38 | F3: 2.41 | G3: 3.83 | H3: 2.76 | I3: 0 | J3: 0.07 | K3: 0 | L3: 2.96 | M3: 4.98 | N3: 4.14 | P3: =P2+100 -> 200 | Q3: =AVERAGE(N4:N5) -> 9.725
A4: 0 | B4: 200 | C4: 0.73 | D4: 1.73 | E4: 1.31 | F4: 2.99 | G4: 3.12 | H4: 3.03 | I4: 8.33 | J4: 19.08 | K4: 8.64 | L4: 12.29 | M4: 23.38 | N4: 12.98 | P4: =P3+100 -> 300 | Q4: =AVERAGE(N6:N7) -> 11.98
A5: 1 | B5: 200 | C5: 0.8 | D5: 1.8 | E5: 1.23 | F5: 5.19 | G5: 5.4 | H5: 5.24 | I5: 0 | J5: 0.08 | K5: 0 | L5: 6.02 | M5: 7.01 | N5: 6.47 | P5: =P4+100 -> 400 | Q5: =AVERAGE(N8:N9) -> 14.2
A6: 0 | B6: 300 | C6: 0.79 | D6: 1.53 | E6: 1.15 | F6: 4.16 | G6: 4.27 | H6: 4.21 | I6: 9.13 | J6: 10.65 | K6: 9.32 | L6: 14.14 | M6: 16.11 | N6: 14.68 | P6: =P5+100 -> 500 | Q6: =AVERAGE(N10:N11) -> 16.505
A7: 1 | B7: 300 | C7: 1.15 | D7: 1.96 | E7: 1.55 | F7: 7.67 | G7: 7.83 | H7: 7.73 | I7: 0 | J7: 0.12 | K7: 0 | L7: 8.89 | M7: 9.81 | N7: 9.28 | P7: =P6+100 -> 600 | Q7: =AVERAGE(N12:N13) -> 18.835
A8: 0 | B8: 400 | C8: 1.24 | D8: 1.95 | E8: 1.69 | F8: 5.31 | G8: 5.48 | H8: 5.37 | I8: 9.75 | J8: 10.12 | K8: 9.93 | L8: 16.52 | M8: 17.27 | N8: 16.99 | P8: =P7+100 -> 700 | Q8: =AVERAGE(N14:N15) -> 20.985
A9: 1 | B9: 400 | C9: 0.89 | D9: 1.62 | E9: 1.19 | F9: 10.11 | G9: 10.44 | H9: 10.22 | I9: 0 | J9: 0.03 | K9: 0 | L9: 11.14 | M9: 11.8 | N9: 11.41 | P9: =P8+100 -> 800 | Q9: =AVERAGE(N16:N17) -> 23.17
A10: 0 | B10: 500 | C10: 1.43 | D10: 2.02 | E10: 1.76 | F10: 6.49 | G10: 6.71 | H10: 6.56 | I10: 10.53 | J10: 13.23 | K10: 10.75 | L10: 18.68 | M10: 21.56 | N10: 19.07 | P10: =P9+100 -> 900 | Q10: =AVERAGE(N18:N19) -> 25.365
A11: 1 | B11: 500 | C11: 1.11 | D11: 1.65 | E11: 1.33 | F11: 12.47 | G11: 12.9 | H11: 12.61 | I11: 0 | J11: 0.02 | K11: 0 | L11: 13.72 | M11: 14.33 | N11: 13.94 | P11: =P10+100 -> 1000 | Q11: =AVERAGE(N20:N21) -> 27.41
A12: 0 | B12: 600 | C12: 1.07 | D12: 2.08 | E12: 1.45 | F12: 7.71 | G12: 7.93 | H12: 7.8 | I12: 11.26 | J12: 29.38 | K12: 11.66 | L12: 20.33 | M12: 39.37 | N12: 20.9 | P12: =P11+100 -> 1100 | Q12: =AVERAGE(N22:N23) -> 29.83
A13: 1 | B13: 600 | C13: 1.43 | D13: 2.17 | E13: 1.8 | F13: 14.83 | G13: 15.59 | H13: 14.97 | I13: 0 | J13: 0.07 | K13: 0 | L13: 16.48 | M13: 17.29 | N13: 16.77 | P13: =P12+100 -> 1200 | Q13: =AVERAGE(N24:N25) -> 32.155
A14: 0 | B14: 700 | C14: 1.6 | D14: 2.09 | E14: 1.81 | F14: 8.95 | G14: 9.16 | H14: 9.05 | I14: 11.86 | J14: 14.81 | K14: 12.15 | L14: 22.62 | M14: 25.6 | N14: 23.01 | P14: =P13+100 -> 1300 | Q14: =AVERAGE(N26:N27) -> 33.5
A15: 1 | B15: 700 | C15: 1.42 | D15: 1.82 | E15: 1.59 | F15: 17.22 | G15: 17.76 | H15: 17.37 | I15: 0 | J15: 0.06 | K15: 0 | L15: 18.72 | M15: 19.4 | N15: 18.96 | P15: =P14+100 -> 1400 | Q15: =AVERAGE(N28:N29) -> 36.635
A16: 0 | B16: 800 | C16: 1.74 | D16: 2.2 | E16: 1.93 | F16: 10.33 | G16: 10.52 | H16: 10.41 | I16: 12.74 | J16: 13.18 | K16: 12.88 | L16: 25.02 | M16: 25.51 | N16: 25.22 | P16: =P15+100 -> 1500 | Q16: =AVERAGE(N30:N31) -> 39.055
A17: 1 | B17: 800 | C17: 1.42 | D17: 1.81 | E17: 1.6 | F17: 19.33 | G17: 19.94 | H17: 19.52 | I17: 0 | J17: 0.05 | K17: 0 | L17: 20.79 | M17: 21.54 | N17: 21.12 | P17: =P16+100 -> 1600 | Q17: =AVERAGE(N32:N33) -> 41.01
A18: 0 | B18: 900 | C18: 0.7 | D18: 1.33 | E18: 0.97 | F18: 11.51 | G18: 11.7 | H18: 11.61 | I18: 13.33 | J18: 13.68 | K18: 13.48 | L18: 25.7 | M18: 26.45 | N18: 26.06 | P18: =P17+100 -> 1700 | Q18: =AVERAGE(N34:N35) -> 42.26
A19: 1 | B19: 900 | C19: 2.28 | D19: 2.95 | E19: 2.69 | F19: 21.89 | G19: 22.05 | H19: 21.96 | I19: 0 | J19: 0.09 | K19: 0.01 | L19: 24.22 | M19: 24.97 | N19: 24.67 | P19: =P18+100 -> 1800 | Q19: =AVERAGE(N36:N37) -> 46.105
A20: 0 | B20: 1000 | C20: 1.49 | D20: 2.24 | E20: 1.9 | F20: 12.5 | G20: 13.17 | H20: 12.68 | I20: 14 | J20: 16.98 | K20: 14.2 | L20: 28.24 | M20: 31.54 | N20: 28.78 | P20: 1900 | Q20: =AVERAGE(N38:N39) -> 48.815
A21: 1 | B21: 1000 | C21: 1.63 | D21: 2.26 | E21: 1.91 | F21: 23.95 | G21: 24.42 | H21: 24.13 | I21: 0 | J21: 0.04 | K21: 0 | L21: 25.74 | M21: 26.46 | N21: 26.04 | P21: 2000 | Q21: =AVERAGE(N40:N41) -> 50.13
A22: 0 | B22: 1100 | C22: 1.37 | D22: 1.82 | E22: 1.62 | F22: 14.14 | G22: 14.37 | H22: 14.26 | I22: 14.73 | J22: 15.17 | K22: 14.92 | L22: 30.51 | M22: 31.12 | N22: 30.8
A23: 1 | B23: 1100 | C23: 2.06 | D23: 2.53 | E23: 2.3 | F23: 26.33 | G23: 26.88 | H23: 26.55 | I23: 0 | J23: 0.03 | K23: 0 | L23: 28.39 | M23: 29.28 | N23: 28.86
